Workbook

Sheet 1
A4: صندوق سرمایه‌گذاری شاخصی هم ‏وزن تراز
A19: گزارش افشای پرتفوی ماهانه برای دوره منتهی به 31 مرداد 1405
A28: در راستای اجرای ابلاغیه 12020093 مورخ 1396/09/05 و ابلاغیه 12020268 مورخ 1402/12/01 سازمان بورس و اوراق بهادار

Sheet  سهام
A1: شاخصی هم ‏وزن تراز
A2: صورت وضعیت پرتفوی
A3: برای ماه منتهی به 1405/05/31
A4: 1- سرمایه گذاری ها
A5: 1-1-سرمایه‌گذاری در سهام و حق تقدم سهام
B7: 1405/04/31 | F7: تغییرات طی دوره | J7: 1405/05/31
A8: شرکت | B8: تعداد | C8: بهای تمام شده | D8: خالص ارزش فروش | E8: خرید طی دوره | H8: فروش طی دوره | J8: تعداد | K8: قیمت بازار هر سهم | L8: بهای تمام شده | M8: خالص ارزش فروش | N8: درصد به کل دارایی‌ها
E9: افزایش سرمایه | F9: تعداد | G9: بهای تمام شده | H9: تعداد | I9: مبلغ فروش
A10: آترا زيست آراي | B10: 6927544 | C10: 30497945722 | D10: 31139193205 | E10: 0 | F10: 0 | G10: 0 | H10: 900000 | I10: 5126066842 | J10: 6027544 | K10: 7040 | L10: 26535769350 | M10: 42105895638 | N10: =M10/10876635978211 -> 0.0038712241
A11: آريان كيميا تك | B11: 6142935 | C11: 44945848553 | D11: 91980342197 | E11: 0 | F11: 0 | G11: 0 | H11: 2900000 | I11: 46043070060 | J11: 3242935 | K11: 16970 | L11: 23727495957 | M11: 54607204898 | N11: =M11/10876635978211 -> 0.0050205969
A12: آلوميناي ايران | B12: 158909 | C12: 18355763158 | D12: 20167353016 | E12: 0 | F12: 0 | G12: 0 | H12: 0 | I12: 0 | J12: 158909 | K12: 193500 | L12: 18355763158 | M12: 30511202569 | N12: =M12/10876635978211 -> 0.0028052058
A13: آلومينيوم ايران | B13: 4862943 | C13: 35264692153 | D13: 55684567280 | E13: 0 | F13: 0 | G13: 0 | H13: 0 | I13: 0 | J13: 4862943 | K13: 14690 | L13: 35264692153 | M13: 70884427499 | N13: =M13/10876635978211 -> 0.0065171279
A14: آنتي بيوتيك سازي ايران | B14: 112243 | C14: 1024541000 | D14: 1881129858 | E14: 0 | F14: 0 | G14: 0 | H14: 0 | I14: 0 | J14: 112243 | K14: 28640 | L14: 1024541000 | M14: 3189790357 | N14: =M14/10876635978211 -> 0.00029326994
A15: آهن و فولاد غدير ايرانيان | B15: 3814542 | C15: 16572695909 | D15: 14829847803 | E15: 0 | F15: 0 | G15: 0 | H15: 0 | I15: 0 | J15: 3814542 | K15: 4490 | L15: 16572695909 | M15: 16994899601 | N15: =M15/10876635978211 -> 0.0015625143
A16: اخشان خراسان | B16: 245000 | C16: 1829159370 | D16: 3388899731 | E16: 0 | F16: 0 | G16: 0 | H16: 0 | I16: 0 | J16: 245000 | K16: 18010 | L16: 1829159370 | M16: 4378341761 | N16: =M16/10876635978211 -> 0.00040254558
A17: ارتباطات سیار | B17: 9524125 | C17: 50137389582 | D17: 52639304572 | E17: 0 | F17: 0 | G17: 0 | H17: 0 | I17: 0 | J17: 9524125 | K17: 9020 | L17: 50137389582 | M17: 85243541694 | N17: =M17/10876635978211 -> 0.0078373076
A18: افست | B18: 3135450 | C18: 33774231367 | D18: 48068240410 | E18: 0 | F18: 0 | G18: 0 | H18: 800000 | I18: 19019831409 | J18: 2335450 | K18: 24090 | L18: 25156844678 | M18: 55826093043 | N18: =M18/10876635978211 -> 0.0051326617
A19: اقتصاد نوين | B19: 10967693 | C19: 14347988206 | D19: 30308911962 | E19: 0 | F19: 0 | G19: 0 | H19: 1200000 | I19: 3988925420 | J19: 9767693 | K19: 3390 | L19: 12778142492 | M19: 32856519805 | N19: =M19/10876635978211 -> 0.0030208347
A20: البرز دارو | B20: 12621427 | C20: 57822572358 | D20: 129621985872 | E20: 0 | F20: 0 | G20: 0 | H20: 1000000 | I20: 12194998362 | J20: 11621427 | K20: 15520 | L20: 53241270073 | M20: 178970329091 | N20: =M20/10876635978211 -> 0.016454566
A21: املاح ايران | B21: 1405609 | C21: 22200418339 | D21: 40489407940 | E21: 0 | F21: 0 | G21: 0 | H21: 60000 | I21: 2052830592 | J21: 1345609 | K21: 34770 | L21: 21252768530 | M21: 46425162773 | N21: =M21/10876635978211 -> 0.0042683384
... A232: گلتاش (تقدم) | B232: 0 | C232: 0 | D232: 0 | E232: 21654910 | F232: 0 | G232: 0 | H232: 0 | I232: 0 | J232: 21654910 | K232: 1332 | L232: 14055549690 | M232: 28621373371 | N232: =M232/10876635978211 -> 0.0026314546
A233: جمع | B233: =SUM(B10:B232) -> 1959687994 | C233: =SUM(C10:C232) -> 6897565486059 | D233: =SUM(D10:D232) -> 9010220177209 | E233: =SUM(E10:E232) -> 36456909 | F233: =SUM(F10:F232) -> 0 | G233: =SUM(G10:G232) -> 0 | H233: =SUM(H10:H232) -> 176840635 | I233: =SUM(I10:I232) -> 1116140482473 | J233: =SUM(J10:J232) -> 1819304268 | L233: =SUM(L10:L232) -> 6197818746650 | M233: =SUM(M10:M232) -> 10156499374743 | N233: =SUM(N10:N232) -> 0.9337905

Sheet اوراق مشتقه
A1: شاخصی هم ‏وزن تراز
A2: صورت وضعیت پرتفوی
A3: برای ماه منتهی به 1405/05/31
A4: اطلاعات آماری مرتبط با اوراق اختیار فروش تبعی خریداری شده توسط صندوق سرمایه گذاری:
B6: 1405/04/31 | F6: 1405/05/31
A7: نام سهام | B7: تعداد اوراق تبعی | C7: قیمت اعمال | D7: تاریخ اعمال | E7: نرخ سود مؤثر | F7: تعداد اوراق تبعی | G7: قیمت اعمال | H7: تاریخ اعمال | I7: نرخ سود مؤثر
A10: اطلاعات آماری مرتبط با موقعیت های اخذ شده در اوراق اختیار معامله توسط صندوق سرمایه گذاری:
B12: 1405/04/31 | H12: 1405/05/31
A13: نام سهام | B13: نوع اختیار | C13: نوع موقعیت | D13: استراتژی ماخوذه | E13: تعداد اوراق | F13: قیمت اعمال | G13: تاریخ اعمال | H13: نوع اختیار | I13: نوع موقعیت | J13: استراتژی ماخوذه | K13: تعداد اوراق | L13: قیمت اعمال | M13: تاریخ اعمال
A16: اطلاعات آماری مرتبط با قراردادهای آتی توسط صندوق سرمایه گذاری:
B18: 1405/04/31 | F18: 1405/05/31
A19: نام سهام | B19: نوع موقعیت | C19: تعداد اوراق | D19: قیمت اعمال | E19: تاریخ اعمال | F19: نوع موقعیت | G19: تعداد اوراق | H19: قیمت اعمال | I19: تاریخ اعمال

Sheet واحدهای صندوق
A1: شاخصی هم ‏وزن تراز
A2: صورت وضعیت پرتفوی
A3: برای ماه منتهی به 1405/05/31
A4: 2-1-سرمایه‌گذاری در واحدهای صندوق های سرمایه گذاری
B6: 1405/04/31 | E6: تغییرات طی دوره | I6: 1405/05/31
A7: صندوق | B7: تعداد واحد | C7: بهای تمام شده | D7: خالص ارزش فروش | E7: خرید/صدور طی دوره | G7: فروش /ابطال طی دوره | I7: تعداد | J7: قیمت ابطال/ بازار هر واحد | K7: بهای تمام شده | L7: خالص ارزش فروش | M7: درصد به کل دارایی‌ها
E8: تعداد | F8: بهای تمام شده | G8: تعداد | H8: مبلغ فروش

Sheet اوراق
A1: شاخصی هم ‏وزن تراز
A2: صورت وضعیت پرتفوی
A3: برای ماه منتهی به 1405/05/31
A4: 3-1-سرمایه‌گذاری در اوراق بهادار با درآمد ثابت یا علی‌الحساب
A6: اطلاعات اوراق بهادار با درآمد ثابت | H6: 1405/04/31 | K6: تغییرات طی دوره | O6: 1405/05/31
A7: نام اوراق | B7: دارای مجوز از سازمان | C7: پذیرفته شده در بورس یا فرابورس | D7: تاریخ انتشار اوراق | E7: تاریخ سررسید | F7: نرخ سود اسمی | G7: نرخ سود مؤثر | H7: تعداد | I7: بهای تمام شده | J7: خالص ارزش فروش | K7: خرید طی دوره | M7: فروش طی دوره | O7: تعداد | P7: قیمت بازار هر ورقه | Q7: بهای تمام شده | R7: خالص ارزش فروش | S7: درصد به کل دارایی‌ها
K8: تعداد | L8: بهای تمام شده | M8: تعداد | N8: مبلغ فروش

Sheet گواهی سپرده کالا
A1: شاخصی هم ‏وزن تراز
A2: صورت وضعیت پرتفوی
A3: برای ماه منتهی به 1405/05/31
A4: 3-1-سرمایه‌گذاری در اوراق بهادار با درآمد ثابت یا علی‌الحساب
A6: اطلاعات اوراق بهادار با درآمد ثابت | H6: 1405/04/31 | K6: تغییرات طی دوره | O6: 1405/05/31
A7: نام اوراق | B7: دارای مجوز از سازمان | C7: پذیرفته شده در بورس یا فرابورس | D7: تاریخ انتشار اوراق | E7: تاریخ سررسید | F7: نرخ سود اسمی | G7: نرخ سود مؤثر | H7: تعداد | I7: بهای تمام شده | J7: خالص ارزش فروش | K7: خرید طی دوره | M7: فروش طی دوره | O7: تعداد | P7: قیمت بازار هر ورقه | Q7: بهای تمام شده | R7: خالص ارزش فروش | S7: درصد به کل دارایی‌ها
K8: تعداد | L8: بهای تمام شده | M8: تعداد | N8: مبلغ فروش

Sheet تعدیل قیمت
A1: شاخصی هم ‏وزن تراز
A2: صورت وضعیت پرتفوی
A3: برای ماه منتهی به 1405/05/31
A4: اوراق بهاداری که ارزش آنها در تاریخ گزارش تعدیل شده
A5: (بر اساس دستورالعمل نحوه تعیین قیمت خرید و فروش اوراق بهادار در صندوق های سرمایه گذاری)
B6: 1405/05/31
A7: نام اوراق بهادار | B7: تعداد | C7: قیمت پایانی | D7: قیمت تعدیل شده | E7: درصد تعدیل | F7: خالص ارزش فروش تعدیل شده | G7: دلیل تعدیل
A9: فولاد خوزستان | B9: 8858150 | C9: 1918 | D9: 800 | E9: -0.58289885 | F9: 7031741200 | G9: -
A10: فجر انرژي خليج فارس | B10: 1200163 | C10: 11080 | D10: 5540 | E10: -0.5 | F10: 6597507000 | G10: -

Sheet سپرده
A1: شاخصی هم ‏وزن تراز
A2: صورت وضعیت پرتفوی
A3: برای ماه منتهی به 1405/05/31
A4: 2-1- سرمایه‌گذاری در سپرده‌ بانکی
B6: 1405/04/31 | C6: تغییرات طی دوره | E6: 1405/05/31
A7: سپرده های بانکی | B7: مبلغ | C7: افزایش | D7: کاهش | E7: مبلغ | F7: درصد به کل دارایی‌ها
A9: سامان | B9: 9812 | E9: 9812 | F9: =E9/10876635978211 -> 9.0211716e-10
A10: سپه | B10: 14928174 | C10: 63126 | D10: 0 | E10: 14991300 | F10: =E10/10876635978211 -> 1.378303e-06
A11: ملت | B11: 6845079 | C11: 29068 | D11: 0 | E11: 6874147 | F11: =E11/10876635978211 -> 6.3201039e-07
A12: پاسارگاد | B12: 11254740 | C12: 1834243732 | D12: 1840049000 | E12: 5449472 | F12: =E12/10876635978211 -> 5.010255e-07
A13: دي | B13: 50358082348 | C13: 958871410930 | D13: 932725527000 | E13: 76503966278 | F13: =E13/10876635978211 -> 0.0070337893
A14: خاورميانه | B14: 7005130 | C14: 412541 | D14: 0 | E14: 7417671 | F14: =E14/10876635978211 -> 6.819821e-07
A15: جمع | B15: =SUM(B9:B14) -> 50398125283 | C15: =SUM(C9:C14) -> 960706159397 | D15: =SUM(D9:D14) -> 934565576000 | E15: =SUM(E9:E14) -> 76538708680 | F15: =SUM(F9:F14) -> 0.0070369836

Sheet درآمدها
A1: شاخصی هم ‏وزن تراز
A2: صورت وضعیت درآمدها
A3: برای ماه منتهی به 1405/05/31
A4: 2- درآمد حاصل از سرمایه گذاری ها
A5: شرح | B5: یادداشت | C5: مبلغ | D5: درصد از کل درآمدها | E5: درصد از کل دارایی ها
A6: درآمد حاصل از سرمایه گذاری در سهام و حق تقدم سهام | B6: 1-2 | C6: ='درآمد سرمایه گذاری در سهام '!J232 -> 5086586415979 | D6: =C6/$C$11 -> 0.99903957 | E6: =C6/10876635978211 -> 0.46766173
A7: درآمد حاصل از سرمایه گذاری در واحدهای صندوق های سرمایه گذاری | B7: 2-2 | C7: 0 | D7: =C7/$C$11 -> 0 | E7: =C7/10876635978211 -> 0
A8: درآمد حاصل از سرمایه گذاری در اوراق بهادار با درآمد ثابت | B8: 3-2 | C8: 0 | D8: =C8/$C$11 -> 0 | E8: =C8/10876635978211 -> 0
A9: درآمد حاصل از سرمایه گذاری در سپرده بانکی و گواهی سپرده | B9: 2-2 | C9: ='درآمد سپرده بانکی'!D14 -> 4890016193 | D9: =C9/$C$11 -> 0.00096043186 | E9: =C9/10876635978211 -> 0.00044958903
A10: سایر درآمدها | B10: 3-2 | C10: ='سایر درآمدها'!C9 -> -3469 | D10: =C10/$C$11 -> -6.8133479e-10 | E10: =C10/10876635978211 -> -3.1894053e-10
A11: جمع | C11: =SUM(C6:C10) -> 5091476428703 | D11: =SUM(D6:D10) -> 1 | E11: =SUM(E6:E10) -> 0.46811132

Sheet درآمد سرمایه گذاری در سهام 
A1: شاخصی هم ‏وزن تراز
A2: صورت وضعیت درآمدها
A3: برای ماه منتهی به 1405/05/31
A5: 1-2-درآمد حاصل از سرمایه­گذاری در سهام و حق تقدم سهام:
B7: طی دوره | G7: 1405/05/31
A8: سهام | B8: درآمد سود سهام | C8: درآمد تغییر ارزش | D8: درآمد فروش | E8: جمع | G8: درآمد سود سهام | H8: درآمد تغییر ارزش | I8: درآمد فروش | J8: جمع
E10: مبلغ | F10: درصد از کل درآمد ها | J10: مبلغ | K10: درصد از کل درآمد ها
A11: لامپ پارس شهاب | B11: 0 | C11: 12339229187 | D11: 2952709025 | E11: 15291938212 | F11: 0.0063935055 | G11: 3282166800 | H11: 17534244271 | I11: 2985679243 | J11: 23802090314 | K11: =J11/درآمدها!$C$11 -> 0.0046748896
A12: عمران فارس | B12: 0 | C12: 7444598577 | D12: -5826902 | E12: 7438771675 | F12: 0.0031101243 | G12: 0 | H12: 3448763635 | I12: -80100604 | J12: 3368663031 | K12: =J12/درآمدها!$C$11 -> 0.00066162793
A13: داروسازي زاگرس | B13: 0 | C13: 6939612900 | D13: 0 | E13: 6939612900 | F13: 0.0029014277 | G13: 6704361535 | H13: 9803490937 | I13: 3845973021 | J13: 20353825493 | K13: =J13/درآمدها!$C$11 -> 0.0039976274
A14: چادرملو | B14: 0 | C14: 11778559296 | D14: 144607093 | E14: 11923166389 | F14: 0.0049850339 | G14: 2864396600 | H14: 2642060483 | I14: -145896556 | J14: 5360560527 | K14: =J14/درآمدها!$C$11 -> 0.0010528499
A15: سرمايه گذاري سپه | B15: 0 | C15: 12407211645 | D15: -82497829 | E15: 12324713816 | F15: 0.0051529195 | G15: 0 | H15: 4503637792 | I15: -82497829 | J15: 4421139963 | K15: =J15/درآمدها!$C$11 -> 0.00086834144
A16: نفت بندر عباس | B16: 4239518613 | C16: 3431913137 | D16: 0 | E16: 7671431750 | F16: 0.0032073986 | G16: 4239518613 | H16: 18079459929 | I16: 203010820 | J16: 22521989362 | K16: =J16/درآمدها!$C$11 -> 0.0044234692
A17: نفت و گاز پارسيان | B17: 0 | C17: 2933740739 | D17: 0 | E17: 2933740739 | F17: 0.0012265867 | G17: 0 | H17: 1190924458 | I17: 0 | J17: 1190924458 | K17: =J17/درآمدها!$C$11 -> 0.00023390552
A18: برق مپنا | B18: 0 | C18: 23046752664 | D18: 0 | E18: 23046752664 | F18: 0.0096357662 | G18: 926433360 | H18: 18990542637 | I18: 0 | J18: 19916975997 | K18: =J18/درآمدها!$C$11 -> 0.0039118272
A19: آلومينيوم ايران | B19: 0 | C19: 15199860219 | D19: 0 | E19: 15199860219 | F19: 0.0063550081 | G19: 3890354400 | H19: 36271178839 | I19: 0 | J19: 40161533239 | K19: =J19/درآمدها!$C$11 -> 0.0078879936
A20: بانك تجارت | B20: 325961964 | C20: 11572045947 | D20: 0 | E20: 11898007911 | F20: 0.0049745152 | G20: 325961964 | H20: 17036690274 | I20: -372 | J20: 17362651866 | K20: =J20/درآمدها!$C$11 -> 0.0034101409
A21: حفاري شمال | B21: 0 | C21: 12051301689 | D21: 404038812 | E21: 12455340501 | F21: 0.005207534 | G21: 4794689120 | H21: 18349923278 | I21: 5682990991 | J21: 28827603389 | K21: =J21/درآمدها!$C$11 -> 0.005661934
A22: پاكديس | B22: 0 | C22: 2792178844 | D22: 3155884705 | E22: 5948063549 | F22: 0.0024868644 | G22: 5115878400 | H22: 20507240628 | I22: 6467131705 | J22: 32090250733 | K22: =J22/درآمدها!$C$11 -> 0.0063027397
... A231: شركت شيرين دارو | B231: 0 | C231: 0 | D231: 0 | E231: 0 | F231: 0 | G231: 0 | H231: 0 | I231: 32508649 | J231: 32508649 | K231: =J231/درآمدها!$C$11 -> 6.3849159e-06
A232: جمع | B232: =SUM(B11:B231) -> 125711995601 | C232: =SUM(C11:C231) -> 1854474887097 | D232: =SUM(D11:D231) -> 410815547068 | E232: =SUM(E11:E231) -> 2391002429766 | F232: =SUM(F11:F231) -> 0.9996697 | G232: =SUM(G11:G231) -> 565111312891 | H232: =SUM(H11:H231) -> 3914360703559 | I232: =SUM(I11:I231) -> 607114399529 | ... K232: =SUM(K11:K231) -> 0.99903957

Sheet درآمد سرمایه گذاری در صندوق
A1: شاخصی هم ‏وزن تراز
A2: صورت وضعیت درآمدها
A3: برای ماه منتهی به 1405/05/31
A5: 2-2-درآمد حاصل از سرمایه­گذاری در واحدهای صندوق:
B7: طی دوره | G7: 1405/05/31
A8: صندوق | B8: درآمد سود صندوق | C8: درآمد تغییر ارزش | D8: درآمد فروش | E8: جمع | G8: درآمد سود صندوق | H8: درآمد تغییر ارزش | I8: درآمد فروش | J8: جمع
B10: یادداشت ... | C10: یادداشت ... | D10: یادداشت ... | E10: مبلغ | F10: درصد از کل درآمد ها | G10: یادداشت ... | H10: یادداشت ... | I10: یادداشت ... | J10: مبلغ | K10: درصد از کل درآمد ها

Sheet درآمد سرمایه گذاری در اوراق بها
A1: شاخصی هم ‏وزن تراز
A2: صورت وضعیت درآمدها
A3: برای ماه منتهی به 1405/05/31
A4: 3-2-درآمد حاصل از سرمایه­گذاری در اوراق بهادار با درآمد ثابت:
C6: طی دوره | H6: 1405/05/31
B7: درآمد سود اوراق | C7: درآمد تعهد پذیره نویسی | D7: درآمد تغییر ارزش | E7: درآمد فروش | F7: جمع | G7: درآمد سود اوراق | H7: درآمد تعهد پذیره نویسی | I7: درآمد تغییر ارزش | J7: درآمد فروش | K7: جمع
B9: یادداشت ... | C9: یادداشت ... | D9: یادداشت .... | E9: یادداشت ... | G9: یادداشت ... | H9: یادداشت ... | I9: یادداشت ... | J9: یادداشت ...

Sheet درآمد سپرده بانکی
A1: شاخصی هم ‏وزن تراز
A2: صورت وضعیت درآمدها
A3: برای ماه منتهی به 1405/05/31
A4: 2-2-درآمد حاصل از سرمایه­گذاری در سپرده بانکی و گواهی سپرده:
A6: نام سپرده بانکی | B6: طی دوره | D6: 1405/05/31
A7: نام سپرده | B7: سود سپرده بانکی و گواهی سپرده | C7: درصد سود به میانگین سپرده | D7: سود سپرده بانکی و گواهی سپرده | E7: درصد سود به میانگین سپرده
A8: سپه | B8: 63126 | C8: =B8/$B$14 -> 7.9904668e-05 | D8: 382530 | E8: =D8/$D$14 -> 7.8226735e-05
A9: ملت | B9: 29068 | C9: =B9/$B$14 -> 3.6794172e-05 | D9: 123458 | E9: =D9/$D$14 -> 2.5246951e-05
A10: پاسارگاد | B10: 3732 | C10: =B10/$B$14 -> 4.7239524e-06 | D10: 6829014 | E10: =D10/$D$14 -> 0.0013965218
A11: دي | B11: 789507957 | C11: =B11/$B$14 -> 0.99935638 | D11: 4879334003 | E11: =D11/$D$14 -> 0.99781551
A12: خاورميانه | B12: 412541 | C12: =B12/$B$14 -> 0.00052219294 | D12: 3344087 | E12: =D12/$D$14 -> 0.00068386011
A13: سامان | C13: =B13/$B$14 -> 0 | D13: 3101 | E13: =D13/$D$14 -> 6.3414923e-07
A14: جمع | B14: =SUM(B8:B13) -> 790016424 | C14: =SUM(C8:C13) -> 1 | D14: =SUM(D8:D13) -> 4890016193 | E14: =SUM(E8:E13) -> 1

Sheet سایر درآمدها
A1: شاخصی هم ‏وزن تراز
A2: صورت وضعیت درآمدها
A3: برای ماه منتهی به 1405/05/31
A4: 3-2-سایر درآمدها:
B5: طی دوره | C5: 1405/05/31
A6: سایر درآمدها | B6: مبلغ | C6: مبلغ
A8: كاريزما | B8: -8134 | C8: -3469
A9: جمع | B9: =SUM(B8:B8) -> -8134 | C9: =SUM(C8:C8) -> -3469

Sheet درآمد سود سهام
A1: شاخصی هم ‏وزن تراز
A2: صورت وضعیت درآمدها
A3: برای ماه منتهی به 1405/05/31
A4: درآمد سود سهام
B5: اطلاعات مجمع | E5: طی دوره | H5: 1405/05/31
A6: نام سهام | B6: تاریخ تشکیل مجمع | C6: تعداد سهام متعلقه در زمان مجمع | D6: سود متعلق به هر سهم | E6: جمع درآمد سود سهام | F6: هزینه تنزیل | G6: خالص درآمد سود سهام | H6: جمع درآمد سود سهام | I6: هزینه تنزیل | J6: خالص درآمد سود سهام
A7: آترا زيست آراي | B7: 1405/04/31 | C7: 6927544 | D7: 57 | E7: 394870008 | F7: -22447391 | G7: 372422617 | H7: 394870008 | I7: -22447391 | J7: 372422617
A8: آريان كيميا تك | B8: 1405/03/16 | C8: 5542935 | D8: 1000 | H8: 5542935000 | I8: -60086016 | J8: 5482848984
A9: آلوميناي ايران | B9: 1405/04/11 | C9: 158909 | D9: 1640 | H9: 260610760 | I9: -10780353 | J9: 249830407
A10: آلومينيوم ايران | B10: 1405/04/30 | C10: 4862943 | D10: 800 | H10: 3890354400 | I10: -83439236 | J10: 3806915164
A11: آنتي بيوتيك سازي ايران | B11: 1405/04/17 | C11: 50000 | D11: 1870 | H11: 93500000 | I11: -4452381 | J11: 89047619
A12: آهن و فولاد غدير ايرانيان | B12: 1405/04/24 | C12: 3814542 | D12: 762 | H12: 2906681004 | I12: -138413381 | J12: 2768267623
A13: ارتباطات سیار | B13: 1405/03/27 | C13: 10724125 | D13: 810 | H13: 8686541250 | I13: 0 | J13: 8686541250
A14: اقتصاد نوين | B14: 1405/04/30 | C14: 8948358 | D14: 126 | H14: 1127493108 | I14: 0 | J14: 1127493108
A15: البرز دارو | B15: 1405/02/30 | C15: 8421427 | D15: 180 | H15: 1515856860 | I15: -25519476 | J15: 1490337384
A16: املاح ايران | B16: 1405/03/24 | C16: 1505609 | D16: 1910 | H16: 2875713190 | I16: -104398829 | J16: 2771314361
A17: انتقال داده هاي آسياتك | B17: 1405/05/28 | C17: 10003637 | D17: 260 | E17: 2600945620 | F17: -152602225 | G17: 2448343395 | H17: 2600945620 | I17: -152602225 | J17: 2448343395
A18: ايران ترانسفو | B18: 1405/04/22 | C18: 28071939 | D18: 210 | H18: 5895107190 | I18: -313488190 | J18: 5581619000
A19: ايمن خودرو شرق | B19: 1405/03/27 | C19: 1750000 | D19: 570 | H19: 997500000 | I19: -38112648 | J19: 959387352
A20: ایرکا پارت صنعت | B20: 1405/04/31 | C20: 31353305 | D20: 50 | E20: 1567665250 | F20: 0 | G20: 1567665250 | H20: 1567665250 | I20: 0 | J20: 1567665250
A21: بانك تجارت | B21: 1405/04/31 | C21: 36217996 | D21: 9 | E21: 325961964 | F21: 0 | G21: 325961964 | H21: 325961964 | I21: 0 | J21: 325961964
A22: بانك خاورميانه | B22: 1405/04/31 | C22: 6800000 | D22: 166 | E22: 1128800000 | F22: 0 | G22: 1128800000 | H22: 1128800000 | I22: 0 | J22: 1128800000
A23: بانك سينا | B23: 1405/04/31 | C23: 6075143 | D23: 125 | E23: 759392875 | F23: 0 | G23: 759392875 | H23: 759392875 | I23: 0 | J23: 759392875
A24: بانك ملت | B24: 1405/04/31 | C24: 43696139 | D24: 46 | E24: 2010022394 | F24: 0 | G24: 2010022394 | H24: 2010022394 | I24: 0 | J24: 2010022394
A25: بهار رز عاليس چناران | B25: 1405/04/28 | C25: 14703159 | D25: 424 | H25: 6234139416 | I25: -365768335 | J25: 5868371081
A26: بهمن دیزل | B26: 1405/04/06 | C26: 16845192 | D26: 290 | H26: 4885105680 | I26: -202075941 | J26: 4683029739
A27: بيمه آسيا | B27: 1405/04/28 | C27: 9210264 | D27: 161 | H27: 1482852504 | I27: -22012655 | J27: 1460839849
A28: بيمه البرز | B28: 1405/04/31 | C28: 16851248 | D28: 120 | E28: 2022149760 | F28: 0 | G28: 2022149760 | H28: 2022149760 | I28: 0 | J28: 2022149760
A29: بيمه ايران - معين | B29: 1405/03/13 | C29: 2875000 | D29: 116 | H29: 333500000 | I29: 0 | J29: 333500000
A30: بيمه زندگي كاريزما | B30: 1405/04/30 | C30: 6000000 | D30: 110 | E30: 660000000 | F30: 0 | G30: 660000000 | H30: 660000000 | I30: 0 | J30: 660000000
A31: بيمه پارسيان | B31: 1405/03/05 | C31: 9863245 | D31: 240 | H31: 2367178800 | I31: 0 | J31: 2367178800
A32: تامين سرمايه لوتوس پارسيان | B32: 1405/01/30 | C32: 3665469 | D32: 615 | H32: 2254263435 | I32: 0 | J32: 2254263435
A33: تامين سرمايه نوين | B33: 1405/03/05 | C33: 29417878 | D33: 390 | H33: 11472972420 | I33: 0 | J33: 11472972420
A34: تايدواتر | B34: 1405/04/29 | C34: 5838695 | D34: 850 | H34: 4962890750 | I34: -67066091 | J34: 4895824659
A35: تجارت الکترونیک پارسیان | B35: 1405/01/26 | C35: 5516183 | D35: 270 | H35: 1489369410 | I35: 0 | J35: 1489369410
A36: تراكتور سازي | B36: 1405/04/17 | C36: 14328056 | D36: 215 | H36: 3080532040 | I36: -125488165 | J36: 2955043875
A37: توزيع دارو پخش | B37: 1405/04/29 | C37: 13400000 | D37: 330 | H37: 4422000000 | I37: -259446809 | J37: 4162553191
A38: توسعه سامانه ي نرم افزاري نگين | B38: 1405/02/05 | C38: 7357161 | D38: 1000 | H38: 7357161000 | I38: 0 | J38: 7357161000
A39: توسعه نيشكر و صنايع جانبي | B39: 1405/01/16 | C39: 285750 | D39: 4000 | H39: 1143000000 | I39: 0 | J39: 1143000000
A40: توسعه و عمران اميد | B40: 1405/01/30 | C40: 11278863 | D40: 160 | H40: 1804618080 | I40: 0 | J40: 1804618080
...

Sheet درآمد سود صندوق
A1: شاخصی هم ‏وزن تراز
A2: صورت وضعیت درآمدها
A3: برای ماه منتهی به 1405/05/31
A4: درآمد سود صندوق
E5: طی دوره | F5: 1405/05/31
A6: نام صندوق | B6: تاریخ تقسیم سود | C6: تعداد واحد صندوق در زمان تقسیم سود | D6: سود متعلق به هر واحد | E6: خالص درآمد سود صندوق | F6: خالص درآمد سود صندوق

Sheet سود اوراق بهادار
A1: شاخصی هم ‏وزن تراز
A2: صورت وضعیت درآمدها
A3: برای ماه منتهی به 1405/05/31
A4: سود اوراق بهادار با درآمد ثابت
E5: طی دوره | H5: 1405/05/31
A6: شرح | B6: تاریخ دریافت سود | C6: تاریخ سررسید | D6: نرخ سود علی الحساب | E6: درآمد سود | F6: هزینه تنزیل | G6: خالص درآمد | H6: درآمد سود | I6: هزینه تنزیل | J6: خالص درآمد

Sheet سود  سپرده بانکی
A1: شاخصی هم ‏وزن تراز
A2: صورت وضعیت درآمدها
A3: برای ماه منتهی به 1405/05/31
A4: سود سپرده بانکی
B5: طی دوره | E5: 1405/05/31
A6: شرح | B6: درآمد سود | C6: هزینه تنزیل | D6: خالص درآمد | E6: درآمد سود | F6: هزینه تنزیل | G6: خالص درآمد
A7: پاسارگاد | B7: 3732 | C7: 0 | D7: 3732 | E7: 6829014 | F7: 0 | G7: 6829014
A8: سپه | B8: 63126 | C8: 0 | D8: 63126 | E8: 382530 | F8: 0 | G8: 382530
A9: ملت | B9: 29068 | C9: 0 | D9: 29068 | E9: 123458 | F9: 0 | G9: 123458
A10: خاورميانه | B10: 412541 | C10: 0 | D10: 412541 | E10: 3344087 | F10: 0 | G10: 3344087
A11: دي | B11: 789507957 | C11: 0 | D11: 789507957 | E11: 4879334003 | F11: 0 | G11: 4879334003
A12: سامان | E12: 3101 | F12: 0 | G12: 3101
A13: جمع | B13: =SUM(B7:B12) -> 790016424 | C13: =SUM(C7:C12) -> 0 | D13: =SUM(D7:D12) -> 790016424 | E13: =SUM(E7:E12) -> 4890016193 | F13: =SUM(F7:F12) -> 0 | G13: =SUM(G7:G12) -> 4890016193

Sheet درآمد ناشی ازفروش
A1: شاخصی هم ‏وزن تراز
A2: صورت وضعیت درآمدها
A3: برای ماه منتهی به 1405/05/31
A4: سود(زیان) حاصل از فروش اوراق بهادار
B5: طی دوره | F5: 1405/05/31
A6: شرح | B6: تعداد | C6: خالص بهای فروش | D6: ارزش دفتری | E6: سود و زیان ناشی از فروش | F6: تعداد | G6: خالص ارزش فروش | H6: ارزش دفتری | I6: سود و زیان ناشی از فروش
A7: سيمان اردستان | B7: 200000 | C7: 5135910694 | D7: 6769742720 | E7: -1633832026 | F7: 200000 | G7: 5135910694 | H7: 6769742720 | I7: -1633832026
A8: منگنز ايران | B8: 2100000 | C8: 15411152580 | D8: 9440888451 | E8: 5970264129 | F8: 2100000 | G8: 15411152580 | H8: 9440888451 | I8: 5970264129
A9: بيمه پارسيان | B9: 0 | C9: 0 | D9: 0 | E9: 0 | F9: 400000 | G9: 491372117 | H9: 492307117 | I9: -935000
A10: پتروشيمي شازند | B10: 2200000 | C10: 41822708784 | D10: 27993503768 | E10: 13829205016 | F10: 37700000 | G10: 570682994509 | H10: 480844277993 | I10: 89838716516
A11: سيمان اروميه | B11: 10000 | C11: 1919050196 | D11: 1231539770 | E11: 687510426 | F11: 10000 | G11: 1919050196 | H11: 1231539770 | I11: 687510426
A12: پتروشيمي خراسان | B12: 810000 | C12: 36588718053 | D12: 38757564145 | E12: -2168846092 | F12: 1230000 | G12: 56296545914 | H12: 58848345993 | I12: -2551800079
A13: بانك تجارت | B13: 0 | C13: 0 | D13: 0 | E13: 0 | F13: 1 | G13: 1 | H13: 373 | I13: -372
A14: كشاورزي مكانيزه اصفهان كشت | B14: 100000 | C14: 2248148675 | D14: 1057114855 | E14: 1191033820 | F14: 100000 | G14: 2248148675 | H14: 1057114855 | I14: 1191033820
A15: پارس توشه | B15: 1800000 | C15: 14449435796 | D15: 11125795753 | E15: 3323640043 | F15: 3000000 | G15: 22202041324 | H15: 18557641252 | I15: 3644400072
A16: سيمان سپاهان | B16: 200000 | C16: 3645129409 | D16: 1884700359 | E16: 1760429050 | F16: 600000 | G16: 7693591019 | H16: 5679355089 | I16: 2014235930
A17: داروسازي‌ اكسير | B17: 337769 | C17: 8468814970 | D17: 2691185301 | E17: 5777629669 | F17: 437769 | G17: 10561512407 | H17: 3491168182 | I17: 7070344225
A18: حمل و نقل گهرترابر سيرجان | B18: 3600000 | C18: 10683771141 | D18: 6384143180 | E18: 4299627961 | F18: 4458894 | G18: 12420385421 | H18: 7913610986 | I18: 4506774435
... A146: آريان كيميا تك | B146: 2900000 | C146: 46043070060 | D146: 21817177049 | E146: 24225893011 | F146: 4300000 | G146: 56489688665 | H146: 31793444374 | I146: 24696244291
A147: جمع | B147: =SUM(B7:B146) -> 176840635 | C147: =SUM(C7:C146) -> 1116140482473 | D147: =SUM(D7:D146) -> 705324935405 | E147: =SUM(E7:E146) -> 410815547068 | F147: =SUM(F7:F146) -> 483858137 | G147: =SUM(G7:G146) -> 2529181213905 | H147: =SUM(H7:H146) -> 1922066814376 | I147: =SUM(I7:I146) -> 607114399529

Sheet درآمد ناشی از تغییر قیمت اوراق 
A1: شاخصی هم ‏وزن تراز
A2: صورت وضعیت درآمدها
A3: برای ماه منتهی به 1405/05/31
A4: درآمد ناشی از تغییر قیمت اوراق بهادار
B5: طی دوره | F5: 1405/05/31
A6: شرح | B6: تعداد | C6: خالص ارزش فروش | D6: ارزش دفتری | E6: سود و زیان ناشی از تغییر قیمت | F6: تعداد | G6: خالص ارزش فروش | H6: ارزش دفتری | I6: سود و زیان ناشی از تغییر قیمت
A7: آترا زيست آراي | B7: 6027544 | C7: 42105895638 | D7: 27530877108 | E7: 14575018530 | F7: 6027544 | G7: 42105895638 | H7: 24165871153 | I7: 17940024485
A8: آريان كيميا تك | B8: 3242935 | C8: 54607204898 | D8: 69804479818 | E8: -15197274920 | F8: 3242935 | G8: 54607204898 | H8: 24798234575 | I8: 29808970323
A9: آلوميناي ايران | B9: 158909 | C9: 30511202569 | D9: 20167353016 | E9: 10343849553 | F9: 158909 | G9: 30511202569 | H9: 17472590990 | I9: 13038611579
A10: آلومينيوم ايران | B10: 4862943 | C10: 70884427499 | D10: 55684567280 | E10: 15199860219 | F10: 4862943 | G10: 70884427499 | H10: 34613248660 | I10: 36271178839
A11: آنتي بيوتيك سازي ايران | B11: 112243 | C11: 3189790357 | D11: 1881129858 | E11: 1308660499 | F11: 112243 | G11: 3189790357 | H11: 1251567125 | I11: 1938223232
A12: آهن و فولاد غدير ايرانيان | B12: 3814542 | C12: 16994899601 | D12: 14829847803 | E12: 2165051798 | F12: 3814542 | G12: 16994899601 | H12: 15851812812 | I12: 1143086789
A13: اخشان خراسان | B13: 245000 | C13: 4378341761 | D13: 3388899731 | E13: 989442030 | F13: 245000 | G13: 4378341761 | H13: 2525872898 | I13: 1852468863
A14: ارتباطات سیار | B14: 9524125 | C14: 85243541694 | D14: 52639304572 | E14: 32604237122 | F14: 9524125 | G14: 85243541694 | H14: 49360527511 | I14: 35883014183
A15: افست | B15: 2335450 | C15: 55826093043 | D15: 39033772120 | E15: 16792320923 | F15: 2335450 | G15: 55826093043 | H15: 26374436210 | I15: 29451656833
A16: اقتصاد نوين | B16: 9767693 | C16: 32856519805 | D16: 28342612408 | E16: 4513907397 | F16: 9767693 | G16: 32856519805 | H16: 16005175324 | I16: 16851344481
A17: البرز دارو | B17: 11621427 | C17: 178970329091 | D17: 125665706334 | E17: 53304622757 | F17: 11621427 | G17: 178970329091 | H17: 45977613840 | I17: 132992715251
A18: املاح ايران | B18: 1345609 | C18: 46425162773 | D18: 39451096612 | E18: 6974066161 | F18: 1345609 | G18: 46425162773 | H18: 23286017796 | I18: 23139144977
... A231: گلتاش (تقدم) | B231: 21654910 | C231: 28621373371 | D231: 14055549690 | E231: 14565823681 | F231: 21654910 | G231: 28621373371 | H231: 14055549690 | I231: 14565823681
A232: جمع | B232: =SUM(B7:B231) -> 1819304268 | C232: =SUM(C7:C231) -> 10156499374743 | D232: =SUM(D7:D231) -> 8302024487646 | E232: =SUM(E7:E231) -> 1854474887097 | F232: =SUM(F7:F231) -> 1819304268 | G232: =SUM(G7:G231) -> 10156499374743 | H232: =SUM(H7:H231) -> 6242138671184 | I232: =SUM(I7:I231) -> 3914360703559
A234: ارزش دفتری برابر است با میانگین موزون خالص ارزش فروش هر سهم/ورقه در ابتدای دوره با خرید طی دوره ضربدر تعداد در پایان دوره
