Workbook

Sheet 1
E7: به ‌نام خدا
A13: صندوق سرمایه گذاری قابل معامله شاخصی شفق رابین
A15: صورت وضعیت پرتفوی
A18: برای ماه منتهی به 1404/08/30
G29: مدیر صندوق

Sheet  سهام
A1: صندوق سرمایه گذاری قابل معامله شاخصی شفق رابین
A2: صورت وضعیت پرتفوی
A3: برای ماه منتهی به 1404/08/30
A4: 1- سرمایه گذاری ها
A5: 1-1-سرمایه‌گذاری در سهام و حق تقدم سهام وصندوق‌های سرمایه‌گذاری
B7: 1404/08/01 | E7: تغییرات طی دوره | I7: 1404/08/30
A8: شرکت | B8: تعداد | C8: بهای تمام شده | D8: خالص ارزش فروش | E8: خرید طی دوره | G8: فروش طی دوره | I8: تعداد | J8: قیمت بازار هر سهم | K8: بهای تمام شده | L8: خالص ارزش فروش | M8: درصد به کل دارایی‌ها
E9: تعداد | F9: مبلغ خرید | G9: تعداد | H9: مبلغ فروش
A10: تاید واتر خاورمیانه (حتاید) | B10: 639981 | C10: 4987865166 | D10: 4306891978 | E10: 0 | F10: 0 | G10: 90000 | H10: 671878402 | I10: 549981 | J10: 7180 | K10: 4286425803 | L10: 3918338870 | M10: 0.56
A11: سر. توسعه معادن و صنایع معدنی خاورمیانه (میدکو) | B11: 1899810 | C11: 8420535011 | D11: 8107356821 | E11: 0 | F11: 0 | G11: 62139 | H11: 296542321 | I11: 1837671 | J11: 4952 | K11: 8145116088 | L11: 9029802661 | M11: 1.28
A12: پتروشیمی نوری (نوری) | B12: 797283 | C12: 39275066689 | D12: 35497829255 | E12: 0 | F12: 0 | G12: 79001 | H12: 3172344815 | I12: 718282 | J12: 41670 | K12: 35383387644 | L12: 29699445777 | M12: 4.22
A13: کشتیرانی ایران (حکشتی) | B13: 771260 | C13: 8380184225 | D13: 4285690910 | E13: 137245 | F13: 809150436 | G13: 52094 | H13: 300290223 | I13: 856411 | J13: 5770 | K13: 8623303340 | L13: 4903293744 | M13: 0.7
A14: سایپا (خساپا) | B14: 13200000 | C14: 6407940850 | D14: 6337665181 | E14: 0 | F14: 0 | G14: 0 | H14: 0 | I14: 13200000 | J14: 485 | K14: 6407940850 | L14: 6352512540 | M14: 0.9
A15: گروه صنعتی پاکشو (پاکشو) | B15: 945380 | C15: 3542993584 | D15: 5187447544 | E15: 0 | F15: 0 | G15: 221738 | H15: 1231553220 | I15: 723642 | J15: 5810 | K15: 2711987733 | L15: 4171860320 | M15: 0.59
A16: سر. غدیر (وغدیر) | B16: 1916392 | C16: 20864873307 | D16: 19202293839 | E16: 0 | F16: 0 | G16: 319426 | H16: 3507191896 | I16: 1596966 | J16: 11240 | K16: 17387096830 | L16: 17811145133 | M16: 2.53
A17: پالایش نفت اصفهان (شپنا) | B17: 7009844 | C17: 28917390138 | D17: 34143863599 | E17: 0 | F17: 0 | G17: 2245246 | H17: 11371202475 | I17: 4764598 | J17: 5233 | K17: 19655179091 | L17: 24740408155 | M17: 3.51
A18: گسترش نفت و گاز پارسیان (پارسان) | B18: 359008 | C18: 22837535009 | D18: 24042460067 | E18: 0 | F18: 0 | G18: 85388 | H18: 5467090066 | I18: 273620 | J18: 65450 | K18: 17405757891 | L18: 17769996847 | M18: 2.52
A19: موتوژن (بموتو) | B19: 5877132 | C19: 10567395005 | D19: 10527577847 | E19: 0 | F19: 0 | G19: 2294601 | H19: 4129541306 | I19: 3582531 | J19: 1860 | K19: 6441580722 | L19: 6611998749 | M19: 0.94
A20: پتروشیمی خارک (شخارک) | B20: 143181 | C20: 12974884880 | D20: 12581890059 | E20: 0 | F20: 0 | G20: 7925 | H20: 693250471 | I20: 135256 | J20: 87300 | K20: 12256731196 | L20: 11716574132 | M20: 1.66
A21: پتروشیمی پردیس (شپدیس) | B21: 57143 | C21: 16373068418 | D21: 16183174461 | E21: 0 | F21: 0 | G21: 5001 | H21: 1485969971 | I21: 52142 | J21: 299700 | K21: 14940141985 | L21: 15506161022 | M21: 2.2
... A68: بیمه اتکایی حامی ما (حامیا) | B68: 50000 | C68: 49863800 | D68: 49702500 | E68: 0 | F68: 0 | G68: 0 | H68: 0 | I68: 50000 | J68: 1000 | K68: 49863800 | L68: 49613500 | M68: 0.01
A69: جمع | C69: 808106868105 | D69: 763957617100 | F69: 7956452814 | H69: 112285293698 | J69: 1353578.1 | K69: 703657941797 | L69: 686855167642 | M69: 97.49

Sheet سپرده
A1: صندوق سرمایه گذاری قابل معامله شاخصی شفق رابین
A2: صورت وضعیت پرتفوی
A3: برای ماه منتهی به 1404/08/30
A4: 3-1- سرمایه‌گذاری در سپرده‌ بانکی
B6: مشخصات حساب بانکی | F6: 1404/08/01 | G6: تغییرات طی دوره | I6: 1404/08/30
A7: سپرده های بانکی | B7: شماره حساب | C7: نوع سپرده | D7: تاریخ افتتاح حساب | E7: نرخ سود علی الحساب | F7: مبلغ | G7: افزایش | H7: کاهش | I7: مبلغ | J7: درصد به کل
A8: جاری گردشگری | B8: 129.71.1709609.1 | C8: جاری | D8: - | E8: - | F8: 224018914 | G8: 107888355510 | H8: 108099000000 | I8: 13374424 | J8: 0
A9: بلند مدت گردشگری129.333.1709609.2 | B9: 129.333.1709609.2 | C9: سپرده سرمایه‌گذاری | D9: - | E9: - | F9: 0 | G9: 0 | H9: 0 | I9: 0 | J9: 0
A10: جمع | F10: 224018914 | G10: 107888355510 | H10: 108099000000 | I10: 13374424 | J10: 0

Sheet درآمدها
A1: صندوق سرمایه گذاری قابل معامله شاخصی شفق رابین
A2: صورت وضعیت درآمدها
A3: برای ماه منتهی به 1404/08/30
A4: 2- درآمد حاصل از سرمایه­گذاری در سهام و حق تقدم سهام و صندوق‌های سرمایه‌گذاری
A5: شرح | B5: یادداشت | C5: مبلغ | D5: درصد از کل درآمدها
A6: سود (زیان) فروش اوراق بهادار | C6: ='درآمد سرمایه گذاری در سهام'!I99 -> -35826002153 | D6: =C6/$C$11 -> -0.90524618
A7: درآمد سود سهام | B7: 2-2 | C7: ='درآمد سرمایه گذاری در سهام'!G99 -> 41012901106 | D7: =C7/$C$11 -> 1.036308
A8: درآمد (هزینه) ناشی از تغییر ارزش سرمایه‌گذاری‌ها | B8: 3-2 | C8: ='درآمد سرمایه گذاری در سهام'!H99 -> -1763712708 | D8: =C8/$C$11 -> -0.044565235
A9: درآمد حاصل از سرمایه گذاری در سپرده بانکی و گواهی سپرده | B9: 4-2 | C9: ='درآمد سپرده بانکی'!E9 -> 33252977 | D9: =C9/$C$11 -> 0.00084023136
A10: سایر درآمدها | B10: 5-2 | C10: ='سایر درآمدها'!C8 -> 293535671 | D10: =C10/$C$11 -> 0.0074170164
A11: جمع | C11: =SUBTOTAL(109,C7:C10) -> 39575977046 | D11: =C11/$C$11 -> 1

Sheet درآمد سود سهام
A1: صندوق سرمایه گذاری قابل معامله شاخصی شفق رابین
A2: صورت وضعیت درآمدها
A3: برای ماه منتهی به 1404/08/30
A4: درآمد سود سهام
B5: اطلاعات مجمع | E5: از 1404/08/01 تا 1404/08/30 | H5: از ابتدای سال مالی تا 1404/08/30
A6: نام سهام | B6: تاریخ تشکیل مجمع | C6: تعداد سهام متعلقه در زمان مجمع | D6: سود متعلق به هر سهم | E6: جمع درآمد سود سهام | F6: هزینه تنزیل | G6: خالص درآمد سود سهام | H6: جمع درآمد سود سهام | I6: هزینه تنزیل | J6: خالص درآمد سود سهام
A7: ارتباطات سیار (همراه) | B7: 1404/03/21 | C7: 532869 | D7: 637 | E7: 0 | H7: 339437553 | I7: 0 | J7: 339437553
A8: آلومینیوم ایران (فایرا) | B8: 1404/05/14 | C8: 663377 | D8: 320 | E8: 0 | H8: 212280640 | I8: 0 | J8: 212280640
A9: بانک اقتصاد نوین (ونوین) | B9: 1404/04/22 | C9: 2374690 | D9: 240 | E9: 0 | H9: 569925600 | I9: 0 | J9: 569925600
A10: بانک تجارت (وتجارت) | B10: 1404/04/31 | C10: 6537658 | D10: 11 | E10: 0 | H10: 71914238 | I10: 0 | J10: 71914238
A11: بانک ملت (وبملت) | B11: 1404/04/31 | C11: 7434657 | D11: 90 | E11: 0 | H11: 669119130 | I11: 0 | J11: 669119130
A12: بورس کالای ایران (کالا) | B12: 1404/04/31 | C12: 346358 | D12: 165 | E12: 0 | H12: 57149070 | I12: 0 | J12: 57149070
A13: پارس دارو (دپارس) | B13: 1404/04/23 | C13: 142765 | D13: 12050 | E13: 0 | H13: 1720318250 | I13: -123582938 | J13: 1596735312
A14: پارس سوئیچ (بسویچ) | B14: 1404/04/21 | C14: 1046788 | D14: 110 | E14: 0 | H14: 115146680 | I14: 0 | J14: 115146680
A15: پالایش نفت اصفهان (شپنا) | B15: 1404/04/30 | C15: 3835211 | D15: 360 | E15: 0 | H15: 1380675960 | I15: 0 | J15: 1380675960
A16: پالایش نفت بندر عباس (شبندر) | B16: 1404/05/08 | C16: 1205960 | D16: 936 | E16: 0 | H16: 1128778560 | I16: 0 | J16: 1128778560
A17: پالایش نفت تبریز (شبریز) | B17: 1404/04/28 | C17: 185793 | D17: 1997 | E17: 0 | H17: 371028621 | I17: 0 | J17: 371028621
A18: پالایش نفت تهران (شتران) | B18: 1404/05/12 | C18: 6683985 | D18: 190 | E18: 0 | H18: 1269957150 | I18: 0 | J18: 1269957150
... A52: همکاران سیستم (سیستم) | B52: 1404/04/17 | C52: 165309 | D52: 2000 | E52: 0 | H52: 330618000 | I52: 0 | J52: 330618000
H53: =SUBTOTAL(109,Table8[[#All],[1250379360.0000]]) -> 41012901106 | J53: =SUBTOTAL(109,Table8[[#All],[Column10]]) -> 39450098863

Sheet سود اوراق بهادار
A1: صندوق سرمایه گذاری قابل معامله شاخصی شفق رابین
A2: صورت وضعیت درآمدها
A3: برای ماه منتهی به 1404/08/30
A4: سود اوراق بهادار با درآمد ثابت
E5: از 1404/08/01 تا 1404/08/30 | H5: از ابتدای سال مالی تا 1404/08/30
A6: شرح | B6: تاریخ دریافت سود | C6: تاریخ سررسید | D6: نرخ سود علی الحساب | E6: درآمد سود | F6: هزینه تنزیل | G6: خالص درآمد | H6: درآمد سود | I6: هزینه تنزیل | J6: خالص درآمد
A7: بلند مدت گردشگری129.333.1709609.2 | B7: 1404/03/06 | C7: - | D7: - | E7: 0 | F7: 0 | G7: 0 | H7: 33252977 | I7: 547948 | J7: 33800925
A8: جمع | E8: 0 | F8: 0 | G8: 0 | H8: 33252977 | I8: 547948 | J8: 33800925

Sheet سود سپرده بانکی
A1: صندوق سرمایه گذاری قابل معامله شاخصی شفق رابین
A2: صورت وضعیت درآمدها
A3: برای ماه منتهی به 1404/08/30
A4: سود سپرده بانکی
B5: از 1404/08/01 تا 1404/08/30 | E5: از ابتدای سال مالی تا 1404/08/30
A6: شرح | B6: درآمد سود | C6: هزینه تنزیل | D6: خالص درآمد | E6: درآمد سود | F6: هزینه تنزیل | G6: خالص درآمد
A7: بلند مدت گردشگری129.333.1709609.2 | B7: 0 | C7: 0 | D7: 0 | E7: 33252977 | F7: 547948 | G7: 33800925
A8: جمع | B8: 0 | C8: 0 | D8: 0 | E8: 33252977 | F8: 547948 | G8: 33800925

Sheet درآمد ناشی ازفروش
A1: صندوق سرمایه گذاری قابل معامله شاخصی شفق رابین
A2: صورت وضعیت درآمدها
A3: برای ماه منتهی به 1404/08/30
A4: سود(زیان) حاصل از فروش اوراق بهادار
B5: از 1404/08/01 تا 1404/08/30 | F5: از ابتدای سال مالی تا 1404/08/30
A6: شرح | B6: تعداد | C6: خالص بهای فروش | D6: ارزش دفتری | E6: سود و زیان ناشی از فروش | F6: تعداد | G6: خالص ارزش فروش | H6: ارزش دفتری | I6: سود و زیان ناشی از فروش
A7: پالایش نفت اصفهان (شپنا) | B7: 2245246 | C7: 11371202475 | D7: -9330896797 | E7: 2112797169 | F7: 2245246 | G7: 11371202475 | H7: -9330896797 | I7: 2112797169
A8: بانک تجارت (وتجارت) | B8: 0 | C8: 0 | D8: 0 | F8: 9158178 | G8: 4214033557 | H8: -5298345746 | I8: -1059088746
A9: بانک پاسارگاد (وپاسار) | B9: 658158 | C9: 3200177107 | D9: -3125460790 | E9: 98128505 | F9: 3658477 | G9: 13397968435 | H9: -13880237163 | I9: -397816511
A10: سر. سپه (وسپه) | B10: 0 | C10: 0 | D10: 0 | F10: 795447 | G10: 4137126571 | H10: -4839170235 | I10: -677280461
A11: سر. نفت و گاز تامین (تاپیکو) | B11: 28079 | C11: 458756832 | D11: -604851522 | E11: -142464962 | F11: 44463 | G11: 769666412 | H11: -957780307 | I11: -182623187
A12: گل گهر (کگل) | B12: 439664 | C12: 889691752 | D12: -1070767598 | E12: -174096766 | F12: 521587 | G12: 1090104664 | H12: -1270284715 | I12: -172001380
A13: دارو عبیدی (دعبید) | B13: 293121 | C13: 2070934580 | D13: -2174013896 | E13: -89791516 | F13: 299792 | G13: 2150775526 | H13: -2251069690 | I13: -86528470
A14: صنعتی سپاهان (فسپا) | B14: 0 | C14: 0 | D14: 0 | F14: 603505 | G14: 1491483622 | H14: -2190886459 | I14: -690475582
A15: پتروشیمی شیراز (شیراز) | B15: 8469 | C15: 299600011 | D15: -305342966 | E15: -3372496 | F15: 10730 | G15: 379837448 | H15: -386861498 | I15: -4173328
A16: پالایش نفت تهران (شتران) | B16: 2290147 | C16: 6853475950 | D16: -6072602332 | E16: 826716546 | F16: 2385851 | G16: 7094166395 | H16: -6334888318 | I16: 806561680
A17: صنعتی بهشهر (غبشهر) | B17: 0 | C17: 0 | D17: 0 | F17: 1009300 | G17: 2097500191 | H17: -3091150867 | I17: -981095912
A18: پارس سوئیچ (بسویچ) | B18: 114429 | C18: 654020190 | D18: -717750809 | E18: -58923959 | F18: 140549 | G18: 812530277 | H18: -881587347 | I18: -63301677
A19: بیمه پاسارگاد (بپاس) | B19: 52184 | C19: 300291269 | D19: -266834238 | E19: 35832962 | F19: 52184 | G19: 300291269 | H19: -266834238 | I19: 35832962
A20: سپید ماکیان (سپید) | B20: 0 | C20: 0 | D20: 0 | F20: 212091 | G20: 1108960870 | H20: -1673982727 | I20: -558384067
A21: سر. غدیر (وغدیر) | B21: 319426 | C21: 3507191896 | D21: -3317472263 | E21: 214322197 | F21: 353977 | G21: 3858202119 | H21: -3689089725 | I21: 195815955
A22: ذوب آهن اصفهان (ذوب) | B22: 3200000 | C22: 1139437247 | D22: -1590480000 | E22: -442080000 | F22: 3700000 | G22: 1357034825 | H22: -1838992500 | I22: -471692500
A23: ارتباطات سیار (همراه) | B23: 190803 | C23: 867690664 | D23: -931342906 | E23: -56892757 | F23: 203833 | G23: 937893063 | H23: -1001027202 | I23: -55954453
A24: پتروشیمی جم (جم) | B24: 4857 | C24: 215670635 | D24: -340139706 | E24: -122788956 | F24: 7790 | G24: 413927946 | H24: -545540108 | I24: -128745358
A25: سر. خوارزمی (وخارزم) | B25: 0 | C25: 0 | D25: 0 | F25: 2652068 | G25: 5610368086 | H25: -6577539050 | I25: -933589506
A26: قند هگمتان (قهکمت) | B26: 0 | C26: 0 | D26: 0 | F26: 269589 | G26: 1200219410 | H26: -1707064106 | I26: -499660653
A27: سر. توسعه معادن و صنایع معدنی خاورمیانه (میدکو) | B27: 62139 | C27: 296542321 | D27: -287227119 | E27: 11661471 | F27: 108297 | G27: 507146947 | H27: -500584743 | I27: 10169067
A28: کشتیرانی ایران (حکشتی) | B28: 52094 | C28: 300290223 | D28: -480989419 | E28: -178323279 | F28: 52094 | G28: 300290223 | H28: -480989419 | I28: -178323279
A29: بیمه اتکایی تهران رواک (بتهران) | B29: 0 | C29: 0 | D29: 0 | F29: 2000000 | G29: 4254534000 | H29: -4424013330 | I29: -144013330
A30: بیمه ملت (ملت) | B30: 0 | C30: 0 | D30: 0 | F30: 863801 | G30: 3539496279 | H30: -4147334489 | I30: -586652166
A31: گروه بهمن (خبهمن) | B31: 0 | C31: 0 | D31: 0 | F31: 3137646 | G31: 6566575577 | H31: -7204836889 | I31: -598956422
A32: چادرملو (کچاد) | B32: 0 | C32: 0 | D32: 0 | F32: 72063 | G32: 200575839 | H32: -200504196 | I32: 1272204
A33: سر. توسعه معادن و فلزات (ومعادن) | B33: 2997927 | C33: 6305023843 | D33: -6276159522 | E33: 69619399 | F33: 3069353 | G33: 6465486141 | H33: -6445283942 | I33: 61917739
A34: پتروشیمی پردیس (شپدیس) | B34: 5001 | C34: 1485969971 | D34: -1426728901 | E34: 70998199 | F34: 6006 | G34: 1756764410 | H34: -1710300800 | I34: 59841600
A35: مخابرات ایران (اخابر) | B35: 0 | C35: 0 | D35: 0 | F35: 5409634 | G35: 3087781374 | H35: -3807232251 | I35: -700968752
A36: سر. تامین اجتماعی (شستا) | B36: 4472176 | C36: 5642157100 | D36: -6890758465 | E36: -1207950710 | F36: 4721251 | G36: 6016517734 | H36: -7304238782 | I36: -1244829627
A37: ایران خودرو (خودرو) | B37: 0 | C37: 0 | D37: 0 | F37: 10000000 | G37: 3804428337 | H37: -6073645502 | I37: -2246445502
A38: گروه مپنا (رمپنا) | B38: 76884 | C38: 1039179884 | D38: -1277087486 | E38: -230925786 | F38: 91778 | G38: 1269847719 | H38: -1524485397 | I38: -246275177
A39: بانک پارسیان (وپارس) | B39: 0 | C39: 0 | D39: 0 | F39: 1066372 | G39: 3053746934 | H39: -3657093452 | I39: -585067992
A40: بانک ملت (وبملت) | B40: 7407303 | C40: 8969062099 | D40: -9157146379 | E40: -122239165 | F40: 15435960 | G40: 17457296383 | H40: -20533034708 | I40: -2959086088
...

Sheet درآمد ناشی از تغییر قیمت اوراق 
A1: صندوق سرمایه گذاری قابل معامله شاخصی شفق رابین
A2: صورت وضعیت درآمدها
A3: برای ماه منتهی به 1404/08/30
A4: درآمد ناشی از تغییر قیمت اوراق بهادار
B5: از 1404/08/01 تا 1404/08/30 | F5: از ابتدای سال مالی تا 1404/08/30
A6: شرح | B6: تعداد | C6: خالص ارزش فروش | D6: ارزش دفتری | E6: سود و زیان ناشی از تغییر قیمت | F6: تعداد | G6: خالص ارزش فروش | H6: ارزش دفتری | I6: سود و زیان ناشی از تغییر قیمت
A7: تاید واتر خاورمیانه (حتاید) | B7: 549981 | C7: 3918338870 | D7: -3605488263 | E7: 312850607 | F7: 549981 | G7: 3918338870 | H7: -4286207963 | I7: -367869093
A8: سر. توسعه معادن و صنایع معدنی خاورمیانه (میدکو) | B8: 1837671 | C8: 9029802661 | D8: -7820129702 | E8: 1209672959 | F8: 1837671 | G8: 9029802661 | H8: -8494326390 | I8: 535476271
A9: پتروشیمی نوری (نوری) | B9: 718282 | C9: 29699445777 | D9: -31805529593 | E9: -2106083816 | F9: 718282 | G9: 29699445777 | H9: -33570617911 | I9: -3871172134
A10: کشتیرانی ایران (حکشتی) | B10: 856411 | C10: 4903293744 | D10: -4613851927 | E10: 289441817 | F10: 856411 | G10: 4903293744 | H10: -7449286272 | I10: -2545992528
A11: سایپا (خساپا) | B11: 13200000 | C11: 6352512540 | D11: -6337665181 | E11: 14847359 | F11: 13200000 | G11: 6352512540 | H11: -6407940850 | I11: -55428310
A12: گروه صنعتی پاکشو (پاکشو) | B12: 723642 | C12: 4171860320 | D12: -4162721198 | E12: 9139122 | F12: 723642 | G12: 4171860320 | H12: -3344194600 | I12: 827665720
A13: سر. غدیر (وغدیر) | B13: 1596966 | C13: 17811145133 | D13: -15884821576 | E13: 1926323557 | F13: 1596966 | G13: 17811145133 | H13: -16585658046 | I13: 1225487087
A14: پالایش نفت اصفهان (شپنا) | B14: 4764598 | C14: 24740408155 | D14: -24812966802 | E14: -72558647 | F14: 4764598 | G14: 24740408155 | H14: -19800935938 | I14: 4939472217
A15: گسترش نفت و گاز پارسیان (پارسان) | B15: 273620 | C15: 17769996847 | D15: -18674999807 | E15: -905002960 | F15: 273620 | G15: 17769996847 | H15: -17199658927 | I15: 570337920
A16: موتوژن (بموتو) | B16: 3582531 | C16: 6611998749 | D16: -6459080193 | E16: 152918556 | F16: 3582531 | G16: 6611998749 | H16: -6352093014 | I16: 259905735
A17: پتروشیمی خارک (شخارک) | B17: 135256 | C17: 11716574132 | D17: -11863180392 | E17: -146606260 | F17: 135256 | G17: 11716574132 | H17: -12266220152 | I17: -549646020
A18: پتروشیمی پردیس (شپدیس) | B18: 52142 | C18: 15506161022 | D18: -14756445560 | E18: 749715462 | F18: 52142 | G18: 15506161022 | H18: -14875524553 | I18: 630636469
... A65: گلتاش (حق تقدم) (شگلح) | B65: 400000 | C65: 1214538480 | D65: -1216717200 | E65: -2178720 | F65: 400000 | G65: 1214538480 | H65: -1225135872 | I65: -10597392
A66: جمع | C66: 686855167642 | D66: -660657871266 | E66: 26197296376 | G66: 686855167642 | H66: -688618880350 | I66: -1763712708
A70: ارزش دفتری برابر است با میانگین موزون خالص ارزش فروش هر سهم/ورقه در ابتدای دوره با خرید طی دوره ضربدر تعداد در پایان دوره

Sheet درآمد سرمایه گذاری در سهام
A1: صندوق سرمایه گذاری قابل معامله شاخصی شفق رابین
A2: صورت وضعیت درآمدها
A3: برای ماه منتهی به 1404/08/30
A5: 1-2-درآمد حاصل از سرمایه­گذاری در سهام و حق تقدم سهام:
B7: از 1404/08/01 تا 1404/08/30 | G7: از ابتدای سال مالی تا 1404/08/30
A8: دارایی | B8: درآمد سود سهام | C8: درآمد تغییر ارزش | D8: درآمد فروش | E8: جمع | G8: درآمد سود سهام | H8: درآمد تغییر ارزش | I8: درآمد فروش | J8: جمع
E10: مبلغ | F10: درصد از کل درآمد ها | J10: مبلغ | K10: درصد از کل درآمد ها
A11: ارتباطات سیار (همراه) | C11: -84738008 | D11: -56892757 | E11: =B11+C11+D11 -> -141630765 | F11: =E11/$E$99 -> -0.0050590695 | G11: 339437553 | H11: -421792020 | I11: -55954453 | J11: =G11+H11+I11 -> -138308920 | K11: =J11/$J$99 -> -0.040403563
A12: ایران خودرو (خودرو) | C12: 52445845 | E12: =B12+C12+D12 -> 52445845 | F12: =E12/$E$99 -> 0.0018733725 | H12: 266128426 | I12: -2246445502 | J12: =G12+H12+I12 -> -1980317076 | K12: =J12/$J$99 -> -0.57850112
A13: آلومینیوم ایران (فایرا) | C13: -25247688 | E13: =B13+C13+D13 -> -25247688 | F13: =E13/$E$99 -> -0.00090185073 | G13: 212280640 | H13: -343092905 | J13: =G13+H13+I13 -> -130812265 | K13: =J13/$J$99 -> -0.038213599
A14: آهنگری تراکتور (خاهن) | E14: =B14+C14+D14 -> 0 | F14: =E14/$E$99 -> 0 | I14: -1205111876 | J14: =G14+H14+I14 -> -1205111876 | K14: =J14/$J$99 -> -0.35204391
A15: بانک اقتصاد نوین (ونوین) | C15: 300590126 | D15: 70436905 | E15: =B15+C15+D15 -> 371027031 | F15: =E15/$E$99 -> 0.013253134 | G15: 569925600 | H15: 102602202 | I15: 70436905 | J15: =G15+H15+I15 -> 742964707 | K15: =J15/$J$99 -> 0.21703894
A16: بانک پارسیان (وپارس) | E16: =B16+C16+D16 -> 0 | F16: =E16/$E$99 -> 0 | I16: -585067992 | J16: =G16+H16+I16 -> -585067992 | K16: =J16/$J$99 -> -0.17091328
A17: بانک پاسارگاد (وپاسار) | C17: -1192332310 | D17: 98128505 | E17: =B17+C17+D17 -> -1094203805 | F17: =E17/$E$99 -> -0.039085104 | H17: -85613824 | I17: -397816511 | J17: =G17+H17+I17 -> -483430335 | K17: =J17/$J$99 -> -0.14122233
A18: بانک تجارت (وتجارت) | E18: =B18+C18+D18 -> 0 | F18: =E18/$E$99 -> 0 | G18: 71914238 | I18: -1059088746 | J18: =G18+H18+I18 -> -987174508 | K18: =J18/$J$99 -> -0.28837885
A19: بانک صادرات ایران (وبصادر) | E19: =B19+C19+D19 -> 0 | F19: =E19/$E$99 -> 0 | I19: -531584691 | J19: =G19+H19+I19 -> -531584691 | K19: =J19/$J$99 -> -0.15528944
A20: بانک ملت (وبملت) | C20: -839412797 | D20: -122239165 | E20: =B20+C20+D20 -> -961651962 | F20: =E20/$E$99 -> -0.034350334 | G20: 669119130 | H20: -1585030305 | I20: -2959086088 | J20: =G20+H20+I20 -> -3874997263 | K20: =J20/$J$99 -> -1.1319855
A21: بورس کالای ایران (کالا) | C21: 75716474 | E21: =B21+C21+D21 -> 75716474 | F21: =E21/$E$99 -> 0.0027046024 | G21: 57149070 | H21: 154391481 | I21: -562420012 | J21: =G21+H21+I21 -> -350879461 | K21: =J21/$J$99 -> -0.10250084
A22: بیمه اتکایی تهران رواک (بتهران) | E22: =B22+C22+D22 -> 0 | F22: =E22/$E$99 -> 0 | I22: -144013330 | J22: =G22+H22+I22 -> -144013330 | K22: =J22/$J$99 -> -0.042069966
A23: بیمه اتکایی حامی ما (حامیا) | C23: -89000 | E23: =B23+C23+D23 -> -89000 | F23: =E23/$E$99 -> -3.1790917e-06 | H23: -250300 | J23: =G23+H23+I23 -> -250300 | K23: =J23/$J$99 -> -7.3119013e-05
A24: بیمه پاسارگاد (بپاس) | C24: 80560526 | D24: 35832962 | E24: =B24+C24+D24 -> 116393488 | F24: =E24/$E$99 -> 0.0041575907 | H24: 245662520 | I24: 35832962 | J24: =G24+H24+I24 -> 281495482 | K24: =J24/$J$99 -> 0.082232009
A25: بیمه ملت (ملت) | E25: =B25+C25+D25 -> 0 | F25: =E25/$E$99 -> 0 | I25: -586652166 | J25: =G25+H25+I25 -> -586652166 | K25: =J25/$J$99 -> -0.17137606
A26: بین المللی توسعه صنایع و معادن غدیر (وکغدیر) | E26: =B26+C26+D26 -> 0 | F26: =E26/$E$99 -> 0 | I26: -490043326 | J26: =G26+H26+I26 -> -490043326 | K26: =J26/$J$99 -> -0.14315415
A27: پارس دارو (دپارس) | C27: 11296238 | D27: -84515764 | E27: =B27+C27+D27 -> -73219526 | F27: =E27/$E$99 -> -0.0026154111 | G27: 1720318250 | H27: -905478205 | I27: -61699451 | J27: =G27+H27+I27 -> 753140594 | K27: =J27/$J$99 -> 0.22001157
A28: پارس سوئیچ (بسویچ) | C28: 987821970 | D28: -58923959 | E28: =B28+C28+D28 -> 928898011 | F28: =E28/$E$99 -> 0.033180359 | G28: 115146680 | H28: -297269149 | I28: -63301677 | J28: =G28+H28+I28 -> -245424146 | K28: =J28/$J$99 -> -0.071694652
A29: پالایش نفت اصفهان (شپنا) | C29: -72558647 | D29: 2112797169 | E29: =B29+C29+D29 -> 2040238522 | F29: =E29/$E$99 -> 0.072877588 | G29: 1380675960 | H29: 4939472217 | I29: 2112797169 | J29: =G29+H29+I29 -> 8432945346 | K29: =J29/$J$99 -> 2.4634784
A30: پالایش نفت بندر عباس (شبندر) | C30: -27184742 | E30: =B30+C30+D30 -> -27184742 | F30: =E30/$E$99 -> -0.00097104255 | G30: 1128778560 | H30: 2318014974 | J30: =G30+H30+I30 -> 3446793534 | K30: =J30/$J$99 -> 1.0068963
A31: پالایش نفت تبریز (شبریز) | C31: -579206668 | E31: =B31+C31+D31 -> -579206668 | F31: =E31/$E$99 -> -0.020689338 | G31: 371028621 | H31: -619837921 | I31: -11638064 | J31: =G31+H31+I31 -> -260447364 | K31: =J31/$J$99 -> -0.076083317
A32: پالایش نفت تهران (شتران) | C32: 285512320 | D32: 826716546 | E32: =B32+C32+D32 -> 1112228866 | F32: =E32/$E$99 -> 0.039728961 | G32: 1269957150 | H32: 1943292005 | I32: 806561680 | J32: =G32+H32+I32 -> 4019810835 | K32: =J32/$J$99 -> 1.1742893
A33: پتروشیمی بوعلی سینا (بوعلی) | C33: -1179070447 | D33: -121250183 | E33: =B33+C33+D33 -> -1300320630 | F33: =E33/$E$99 -> -0.046447624 | G33: 802785448 | H33: -2802318339 | I33: -125632000 | J33: =G33+H33+I33 -> -2125164891 | K33: =J33/$J$99 -> -0.62081486
A34: پتروشیمی پارس (پارس) | E34: =B34+C34+D34 -> 0 | F34: =E34/$E$99 -> 0 | G34: 84800 | I34: -833263239 | J34: =G34+H34+I34 -> -833178439 | K34: =J34/$J$99 -> -0.24339267
A35: پتروشیمی پردیس (شپدیس) | C35: 749715462 | D35: 70998199 | E35: =B35+C35+D35 -> 820713661 | F35: =E35/$E$99 -> 0.029316 | G35: 1524028000 | H35: 630636469 | I35: 59841600 | J35: =G35+H35+I35 -> 2214506069 | K35: =J35/$J$99 -> 0.6469137
A36: پتروشیمی جم (جم) | C36: 289633585 | D36: -122788956 | E36: =B36+C36+D36 -> 166844629 | F36: =E36/$E$99 -> 0.0059597121 | G36: 490736400 | H36: -2875366447 | I36: -128745358 | J36: =G36+H36+I36 -> -2513375405 | K36: =J36/$J$99 -> -0.73422105
A37: پتروشیمی خارک (شخارک) | C37: -146606260 | D37: -21309667 | E37: =B37+C37+D37 -> -167915927 | F37: =E37/$E$99 -> -0.005997979 | G37: 391380000 | H37: -549646020 | I37: -7621420 | J37: =G37+H37+I37 -> -165887440 | K37: =J37/$J$99 -> -0.048459952
A38: پتروشیمی خراسان (خراسان) | E38: =B38+C38+D38 -> 0 | F38: =E38/$E$99 -> 0 | I38: -179665178 | J38: =G38+H38+I38 -> -179665178 | K38: =J38/$J$99 -> -0.05248478
A39: پتروشیمی شیراز (شیراز) | C39: -15507291 | D39: -3372496 | E39: =B39+C39+D39 -> -18879787 | F39: =E39/$E$99 -> -0.00067438847 | G39: 470205512 | H39: -38952709 | I39: -4173328 | J39: =G39+H39+I39 -> 427079475 | K39: =J39/$J$99 -> 0.12476081
A40: پتروشیمی نوری (نوری) | C40: -2106083816 | D40: -497861462 | E40: =B40+C40+D40 -> -2603945278 | F40: =E40/$E$99 -> -0.093013267 | G40: 1366592600 | H40: -3871172134 | I40: -499893774 | J40: =G40+H40+I40 -> -3004473308 | K40: =J40/$J$99 -> -0.87768327
A41: پلی پروپیلن جم (جم پیلن) | C41: 140503478 | D41: 49312339 | E41: =B41+C41+D41 -> 189815817 | F41: =E41/$E$99 -> 0.0067802459 | H41: 803190259 | I41: 49312339 | J41: =G41+H41+I41 -> 852502598 | K41: =J41/$J$99 -> 0.24903775
A42: پویا زرکان آق دره (فزر) | C42: 1871266406 | E42: =B42+C42+D42 -> 1871266406 | F42: =E42/$E$99 -> 0.066841882 | H42: 1204005317 | I42: 320413071 | J42: =G42+H42+I42 -> 1524418388 | K42: =J42/$J$99 -> 0.44532149
A43: تامین سرمایه کاردان (تکاردان) | E43: =B43+C43+D43 -> 0 | F43: =E43/$E$99 -> 0 | I43: -315643873 | J43: =G43+H43+I43 -> -315643873 | K43: =J43/$J$99 -> -0.092207625
...

Sheet درآمد سپرده بانکی
A1: صندوق سرمایه گذاری قابل معامله شاخصی شفق رابین
A2: صورت وضعیت درآمدها
A3: برای ماه منتهی به 1404/08/30
A4: 3-2-درآمد حاصل از سرمایه­گذاری در سپرده بانکی و گواهی سپرده:
A6: نام سپرده بانکی | C6: از 1404/08/01 تا 1404/08/30 | E6: از ابتدای سال مالی تا 1404/08/30
A7: نام سپرده | B7: شماره حساب | C7: سود سپرده بانکی و گواهی سپرده | D7: درصد سود به میانگین سپرده | E7: سود سپرده بانکی و گواهی سپرده | F7: درصد سود به میانگین سپرده
C8: یادداشت … | E8: یادداشت …
A9: بلند مدت گردشگری129.333.1709609.2 | B9: 129.333.1709609.2 | C9: 0 | D9: - | E9: 33252977 | F9: -
A10: جمع | C10: 0 | E10: =SUBTOTAL(109,E9) -> 33252977

Sheet سایر درآمدها
A1: صندوق سرمایه گذاری قابل معامله شاخصی شفق رابین
A2: صورت وضعیت درآمدها
A3: برای ماه منتهی به 1404/08/30
A4: 4-2-سایر درآمدها:
B5: از 1404/08/01 تا 1404/08/30 | C5: از ابتدای سال مالی تا 1404/08/30
A6: سایر درآمدها | B6: مبلغ | C6: مبلغ
A8: سایر درآمدها | B8: -145448 | C8: 293535671
A9: جمع | B9: -145448 | C9: 293535671

Sheet Sheet1
