Workbook

Sheet 1
D3: به ‌نام خدا
A15: صندوق سرمایه گذاری قابل معامله شاخصی شفق رابین
A17: صورت وضعیت پرتفوی
A20: برای ماه منتهی به 1404/10/30
F37: مدیر صندوق

Sheet  سهام
A1: صندوق سرمایه گذاری قابل معامله شاخصی شفق رابین
A2: صورت وضعیت پرتفوی
A3: برای ماه منتهی به 1404/10/30
A4: 1- سرمایه گذاری ها
A5: 1-1-سرمایه‌گذاری در سهام و حق تقدم سهام وصندوق‌های سرمایه‌گذاری
M6: 1386939178472
B7: 1404/10/01 | E7: تغییرات طی دوره | I7: 1404/10/30
A8: شرکت | B8: تعداد | C8: بهای تمام شده | D8: خالص ارزش فروش | E8: خرید طی دوره | G8: فروش طی دوره | I8: تعداد | J8: قیمت بازار هر سهم | K8: بهای تمام شده | L8: خالص ارزش فروش | M8: درصد به کل دارایی‌ها
E9: تعداد | F9: مبلغ خرید | G9: تعداد | H9: مبلغ فروش
A10: سر. توسعه معادن و صنایع معدنی خاورمیانه (میدکو) | B10: 2274591 | C10: 10895398916 | D10: 13722611145 | E10: 4600000 | F10: 27358689723 | G10: 2871603 | H10: 16458786236 | I10: 4002988 | J10: 5660 | K10: 22274875374 | L10: 22481774152 | M10: =Table1[[#This Row],[22481774152.0000]]/$M$6 -> 0.016209632
A11: پتروشیمی نوری (نوری) | B11: 665849 | C11: 32800478474 | D11: 34911493009 | E11: 3400000 | F11: 212440639408 | G11: 3300000 | H11: 201928929973 | I11: 765849 | J11: 60700 | K11: 47381246045 | L11: 46120090239 | M11: =Table1[[#This Row],[22481774152.0000]]/$M$6 -> 0.033253145
A12: کشتیرانی ایران (حکشتی) | B12: 856411 | C12: 8623303340 | D12: 6458411169 | E12: 2400000 | F12: 19732427445 | G12: 1600000 | H12: 11971569372 | I12: 1656411 | J12: 7430 | K12: 14423469392 | L12: 12080511034 | M12: =Table1[[#This Row],[22481774152.0000]]/$M$6 -> 0.0087101952
A13: سایپا (خساپا) | B13: 35200000 | C13: 18195408915 | D13: 19839049473 | E13: 5200000 | F13: 2977109870 | G13: 14000000 | H13: 7584887822 | I13: 26400000 | J13: 552 | K13: 13907981543 | L13: 14643523753 | M13: =Table1[[#This Row],[22481774152.0000]]/$M$6 -> 0.010558159
A14: گروه صنعتی پاکشو (پاکشو) | B14: 723642 | C14: 2711987733 | D14: 4.2077627e+09 | E14: 1141479 | F14: 6523493442 | G14: 1865121 | H14: 9575619036 | I14: 0 | J14: 0 | K14: 0 | L14: 0 | M14: =Table1[[#This Row],[22481774152.0000]]/$M$6 -> 0
A15: سر. غدیر (وغدیر) | B15: 2093280 | C15: 25144373676 | D15: 28643194464 | E15: 2600000 | F15: 40657116305 | G15: 1550000 | H15: 24047167445 | I15: 3143280 | J15: 16750 | K15: 44578656037 | L15: 51338451059 | M15: =Table1[[#This Row],[22481774152.0000]]/$M$6 -> 0.037015647
A16: بانک تجارت (وتجارت) | B16: 10400000 | C16: 5318129700 | D16: 6006011857 | E16: 13600000 | F16: 7851260025 | G16: 4000000 | H16: 2140127999 | I16: 20000000 | J16: 534 | K16: 10974491437 | L16: 10637134400 | M16: =Table1[[#This Row],[22481774152.0000]]/$M$6 -> 0.0076695032
A17: پالایش نفت اصفهان (شپنا) | B17: 5518621 | C17: 24916120903 | D17: 33567647429 | E17: 5675000 | F17: 43051133305 | G17: 4400000 | H17: 29321578557 | I17: 6793621 | J17: 8110 | K17: 46410787570 | L17: 54131083671 | M17: =Table1[[#This Row],[22481774152.0000]]/$M$6 -> 0.039029169
A18: گسترش نفت و گاز پارسیان (پارسان) | B18: 489090 | C18: 34163282689 | D18: 41537625927 | F18: 0 | G18: 0 | H18: 0 | I18: 1467270 | J18: 25573.333 | K18: 34163282689 | L18: 37315434719 | M18: =Table1[[#This Row],[22481774152.0000]]/$M$6 -> 0.026904882
A19: موتوژن (بموتو) | B19: 2965422 | C19: 5331986014 | D19: 6829540850 | E19: 0 | F19: 0 | G19: 2965422 | H19: 6538233479 | I19: 0 | J19: 0 | K19: 0 | L19: 0 | M19: =Table1[[#This Row],[22481774152.0000]]/$M$6 -> 0
A20: پتروشیمی خارک (شخارک) | B20: 115127 | C20: 10432666147 | D20: 11487679590 | E20: 0 | F20: 0 | G20: 52719 | H20: 5437703565 | I20: 62408 | J20: 150770 | K20: 5655335663 | L20: 9336520630 | M20: =Table1[[#This Row],[22481774152.0000]]/$M$6 -> 0.0067317448
A21: پتروشیمی پردیس (شپدیس) | B21: 97177 | C21: 33323653877 | D21: 39226024307 | E21: 228783 | F21: 135150158048 | G21: 97177 | H21: 43827808612 | I21: 228783 | J21: 612690 | K21: 135150158048 | L21: 137554900480 | M21: =Table1[[#This Row],[22481774152.0000]]/$M$6 -> 0.099178755
A22: بیمه پاسارگاد (بپاس) | B22: 444616 | C22: 2273470249 | D22: 3061783084 | E22: 1000000 | F22: 6587371018 | G22: 1444616 | H22: 9161327073 | I22: 0 | J22: 0 | K22: 0 | L22: 0 | M22: =Table1[[#This Row],[22481774152.0000]]/$M$6 -> 0
A23: ایران خودرو (خودرو) | B23: 43457527 | C23: 25036194913 | D23: 26347297798 | E23: 34800000 | F23: 21830344412 | G23: 36000000 | H23: 21219912820 | I23: 42257527 | J23: 612 | K23: 25534375864 | L23: 25661696310 | M23: =Table1[[#This Row],[22481774152.0000]]/$M$6 -> 0.018502395
A24: فولاد مبارکه اصفهان (فولاد) | B24: 20230493 | C24: 77663320898 | D24: 76783475683 | E24: 8400000 | F24: 36696299021 | G24: 8350000 | H24: 33133780698 | I24: 20280493 | J24: 3992 | K24: 82304606257 | L24: 79850939967 | M24: =Table1[[#This Row],[22481774152.0000]]/$M$6 -> 0.057573498
A25: صنایع شیمیایی ایران (شیران) | B25: 644433 | C25: 3596426442 | D25: 4680785226 | E25: 400000 | F25: 3003981312 | G25: 86905 | H25: 616150813 | I25: 957528 | J25: 8160 | K25: 6115411734 | L25: 7686521838 | M25: =Table1[[#This Row],[22481774152.0000]]/$M$6 -> 0.0055420756
A26: دارو عبیدی (دعبید) | B26: 1054588 | C26: 7673914766 | D26: 1.039111e+10 | E26: 0 | F26: 0 | G26: 135000 | H26: 1494953989 | I26: 919588 | J26: 11650 | K26: 6691561000 | L26: 10639511961 | M26: =Table1[[#This Row],[22481774152.0000]]/$M$6 -> 0.0076712174
A27: بانک اقتصاد نوین (ونوین) | B27: 1912948 | C27: 7251257422 | D27: 9244043644 | F27: 0 | G27: 1912948 | H27: 4178769552 | I27: 2591721 | J27: 2234 | K27: 4171946071 | L27: 5745148754 | M27: =Table1[[#This Row],[22481774152.0000]]/$M$6 -> 0.0041423221
A28: سر. امید (وامید) | B28: 1520842 | C28: 6692544181 | D28: 8963970197 | G28: 853067 | H28: 4951865875 | I28: 667775 | J28: 5970 | K28: 2.9385786e+09 | L28: 14511401813 | M28: =Table1[[#This Row],[22481774152.0000]]/$M$6 -> 0.010462897
A29: بانک پاسارگاد (وپاسار) | B29: 3392425 | C29: 16667368631 | D29: 18514108554 | E29: 3095686 | F29: 18114834009 | G29: 0 | H29: 0 | I29: 6488111 | J29: 5530 | K29: 34782202640 | L29: 35408768466 | M29: =Table1[[#This Row],[22481774152.0000]]/$M$6 -> 0.025530152
A30: چادرملو (کچاد) | B30: 4309843 | C30: 12339942850 | D30: 13586529184 | E30: 10000000 | F30: 32738984773 | G30: 8713349 | H30: 27114440984 | I30: 5596494 | J30: 3045 | K30: 17779057172 | L30: 16826296301 | M30: =Table1[[#This Row],[22481774152.0000]]/$M$6 -> 0.012131964
A31: پارس دارو (دپارس) | B31: 130253 | C31: 3880795746 | D31: 3916158178 | E31: 98127 | F31: 3026219137 | G31: 113758 | H31: 3314725324 | I31: 114622 | J31: 28470 | K31: 3469873419 | L31: 3249436721 | M31: =Table1[[#This Row],[22481774152.0000]]/$M$6 -> 0.0023428834
A32: بانک ملت (وبملت) | B32: 23200130 | C32: 28948025900 | D32: 33541295396 | E32: 14400000 | F32: 23662068040 | G32: 4800000 | H32: 7506324199 | I32: 32800130 | J32: 1474 | K32: 46472634548 | L32: 47843479946 | M32: =Table1[[#This Row],[22481774152.0000]]/$M$6 -> 0.03449573
A33: گروه مپنا (رمپنا) | B33: 525145 | C33: 7739012532 | D33: 7821495297 | E33: 988000 | F33: 15672721185 | G33: 713145 | H33: 10708173756 | I33: 800000 | J33: 14810 | K33: 12673672960 | L33: 11891363680 | M33: =Table1[[#This Row],[22481774152.0000]]/$M$6 -> 0.0085738177
A34: پالایش نفت بندر عباس (شبندر) | B34: 3768747 | C34: 13516813869 | D34: 23634364185 | E34: 1916000 | F34: 14520259136 | G34: 1400000 | H34: 11085640527 | I34: 4284747 | J34: 9070 | K34: 21836036907 | L34: 38604763226 | M34: =Table1[[#This Row],[22481774152.0000]]/$M$6 -> 0.027834503
A35: سر. توسعه صنعتی ایران (وتوصا) | B35: 1267487 | C35: 2212083394 | D35: 2267613856 | E35: 293145 | F35: 511725052 | G35: 1560632 | H35: 2600046234 | I35: 0 | J35: 0 | K35: 0 | L35: 0 | M35: =Table1[[#This Row],[22481774152.0000]]/$M$6 -> 0
A36: گل گهر (کگل) | B36: 5652508 | C36: 13554820625 | D36: 1.4925054e+10 | E36: 4800000 | F36: 13124470680 | G36: 2485244 | H36: 6346573071 | I36: 7967264 | J36: 2687 | K36: 20501592291 | L36: 21116063403 | M36: =Table1[[#This Row],[22481774152.0000]]/$M$6 -> 0.015224938
A37: ملی صنایع مس ایران (فملی) | B37: 11384675 | C37: 93294550580 | D37: 1.2923392e+11 | E37: 6849599 | F37: 106993168700 | G37: 7700000 | H37: 116367939529 | I37: 10534274 | J37: 15890 | K37: 119329897816 | L37: 165886635268 | M37: =Table1[[#This Row],[22481774152.0000]]/$M$6 -> 0.11960628
A38: توسعه ساختمان (ثاخت) | B38: 4293355 | C38: 2354111858 | D38: 2458116574 | E38: 0 | F38: 0 | G38: 4293355 | H38: 2080486539 | I38: 0 | J38: 0 | K38: 0 | L38: 0 | M38: =Table1[[#This Row],[22481774152.0000]]/$M$6 -> 0
A39: سیمان بجنورد (سبجنو) | B39: 235209 | C39: 6972451456 | D39: 8236362550 | E39: 155768 | F39: 5300630370 | G39: 200000 | H39: 6787126806 | I39: 190977 | J39: 32430 | K39: 6344353371 | L39: 6173934368 | M39: =Table1[[#This Row],[22481774152.0000]]/$M$6 -> 0.0044514817
A40: صنایع پتروشیمی خلیج فارس (فارس) | B40: 11247680 | C40: 103869843518 | D40: 116629685283 | E40: 4351571 | F40: 51040338900 | G40: 1801941 | H40: 19666848554 | I40: 13797310 | J40: 13550 | K40: 138024484973 | L40: 183317894471 | M40: =Table1[[#This Row],[22481774152.0000]]/$M$6 -> 0.13217443
...

Sheet سپرده
A1: صندوق سرمایه گذاری قابل معامله شاخصی شفق رابین
A2: صورت وضعیت پرتفوی
A3: برای ماه منتهی به 1404/10/30
A4: 3-1- سرمایه‌گذاری در سپرده‌ بانکی
B6: 1404/10/01 | C6: تغییرات طی دوره | E6: 1404/10/30
A7: سپرده های بانکی | B7: مبلغ | C7: افزایش | D7: کاهش | E7: مبلغ | F7: درصد به کل
A8: بانک گردشگری | B8: 521459351 | C8: 793527027212 | D8: 759679770459 | E8: 34368716104 | F8: =Table6[[#This Row],[34368716104.0000]]/' سهام'!M6 -> 0.024780262
A9: بانک خاورمیانه | B9: 0 | C9: 5000000 | D9: 3329100 | E9: 1670900 | F9: =Table6[[#This Row],[34368716104.0000]]/' سهام'!M6 -> 1.2047392e-06
A10: جمع | B10: 521459351 | C10: 793532027212 | D10: 759683099559 | E10: 34370387004 | F10: =SUBTOTAL(109,F8:F9) -> 0.024781467

Sheet درآمدها
A1: صندوق سرمایه گذاری قابل معامله شاخصی شفق رابین
A2: صورت وضعیت درآمدها
A3: برای ماه منتهی به 1404/10/30
A4: 2- درآمد حاصل از سرمایه­گذاری در سهام و حق تقدم سهام و صندوق‌های سرمایه‌گذاری
A5: شرح | B5: یادداشت | C5: مبلغ | D5: درصد از کل درآمدها | E5: درصد از کل دارایی ها
A6: درآمد حاصل از سرمایه­گذاری در سهام و حق تقدم سهام | B6: 1-2 | C6: 289745263294 | D6: =Table7[[#This Row],[289745263294.0000]]/D12 -> 0.96147183 | E6: =Table7[[#This Row],[289745263294.0000]]/' سهام'!M6 -> 0.20890986
A7: درآمد حاصل از سرمایه­گذاری در واحدهای صندوق های سرمایه­گذاری | B7: 2-2 | C7: 0 | D7: 0 | E7: 0
A8: درآمد حاصل از سرمایه گذاری در اوراق بهادار با درآمد ثابت | B8: 3-2 | C8: 0 | D8: 0 | E8: 0
A9: درآمد حاصل از سرمایه گذاری در سپرده بانکی و گواهی سپرده | B9: 4-2 | C9: 33800925 | D9: =Table7[[#This Row],[289745263294.0000]]/D12 -> 0.00011216279 | E9: =Table7[[#This Row],[289745263294.0000]]/' سهام'!M6 -> 2.4370878e-05
A10: سایر درآمدها | B10: 5-2 | C10: 2006336326 | D10: =Table7[[#This Row],[289745263294.0000]]/D12 -> 0.0066576959 | E10: =Table7[[#This Row],[289745263294.0000]]/' سهام'!M6 -> 0.0014465929
A11: جمع | C11: 291785400545 | D11: =SUBTOTAL(109,D6:D10) -> 0.96824169 | E11: =SUBTOTAL(109,E6:E10) -> 0.21038082
D12: 301355956828 | E12: 301355956828

Sheet درآمد سود سهام
A1: صندوق سرمایه گذاری قابل معامله شاخصی شفق رابین
A2: صورت وضعیت درآمدها
A3: برای ماه منتهی به 1404/10/30
A4: درآمد سود سهام
B5: اطلاعات مجمع | E5: از 1404/10/01 تا 1404/10/30 | H5: از ابتدای سال مالی تا 1404/10/30
A6: نام سهام | B6: تاریخ تشکیل مجمع | C6: تعداد سهام متعلقه در زمان مجمع | D6: سود متعلق به هر سهم | E6: جمع درآمد سود سهام | F6: هزینه تنزیل | G6: خالص درآمد سود سهام | H6: جمع درآمد سود سهام | I6: هزینه تنزیل | J6: خالص درآمد سود سهام
A7: سیمان خوزستان (سخوز) | B7: 1404/03/04 | C7: 137103 | D7: 9120 | E7: 0 | F7: 0 | G7: 0 | H7: 1250379360 | I7: 0 | J7: 1250379360
A8: لیزینگ بانک اقتصاد نوین (ولنوین) | B8: 1404/03/11 | C8: 411 | D8: 285 | E8: 0 | F8: 0 | G8: 0 | H8: 117135 | I8: 0 | J8: 117135
A9: سپید ماکیان (سپید) | B9: 1404/03/18 | C9: 212091 | D9: 20 | E9: 0 | F9: 0 | G9: 0 | H9: 4241820 | I9: 0 | J9: 4241820
A10: مس باهنر (فباهنر) | B10: 1404/03/20 | C10: 195474 | D10: 1025 | E10: 0 | F10: 0 | G10: 0 | H10: 200360850 | I10: 0 | J10: 200360850
A11: پتروشیمی خارک (شخارک) | B11: 1404/03/20 | C11: 39138 | D11: 10000 | E11: 0 | F11: 0 | G11: 0 | H11: 391380000 | I11: 0 | J11: 391380000
A12: ارتباطات سیار (همراه) | B12: 1404/03/21 | C12: 532869 | D12: 637 | E12: 0 | F12: 0 | G12: 0 | H12: 339437553 | I12: 0 | J12: 339437553
A13: مخابرات ایران (اخابر) | B13: 1404/04/12 | C13: 5281023 | D13: 40 | E13: 0 | F13: 0 | G13: 0 | H13: 211240920 | I13: 0 | J13: 211240920
A14: همکاران سیستم (سیستم) | B14: 1404/04/17 | C14: 165309 | D14: 2000 | E14: 0 | F14: 0 | G14: 0 | H14: 330618000 | I14: 0 | J14: 330618000
A15: صنعتی بارز (پکرمان) | B15: 1404/04/19 | C15: 263826 | D15: 1430 | E15: 0 | F15: 0 | G15: 0 | H15: 377271180 | I15: 0 | J15: 377271180
A16: پارس سوئیچ (بسویچ) | B16: 1404/04/21 | C16: 1046788 | D16: 110 | E16: 0 | F16: 0 | G16: 0 | H16: 115146680 | I16: 0 | J16: 115146680
A17: بانک اقتصاد نوین (ونوین) | B17: 1404/04/22 | C17: 2374690 | D17: 240 | E17: 0 | F17: 0 | G17: 0 | H17: 569925600 | I17: 0 | J17: 569925600
A18: پارس دارو (دپارس) | B18: 1404/04/23 | C18: 142765 | D18: 12050 | E18: 0 | F18: 0 | G18: 0 | H18: 1720318250 | I18: 0 | J18: 1720318250
... A56: گسترش نفت و گاز پارسیان (پارسان) | B56: 1404/10/23 | C56: 489090 | D56: 8700 | E56: 4255083000 | F56: -308182632 | G56: 3946900368 | H56: 4255083000 | I56: -308182632 | J56: 3946900368
A57: جمع | E57: 5501457330 | F57: -813456 | G57: 5500643874 | H57: =SUBTOTAL(109,H7:H56) -> 47451576146 | I57: -420915598 | J57: 47095350092

Sheet سود اوراق بهادار
A1: صندوق سرمایه گذاری قابل معامله شاخصی شفق رابین
A2: صورت وضعیت درآمدها
A3: برای ماه منتهی به 1404/10/30
A4: سود اوراق بهادار با درآمد ثابت
E5: از 1404/10/01 تا 1404/10/30 | H5: از ابتدای سال مالی تا 1404/10/30
A6: شرح | B6: تاریخ دریافت سود | C6: تاریخ سررسید | D6: نرخ سود علی الحساب | E6: درآمد سود | F6: هزینه تنزیل | G6: خالص درآمد | H6: درآمد سود | I6: هزینه تنزیل | J6: خالص درآمد
A7: بلند مدت گردشگری129.333.1709609.2 | B7: 1404/03/06 | C7: - | D7: - | E7: 0 | F7: 0 | G7: 0 | H7: 33252977 | I7: 547948 | J7: 33800925
A8: جمع | E8: 0 | F8: 0 | G8: 0 | H8: 33252977 | I8: 547948 | J8: 33800925

Sheet سود سپرده بانکی
A1: صندوق سرمایه گذاری قابل معامله شاخصی شفق رابین
A2: صورت وضعیت درآمدها
A3: برای ماه منتهی به 1404/10/30
A4: سود سپرده بانکی
B5: از 1404/10/01 تا 1404/10/30 | E5: از ابتدای سال مالی تا 1404/10/30
A6: شرح | B6: درآمد سود | C6: هزینه تنزیل | D6: خالص درآمد | E6: درآمد سود | F6: هزینه تنزیل | G6: خالص درآمد
A7: بلند مدت گردشگری129.333.1709609.2 | B7: 0 | C7: 0 | D7: 0 | E7: 33252977 | F7: 547948 | G7: 33800925
A8: جمع | B8: 0 | C8: 0 | D8: 0 | E8: 33252977 | F8: 547948 | G8: 33800925

Sheet درآمد ناشی ازفروش
A1: صندوق سرمایه گذاری قابل معامله شاخصی شفق رابین
A2: صورت وضعیت درآمدها
A3: برای ماه منتهی به 1404/10/30
A4: سود(زیان) حاصل از فروش اوراق بهادار
B5: از 1404/10/01 تا 1404/10/30 | F5: از ابتدای سال مالی تا 1404/10/30
A6: شرح | B6: تعداد | C6: خالص بهای فروش | D6: ارزش دفتری | E6: سود و زیان ناشی از فروش | F6: تعداد | G6: خالص ارزش فروش | H6: ارزش دفتری | I6: سود و زیان ناشی از فروش
A7: فروشگاه های افق کوروش (افق) | B7: 0 | C7: 0 | D7: 0 | E7: 0 | F7: 66049 | G7: 1731549273 | H7: -1449798734 | I7: 281750539
A8: بیمه اتکایی تهران رواک (بتهران) | B8: 0 | C8: 0 | D8: 0 | E8: 0 | F8: 2000000 | G8: 4254534000 | H8: -4424013330 | I8: -169479330
A9: گروه مالی صبا تامین (صبا) | B9: 949361 | C9: 4475531980 | D9: -2843124071 | E9: 1632407909 | F9: 2018267 | G9: 7749455023 | H9: -6944119520 | I9: 805335503
A10: سر. گروه توسعه ملی (وبانک) | B10: 114549 | C10: 987628382 | D10: -797629513 | E10: 189998869 | F10: 1243856 | G10: 8887520561 | H10: -9381907803 | I10: -494387242
A11: سایپا (خساپا) | B11: 14000000 | C11: 7584887822 | D11: -7264537242 | E11: 320350580 | F11: 22348792 | G11: 11075182592 | H11: -11734333554 | I11: -659150962
A12: بانک تجارت (وتجارت) | B12: 4000000 | C12: 2140127999 | D12: -2194898288 | E12: -54770289 | F12: 13158178 | G12: 6354161556 | H12: -7493244034 | I12: -1139082478
A13: گروه بهمن (خبهمن) | B13: 0 | C13: 0 | D13: 0 | E13: 0 | F13: 3137646 | G13: 6566575577 | H13: -7204836889 | I13: -638261312
A14: پالایش نفت تبریز (شبریز) | B14: 67068 | C14: 1977187565 | D14: -1758866565 | E14: 218321000 | F14: 95757 | G14: 2571724540 | H14: -2437477629 | I14: 134246911
A15: فولاد مبارکه اصفهان (فولاد) | B15: 8350000 | C15: 33133780698 | D15: -30097175501 | E15: 3036605197 | F15: 11270408 | G15: 41184525664 | H15: -40699399202 | I15: 485126462
A16: گروه صنعتی پاکشو (پاکشو) | B16: 1865121 | C16: 9575619036 | D16: -9867688042 | E16: -292069006 | F16: 2243024 | G16: 11634070886 | H16: -11614105709 | I16: 19965177
A17: پالایش نفت تهران (شتران) | B17: 0 | C17: 0 | D17: 0 | E17: 0 | F17: 3202137 | G17: 9877284167 | H17: -8609631262 | I17: 1267652905
A18: سر. تامین اجتماعی (شستا) | B18: 3200000 | C18: 5566237852 | D18: -5034417792 | E18: 531820060 | F18: 11074323 | G18: 16631723137 | H18: -17196930838 | I18: -565207701
... A93: قند هگمتان (قهکمت) | B93: 0 | C93: 0 | D93: 0 | E93: 0 | F93: 269589 | G93: 1200219410 | H93: -1707064106 | I93: -506844696
A94: جمع | C94: 823609993676 | D94: -736072549295 | E94: 87537444381 | G94: 1236343072837 | H94: -1174531387163 | I94: 61811685674
A97: ارزش دفتری برابر است با میانگین موزون خالص ارزش فروش هر سهم/ورقه در ابتدای دوره با خرید طی دوره ضربدر تعداد در پایان دوره

Sheet درآمد ناشی از تغییر قیمت اوراق 
A1: صندوق سرمایه گذاری قابل معامله شاخصی شفق رابین
A2: صورت وضعیت درآمدها
A3: برای ماه منتهی به 1404/10/30
A4: درآمد ناشی از تغییر قیمت اوراق بهادار
B5: از 1404/10/01 تا 1404/10/30 | F5: از ابتدای سال مالی تا 1404/10/30
A6: شرح | B6: تعداد | C6: خالص ارزش فروش | D6: ارزش دفتری | E6: سود و زیان ناشی از تغییر قیمت | F6: تعداد | G6: خالص ارزش فروش | H6: ارزش دفتری | I6: سود و زیان ناشی از تغییر قیمت
A7: سر. توسعه معادن و صنایع معدنی خاورمیانه (میدکو) | B7: 4002988 | C7: 22481774152 | D7: -24806104070 | E7: -2324329918 | F7: 4002988 | G7: 22481774152 | H7: -22435773773 | I7: 46000379
A8: پتروشیمی نوری (نوری) | B8: 765849 | C8: 46120090239 | D8: -50091753071 | E8: -3971662832 | F8: 765849 | G8: 46120090239 | H8: -47291349972 | I8: -1171259733
A9: کشتیرانی ایران (حکشتی) | B9: 1656411 | C9: 12080511034 | D9: -12784429514 | E9: -703918480 | F9: 1656411 | G9: 12080511034 | H9: -13826292073 | I9: -1745781039
A10: سایپا (خساپا) | B10: 26400000 | C10: 14643523753 | D10: -15027703541 | E10: -384179788 | F10: 26400000 | G10: 14643523753 | H10: -13907981543 | I10: 735542210
A11: گروه صنعتی پاکشو (پاکشو) | B11: 0 | C11: 0 | D11: -1064621642 | E11: -1064621642 | F11: 0 | G11: 0 | H11: 0 | I11: 0
A12: سر. غدیر (وغدیر) | B12: 3143280 | C12: 51338451059 | D12: -49195798113 | E12: 2142652946 | F12: 3143280 | G12: 51338451059 | H12: -44174049542 | I12: 7164401517
A13: بانک تجارت (وتجارت) | B13: 20000000 | C13: 10637134400 | D13: -11744930457 | E13: -1107796057 | F13: 20000000 | G13: 10637134400 | H13: -10974491437 | I13: -337357037
A14: پالایش نفت اصفهان (شپنا) | B14: 6793621 | C14: 54131083671 | D14: -55630420236 | E14: -1499336565 | F14: 6793621 | G14: 54131083671 | H14: -46449600101 | I14: 7681483570
A15: گسترش نفت و گاز پارسیان (پارسان) | B15: 1467270 | C15: 37315434719 | D15: -40751424805 | E15: -3435990086 | F15: 1467270 | G15: 37315434719 | H15: -33996867421 | I15: 3318567298
A16: موتوژن (بموتو) | B16: 0 | C16: 0 | D16: -1807027778 | E16: -1807027778 | F16: 0 | G16: 0 | H16: 0 | I16: 0
A17: پتروشیمی خارک (شخارک) | B17: 62408 | C17: 9336520630 | D17: -6527298382 | E17: 2809222248 | F17: 62408 | G17: 9336520630 | H17: -5659713929 | I17: 3676806701
A18: پتروشیمی پردیس (شپدیس) | B18: 228783 | C18: 137554900480 | D18: -139979918101 | E18: -2425017621 | F18: 228783 | G18: 137554900480 | H18: -135150158048 | I18: 2404742432
... A66: سر. امید (حق تقدم) (وامیدح) | B66: 0 | C66: 0 | D66: -2810044275 | E66: -2810044275 | F66: 0 | G66: 0 | H66: 0 | I66: 0
A67: جمع | C67: 1332542559206 | D67: -1304399542224 | E67: =SUBTOTAL(109,E7:E66) -> 28143016982 | G67: 1332542559206 | H67: -1151704331678 | I67: =SUBTOTAL(109,I7:I66) -> 180838227528
A71: ارزش دفتری برابر است با میانگین موزون خالص ارزش فروش هر سهم/ورقه در ابتدای دوره با خرید طی دوره ضربدر تعداد در پایان دوره

Sheet درآمد سرمایه گذاری در سهام
A1: صندوق سرمایه گذاری قابل معامله شاخصی شفق رابین
A2: صورت وضعیت درآمدها
A3: برای ماه منتهی به 1404/10/30
A5: 1-2-درآمد حاصل از سرمایه­گذاری در سهام و حق تقدم سهام:
B7: از 1404/10/01 تا 1404/10/30 | G7: از ابتدای سال مالی تا 1404/10/30
A8: دارایی | B8: درآمد سود سهام | C8: درآمد تغییر ارزش | D8: درآمد فروش | E8: جمع | G8: درآمد سود سهام | H8: درآمد تغییر ارزش | I8: درآمد فروش | J8: جمع
B10: یادداشت … | C10: یادداشت ... | D10: یادداشت ... | E10: مبلغ | F10: درصد از کل درآمد ها | G10: یادداشت … | H10: یادداشت ... | I10: یادداشت ... | J10: مبلغ | K10: درصد از کل درآمد ها
A11: تاید واتر خاورمیانه (حتاید) | B11: 0 | C11: 0 | D11: 0 | E11: 0 | F11: =Table14[[#This Row],[Column5]]/درآمدها!$E$12 -> 0 | G11: 239981000 | H11: 0 | I11: -565874784 | J11: -325893784 | K11: =Table14[[#This Row],[-325893784.0000]]/درآمدها!$E$12 -> -0.0010814247
A12: سر. توسعه معادن و صنایع معدنی خاورمیانه (میدکو) | B12: 0 | C12: -2324329918 | D12: 364150110 | E12: -1960179808 | F12: =Table14[[#This Row],[Column5]]/درآمدها!$E$12 -> -0.0065045331 | G12: 64593540 | H12: 46000379 | I12: 995966800 | J12: 1106560719 | K12: =Table14[[#This Row],[-325893784.0000]]/درآمدها!$E$12 -> 0.0036719391
A13: پتروشیمی نوری (نوری) | B13: 0 | C13: -3971662832 | D13: 5659603608 | E13: 1687940776 | F13: =Table14[[#This Row],[Column5]]/درآمدها!$E$12 -> 0.0056011528 | G13: 1366592600 | H13: -1171259733 | I13: 4885008211 | J13: 5080341078 | K13: =Table14[[#This Row],[-325893784.0000]]/درآمدها!$E$12 -> 0.016858273
A14: کشتیرانی ایران (حکشتی) | B14: 0 | C14: -703918480 | D14: -1383852272 | E14: -2087770752 | F14: =Table14[[#This Row],[Column5]]/درآمدها!$E$12 -> -0.0069279226 | G14: 809823000 | H14: -1745781039 | I14: -1564551468 | J14: -2500509507 | K14: =Table14[[#This Row],[-325893784.0000]]/درآمدها!$E$12 -> -0.0082975281
A15: گلتاش (شگل) | B15: 0 | C15: 0 | D15: 0 | E15: 0 | F15: =Table14[[#This Row],[Column5]]/درآمدها!$E$12 -> 0 | G15: 0 | H15: 0 | I15: 56917340 | J15: 56917340 | K15: =Table14[[#This Row],[-325893784.0000]]/درآمدها!$E$12 -> 0.0001888708
A16: سایپا (خساپا) | B16: 0 | C16: -384179788 | D16: 320350580 | E16: -63829208 | F16: =Table14[[#This Row],[Column5]]/درآمدها!$E$12 -> -0.00021180669 | G16: 0 | H16: 735542210 | I16: -659150962 | J16: 76391248 | K16: =Table14[[#This Row],[-325893784.0000]]/درآمدها!$E$12 -> 0.00025349175
A17: گروه صنعتی پاکشو (پاکشو) | B17: 0 | C17: -1064621642 | D17: -292069006 | E17: -1356690648 | F17: =Table14[[#This Row],[Column5]]/درآمدها!$E$12 -> -0.004501954 | G17: 383205942 | H17: 0 | I17: 19965177 | J17: 403171119 | K17: =Table14[[#This Row],[-325893784.0000]]/درآمدها!$E$12 -> 0.0013378568
A18: سر. غدیر (وغدیر) | B18: 0 | C18: 2142652946 | D18: 3091044222 | E18: 5233697168 | F18: =Table14[[#This Row],[Column5]]/درآمدها!$E$12 -> 0.01736716 | G18: 0 | H18: 7164401517 | I18: 3815695707 | J18: 10980097224 | K18: =Table14[[#This Row],[-325893784.0000]]/درآمدها!$E$12 -> 0.03643564
A19: بانک تجارت (وتجارت) | B19: 0 | C19: -1107796057 | D19: -54770289 | E19: -1162566346 | F19: =Table14[[#This Row],[Column5]]/درآمدها!$E$12 -> -0.0038577845 | G19: 71914238 | H19: -337357037 | I19: -1139082478 | J19: -1404525277 | K19: =Table14[[#This Row],[-325893784.0000]]/درآمدها!$E$12 -> -0.0046606853
A20: پالایش نفت اصفهان (شپنا) | B20: 0 | C20: -1499336565 | D20: 7676102612 | E20: 6176766047 | F20: =Table14[[#This Row],[Column5]]/درآمدها!$E$12 -> 0.020496579 | G20: 1380675960 | H20: 7681483570 | I20: 10580874183 | J20: 19643033713 | K20: =Table14[[#This Row],[-325893784.0000]]/درآمدها!$E$12 -> 0.065182165
A21: سر. سپه (وسپه) | B21: 0 | C21: 0 | D21: 0 | E21: 0 | F21: =Table14[[#This Row],[Column5]]/درآمدها!$E$12 -> 0 | G21: 0 | H21: 0 | I21: -702043664 | J21: -702043664 | K21: =Table14[[#This Row],[-325893784.0000]]/درآمدها!$E$12 -> -0.002329616
A22: گسترش نفت و گاز پارسیان (پارسان) | B22: 3946900368 | C22: -3435990086 | D22: 0 | E22: 510910282 | F22: =Table14[[#This Row],[Column5]]/درآمدها!$E$12 -> 0.0016953714 | G22: 3946900368 | H22: 3318567298 | I22: 1219954486 | J22: 8485422152 | K22: =Table14[[#This Row],[-325893784.0000]]/درآمدها!$E$12 -> 0.028157473
... A100: سر. امید (حق تقدم) (وامیدح) | B100: 0 | C100: -2810044275 | D100: 0 | E100: -2810044275 | F100: =Table14[[#This Row],[Column5]]/درآمدها!$E$12 -> -0.0093246681 | G100: 0 | H100: 0 | I100: 0 | J100: 0 | K100: =Table14[[#This Row],[-325893784.0000]]/درآمدها!$E$12 -> 0
A101: جمع | B101: =SUBTOTAL(109,B11:B100) -> 5500643874 | C101: =SUBTOTAL(109,C11:C100) -> 28143016982 | D101: =SUBTOTAL(109,D11:D100) -> 87537444381 | E101: =SUBTOTAL(109,E11:E100) -> 121181105237 | F101: =Table14[[#This Row],[Column5]]/درآمدها!$E$12 -> 0.4021195 | G101: =SUBTOTAL(109,G11:G100) -> 47095350092 | H101: 180838227528 | I101: 61811685674 | J101: 289745263294 | K101: =SUBTOTAL(109,K11:K100) -> 0.96147183

Sheet درآمد سپرده بانکی
A1: صندوق سرمایه گذاری قابل معامله شاخصی شفق رابین
A2: صورت وضعیت درآمدها
A3: برای ماه منتهی به 1404/10/30
A4: 3-2-درآمد حاصل از سرمایه­گذاری در سپرده بانکی و گواهی سپرده:
A6: نام سپرده بانکی | C6: از 1404/10/01 تا 1404/10/30 | E6: از ابتدای سال مالی تا 1404/10/30
A7: نام سپرده | B7: شماره حساب | C7: سود سپرده بانکی و گواهی سپرده | D7: درصد سود به میانگین سپرده | E7: سود سپرده بانکی و گواهی سپرده | F7: درصد سود به میانگین سپرده
C8: یادداشت … | E8: یادداشت …
A9: بلند مدت گردشگری129.333.1709609.2 | B9: 129.333.1709609.2 | C9: 0 | D9: - | E9: 33800925 | F9: -
A10: جمع | C10: 0 | E10: 33800925

Sheet سایر درآمدها
A1: صندوق سرمایه گذاری قابل معامله شاخصی شفق رابین
A2: صورت وضعیت درآمدها
A3: برای ماه منتهی به 1404/10/30
A4: 4-2-سایر درآمدها:
B5: از 1404/10/01 تا 1404/10/30 | C5: از ابتدای سال مالی تا 1404/10/30
A6: سایر درآمدها | B6: مبلغ | C6: مبلغ
A8: سایر درآمدها | B8: 0 | C8: 292888489
A9: تعدیل کارمزد کارگزاری | B9: 1713447837 | C9: 1713447837
A10: جمع | B10: 1713447837 | C10: 2006336326
