Workbook

Sheet 0
A22: ‫سرمایه گذاری قابل معامله شاخصی بازار آشنا
A23: ‫صورت وضعیت پورتفوی
A24: ‫برای ماه منتهی به 1404/02/31

Sheet 1
A1: ‫سرمایه گذاری قابل معامله شاخصی بازار آشنا
A2: ‫صورت وضعیت پورتفوی
A3: ‫برای ماه منتهی به 1404/02/31
A5: ‫1- سرمایه گذاری ها
A6: ‫1-1- سرمایه گذاری در سهام و حق تقدم سهام
C8: ‫1404/01/31 | I8: ‫تغییرات طی دوره | O8: ‫1404/02/31
A9: ‫شرکت | C9: ‫تعداد | E9: ‫بهای تمام شده | G9: ‫خالص ارزش فروش | I9: ‫خرید طی دوره | L9: ‫فروش طی دوره | O9: ‫تعداد | Q9: ‫قیمت بازار هر سهم | S9: ‫بهای تمام شده | U9: ‫خالص ارزش فروش | W9: ‫درصد به کل دارایی ها
I10: ‫تعداد | J10: ‫بهای تمام شده | L10: ‫تعداد | M10: ‫مبلغ فروش
A11: ‫اخشان خراسان | C11: 75000 | E11: 525487200 | G11: 583755862 | I11: 0 | J11: 0 | L11: 0 | M11: 0 | O11: 75000 | Q11: 8940 | S11: 525487200 | U11: 674711437 | W11: =U11/$U$78 -> 0.00048719353
A12: ‫ارتباطات سیار | C12: 1000000 | E12: 4399636215 | G12: 4717761300 | I12: 0 | J12: 0 | L12: 0 | M12: 0 | O12: 1000000 | Q12: 5350 | S12: 4399636215 | U12: 5347989000 | W12: =U12/$U$78 -> 0.0038616592
A13: ‫اقتصاد نوين | C13: 4242039 | E13: 11089731654 | G13: 13253398842 | I13: 0 | J13: 0 | L13: 1000000 | M13: 3621324170 | O13: 3242039 | Q13: 4246 | S13: 8475486086 | U13: 14089858051 | W13: =U13/$U$78 -> 0.010173961
A14: ‫انتقال داده هاي آسياتك | C14: 0 | E14: 0 | G14: 0 | I14: 2700000 | J14: 11676408711 | L14: 0 | M14: 0 | O14: 2700000 | Q14: 3983 | S14: 11676408711 | U14: 10690113105 | W14: =U14/$U$78 -> 0.0077190835
A15: ‫ايران خودرو | C15: 7726948 | E15: 17704787532 | G15: 29663916411 | I15: 10000000 | J15: 6382274721 | L15: 0 | M15: 0 | O15: 75670591 | Q15: 602 | S15: 24087062253 | U15: 45959634451 | W15: =U15/$U$78 -> 0.03318639
A16: ‫بانك تجارت | C16: 44066235 | E16: 14560081342 | G16: 27508937686 | I16: 0 | J16: 0 | L16: 6000000 | M16: 3554722902 | O16: 38066235 | Q16: 575 | S16: 12577600015 | U16: 22022729205 | W16: =U16/$U$78 -> 0.015902104
A17: ‫بانك صادرات | C17: 39560926 | E17: 24801576148 | G17: 25050368018 | I17: 14000000 | J17: 10047648955 | L17: 0 | M17: 0 | O17: 53560926 | Q17: 662 | S17: 34849225103 | U17: 35193119642 | W17: =U17/$U$78 -> 0.025412138
A18: ‫بانك ملت | C18: 25392957 | E18: 22714344403 | G18: 73479080385 | I18: 0 | J18: 0 | L18: 0 | M18: 0 | O18: 25392957 | Q18: 2587 | S18: 22714344403 | U18: 66007487189 | W18: =U18/$U$78 -> 0.047662481
A19: ‫بين المللي توسعه ص. معادن غدير | C19: 1700000 | E19: 8016464339 | G19: 6766299540 | I19: 0 | J19: 0 | L19: 0 | M19: 0 | O19: 1700000 | Q19: 4438 | S19: 8016464339 | U19: 7513228710 | W19: =U19/$U$78 -> 0.0054251288
A20: ‫توسعه نيشكر و صنايع جانبي | C20: 285750 | E20: 13013430474 | G20: 15253473589 | I20: 0 | J20: 0 | L20: 0 | M20: 0 | O20: 285750 | Q20: 55400 | S20: 13013430474 | U20: 15693750759 | W20: =U20/$U$78 -> 0.011332095
A21: ‫توسعه‌معادن‌وفلزات‌ | C21: 6603333 | E21: 13662777497 | G21: 16777694339 | I21: 0 | J21: 0 | L21: 0 | M21: 0 | O21: 6603333 | Q21: 2362 | S21: 13662777497 | U21: 15635550828 | W21: =U21/$U$78 -> 0.01129007
A22: ‫توليد انرژي برق شمس پاسارگاد | C22: 900000 | E22: 2932719040 | G22: 3117837825 | I22: 0 | J22: 0 | L22: 0 | M22: 0 | O22: 900000 | Q22: 3868 | S22: 2932719040 | U22: 3436331445 | W22: =U22/$U$78 -> 0.0024812955
... A71: ‫گل گهر (تقدم) | C71: 1403444 | E71: 1624688341 | G71: 1330919207 | I71: 0 | J71: 0 | L71: 1403444 | M71: 1452292363 | O71: 0 | Q71: 0 | S71: 0 | U71: 0 | W71: =U71/$U$78 -> 0
A72: ‫جمع | E72: =SUM(E11:$E$71) -> 870387153099 | G72: =SUM(G11:$G$71) -> 1244539141744 | J72: =SUM(J11:$J$71) -> 178892422196 | M72: =SUM(M11:$M$71) -> 82789926720 | S72: =SUM(S11:$S$71) -> 968017703781 | U72: =SUM(U11:$U$71) -> 1346701209797 | W72: =SUM(W11:$W$71) -> 0.97242181
U78: 1384894081856

Sheet 2
A1: ‫سرمایه گذاری قابل معامله شاخصی بازار آشنا
A2: ‫صورت وضعیت پورتفوی
A3: ‫برای ماه منتهی به 1404/02/31
A5: ‫2-1- سرمایه گذاری در سپرده بانکی
C7: ‫مشخصات حساب بانکی | K7: ‫1404/01/31 | M7: ‫تغییرات طی دوره | Q7: ‫1404/02/31
A8: ‫سپرده‌های بانکی | C8: ‫شماره حساب | E8: ‫نوع سپرده | G8: ‫تاریخ افتتاح حساب | I8: ‫نرخ سود علی الحساب | K8: ‫مبلغ | M8: ‫افزایش | O8: ‫کاهش | Q8: ‫مبلغ | S8: ‫درصد به کل دارایی ها
A9: ‫سپرده بانکی نزد بانک پاسارگاد | C9: ‫415.8100.14938708.1 | E9: ‫کوتاه مدت | G9: ‫1400/08/09 | I9: 10 | K9: 869978267 | M9: 3247851428 | O9: 2225473424 | Q9: 1892356271 | S9: =Q9/'1'!$U$78 -> 0.0013664267 | T9: =K9+M9-O9-Q9 -> 0
A10: ‫سپرده بانکی نزد بانک گردشگري | C10: ‫132-711270160-1 | E10: ‫جاري | G10: ‫1401/09/22 | I10: ‫0 | K10: 156818 | M10: 0 | O10: 0 | Q10: 156818 | S10: =Q10/'1'!$U$78 -> 1.1323465e-07 | T10: =K10+M10-O10-Q10 -> 0
A11: ‫سپرده بانکی نزد بانک گردشگري | C11: ‫132.9967.1270160.1 | E11: ‫کوتاه مدت | G11: ‫1403/05/03 | I11: 10 | K11: 777839363 | M11: 158184564444 | O11: 156350200000 | Q11: 2612203807 | S11: =Q11/'1'!$U$78 -> 0.001886212 | T11: =K11+M11-O11-Q11 -> 0
A12: ‫جمع | K12: =SUM(K9:$K$11) -> 1647974448 | M12: =SUM(M9:$M$11) -> 161432415872 | O12: =SUM(O9:$O$11) -> 158575673424 | Q12: =SUM(Q9:$Q$11) -> 4504716896 | S12: =SUM(S9:$S$11) -> 0.0032527519 | T12: =K12+M12-O12-Q12 -> 0

Sheet 3
A1: ‫سرمایه گذاری قابل معامله شاخصی بازار آشنا
A2: ‫صورت وضعیت درآمدها
A3: ‫برای ماه منتهی به 1404/02/31
A5: ‫2- درآمد حاصل از سرمایه گذاری ها
E6: از ابتدای سال مالی تا پایان اردیبهشت ماه
A7: ‫شرح | C7: ‫یادداشت | E7: ‫مبلغ | G7: ‫درصد از کل درآمدها | I7: ‫درصد از کل دارایی ها
A8: ‫درآمد حاصل از سرمایه گذاری در سهام و حق تقدم سهام | C8: ‫1-2 | E8: 227185021368 | G8: =E8/$E$17 -> 0.97895494 | I8: =E8/'1'!$U$78 -> 0.16404505
A9: ‫درآمد حاصل از سرمایه گذاری در سپرده بانکی و گواهی سپرده | C9: ‫2-2 | E9: 4798829524 | G9: =E9/$E$17 -> 0.020678467 | I9: =E9/'1'!$U$78 -> 0.0034651239
A10: ‫سایر درآمدها | C10: ‫3-2 | E10: 85074555 | G10: =E10/$E$17 -> 0.00036659176 | I10: =E10/'1'!$U$78 -> 6.1430369e-05
A11: ‫جمع | E11: =SUM(E8:$E$10) -> 232068925447 | G11: =SUM(G8:$G$10) -> 1 | I11: =SUM(I8:$I$10) -> 0.16757161
E17: 232068925447

Sheet 4
A1: ‫سرمایه گذاری قابل معامله شاخصی بازار آشنا
A2: ‫صورت وضعیت درآمدها
A3: ‫برای ماه منتهی به 1404/02/31
A5: ‫1-2- درآمد سود سهام
C7: ‫اطلاعات مجمع | I7: طی اردیبهشت ماه | O7: از ابتدای سال مالی تا پایان اردیبهشت ماه
A8: ‫نام سهام | C8: ‫تاریخ تشکیل مجمع | E8: ‫تعداد سهام متعلقه در زمان مجمع | G8: ‫سود متعلق به هر سهم | I8: ‫جمع درآمد سود سهام | K8: ‫هزینه تنزیل | M8: ‫خالص درآمد سود سهام | O8: ‫جمع درآمد سود سهام | Q8: ‫هزینه تنزیل | S8: ‫خالص درآمد سود سهام
A9: ‫بين المللي توسعه ص. معادن غدير | C9: ‫1403/10/15 | E9: 1700000 | G9: 560 | O9: 952000000 | Q9: 0 | S9: 952000000 | T9: =I9+K9-M9 -> 0 | U9: =O9+Q9-S9 -> 0
A10: ‫توسعه نيشكر و صنايع جانبي | C10: ‫1403/12/20 | E10: 285750 | G10: 4400 | O10: 1257300000 | Q10: 0 | S10: 1257300000 | T10: =I10+K10-M10 -> 0 | U10: =O10+Q10-S10 -> 0
A11: ‫توليد انرژي برق شمس پاسارگاد | C11: ‫1403/12/22 | E11: 900000 | G11: 325 | O11: 292500000 | Q11: -30506135 | S11: 261993865 | T11: =I11+K11-M11 -> 0 | U11: =O11+Q11-S11 -> 0
A12: ‫سرمايه گذاري غدير | C12: ‫1403/12/08 | E12: 4279048 | G12: 1170 | O12: 5006486160 | Q12: 0 | S12: 5006486160 | T12: =I12+K12-M12 -> 0 | U12: =O12+Q12-S12 -> 0
A13: ‫سرمايه گذاري ملي ايران | C13: ‫1404/01/27 | E13: 1285714 | G13: 500 | O13: 642857000 | Q13: 0 | S13: 642857000 | T13: =I13+K13-M13 -> 0 | U13: =O13+Q13-S13 -> 0
A14: ‫صبا فولاد خليج فارس | C14: ‫1404/01/31 | E14: 2400000 | G14: 560 | I14: 1344000000 | K14: 0 | M14: 1344000000 | O14: 1344000000 | Q14: 0 | S14: 1344000000 | T14: =I14+K14-M14 -> 0 | U14: =O14+Q14-S14 -> 0
A15: ‫نفت و گاز پارسیان | C15: ‫1403/10/19 | E15: 607000 | G15: 7240 | O15: 4394680000 | Q15: 0 | S15: 4394680000 | T15: =I15+K15-M15 -> 0 | U15: =O15+Q15-S15 -> 0
A16: ‫پخش هجرت | C16: ‫1404/02/15 | E16: 350000 | G16: 5330 | I16: 1865500000 | K16: -248142518 | M16: 1617357482 | O16: 1865500000 | Q16: -248142518 | S16: 1617357482 | T16: =I16+K16-M16 -> 0 | U16: =O16+Q16-S16 -> 0
A17: ‫جمع | I17: =SUM(I9:$I$16) -> 3209500000 | K17: =SUM(K9:$K$16) -> -248142518 | M17: =SUM(M9:$M$16) -> 2961357482 | O17: =SUM(O9:$O$16) -> 15755323160 | Q17: =SUM(Q9:$Q$16) -> -278648653 | S17: =SUM(S9:$S$16) -> 15476674507 | T17: =I17+K17-M17 -> 0 | U17: =O17+Q17-S17 -> 0

Sheet 7
A1: ‫سرمایه گذاری قابل معامله شاخصی بازار آشنا
A2: ‫صورت وضعیت درآمدها
A3: ‫برای ماه منتهی به 1404/02/31
A5: 1-2- ‫درآمد ناشی از تغییر قیمت اوراق بهادار
C7: ='6'!C7:I7 -> طی اردیبهشت ماه | K7: ='6'!K7:Q7 -> از ابتدای سال مالی تا پایان اردیبهشت ماه
A8: ‫شرح | C8: ‫تعداد | E8: ‫خالص ارزش فروش | G8: ‫ارزش دفتری | I8: ‫سود و زیان ناشی از تغییر قیمت | K8: ‫تعداد | M8: ‫خالص ارزش فروش | O8: ‫ارزش دفتری | Q8: ‫سود و زیان ناشی از تغییر قیمت
A9: ‫اخشان خراسان | C9: 75000 | E9: 674711437 | G9: 583755862 | I9: 90955575 | K9: 75000 | M9: 674711437 | O9: 525487200 | Q9: 149224237
A10: ‫ارتباطات سیار | C10: 1000000 | E10: 5347989000 | G10: 4717761300 | I10: 630227700 | K10: 1000000 | M10: 5347989000 | O10: 4540820400 | Q10: 807168600
A11: ‫اقتصاد نوين | C11: 3242039 | E11: 14089858051 | G11: 10639153274 | I11: 3450704777 | K11: 3242039 | M11: 14089858051 | O11: 8475486086 | Q11: 5614371965
A12: ‫انتقال داده هاي آسياتك | C12: 2700000 | E12: 10690113105 | G12: 11676408711 | I12: -986295606 | K12: 2700000 | M12: 10690113105 | O12: 11676408711 | Q12: -986295606
A13: ‫ايران خودرو | C13: 75670591 | E13: 45959634451 | G13: 36046191132 | I13: 9913443319 | K13: 75670591 | M13: 45959634451 | O13: 32881630396 | Q13: 13078004055
A14: ‫بانك تجارت | C14: 38066235 | E14: 22022729205 | G14: 24896711114 | I14: -2873981909 | K14: 38066235 | M14: 22022729205 | O14: 16572938428 | Q14: 5449790777
A15: ‫بانك صادرات | C15: 53560926 | E15: 35193119642 | G15: 35098016973 | I15: 95102669 | K15: 53560926 | M15: 35193119642 | O15: 34956720664 | Q15: 236398978
A16: ‫بانك ملت | C16: 25392957 | E16: 66007487189 | G16: 73479080385 | I16: -7471593196 | K16: 25392957 | M16: 66007487189 | O16: 48018380490 | Q16: 17989106699
A17: ‫بين المللي توسعه ص. معادن غدير | C17: 1700000 | E17: 7513228710 | G17: 6766299540 | I17: 746929170 | K17: 1700000 | M17: 7513228710 | O17: 9023985900 | Q17: -1510757190
A18: ‫توسعه نيشكر و صنايع جانبي | C18: 285750 | E18: 15693750759 | G18: 15253473589 | I18: 440277170 | K18: 285750 | M18: 15693750759 | O18: 13013430474 | Q18: 2680320285
A19: ‫توسعه‌معادن‌وفلزات‌ | C19: 6603333 | E19: 15635550828 | G19: 16777694339 | I19: -1142143511 | K19: 6603333 | M19: 15635550828 | O19: 18202576065 | Q19: -2567025237
A20: ‫توليد انرژي برق شمس پاسارگاد | C20: 900000 | E20: 3436331445 | G20: 3117837825 | I20: 318493620 | K20: 900000 | M20: 3436331445 | O20: 2932719040 | Q20: 503612405
... A65: ‫گل گهر | C65: 6710221 | E65: 16342223203 | G65: 14614616750 | I65: 1727606453 | K65: 6710221 | M65: 16342223203 | O65: 21921018887 | Q65: -5578795684
A66: اختيارخ خساپا-3000-1403/12/22 | Q66: 3399125
A67: اختيارخ خساپا-3250-1403/12/22 | Q67: 6998198
A68: اختيارخ خگستر-5500-1404/04/04 | Q68: 258361015
A69: اختيارخ خودرو-3250-1404/02/03 | Q69: -132110973
A70: اختيارخ خودرو-3750-1403/12/01 | Q70: 18005293
A71: اختيارخ خودرو-3750-1404/01/06 | Q71: 2998
A72: اختيارخ خودرو-4000-1403/11/03 | Q72: 552857603
A73: اختيارخ خودرو-4000-1404/01/06 | Q73: 36052714
A74: اختيارخ خودرو-5000-1403/12/01 | Q74: -3898996
A75: اختيارخ خودرو-647-1404/03/07 | Q75: 336473735
A76: اختيارخ خودرو-700-1404/03/07 | Q76: 169936230
A77: اختيارخ ذوب-500-1403/12/22 | Q77: 29992
... A132: اختيارف وبملت-3000-1403/11/24 | Q132: -1887514
A133: ‫جمع | E133: =SUM(E9:E132) -> 1346701209797 | G133: =SUM(G9:G132) -> 1344673494088 | I133: =SUM(I9:I132) -> 2027715709 | M133: =SUM(M9:M132) -> 1346701209797 | O133: =SUM(O9:O132) -> 1176646392823 | Q133: =SUM(Q9:Q132) -> 174897042029

Sheet 6
A1: ‫سرمایه گذاری قابل معامله شاخصی بازار آشنا
A2: ‫صورت وضعیت درآمدها
A3: ‫برای ماه منتهی به 1404/02/31
A5: ‫1-2- سود(زیان) حاصل از فروش اوراق بهادار
C7: ='5'!I7 -> طی اردیبهشت ماه | K7: ='5'!O7 -> از ابتدای سال مالی تا پایان اردیبهشت ماه
A8: ‫شرح | C8: ‫تعداد | E8: ‫خالص ارزش فروش | G8: ‫ارزش دفتری | I8: ‫سود و زیان ناشی از فروش | K8: ‫تعداد | M8: ‫خالص ارزش فروش | O8: ‫ارزش دفتری | Q8: ‫سود و زیان ناشی از فروش
A9: ‫آلومينيوم ايران | K9: 579887 | M9: 3249801158 | O9: 2839489099 | Q9: 410312059
A10: ‫اخشان خراسان | K10: 75000 | M10: 717207107 | O10: 521194307 | Q10: 196012800
A11: ‫ارتباطات سیار | K11: 1000000 | M11: 4170420373 | O11: 4515857909 | Q11: -345437536
A12: ‫اقتصاد نوين | C12: 1000000 | E12: 3621324170 | G12: 2592569738 | I12: 1028754432 | K12: 1000000 | M12: 3621324170 | O12: 2592569738 | Q12: 1028754432
A13: ‫بانك تجارت | C13: 6000000 | E13: 3554722902 | G13: 2590949474 | I13: 963773428 | K13: 6000000 | M13: 3554722902 | O13: 2590949474 | Q13: 963773428
A14: ‫توسعه معادن وص.معدني خاورميانه | K14: 491813 | M14: 2682696973 | O14: 2819485476 | Q14: -136788503
A15: ‫توسعه نيشكر و صنايع جانبي | K15: 285750 | M15: 15769900291 | O15: 12919038315 | Q15: 2850861976
A16: ‫توسعه‌معادن‌وفلزات‌ | K16: 2000000 | M16: 4769451925 | O16: 5871486070 | Q16: -1102034145
A17: ‫توليد انرژي برق شمس پاسارگاد | K17: 900000 | M17: 3867396344 | O17: 2909570409 | Q17: 957825935
A18: ‫توليدي برنا باطري | K18: 800000 | M18: 6202872074 | O18: 5195551274 | Q18: 1007320800
A19: ‫دارويي و نهاده هاي زاگرس دارو | K19: 595000 | M19: 17461482461 | O19: 11150692921 | Q19: 6310789540
A20: ‫ذوب آهن اصفهان | K20: 24500000 | M20: 10435935006 | O20: 12893982706 | Q20: -2458047700
A21: ‫سرمايه گذاري اميد | C21: 700000 | E21: 13113781594 | G21: 11995700499 | I21: 1118081095 | K21: 700000 | M21: 13113781594 | O21: 11995700499 | Q21: 1118081095
A22: ‫سرمايه گذاري تامين اجتماعي | K22: 6600000 | M22: 8504700751 | O22: 9265330938 | Q22: -760630187
A23: ‫سرمايه گذاري جامي | K23: 24869520 | M23: 29276157072 | O23: 29713114579 | Q23: -436957507
A24: ‫سرمايه گذاري دارويي تامين | C24: 100000 | E24: 3130082309 | G24: 2654609820 | I24: 475472489 | K24: 300000 | M24: 9187205683 | O24: 7809283394 | Q24: 1377922289
A25: ‫سرمايه گذاري غدير | K25: 379048 | M25: 3555752666 | O25: 3972718969 | Q25: -416966303
A26: ‫سرمايه گذاري ملي ايران | K26: 1500000 | M26: 7997741250 | O26: 7322627909 | Q26: 675113341
A27: ‫سرمايه گذاري پايا تدبيرپارسا | C27: 3250000 | E27: 4755535365 | G27: 3875154565 | I27: 880380800 | K27: 3250000 | M27: 4755535365 | O27: 3875154565 | Q27: 880380800
A28: ‫سيمان سپاهان | C28: 200000 | E28: 3244579200 | G28: 2977357612 | I28: 267221588 | K28: 1383146 | M28: 16041014404 | O28: 13226976376 | Q28: 2814038028
A29: ‫صنايع ارتباطي آوا | C29: 250000 | E29: 2184424901 | G29: 1854886835 | I29: 329538066 | K29: 500001 | M29: 4453353147 | O29: 3550397338 | Q29: 902955809
A30: ‫صنايع الكترونيك ماديران | K30: 1500000 | M30: 5355941527 | O30: 4622256727 | Q30: 733684800
A31: ‫صنايع شيميايي كيمياگران امروز | K31: 9506493 | M31: 25599861319 | O31: 24151987937 | Q31: 1447873382
A32: ‫صنايع پتروشيمي خليج فارس | K32: 1899204 | M32: 20137787069 | O32: 17153782575 | Q32: 2984004494
A33: ‫صندوق بازنشستگي | K33: 442665 | M33: 10269779848 | O33: 10032843674 | Q33: 236936174
A34: ‫صنعتی صبانور | K34: 3800000 | M34: 23683463035 | O34: 25997778915 | Q34: -2314315880
A35: ‫فروشگاههاي زنجيره اي افق كوروش | K35: 265 | M35: 5023485 | O35: 4865758 | Q35: 157727
A36: ‫فولاد اميركبير | K36: 800000 | M36: 2926501004 | O36: 3290681565 | Q36: -364180561
A37: ‫فولاد خوزستان | C37: 10714566 | E37: 19957292440 | G37: 22854446815 | I37: -2897154375 | K37: 16214566 | M37: 32438711144 | O37: 39973740709 | Q37: -7535029565
A38: ‫قند چهار محال | K38: 100000 | M38: 596430000 | O38: 536199150 | Q38: 60230850
A39: ‫مديريت نيروگاهي ايرانيان مپنا | K39: 800000 | M39: 14622475665 | O39: 12784409745 | Q39: 1838065920
A40: ‫معادن روي | C40: 2421626 | E40: 13863899230 | G40: 14571250792 | I40: -707351562 | K40: 2421626 | M40: 13863899230 | O40: 14571250792 | Q40: -707351562
A41: ‫معدنكاران نسوز | K41: 175000 | M41: 8066371716 | O41: 7133232866 | Q41: 933138850
A42: ‫ملي مس | K42: 1000000 | M42: 8617419289 | O42: 7791474059 | Q42: 825945230
...

Sheet 12
A1: ‫سرمایه گذاری قابل معامله شاخصی بازار آشنا
A2: ‫صورت وضعیت درآمدها
A3: ‫برای ماه منتهی به 1404/02/31
A5: ‫1-2- درآمد حاصل از سرمایه گذاری در سهام و حق تقدم سهام:
C7: ‫طی دوره | M7: ‫1404/02/31
A8: ‫سهام | C8: ‫درآمد سود سهام | E8: ‫درآمد تغییر ارزش | G8: ‫درآمد فروش | I8: ‫جمع مبلغ | K8: ‫درصد از کل درآمد ها | M8: ‫درآمد سود سهام | O8: ‫درآمد تغییر ارزش | Q8: ‫درآمد فروش | S8: ‫جمع مبلغ | U8: ‫درصد از کل درآمد ها
A9: ‫اخشان خراسان | C9: 0 | E9: 90955575 | G9: 0 | I9: 90955575 | K9: 0.0060396451 | M9: 0 | O9: 149224237 | Q9: 196012800 | S9: 345237037 | U9: 0.0014876487
A10: ‫انتقال داده هاي آسياتك | C10: 0 | E10: -986295606 | G10: 0 | I10: -986295606 | K10: -0.065492142 | M10: 0 | O10: -986295606 | Q10: 0 | S10: -986295606 | U10: -0.0042500115
A11: ‫ايران خودرو | C11: 0 | E11: 9913443319 | G11: 0 | I11: 9913443319 | K11: 0.65827388 | M11: 0 | O11: 13078004055 | Q11: 0 | S11: 13078004055 | U11: 0.056353965
A12: ‫بانك اقتصاد نوين | C12: 0 | E12: 3450704777 | G12: 1028754432 | I12: 4479459209 | K12: 0.29744569 | M12: 0 | O12: 5614371965 | Q12: 1028754432 | S12: 6643126397 | U12: 0.028625661
A13: ‫بانك تجارت | C13: 0 | E13: -2873981909 | G13: 963773428 | I13: -1910208481 | K13: -0.12684194 | M13: 0 | O13: 5449790777 | Q13: 963773428 | S13: 6413564205 | U13: 0.027636463
A14: ‫بانك صادرات ايران | C14: 0 | E14: 95102669 | G14: 0 | I14: 95102669 | K14: 0.006315021 | M14: 0 | O14: 236398978 | Q14: 0 | S14: 236398978 | U14: 0.0010186585
A15: ‫بانك ملت | C15: 0 | E15: -7471593196 | G15: 0 | I15: -7471593196 | K15: -0.4961298 | M15: 0 | O15: 17989106699 | Q15: 0 | S15: 17989106699 | U15: 0.077516224
A16: ‫بين المللي توسعه ص. معادن غدير | C16: 0 | E16: 746929170 | G16: 0 | I16: 746929170 | K16: 0.049597697 | M16: 952000000 | O16: -1510757190 | Q16: 0 | S16: -558757190 | U16: -0.0024077208
A17: ‫توسعه معادن روي ايران | C17: 0 | E17: 210930290 | G17: -707351562 | I17: -496421272 | K17: -0.032963436 | M17: 0 | O17: 0 | Q17: -707351562 | S17: -707351562 | U17: -0.0030480236
A18: ‫توسعه نيشكر و صنايع جانبي | C18: 0 | E18: 440277170 | G18: 0 | I18: 440277170 | K18: 0.029235347 | M18: 1257300000 | O18: 2680320285 | Q18: 2850861976 | S18: 6788482261 | U18: 0.029252009
A19: ‫توليد انرژي برق شمس پاسارگاد | C19: 0 | E19: 318493620 | G19: 0 | I19: 318493620 | K19: 0.021148659 | M19: 292500000 | O19: 503612405 | Q19: 957825935 | S19: 1753938340 | U19: 0.0075578337
A20: ‫توليدي برنا باطري | C20: 0 | E20: 501001200 | G20: 0 | I20: 501001200 | K20: 0.033267553 | M20: 0 | O20: 683906400 | Q20: 1007320800 | S20: 1691227200 | U20: 0.0072876073
... A81: ‫اختيارخ شستا-2200-1404/04/11 | C81: 0 | E81: 899003100 | G81: 0 | I81: 899003100 | K81: 0.059695732 | M81: 0 | O81: 899003100 | Q81: 0 | S81: 899003100 | U81: 0.0038738625
A82: ‫آلومينيوم ايران | M82: 0 | O82: 0 | Q82: 410312059 | S82: 410312059 | U82: 0.0017680612
A83: ‫توسعه معادن وص.معدني خاورميانه | M83: 0 | O83: 0 | Q83: -136788503 | S83: -136788503 | U83: -0.0005894305
A84: ‫توسعه معدني و صنعتي صبانور | M84: 0 | O84: 0 | Q84: -2314315880 | S84: -2314315880 | U84: -0.0099725367
A85: ‫دارويي و نهاده هاي زاگرس دارو | M85: 0 | O85: 0 | Q85: 6310789540 | S85: 6310789540 | U85: 0.0271936
A86: ‫ذوب آهن اصفهان | M86: 0 | O86: 0 | Q86: -2458047700 | S86: -2458047700 | U86: -0.010591886
A87: ‫سرمايه گذاري جامي | M87: 0 | O87: 0 | Q87: -436957507 | S87: -436957507 | U87: -0.0018828781
A88: ‫صنايع شيميايي كيمياگران امروز | M88: 0 | O88: 0 | Q88: 1447873382 | S88: 1447873382 | U88: 0.00623898
A89: ‫فروشگاههاي زنجيره اي افق كوروش | M89: 0 | O89: 0 | Q89: 157727 | S89: 157727 | U89: 6.7965584e-07
A90: ‫فولاد اميركبير كاشان | M90: 0 | O90: 0 | Q90: -364180561 | S90: -364180561 | U90: -0.0015692776
A91: ‫نساجي بابكان | M91: 0 | O91: 0 | Q91: 2697705400 | S91: 2697705400 | U91: 0.011624587
A92: ‫جمع | C92: =SUM(C9:$C$91) -> 3209500000 | E92: =SUM(E9:$E$91) -> 9366812849 | G92: =SUM(G9:$G$91) -> 4158152791 | I92: =SUM(I9:$I$91) -> 16734465640 | K92: =SUM(K9:$K$91) -> 1.1112044 | M92: =SUM(M9:$M$91) -> 15755323160 | O92: =SUM(O9:$O$91) -> 172965543767 | Q92: =SUM(Q9:$Q$91) -> 20169962312 | S92: =SUM(S9:$S$91) -> 208890829239 | U92: =SUM(U9:$U$91) -> 0.90012409

Sheet 5
A1: ‫سرمایه گذاری قابل معامله شاخصی بازار آشنا
A2: ‫صورت وضعیت درآمدها
A3: ‫برای ماه منتهی به 1404/02/31
A5: ‫2-2- سود اوراق بهادار با درآمد ثابت و سپرده بانکی
I7: ='4'!I7:M7 -> طی اردیبهشت ماه | O7: ='4'!O7:S7 -> از ابتدای سال مالی تا پایان اردیبهشت ماه
A8: ‫شرح | C8: ‫تاریخ دریافت سود | E8: ‫تاریخ سررسید | G8: ‫نرخ سود علی الحساب | I8: ‫درآمد سود | K8: ‫هزینه تنزیل | M8: ‫خالص درآمد | O8: ‫درآمد سود | Q8: ‫هزینه تنزیل | S8: ‫خالص درآمد
A9: ‫كوتاه مدت-1.1270160.9967.132-گردشگري | C9: ‫1404/02/03 | E9: ‫- | G9: ‫23 | I9: 451907726 | K9: -1532405 | M9: 450375321 | O9: 4781474622 | Q9: 0 | S9: 4781474622 | T9: =I9+K9-M9 -> 0
A10: ‫كوتاه مدت-1.14938708.8100.415-پاسارگاد | C10: ‫1404/02/01 | E10: ‫- | G10: ‫0 | I10: 3694428 | K10: 0 | M10: 3694428 | O10: 17354902 | Q10: 0 | S10: 17354902 | T10: =I10+K10-M10 -> 0
A11: ‫جمع | I11: =SUM(I9:$I$10) -> 455602154 | K11: =SUM(K9:$K$10) -> -1532405 | M11: =SUM(M9:$M$10) -> 454069749 | O11: =SUM(O9:$O$10) -> 4798829524 | Q11: =SUM(Q9:$Q$10) -> 0 | S11: =SUM(S9:$S$10) -> 4798829524 | T11: =I11+K11-M11 -> 0

Sheet 8
A1: ‫سرمایه گذاری قابل معامله شاخصی بازار آشنا
A2: ‫صورت وضعیت درآمدها
A3: ‫برای ماه منتهی به 1404/02/31
A5: ‫2-2- درآمد حاصل از سرمایه گذاری در سپرده بانکی و گواهی سپرده:
A7: ‫نام سپرده بانکی | E7: ='7'!C7 -> طی اردیبهشت ماه | I7: ='7'!K7 -> از ابتدای سال مالی تا پایان اردیبهشت ماه
A8: ‫نام سپرده | C8: ‫شماره حساب | E8: ‫سود سپرده بانکی و گواهی سپرده | G8: ‫درصد سود به کل سود سپرده | I8: ‫سود سپرده بانکی و گواهی سپرده | K8: ‫درصد سود به کل سود سپرده
A9: ‫سپرده بانکی کوتاه مدت - پاسارگاد | C9: ‫415.8100.14938708.1 | E9: 3694428 | G9: =E9/E11 -> 0.0081088905 | I9: 17354902 | K9: =I9/I11 -> 0.0036164865
A10: ‫سپرده بانکی کوتاه مدت - گردشگري | C10: ‫132.9967.1270160.1 | E10: 451907726 | G10: =E10/E11 -> 0.99189111 | I10: 4781474622 | K10: =I10/I11 -> 0.99638351
A11: ‫جمع | E11: =SUM(E9:$E$10) -> 455602154 | G11: =SUM(G9:$G$10) -> 1 | I11: =SUM(I9:$I$10) -> 4798829524 | K11: =SUM(K9:$K$10) -> 1

Sheet 9
A1: ‫سرمایه گذاری قابل معامله شاخصی بازار آشنا
A2: ‫صورت وضعیت درآمدها
A3: ‫برای ماه منتهی به 1404/02/31
A5: ‫3-2- سایر درآمدها:
C7: ='8'!E7 -> طی اردیبهشت ماه | E7: ='8'!I7 -> از ابتدای سال مالی تا پایان اردیبهشت ماه
A8: ‫سایر درآمدها | C8: ‫مبلغ | E8: ‫مبلغ
A9: تعدیل کارمزد کارگزاری | C9: 29990625 | E9: 85074555
A10: ‫جمع | C10: =SUM(C9:$C$9) -> 29990625 | E10: =SUM(E9:$E$9) -> 85074555
