Workbook

Sheet 0
A18: صندوق ‫سرمایه گذاری قابل معامله شاخصی بازار آشنا
A19: ‫صورت وضعیت پورتفوی
A20: ‫برای ماه منتهی به 1404/01/31
B24: رکن صندوق | D24: شرکت | F24: نماینده | H24: امضا
B25: مدیر صندوق | D25: شرکت سبدگردان سهم آشنا | F25: علی اسماعیلی

Sheet 1
A1: ‫سرمایه گذاری قابل معامله شاخصی بازار آشنا
A2: ‫صورت وضعیت پورتفوی
A3: ‫برای ماه منتهی به 1404/01/31
A5: ‫1- سرمایه گذاری ها
A6: ‫1-1- سرمایه گذاری در سهام و حق تقدم سهام
C8: ‫1403/12/30 | I8: ‫تغییرات طی فروردین ماه | O8: ‫1404/01/31
A9: ‫شرکت | C9: ‫تعداد | E9: ‫بهای تمام شده | G9: ‫خالص ارزش فروش | I9: ‫خرید طی فروردین ماه | L9: ‫فروش طی فروردین ماه | O9: ‫تعداد | Q9: ‫قیمت بازار هر سهم | S9: ‫بهای تمام شده | U9: ‫خالص ارزش فروش | W9: ‫درصد به کل دارایی ها
I10: ‫تعداد | J10: ‫بهای تمام شده | L10: ‫تعداد | M10: ‫مبلغ فروش
A11: ‫آلومينيوم ايران | C11: 112236 | E11: 565484413 | G11: 624781896 | I11: 0 | J11: 0 | L11: 112236 | M11: 660483729 | O11: 0 | Q11: 0 | S11: 0 | U11: 0 | W11: 0
A12: اختیارخ وتجارت-2200-1404/02/17 | C12: 0 | E12: 0 | G12: 0 | I12: 31163829 | J12: 4547775069 | L12: 0 | M12: 0 | O12: 31163829 | Q12: 214 | S12: 4547775069 | U12: 6667342123 | W12: 0.0051501022
A13: اختیارخ شپنا-5500-1404/02/17 | C13: 0 | E13: 0 | G13: 0 | I13: 1634640 | J13: 177150202 | L13: 0 | M13: 0 | O13: 1634640 | Q13: 200 | S13: 177150202 | U13: 326843816 | W13: 0.00025246628
A14: ‫اخشان خراسان | C14: 75000 | E14: 525487200 | G14: 534550387 | I14: 0 | J14: 0 | L14: 0 | M14: 0 | O14: 75000 | Q14: 7820 | S14: 525487200 | U14: 583755862 | W14: 0.00045091467
A15: ‫ارتباطات سیار | C15: 1000000 | E15: 4399636215 | G15: 4205825550 | I15: 0 | J15: 0 | L15: 0 | M15: 0 | O15: 1000000 | Q15: 4613 | S15: 4399636215 | U15: 4717761300 | W15: 0.0036441737
A16: ‫اقتصاد نوين | C16: 4242039 | E16: 11089731654 | G16: 10280555640 | I16: 0 | J16: 0 | L16: 0 | M16: 0 | O16: 4242039 | Q16: 3143 | S16: 11089731654 | U16: 13253398842 | W16: 0.010237417
A17: ‫ايران خودرو | C17: 7726948 | E17: 17704787532 | G17: 29663916411 | I17: 0 | J17: 0 | L17: 0 | M17: 0 | O17: 7726948 | Q17: 3868 | S17: 17704787532 | U17: 29663916411 | W17: 0.022913509
A18: ‫بانك تجارت | C18: 10000000 | E18: 14560081342 | G18: 18032067000 | I18: 0 | J18: 0 | L18: 0 | M18: 0 | O18: 44066235 | Q18: 628 | S18: 14560081342 | U18: 27508937686 | W18: 0.021248923
A19: ‫بانك صادرات | C19: 37560926 | E19: 23562427309 | G19: 20759615801 | I19: 2000000 | J19: 1239148839 | L19: 0 | M19: 0 | O19: 39560926 | Q19: 637 | S19: 24801576148 | U19: 25050368018 | W19: 0.019349833
A20: ‫بانك ملت | C20: 25392957 | E20: 22714344403 | G20: 54598162443 | I20: 0 | J20: 0 | L20: 0 | M20: 0 | O20: 25392957 | Q20: 2911 | S20: 22714344403 | U20: 73479080385 | W20: 0.056757965
A21: ‫بين المللي توسعه ص. معادن غدير | C21: 1700000 | E21: 8016464339 | G21: 6587171730 | I21: 0 | J21: 0 | L21: 0 | M21: 0 | O21: 1700000 | Q21: 3927 | S21: 8016464339 | U21: 6766299540 | W21: 0.0052265406
A22: ‫توسعه نيشكر و صنايع جانبي | C22: 285750 | E22: 13013430474 | G22: 13620187311 | I22: 0 | J22: 0 | L22: 0 | M22: 0 | O22: 285750 | Q22: 53700 | S22: 13013430474 | U22: 15253473589 | W22: 0.011782348
... A71: ‫گل گهر (تقدم) | C71: 1403444 | E71: 1624688341 | G71: 1851289085 | I71: 0 | J71: 0 | L71: 0 | M71: 0 | O71: 1403444 | Q71: 954 | S71: 1624688341 | U71: 1330919207 | W71: 0.0010280513
A72: ‫جمع | E72: =SUM(E11:E71) -> 789375930931 | G72: =SUM(G11:G71) -> 1011814854927 | J72: =SUM(J11:J71) -> 92033146752 | M72: =SUM(M11:M71) -> 8726855445 | S72: =SUM(S11:S71) -> 875112078370 | U72: =SUM(U11:U71) -> 1251533327683 | W72: =SUM(W11:W71) -> 0.96673073

Sheet 2
A1: ‫سرمایه گذاری قابل معامله شاخصی بازار آشنا
A2: ‫صورت وضعیت پورتفوی
A3: ‫برای ماه منتهی به 1404/01/31
A5: ‫1-2- سرمایه گذاری در سپرده بانکی
C7: ‫مشخصات حساب بانکی | K7: ‫1403/12/30 | M7: ‫تغییرات طی دوره | Q7: ‫1404/01/31
A8: ‫سپرده‌های بانکی | C8: ‫شماره حساب | E8: ‫نوع سپرده | G8: ‫تاریخ افتتاح حساب | I8: ‫نرخ سود علی الحساب | K8: ‫مبلغ | M8: ‫افزایش | O8: ‫کاهش | Q8: ‫مبلغ | S8: ‫درصد به کل دارایی ها
A9: ‫سپرده بانکی نزد بانک پاسارگاد | C9: ‫415.8100.14938708.1 | E9: ‫کوتاه مدت | G9: ‫1400/08/09 | I9: 5 | K9: 8832875625 | M9: 50007853271 | O9: 57970750629 | Q9: 869978267 | S9: 0.00067200346
A10: ‫سپرده بانکی نزد بانک گردشگري | C10: ‫132-711270160-1 | E10: ‫جاري | G10: ‫1401/09/22 | I10: ‫0 | K10: 156818 | M10: 0 | O10: 0 | Q10: 156818 | S10: 1.2113204e-07
A11: ‫سپرده بانکی نزد بانک گردشگري | C11: ‫132.9967.1270160.1 | E11: ‫کوتاه مدت | G11: ‫1403/05/03 | I11: ‫23 | K11: 66771719942 | M11: 44438259729 | O11: 110432140308 | Q11: 777839363 | S11: 0.00060083196
A12: ‫جمع | K12: =SUM(K9:$K$11) -> 75604752385 | M12: =SUM(M9:$M$11) -> 94446113000 | O12: =SUM(O9:$O$11) -> 168402890937 | Q12: =SUM(Q9:$Q$11) -> 1647974448 | S12: =SUM(S9:$S$11) -> 0.0012729565

Sheet 3
A1: ‫سرمایه گذاری قابل معامله شاخصی بازار آشنا
A2: ‫صورت وضعیت درآمدها
A3: ‫برای ماه منتهی به 1404/01/31
A5: ‫2- درآمد حاصل از سرمایه گذاری ها
A7: ‫شرح | C7: ‫یادداشت | E7: ‫مبلغ | G7: ‫درصد از کل درآمدها | I7: ‫درصد از کل دارایی ها
A8: ‫درآمد حاصل از سرمایه گذاری در سهام و حق تقدم سهام | C8: 2-1 | E8: ='4'!$S$76 -> 193506377473 | G8: =E8/$E$12 -> 0.89169678 | I8: 0.1494715
A9: ‫درآمد حاصل از سرمایه گذاری در اختیار معامله سهام | C9: ‫2-2 | E9: ='5'!$O$66 -> 19104481691 | G9: =E9/$E$12 -> 0.088035366 | I9: 0.03801187
A10: ‫درآمد حاصل از سرمایه گذاری در سپرده بانکی و گواهی سپرده | C10: 2-3 | E10: ='6'!$I$11 -> 4343227370 | G10: =E10/$E$12 -> 0.020014027 | I10: 0.0033548698
A11: ‫سایر درآمدها | C11: 2-4 | E11: ='7'!E10 -> 55083930 | G11: =E11/$E$12 -> 0.00025383227 | I11: 4.2548869e-05
A12: ‫جمع | E12: =SUM(E8:$E$11) -> 217009170464 | G12: =SUM(G8:$G$11) -> 1 | I12: =SUM(I8:$I$11) -> 0.19088079

Sheet 4
A1: ‫سرمایه گذاری قابل معامله شاخصی بازار آشنا
A2: ‫صورت وضعیت درآمدها
A3: ‫برای ماه منتهی به 1404/01/31
A5: ‫2-1- درآمد حاصل از سرمایه گذاری در سهام و حق تقدم سهام:
C7: طی فروردین ماه | M7: از ابتدای سال مالی تا پایان فروردین ماه
A8: ‫سهام | C8: ‫درآمد سود سهام | E8: ‫درآمد تغییر ارزش | G8: ‫درآمد فروش | I8: ‫جمع مبلغ | K8: ‫درصد از کل درآمد ها | M8: ‫درآمد سود سهام | O8: ‫درآمد تغییر ارزش | Q8: ‫درآمد فروش | S8: ‫جمع مبلغ | U8: ‫درصد از کل درآمد ها
A9: ‫آلومينيوم ايران | C9: 0 | E9: -71439405 | G9: 111094629 | I9: 39655224 | K9: 0.00026405601 | M9: 0 | O9: 0 | Q9: 410312059 | S9: 410312059 | U9: 0.0018907591
A10: ‫اخشان خراسان | C10: 0 | E10: 49205475 | G10: 0 | I10: 49205475 | K10: 0.00032764918 | M10: 0 | O10: 58268662 | Q10: 196012800 | S10: 254281462 | U10: 0.0011717545
A11: ‫بانك اقتصاد نوين | C11: 0 | E11: 2972843202 | G11: 0 | I11: 2972843202 | K11: 0.019795554 | M11: 0 | O11: 2163667188 | Q11: 0 | S11: 2163667188 | U11: 0.0099703952
A12: ‫بانك تجارت | C12: 0 | E12: 9476870686 | G12: 0 | I12: 9476870686 | K12: 0.06310454 | M12: 0 | O12: 8323772686 | Q12: 0 | S12: 8323772686 | U12: 0.038356779
A13: ‫بانك صادرات ايران | C13: 0 | E13: 3051603378 | G13: 0 | I13: 3051603378 | K13: 0.020320002 | M13: 0 | O13: 141296309 | Q13: 0 | S13: 141296309 | U13: 0.00065110755
A14: ‫بانك ملت | C14: 0 | E14: 18880917942 | G14: 0 | I14: 18880917942 | K14: 0.12572416 | M14: 0 | O14: 25460699895 | Q14: 0 | S14: 25460699895 | U14: 0.11732546
A15: ‫بين المللي توسعه ص. معادن غدير | C15: 0 | E15: 179127810 | G15: 0 | I15: 179127810 | K15: 0.0011927754 | M15: 952000000 | O15: -2257686360 | Q15: 0 | S15: -1305686360 | U15: -0.0060167336
A16: ‫توسعه معادن روي ايران | C16: 0 | E16: 722165198 | G16: 0 | I16: 722165198 | K16: 0.0048087501 | M16: 0 | O16: -210930290 | Q16: 0 | S16: -210930290 | U16: -0.00097198791
A17: ‫توسعه نيشكر و صنايع جانبي | C17: 0 | E17: 1633286278 | G17: 0 | I17: 1633286278 | K17: 0.010875719 | M17: 1257300000 | O17: 2240043115 | Q17: 2850861976 | S17: 6348205091 | U17: 0.029253165
A18: ‫توليد انرژي برق شمس پاسارگاد | C18: 0 | E18: 137775330 | G18: 0 | I18: 137775330 | K18: 0.0009174177 | M18: 292500000 | O18: 185118785 | Q18: 957825935 | S18: 1435444720 | U18: 0.0066146731
A19: ‫توليدي برنا باطري | C19: 0 | E19: 302191200 | G19: 0 | I19: 302191200 | K19: 0.0020122293 | M19: 0 | O19: 182905200 | Q19: 1007320800 | S19: 1190226000 | U19: 0.0054846807
A20: ‫س. نفت و گاز و پتروشيمي تامين | C20: 0 | E20: 3255015115 | G20: 0 | I20: 3255015115 | K20: 0.021674479 | M20: 0 | O20: 1078393438 | Q20: -546347714 | S20: 532045724 | U20: 0.00245172
... A75: ‫نساجي بابكان | C75: 0 | E75: 0 | G75: 0 | I75: 0 | K75: 0 | M75: 0 | O75: 0 | Q75: 2697705400 | S75: 2697705400 | U75: 0.012431297
A76: ‫جمع | C76: =SUM(C9:C75) -> 642857000 | E76: =SUM(E9:E75) -> 151700922727 | G76: =SUM(G9:G75) -> 1044233479 | I76: =SUM(I9:I75) -> 153388013206 | K76: =SUM(K9:K75) -> 1.0213794 | M76: =SUM(M9:M75) -> 12545823160 | O76: =SUM(O9:O75) -> 164948744792 | Q76: =SUM(Q9:Q75) -> 16011809521 | S76: =SUM(S9:S75) -> 193506377473 | U76: =SUM(U9:U75) -> 0.89169678

Sheet 5
A1: ‫سرمایه گذاری قابل معامله شاخصی بازار آشنا
A2: ‫صورت وضعیت درآمدها
A3: ‫برای ماه منتهی به 1404/01/31
A5: ‫2-2- درآمد حاصل از سرمایه گذاری در اختیار معامله سهام:
C7: طی فروردین ماه | K7: از ابتدای سال مالی تا پایان فروردین ماه
A8: اختیار معامله | C8: ‫درآمد تغییر ارزش | E8: ‫درآمد فروش | G8: ‫جمع مبلغ | I8: ‫درصد از کل درآمد ها | K8: ‫درآمد تغییر ارزش | M8: ‫درآمد فروش | O8: ‫جمع مبلغ | Q8: ‫درصد از کل درآمد ها
A9: اختيارخ شستا-1350-1403/10/12 | C9: 0 | E9: 0 | G9: =C9+E9 -> 0 | I9: 0 | K9: 322177018 | M9: 2539867414 | O9: =K9+M9 -> 2862044432 | Q9: 0.013188587
A10: اختيارخ ذوب-600-1403/11/24 | C10: 0 | E10: 0 | G10: =C10+E10 -> 0 | I10: 0 | K10: 26803097 | M10: 798978106 | O10: =K10+M10 -> 825781203 | Q10: 0.0038052825
A11: اختيارخ شستا-1450-1403/10/12 | C11: 0 | E11: 0 | G11: =C11+E11 -> 0 | I11: 0 | K11: 136568824 | M11: 288880900 | O11: =K11+M11 -> 425449724 | Q11: 0.001960515
A12: اختيارخ ذوب-700-1403/11/24 | C12: 0 | E12: 0 | G12: =C12+E12 -> 0 | I12: 0 | K12: 25493434 | M12: 416670792 | O12: =K12+M12 -> 442164226 | Q12: 0.0020375371
A13: اختيارخ شستا-1650-1403/11/10 | C13: 0 | E13: 0 | G13: =C13+E13 -> 0 | I13: 0 | K13: -1999485 | M13: 103932028 | O13: =K13+M13 -> 101932543 | Q13: 0.00046971537
A14: اختيارخ شستا-1550-1403/11/10 | C14: 0 | E14: 0 | G14: =C14+E14 -> 0 | I14: 0 | K14: -11996910 | M14: 818500907 | O14: =K14+M14 -> 806503997 | Q14: 0.0037164512
A15: اختيارخ خودرو-4000-1403/11/03 | C15: 0 | E15: 0 | G15: =C15+E15 -> 0 | I15: 0 | K15: 552857603 | M15: 652987649 | O15: =K15+M15 -> 1205845252 | Q15: 0.0055566557
A16: اختيارخ وبصادر-2200-1403/11/17 | C16: 0 | E16: 0 | G16: =C16+E16 -> 0 | I16: 0 | K16: -3551085 | M16: 1027103692 | O16: =K16+M16 -> 1023552607 | Q16: 0.004716633
A17: اختيارخ وبصادر-2400-1403/11/17 | C17: 0 | E17: 0 | G17: =C17+E17 -> 0 | I17: 0 | K17: -2469364 | M17: 394213597 | O17: =K17+M17 -> 391744233 | Q17: 0.0018051967
A18: اختيارخ خودرو-3750-1403/12/01 | C18: 0 | E18: 0 | G18: =C18+E18 -> 0 | I18: 0 | K18: 18005293 | M18: 17872710 | O18: =K18+M18 -> 35878003 | Q18: 0.00016532943
A19: اختيارخ خودرو-5000-1403/12/01 | C19: 0 | E19: 0 | G19: =C19+E19 -> 0 | I19: 0 | K19: -3898996 | M19: 330679973 | O19: =K19+M19 -> 326780977 | Q19: 0.0015058395
A20: اختيارخ شپنا-5500-1403/12/08 | C20: 0 | E20: 0 | G20: =C20+E20 -> 0 | I20: 0 | K20: -79979 | M20: 2313123597 | O20: =K20+M20 -> 2313043618 | Q20: 0.010658737
... A24: اختيارخ وتجارت-2200-1403/12/15 | C24: 0 | E24: 0 | G24: =C24+E24 -> 0 | I24: 0 | K24: -2499356 | M24: 593579598 | O24: =K24+M24 -> 591080242 | Q24: 0.002723757
A25: اختيارخ وتجارت-2200-1404/02/17 | C25: 1701932249 | E25: -451349557 | G25: =C25+E25 -> 1250582692 | I25: 0.0083273739 | K25: =2119567054-128086707 -> 1991480347 | M25: -451349557 | O25: =K25+M25 -> 1540130790 | Q25: 0.007097077
A26: اختيارخ شستا-1650-1403/12/08 | C26: 0 | E26: 0 | G26: =C26+E26 -> 0 | I26: 0 | K26: -9760486 | M26: 853398759 | O26: =K26+M26 -> 843638273 | Q26: 0.0038875697
A27: اختيارخ ذوب-500-1403/12/22 | C27: 0 | E27: 0 | G27: =C27+E27 -> 0 | I27: 0 | K27: 29992 | M27: 836739081 | O27: =K27+M27 -> 836769073 | Q27: 0.0038559157
A28: اختيارخ فولاد-6500-1403/12/01 | C28: 0 | E28: 0 | G28: =C28+E28 -> 0 | I28: 0 | K28: 6238393 | M28: =718839896-182515 -> 718657381 | O28: =K28+M28 -> 724895774 | Q28: 0.0033403924
A29: اختيارخ فولاد-6000-1403/12/01 | C29: 0 | E29: 0 | G29: =C29+E29 -> 0 | I29: 0 | K29: 1519609 | M29: 1596292 | O29: =K29+M29 -> 3115901 | Q29: 1.4358384e-05
A30: اختيارخ شپنا-5000-1403/12/08 | C30: 0 | E30: 0 | G30: =C30+E30 -> 0 | I30: 0 | K30: -22527198 | M30: 299720319 | O30: =K30+M30 -> 277193121 | Q30: 0.0012773337
A31: اختيارخ فملي-10000-1404/01/06 | C31: 0 | E31: 0 | G31: =C31+E31 -> 0 | I31: 0 | K31: -15336050 | M31: 429981911 | O31: =K31+M31 -> 414645861 | Q31: 0.0019107297
A32: اختيارخ فملي-10000-1404/03/07 | C32: -842596102 | E32: 0 | G32: =C32+E32 -> -842596102 | I32: -0.0056106748 | K32: -842596102 | M32: 0 | O32: =K32+M32 -> -842596102 | Q32: -0.0038827673
A33: اختيارخ وبملت-3500-1404/01/27 | C33: -19478929 | E33: -1748667246 | G33: =C33+E33 -> -1768146175 | I33: -0.011773723 | K33: -85859485 | M33: =2137548559-1748667246 -> 388881313 | O33: =K33+M33 -> 303021828 | Q33: 0.0013963549
A34: اختيارخ خساپا-3250-1403/12/22 | C34: 0 | E34: 0 | G34: =C34+E34 -> 0 | I34: 0 | K34: 6998198 | M34: 153286869 | O34: =K34+M34 -> 160285067 | Q34: 0.00073860965
A35: اختيارخ خودرو-3750-1404/01/06 | C35: 0 | E35: 0 | G35: =C35+E35 -> 0 | I35: 0 | K35: 2998 | M35: =16998970-2617102250 -> -2600103280 | O35: =K35+M35 -> -2600100282 | Q35: -0.011981523
A36: اختيارخ خودرو-4000-1404/01/06 | C36: 0 | E36: 0 | G36: =C36+E36 -> 0 | I36: 0 | K36: 36052714 | M36: =21866921-165219669 -> -143352748 | O36: =K36+M36 -> -107300034 | Q36: -0.00049444931
A37: اختيارخ شستا-1500-1404/01/20 | C37: 0 | E37: 0 | G37: =C37+E37 -> 0 | I37: 0 | K37: -59984550 | M37: 64568918 | O37: =K37+M37 -> 4584368 | Q37: 2.1125227e-05
A38: اختيارخ خساپا-3000-1403/12/22 | C38: 0 | E38: 0 | G38: =C38+E38 -> 0 | I38: 0 | K38: 3399125 | M38: 165978980 | O38: =K38+M38 -> 169378105 | Q38: 0.00078051128
A39: اختيارخ خودرو-3250-1404/02/03 | C39: 0 | E39: 0 | G39: =C39+E39 -> 0 | I39: 0 | K39: -132110973 | M39: -987077134 | O39: =K39+M39 -> -1119188107 | Q39: -0.0051573309
A40: اختيارخ خودرو-5000-1404/02/03 | C40: 0 | E40: 0 | G40: =C40+E40 -> 0 | I40: 0 | K40: 0 | M40: 152611430 | O40: =K40+M40 -> 152611430 | Q40: 0.00070324876
A41: اختيارخ وبملت-3750-1404/01/27 | C41: 6669180 | E41: -1845712307 | G41: =C41+E41 -> -1839043127 | I41: -0.012245811 | K41: -20820926 | M41: =9166510-1845712307 -> -1836545797 | O41: =K41+M41 -> -1857366723 | Q41: -0.008558932
A42: اختيارخ شپنا-5500-1404/02/17 | C42: 231713388 | E42: 367896896 | G42: =C42+E42 -> 599610284 | I42: 0.003992682 | K42: =149693614-31749722 -> 117943892 | M42: 367896896 | O42: =K42+M42 -> 485840788 | Q42: 0.002238803
A43: اختيارخ شستا-1400-1404/02/10 | C43: -2207284450 | E43: 0 | G43: =C43+E43 -> -2207284450 | I43: -0.014697855 | K43: -2207284450 | M43: 0 | O43: =K43+M43 -> -2207284450 | Q43: -0.010171388
A44: اختيارخ وبملت-2934-1404/03/21 | C44: -1747009235 | E44: 0 | G44: =C44+E44 -> -1747009235 | I44: -0.011632977 | K44: -1747009235 | M44: 0 | O44: =K44+M44 -> -1747009235 | Q44: -0.0080503936
A45: اختيارف خودرو-3250-1403/11/03 | C45: 0 | E45: 0 | G45: =C45+E45 -> 0 | I45: 0 | K45: -24993562 | M45: 2635614794 | O45: =K45+M45 -> 2610621232 | Q45: 0.012030004
...

Sheet 6
A1: ‫سرمایه گذاری قابل معامله شاخصی بازار آشنا
A2: ‫صورت وضعیت درآمدها
A3: ‫برای ماه منتهی به 1404/01/31
A5: ‫2-3- درآمد حاصل از سرمایه گذاری در سپرده بانکی و گواهی سپرده:
A7: ‫نام سپرده بانکی | E7: طی فروردین ماه | I7: از ابتدای سال مالی تا پایان فروردین ماه
A8: ‫نام سپرده | C8: ‫شماره حساب | E8: ‫سود سپرده بانکی و گواهی سپرده | G8: ‫درصد سود به میانگین سپرده | I8: ‫سود سپرده بانکی و گواهی سپرده | K8: ‫درصد سود به میانگین سپرده
A9: ‫سپرده بانکی کوتاه مدت - پاسارگاد | C9: ‫415.8100.14938708.1 | E9: 7853271 | G9: =E9/$E$11 -> 0.0071736809 | I9: 13660474 | K9: =I9/$I$11 -> 0.0031452358
A10: ‫سپرده بانکی کوتاه مدت - گردشگري | C10: ‫132.9967.1270160.1 | E10: 1086880533 | G10: =E10/$E$11 -> 0.99282632 | I10: 4329566896 | K10: =I10/$I$11 -> 0.99685476
A11: ‫جمع | E11: =SUM(E9:$E$10) -> 1094733804 | G11: =SUM(G9:$G$10) -> 1 | I11: =SUM(I9:$I$10) -> 4343227370 | K11: =SUM(K9:$K$10) -> 1

Sheet 7
A1: ‫سرمایه گذاری قابل معامله شاخصی بازار آشنا
A2: ‫صورت وضعیت درآمدها
A3: ‫برای ماه منتهی به 1404/01/31
A5: ‫2-4- سایر درآمدها:
C7: طی فروردین ماه | E7: از ابتدای سال مالی تا پایان فروردین ماه
A8: ‫سایر درآمدها | C8: ‫مبلغ | E8: ‫مبلغ
A9: تعدیل کارمزد کارگزاری | C9: 5911465 | E9: 55083930
A10: ‫جمع | C10: =SUM(C9:$C$9) -> 5911465 | E10: =SUM(E9:$E$9) -> 55083930

Sheet 9
A1: ‫سرمایه گذاری قابل معامله شاخصی بازار آشنا
A2: ‫صورت وضعیت درآمدها
A3: ‫برای ماه منتهی به 1404/01/31
A5: ‫سود سپرده های بانکی
I7: ‫طی دوره | O7: ‫1404/01/31
A8: ‫شرح | C8: ‫تاریخ دریافت سود | E8: ‫تاریخ سررسید | G8: ‫نرخ سود علی الحساب | I8: ‫درآمد سود | K8: ‫هزینه تنزیل | M8: ‫خالص درآمد | O8: ‫درآمد سود | Q8: ‫هزینه تنزیل | S8: ‫خالص درآمد
A9: ‫كوتاه مدت-1.1270160.9967.132-گردشگري | C9: ‫1404/01/03 | E9: ‫- | G9: ‫23 | I9: 1086880533 | K9: -21415702 | M9: 1065464831 | O9: 4329566896 | Q9: 0 | S9: 4329566896
A10: ‫كوتاه مدت-1.14938708.8100.415-پاسارگاد | C10: ‫1404/01/01 | E10: ‫- | G10: 5 | I10: 7853271 | K10: 0 | M10: 7853271 | O10: 13660474 | Q10: 0 | S10: 13660474
A11: ‫جمع | I11: =SUM(I9:$I$10) -> 1094733804 | K11: =SUM(K9:$K$10) -> -21415702 | M11: =SUM(M9:$M$10) -> 1073318102 | O11: =SUM(O9:$O$10) -> 4343227370 | Q11: =SUM(Q9:$Q$10) -> 0 | S11: =SUM(S9:$S$10) -> 4343227370

Sheet 8
A1: ‫سرمایه گذاری قابل معامله شاخصی بازار آشنا
A2: ‫صورت وضعیت درآمدها
A3: ‫برای ماه منتهی به 1404/01/31
A5: ‫درآمد سود سهام
C7: ‫اطلاعات مجمع | I7: طی فروردین ماه | O7: از ابتدای سال مالی تا پایان فروردین ماه
A8: ‫نام سهام | C8: ‫تاریخ تشکیل مجمع | E8: ‫تعداد سهام متعلقه در زمان مجمع | G8: ‫سود متعلق به هر سهم | I8: ‫جمع درآمد سود سهام | K8: ‫هزینه تنزیل | M8: ‫خالص درآمد سود سهام | O8: ‫جمع درآمد سود سهام | Q8: ‫هزینه تنزیل | S8: ‫خالص درآمد سود سهام
A9: ‫بين المللي توسعه ص. معادن غدير | C9: ‫1403/10/15 | E9: 1700000 | G9: 560 | I9: 0 | K9: 0 | M9: 0 | O9: 952000000 | Q9: 0 | S9: 952000000
A10: ‫توسعه نيشكر و صنايع جانبي | C10: ‫1403/12/20 | E10: 285750 | G10: 4400 | I10: 0 | K10: 0 | M10: 0 | O10: 1257300000 | Q10: -150815371 | S10: 1106484629
A11: ‫توليد انرژي برق شمس پاسارگاد | C11: ‫1403/12/22 | E11: 900000 | G11: 325 | I11: 0 | K11: 0 | M11: 0 | O11: 292500000 | Q11: -35395846 | S11: 257104154
A12: ‫سرمايه گذاري غدير | C12: ‫1403/12/08 | E12: 4279048 | G12: 1170 | I12: 0 | K12: 0 | M12: 0 | O12: 5006486160 | Q12: 0 | S12: 5006486160
A13: ‫سرمايه گذاري ملي ايران | C13: ‫1404/01/27 | E13: 1285714 | G13: 500 | I13: 642857000 | K13: -89454158 | M13: 553402842 | O13: 642857000 | Q13: -89454158 | S13: 553402842
A14: ‫نفت و گاز پارسیان | C14: ‫1403/10/19 | E14: 607000 | G14: 7240 | I14: 0 | K14: 0 | M14: 0 | O14: 4394680000 | Q14: 0 | S14: 4394680000
A15: ‫جمع | I15: =SUM(I9:$I$14) -> 642857000 | K15: =SUM(K9:$K$14) -> -89454158 | M15: =SUM(M9:$M$14) -> 553402842 | O15: =SUM(O9:$O$14) -> 12545823160 | Q15: =SUM(Q9:$Q$14) -> -275665375 | S15: =SUM(S9:$S$14) -> 12270157785

Sheet 10
A1: ‫سرمایه گذاری قابل معامله شاخصی بازار آشنا
A2: ‫صورت وضعیت درآمدها
A3: ‫برای ماه منتهی به 1404/01/31
A5: ‫سود(زیان) حاصل از فروش اوراق بهادار
C7: ='8'!I7 -> طی فروردین ماه | K7: ='8'!O7 -> از ابتدای سال مالی تا پایان فروردین ماه
A8: ‫شرح | C8: ‫تعداد | E8: ‫خالص ارزش فروش | G8: ‫ارزش دفتری | I8: ‫سود و زیان ناشی از فروش | K8: ‫تعداد | M8: ‫خالص ارزش فروش | O8: ‫ارزش دفتری | Q8: ‫سود و زیان ناشی از فروش
A9: ‫آلومينيوم ايران | C9: 112236 | E9: 660483729 | G9: 549389100 | I9: 111094629 | K9: 579887 | M9: 3249801158 | O9: 2839489099 | Q9: 410312059
A10: ‫اختيارخ خساپا-3000-1403/12/22 | C10: 0 | E10: 0 | G10: 0 | I10: 0 | K10: 3400000 | M10: 204947225 | O10: 38968245 | Q10: 165978980
A11: ‫اختيارخ خساپا-3250-1403/12/22 | C11: 0 | E11: 0 | G11: 0 | I11: 0 | K11: 3400000 | M11: 204247405 | O11: 50960536 | Q11: 153286869
A12: ‫اختيارخ خودرو-3750-1403/12/01 | C12: 0 | E12: 0 | G12: 0 | I12: 0 | K12: 542000 | M12: 275318095 | O12: 257445385 | Q12: 17872710
A13: ‫اختيارخ خودرو-3750-1404/01/06 | C13: 0 | E13: 0 | G13: 0 | I13: 0 | K13: 10050000 | M13: 974552024 | O13: 3574655304 | Q13: -2600103280
A14: ‫اختيارخ خودرو-382-1404/02/03 | C14: 0 | E14: 0 | G14: 0 | I14: 0 | K14: 3391000 | M14: 1506997858 | O14: 2494074992 | Q14: -987077134
A15: ‫اختيارخ خودرو-4000-1403/11/03 | C15: 0 | E15: 0 | G15: 0 | I15: 0 | K15: 3531000 | M15: 798637324 | O15: 145649675 | Q15: 652987649
A16: ‫اختيارخ خودرو-4000-1404/01/06 | C16: 0 | E16: 0 | G16: 0 | I16: 0 | K16: 4309000 | M16: 469382136 | O16: 612734884 | Q16: -143352748
A17: ‫اختيارخ خودرو-5000-1403/12/01 | C17: 0 | E17: 0 | G17: 0 | I17: 0 | K17: 7700000 | M17: 587094792 | O17: 256414819 | Q17: 330679973
A18: ‫اختيارخ خودرو-588-1404/02/03 | C18: 0 | E18: 0 | G18: 0 | I18: 0 | K18: 4000000 | M18: 329585143 | O18: 176973713 | Q18: 152611430
A19: ‫اختيارخ ذوب-500-1403/12/22 | C19: 0 | E19: 0 | G19: 0 | I19: 0 | K19: 14000000 | M19: 1232505640 | O19: 395766559 | Q19: 836739081
A20: ‫اختيارخ ذوب-700-1403/11/24 | C20: 0 | E20: 0 | G20: 0 | I20: 0 | K20: 1500000 | M20: 64903292 | O20: -351767500 | Q20: 416670792
... A62: ‫اختيارف وتجارت-545-1404/02/17 | C62: 79326 | E62: 793060 | G62: 793060 | I62: 0 | K62: 79326 | M62: 793060 | O62: 793060 | Q62: 0
A63: اختيارخ شستا-1350-1403/10/12 | Q63: 2539867414
A64: اختيارخ ذوب-600-1403/11/24 | Q64: 798978106
A65: اختيارخ شستا-1450-1403/10/12 | Q65: 288880900
A66: اختيارخ شستا-1650-1403/11/10 | Q66: 103932028
A67: ‫اخشان خراسان | C67: 0 | E67: 0 | G67: 0 | I67: 0 | K67: 75000 | M67: 717207107 | O67: 521194307 | Q67: 196012800
A68: ‫ارتباطات سیار | C68: 0 | E68: 0 | G68: 0 | I68: 0 | K68: 1000000 | M68: 4170420373 | O68: 4515857909 | Q68: -345437536
A69: ‫توسعه معادن وص.معدني خاورميانه | C69: 0 | E69: 0 | G69: 0 | I69: 0 | K69: 491813 | M69: 2682696973 | O69: 2819485476 | Q69: -136788503
A70: ‫توسعه نيشكر و صنايع جانبي | C70: 0 | E70: 0 | G70: 0 | I70: 0 | K70: 285750 | M70: 15769900291 | O70: 12919038315 | Q70: 2850861976
A71: ‫توسعه‌معادن‌وفلزات‌ | C71: 0 | E71: 0 | G71: 0 | I71: 0 | K71: 2000000 | M71: 4769451925 | O71: 5871486070 | Q71: -1102034145
A72: ‫توليد انرژي برق شمس پاسارگاد | C72: 0 | E72: 0 | G72: 0 | I72: 0 | K72: 900000 | M72: 3867396344 | O72: 2909570409 | Q72: 957825935
A73: ‫توليدي برنا باطري | C73: 0 | E73: 0 | G73: 0 | I73: 0 | K73: 800000 | M73: 6202872074 | O73: 5195551274 | Q73: 1007320800
A74: ‫دارويي و نهاده هاي زاگرس دارو | C74: 0 | E74: 0 | G74: 0 | I74: 0 | K74: 595000 | M74: 17461482461 | O74: 11150692921 | Q74: 6310789540
A75: ‫ذوب آهن اصفهان | C75: 0 | E75: 0 | G75: 0 | I75: 0 | K75: 24500000 | M75: 10435935006 | O75: 12893982706 | Q75: -2458047700
A76: ‫سرمايه گذاري تامين اجتماعي | C76: 0 | E76: 0 | G76: 0 | I76: 0 | K76: 6600000 | M76: 8504700751 | O76: 9265330938 | Q76: -760630187
A77: ‫سرمايه گذاري جامي | C77: 0 | E77: 0 | G77: 0 | I77: 0 | K77: 24869520 | M77: 29276157072 | O77: 29713114579 | Q77: -436957507
A78: ‫سرمايه گذاري دارويي تامين | C78: 0 | E78: 0 | G78: 0 | I78: 0 | K78: 200000 | M78: 6057123374 | O78: 5154673574 | Q78: 902449800
... A103: ‫چادرملو | C103: 0 | E103: 0 | G103: 0 | I103: 0 | K103: 1200000 | M103: 3796872247 | O103: 4593207100 | Q103: -796334853
A104: ‫جمع | E104: =SUM(E9:$E$103) -> 15285475852 | G104: =SUM(G9:$G$103) -> 13184244094 | I104: =SUM(I9:$I$103) -> 2101231758 | M104: =SUM(M9:$M$103) -> 370490453686 | O104: =SUM(O9:$O$103) -> 338106896557 | Q104: =SUM(Q9:$Q$103) -> 36115215577

Sheet 11
A1: ‫سرمایه گذاری قابل معامله شاخصی بازار آشنا
A2: ‫صورت وضعیت درآمدها
A3: ‫برای ماه منتهی به 1404/01/31
A5: ‫درآمد ناشی از تغییر قیمت اوراق بهادار
C7: ='10'!C7:I7 -> طی فروردین ماه | K7: ='10'!K7:Q7 -> از ابتدای سال مالی تا پایان فروردین ماه
A8: ‫شرح | C8: ‫تعداد | E8: ‫خالص ارزش فروش | G8: ‫ارزش دفتری | I8: ‫سود و زیان ناشی از تغییر قیمت | K8: ‫تعداد | M8: ‫خالص ارزش فروش | O8: ‫ارزش دفتری | Q8: ‫سود و زیان ناشی از تغییر قیمت
A9: ‫آلومينيوم ايران | C9: 0 | E9: 0 | G9: 71439405 | I9: -71439405 | K9: 0 | M9: 0 | O9: 0 | Q9: 0
A10: ‫اختيارخ شستا-1400-1404/02/10 | C10: -10000000 | E10: -2739294450 | G10: -532010000 | I10: -2207284450 | K10: -10000000 | M10: -2739294450 | O10: -532010000 | Q10: -2207284450
A11: ‫اختيارخ شپنا-3873-1404/02/17 | C11: 1634640 | E11: 295094094 | G11: 63380706 | I11: 231713388 | K11: 1634640 | M11: 295094094 | O11: 177150202 | Q11: 117943892
A12: ‫اختيارخ فملي-10000-1404/03/07 | C12: -1446000 | E12: -1280826102 | G12: -438230000 | I12: -842596102 | K12: -1446000 | M12: -1280826102 | O12: -438230000 | Q12: -842596102
A13: ‫اختيارخ وبملت-2934-1404/03/21 | C13: -9128328 | E13: -3531753275 | G13: -1784744040 | I13: -1747009235 | K13: -9128328 | M13: -3531753275 | O13: -1784744040 | Q13: -1747009235
A14: ‫اختيارخ وتجارت-499-1404/02/17 | C14: 31163829 | E14: 6539255416 | G14: 4837323167 | I14: 1701932249 | K14: 31163829 | M14: 6539255416 | O14: 4547775069 | Q14: 1991480347
A15: ‫اختيارف شستا-1500-1404/02/10 | C15: -60000000 | E15: -1139706450 | G15: -1212733000 | I15: 73026550 | K15: -60000000 | M15: -1139706450 | O15: -1212733000 | Q15: 73026550
A16: ‫اختيارف شستا-1500-1404/03/13 | C16: -1000000 | E16: -59984550 | G16: -70000000 | I16: 10015450 | K16: -1000000 | M16: -59984550 | O16: -70000000 | Q16: 10015450
A17: ‫اختيارف فملي-9000-1404/03/07 | C17: -486000 | E17: -72881228 | G17: -64317951 | I17: -8563277 | K17: -486000 | M17: -72881228 | O17: -64317951 | Q17: -8563277
A18: ‫اختيارف فولاد-3960-1404/03/13 | C18: -287523 | E18: -5748979 | G18: -23001840 | I18: 17252861 | K18: -287523 | M18: -5748979 | O18: -23001840 | Q18: 17252861
A19: ‫اختيارف وبملت-1907-1404/03/21 | C19: -1073520 | E19: -11805679 | G19: -28627200 | I19: 16821521 | K19: -1073520 | M19: -11805679 | O19: -28627200 | Q19: 16821521
A20: ‫اختيارف وبملت-2347-1404/03/21 | C20: -13666080 | E20: -314238903 | G20: -711234264 | I20: 396995361 | K20: -13666080 | M20: -314238903 | O20: -711234264 | Q20: 396995361
... A79: ‫گل گهر (تقدم) | C79: 1403444 | E79: 1330919207 | G79: 1851289085 | I79: -520369878 | K79: 1403444 | M79: 1330919207 | O79: 1624688341 | Q79: -293769134
A80: اختيارخ خودرو-4000-1403/11/03 | Q80: 552857603
A81: اختيارخ شستا-1350-1403/10/12 | Q81: 322177018
A82: اختيارف شستا-1400-1404/02/10 | Q82: 186951848
A83: اختيارخ وتجارت-1800-1403/12/15 | Q83: 180993382
A84: اختيارخ شستا-1450-1403/10/12 | Q84: 136568824
A85: اختيارف خودرو-3250-1403/12/01 | Q85: 51986610
A86: اختيارخ خودرو-4000-1404/01/06 | Q86: 36052714
A87: اختيارخ ذوب-600-1403/11/24 | Q87: 26803097
A88: اختيارخ ذوب-700-1403/11/24 | Q88: 25493434
A89: اختيارف خودرو-3500-1403/12/01 | Q89: 24667646
A90: اختيارخ خودرو-3750-1403/12/01 | Q90: 18005293
A91: اختيارف وبملت-1907-1404/01/27 | Q91: 17717036
... A119: اختيارخ خودرو-3250-1404/02/03 | Q119: -132110973
A120: ‫جمع | E120: =SUM(E9:E79) -> 1242216458582 | G120: =SUM(G9:G79) -> 1092873231335 | I120: =SUM(I9:I79) -> 149343227247 | M120: =SUM(M9:M79) -> 1242216458582 | O120: =SUM(O9:O79) -> 1079449630668 | Q120: =SUM(Q9:Q119) -> 163949820427
