Workbook

Sheet 0
A22: ‫سرمایه گذاری قابل معامله شاخصی بازار آشنا
A23: ‫صورت وضعیت پورتفوی
A24: ‫برای ماه منتهی به 1404/05/31

Sheet 1
A1: ‫سرمایه گذاری قابل معامله شاخصی بازار آشنا
A2: ‫صورت وضعیت پورتفوی
A3: ‫برای ماه منتهی به 1404/05/31
A5: ‫1- سرمایه گذاری ها
A6: ‫1-1- سرمایه گذاری در سهام و حق تقدم سهام
C8: ‫1404/04/31 | I8: ‫تغییرات طی مرداد ماه | O8: ‫1404/05/31
A9: ‫شرکت | C9: ‫تعداد | E9: ‫بهای تمام شده | G9: ‫خالص ارزش فروش | I9: ‫خرید طی دوره | L9: ‫فروش طی دوره | O9: ‫تعداد | Q9: ‫قیمت بازار هر سهم | S9: ‫بهای تمام شده | U9: ‫خالص ارزش فروش | W9: ‫درصد به کل دارایی ها
I10: ‫تعداد | J10: ‫بهای تمام شده | L10: ‫تعداد | M10: ‫مبلغ فروش
A11: ‫ارتباطات سیار | C11: 1000000 | E11: 4399636215 | G11: 4389724800 | I11: 0 | J11: 0 | L11: 1000000 | M11: 4146649571
A12: ‫اقتصاد نوين | C12: 5242039 | E12: 17597870612 | G12: 19134237043 | I12: 0 | J12: 0 | L12: 242039 | M12: 770878777 | O12: 5000000 | Q12: 3281 | S12: 16785329728 | U12: 16406795250 | W12: 0.022228522
A13: ‫ايران خودرو | C13: 79659591 | E13: 26481658953 | G13: 37217239724 | I13: 0 | J13: 0 | L13: 21659591 | M13: 8587556258 | O13: 58000000 | Q13: 384 | S13: 19281246614 | U13: 22024171800 | W13: 0.029839148
A14: ‫بانك تجارت | C14: 26466235 | E14: 8744802782 | G14: 12522970189 | I14: 0 | J14: 0 | L14: 26466235 | M14: 10889436543
A15: ‫بانك ملت | C15: 20000000 | E15: 17890271230 | G15: 48728331000 | O15: 39313066 | Q15: 1008 | S15: 17890271230 | U15: 39352707330 | W15: 0.053316478
A16: ‫توسعه‌معادن‌وفلزات‌ | C16: 6603333 | E16: 13662777497 | G16: 12767063963 | I16: 0 | J16: 0 | L16: 5153333 | M16: 8410374461 | O16: 1450000 | Q16: 1564 | S16: 3000155735 | U16: 2248541100 | W16: 0.0030464052
A17: ‫سرمايه گذاري تامين اجتماعي | C17: 30000000 | E17: 40111703839 | G17: 38767950000 | I17: 0 | J17: 0 | L17: 14000000 | M17: 17051986481 | O17: 16000000 | Q17: 1098 | S17: 21392908714 | U17: 17479375200 | W17: 0.023681693
A18: ‫سرمايه گذاري دارويي تامين | C18: 500000 | E18: 12833873485 | G18: 13936581000 | I18: 0 | J18: 0 | L18: 150000 | M18: 3823116323 | O18: 350000 | Q18: 24800 | S18: 8983711439 | U18: 8729250075 | W18: 0.011826705
A19: ‫سرمايه گذاري صدرتامين | C19: 1288004 | E19: 14045283146 | G19: 14429436040 | O19: 1288004 | Q19: 10320 | S19: 14045283146 | U19: 13225916086 | W19: 0.017918952
A20: ‫سرمايه گذاري غدير | C20: 4400000 | E20: 35677020520 | G20: 42032410200 | I20: 0 | J20: 0 | L20: 1200000 | M20: 9932547737 | O20: 3200000 | Q20: 7950 | S20: 25946924014 | U20: 24906916800 | W20: 0.033744796
A21: ‫سرمايه گذاري مهر | C21: 750000 | E21: 2327157600 | G21: 2730903862 | O21: 750000 | Q21: 3096 | S21: 2327157600 | U21: 2299237650 | W21: 0.0031150907
A22: ‫سرمايه گذاري پايا تدبيرپارسا | C22: 3250000 | E22: 3903619200 | G22: 3889717650 | O22: 3250000 | Q22: 1094 | S22: 3903619200 | U22: 3537575437 | W22: 0.0047928358
A23: ‫سيمان تهران | C23: 2000000 | E23: 19533230776 | G23: 19105641000 | I23: 500000 | J23: 3638373248 | L23: 0 | M23: 0 | O23: 2500000 | Q23: 7390 | S23: 23171604024 | U23: 18539032500 | W23: 0.025117355
A24: ‫صنايع غذايي رضوي | C24: 1875000 | E24: 6098945898 | G24: 6504814687 | O24: 1875000 | Q24: 3268 | S24: 6098945898 | U24: 6038853750 | W24: 0.0081816585
A25: ‫صنايع پتروشيمي خليج فارس | C25: 10000000 | E25: 48734682997 | G25: 75348990000 | I25: 0 | J25: 0 | L25: 900000 | M25: 6218776887 | O25: 9100000 | Q25: 6800 | S25: 44348561527 | U25: 61240438350 | W25: 0.082970772
A26: ‫صندوق بازنشستگي | C26: 650000 | E26: 12030071874 | G26: 12987263250 | I26: 0 | J26: 0 | L26: 200000 | M26: 3123305112 | O26: 450000 | Q26: 14260 | S26: 8328511297 | U26: 6316193700 | W26: 0.0085574088
A27: ‫فولاد مباركه | C27: 18000000 | E27: 59837986567 | G27: 56058455700 | I27: 0 | J27: 0 | L27: 3600000 | M27: 8848962363 | O27: 14400000 | Q27: 2146 | S27: 47870389253 | U27: 30489501600 | W27: 0.041308285
A28: ‫قند چهار محال | C28: 1800000 | E28: 7757852041 | G28: 5868871200 | I28: 0 | J28: 0 | L28: 1800000 | M28: 5444809517
A29: ‫كشتيراني ايران | C29: 1200000 | E29: 7920501074 | G29: 8707878000 | I29: 0 | J29: 0 | L29: 1200000 | M29: 7407660636
A30: ‫مخابرات | C30: 14000000 | E30: 7253339611 | G30: 7584601500 | I30: 0 | J30: 0 | L30: 14000000 | M30: 6401682053
A31: ‫معدنكاران نسوز | C31: 175000 | E31: 7181514900 | G31: 8036894250 | O31: 175000 | Q31: 40800 | S31: 7181514900 | U31: 7045329375 | W31: 0.0095452683
A32: ‫ملي مس | C32: 12000000 | E32: 48760441909 | G32: 80637336000 | I32: 0 | J32: 0 | L32: 1000000 | M32: 5574632612 | O32: 11000000 | Q32: 5440 | S32: 44697071750 | U32: 59593297500 | W32: 0.080739165
A33: ‫مپنا | C33: 1164500 | E33: 16528576490 | G33: 16182845725 | I33: 0 | J33: 0 | L33: 364500 | M33: 4769154935 | O33: 800000 | Q33: 11930 | S33: 11354968821 | U33: 9487213200 | W33: 0.012853621
A34: ‫نفت اصفهان | C34: 9250000 | E34: 24114875525 | G34: 31649060925 | I34: 0 | J34: 0 | L34: 1400000 | M34: 4362023689 | O34: 7850000 | Q34: 3130 | S34: 20465056527 | U34: 24237026505 | W34: 0.032837204
A35: ‫نفت بندر عباس | C35: 1500000 | E35: 15412896106 | G35: 15894859500 | I35: 0 | J35: 0 | L35: 100000 | M35: 1065621606 | O35: 1400000 | Q35: 9250 | S35: 14385369699 | U35: 12789447300 | W35: 0.017327608
A36: ‫نفت بهران | C36: 400000 | E36: 6776045113 | G36: 6008038200 | I36: 0 | J36: 0 | L36: 400000 | M36: 5118865042
A37: ‫نفت تبريز | C37: 650000 | E37: 10326401749 | G37: 11727304875 | I37: 0 | J37: 0 | L37: 50000 | M37: 832086211 | O37: 600000 | Q37: 16380 | S37: 9532063153 | U37: 9775487700 | W37: 0.013244186
A38: ‫نفت تهران | C38: 6485981 | E38: 12347277052 | G38: 15995973134 | I38: 0 | J38: 0 | L38: 1385981 | M38: 3072424933 | O38: 5100000 | Q38: 1987 | S38: 9708803181 | U38: 10012568625 | W38: 0.013565392
A39: ‫نفت و گاز پارسیان | C39: 400000 | E39: 14045770018 | G39: 21892957200 | I39: 0 | J39: 0 | L39: 50000 | M39: 2407092107 | O39: 350000 | Q39: 50360 | S39: 12290048766 | U39: 17423708400 | W39: 0.023606273
A40: ‫پارس مينو | C40: 4300000 | E40: 19240919913 | G40: 18200459070 | I40: 0 | J40: 0 | L40: 400000 | M40: 1641680836 | O40: 3900000 | Q40: 3742 | S40: 17451066898 | U40: 14549611635 | W40: 0.019712343
A41: ‫پتروشيمي بوعلي سينا | C41: 220000 | E41: 13591734748 | G41: 13370330358 | I41: 0 | J41: 0 | L41: 220000 | M41: 11235783065
A42: ‫پتروشيمي جم | C42: 227029 | E42: 9721636580 | G42: 11342585199 | I42: 0 | J42: 0 | L42: 27029 | M42: 1164181208 | O42: 200000 | Q42: 38780 | S42: 8564224465 | U42: 7624363500 | W42: 0.010329765
...

Sheet 2
A1: ‫سرمایه گذاری قابل معامله شاخصی بازار آشنا
A2: ‫صورت وضعیت پورتفوی
A3: ‫برای ماه منتهی به 1404/05/31
A5: ‫3-1- سرمایه گذاری در سپرده بانکی
C7: ‫مشخصات حساب بانکی | K7: ‫1404/04/31 | M7: ‫تغییرات طی مرداد ماه | Q7: ‫1404/05/31
A8: ‫سپرده‌های بانکی | C8: ‫شماره حساب | E8: ‫نوع سپرده | G8: ‫تاریخ افتتاح حساب | I8: ‫نرخ سود علی الحساب | K8: ‫مبلغ | M8: ‫افزایش | O8: ‫کاهش | Q8: ‫مبلغ | S8: ‫درصد به کل دارایی ها
A9: ‫سپرده بانکی نزد بانک پاسارگاد | C9: ‫415.8100.14938708.1 | E9: ‫کوتاه مدت | G9: ‫1400/08/09 | I9: ‫0 | K9: 116796324 | M9: 17787547991 | O9: 11512083244 | Q9: 6392261071 | S9: 0.0086604676
A10: ‫سپرده بانکی نزد بانک گردشگري | C10: ‫132-711270160-1 | E10: ‫جاري | G10: ‫1401/09/22 | I10: ‫0 | K10: 156818 | Q10: 156818 | S10: 2.1246273e-07
A11: ‫سپرده بانکی نزد بانک گردشگري | C11: ‫132.9967.1270160.1 | E11: ‫کوتاه مدت | G11: ‫1403/05/03 | I11: ‫23 | K11: 136650511354 | M11: 184904552314 | O11: 241351210000 | Q11: 80203853668 | S11: 0.1086631
A12: ‫جمع | K12: =SUM(K9:$K$11) -> 136767464496 | M12: =SUM(M9:$M$11) -> 202692100305 | O12: =SUM(O9:$O$11) -> 252863293244 | Q12: =SUM(Q9:$Q$11) -> 86596271557 | S12: =SUM(S9:$S$11) -> 0.11732378

Sheet 3
A1: ‫سرمایه گذاری قابل معامله شاخصی بازار آشنا
A2: ‫صورت وضعیت درآمدها
A3: ‫برای ماه منتهی به 1404/05/31
A5: ‫2- درآمد حاصل از سرمایه گذاری ها
E6: از ابتدای سال مالی تا 1404/05/31
A7: ‫شرح | C7: ‫یادداشت | E7: ‫مبلغ | G7: ‫درصد از کل درآمدها | I7: ‫درصد از کل دارایی ها
A8: ‫درآمد حاصل از سرمایه گذاری در سهام و حق تقدم سهام | C8: ‫1-2 | E8: -27033613424 | G8: =E8/-18673526365 -> 1.4476973 | I8: =E8/738096527143 -> -0.036626122
A9: ‫درآمد حاصل از سرمایه گذاری در سپرده بانکی و گواهی سپرده | C9: ‫2-2 | E9: 8219419690 | G9: =E9/-18673526365 -> -0.4401643 | I9: =E9/738096527143 -> 0.011135969
A10: ‫سایر درآمدها | C10: ‫3-2 | E10: 140667369 | G10: =E10/-18673526365 -> -0.0075329837 | I10: =E10/738096527143 -> 0.00019058126
A11: ‫جمع | E11: =SUM(E8:$E$10) -> -18673526365 | G11: =SUM(G8:$G$10) -> 1 | I11: =SUM(I8:$I$10) -> -0.025299572

Sheet 4
A1: ‫سرمایه گذاری قابل معامله شاخصی بازار آشنا
A2: ‫صورت وضعیت درآمدها
A3: ‫برای ماه منتهی به 1404/05/31
A5: ‫1-2- درآمد حاصل از سرمایه گذاری در سهام و حق تقدم سهام:
C7: ='9'!C7:I7 -> تغییرات طی مرداد ماه | M7: ='9'!K7 -> از ابتدای سال مالی تا 1404/05/31
A8: ‫سهام | C8: ‫درآمد سود سهام | E8: ‫درآمد تغییر ارزش | G8: ‫درآمد فروش | I8: ‫جمع مبلغ | K8: ‫درصد از کل درآمد ها | M8: ‫درآمد سود سهام | O8: ‫درآمد تغییر ارزش | Q8: ‫درآمد فروش | S8: ‫جمع مبلغ | U8: ‫درصد از کل درآمد ها
A9: ‫ايران خودرو | C9: 0 | E9: -5601396145 | G9: -952714084 | I9: -6554110229 | K9: 0.067039115 | M9: 0 | O9: -3660383517 | Q9: -952714084 | S9: -4613097601 | U9: 0.24703945
A10: ‫بانك اقتصاد نوين | C10: 0 | E10: -1914900909 | G10: -37047928 | I10: -1951948837 | K10: 0.019965627 | M10: 1258089360 | O10: -378534478 | Q10: 991706504 | S10: 1871261386 | U10: -0.10020932
A11: ‫بانك تجارت | C11: 291128585 | E11: -1000336467 | G11: -568017612 | I11: -1277225494 | K11: 0.013064179 | M11: 291128585 | O11: 0 | Q11: 820651110 | S11: 1111779695 | U11: -0.059537747
A12: ‫بانك ملت | C12: 1800000000 | E12: -9375623670 | G12: 0 | I12: -7575623670 | K12: 0.077487727 | M12: 1800000000 | O12: 1532471988 | Q12: 2282088371 | S12: 5614560359 | U12: -0.30066953
A13: ‫س. نفت و گاز و پتروشيمي تامين | C13: 0 | E13: -698634662 | G13: -2290783978 | I13: -2989418640 | K13: 0.03057745 | M13: 0 | O13: -5811021342 | Q13: -3087240096 | S13: -8898261438 | U13: 0.47651746
A14: ‫سرمايه گذاري تامين اجتماعي | C14: 0 | E14: -767790739 | G14: -3366731235 | I14: -4134521974 | K14: 0.042290209 | M14: 0 | O14: -5972949442 | Q14: -5928526497 | S14: -11901475939 | U14: 0.63734485
A15: ‫سرمايه گذاري توسعه معادن و فلزات (هلدينگ) | C15: 0 | E15: 3687020901 | G15: -5744828168 | I15: -2057807267 | K15: 0.021048407 | M15: 646000000 | O15: -1748491201 | Q15: -6846862313 | S15: -7949353514 | U15: 0.42570179
A16: ‫سرمايه گذاري دارويي تامين | C16: 0 | E16: -1197313034 | G16: -164017891 | I16: -1361330925 | K16: 0.013924456 | M16: 0 | O16: -627458337 | Q16: 1293559138 | S16: 666100801 | U16: -0.035670863
A17: ‫سرمايه گذاري صدرتامين | C17: 0 | E17: -1203519954 | G17: 0 | I17: -1203519954 | K17: 0.012310277 | M17: 0 | O17: -2604624469 | Q17: 0 | S17: -2604624469 | U17: 0.1394822
A18: ‫سرمايه گذاري صندوق بازنشستگي كشوري (هلدينگ) | C18: 1553500000 | E18: -2110368150 | G18: -1418701400 | I18: -1975569550 | K18: 0.020207233 | M18: 1553500000 | O18: -3945384450 | Q18: -1181765226 | S18: -3573649676 | U18: 0.19137519
A19: ‫سرمايه گذاري غدير (هلدينگ) | C19: 0 | E19: -4261356658 | G19: -2872136742 | I19: -7133493400 | K19: 0.072965371 | M19: 5006486160 | O19: -9397447847 | Q19: -4220285512 | S19: -8611247199 | U19: 0.46114735
A20: ‫سرمايه گذاري مهر | C20: 0 | E20: -431666212 | G20: 0 | I20: -431666212 | K20: 0.0044153241 | M20: 0 | O20: -27919950 | Q20: 549092400 | S20: 521172450 | U20: -0.027909696
... A54: ‫اختيارخ خودرو-500-1404/08/07 | C54: 0 | E54: 26966527 | G54: 0 | I54: 26966527 | K54: -0.00027582876 | M54: 0 | O54: 26966527 | Q54: 0 | S54: 26966527 | U54: -0.0014441047
A55: ‫آلومينيوم ايران | M55: 0 | O55: 0 | Q55: 410312059 | S55: 410312059 | U55: -0.021972928
A56: ‫اخشان خراسان | M56: 0 | O56: 0 | Q56: 191025600 | S56: 191025600 | U56: -0.010229755
A57: ‫انتقال داده هاي آسياتك | M57: 0 | O57: 0 | Q57: -1476525993 | S57: -1476525993 | U57: 0.07907055
A58: ‫بانك صادرات ايران | M58: 0 | O58: 0 | Q58: -2841925362 | S58: -2841925362 | U58: 0.15219007
A59: ‫بين المللي توسعه ص. معادن غدير | M59: 952000000 | O59: 0 | Q59: -2453485900 | S59: -1501485900 | U59: 0.080407196
A60: ‫توسعه معادن روي ايران | M60: 0 | O60: 0 | Q60: -707351562 | S60: -707351562 | U60: 0.037879913
A61: ‫توسعه معادن وص.معدني خاورميانه | M61: 0 | O61: 0 | Q61: -136788503 | S61: -136788503 | U61: 0.0073252636
A62: ‫توسعه معدني و صنعتي صبانور | M62: 0 | O62: 0 | Q62: -2314315880 | S62: -2314315880 | U62: 0.12393566
A63: ‫توسعه نيشكر و صنايع جانبي | M63: 1257300000 | O63: 0 | Q63: 2831026152 | S63: 4088326152 | U63: -0.21893702
A64: ‫توليد انرژي برق شمس پاسارگاد | M64: 292500000 | O64: 0 | Q64: 1119306895 | S64: 1411806895 | U64: -0.075604729
A65: ‫توليد نيروي برق دماوند | M65: 0 | O65: 0 | Q65: -201510906 | S65: -201510906 | U65: 0.010791261
A66: ‫توليدي برنا باطري | M66: 0 | O66: 0 | Q66: 694641600 | S66: 694641600 | U66: -0.037199273
... A86: ‫گسترش سرمايه گذاري ايران خودرو | M86: 0 | O86: 0 | Q86: -1517070806 | S86: -1517070806 | U86: 0.081241795
A87: ‫جمع | C87: =SUM(C9:$C$86) -> 21233868375 | E87: =SUM(E9:$E$86) -> -82506134061 | G87: =SUM(G9:$G$86) -> -38684707496 | I87: =SUM(I9:$I$86) -> -99956973182 | K87: =SUM(K9:$K$86) -> 1.022416 | M87: =SUM(M9:$M$86) -> 60677918775 | O87: =SUM(O9:$O$86) -> -86522824790 | Q87: =SUM(Q9:$Q$86) -> -27407010990 | S87: =SUM(S9:$S$86) -> -53251917005 | U87: =SUM(U9:$U$86) -> 2.8517333

Sheet 5
A1: ‫سرمایه گذاری قابل معامله شاخصی بازار آشنا
A2: ‫صورت وضعیت درآمدها
A3: ‫برای ماه منتهی به 1404/05/31
A5: ‫2-2- درآمد حاصل از سرمایه گذاری در سپرده بانکی و گواهی سپرده:
A7: ‫نام سپرده بانکی | E7: ='4'!C7 -> تغییرات طی مرداد ماه | I7: ='4'!M7 -> از ابتدای سال مالی تا 1404/05/31
A8: ‫نام سپرده | C8: ‫شماره حساب | E8: ‫سود سپرده بانکی و گواهی سپرده | G8: ‫درصد سود به کل سود سپرده | I8: ‫سود سپرده بانکی و گواهی سپرده | K8: ‫درصد سود به کل سود سپرده
A9: ‫سپرده بانکی کوتاه مدت - پاسارگاد | C9: ‫415.8100.14938708.1 | E9: 493656 | G9: =E9/E11 -> 0.00024730231 | I9: 21041703 | K9: =I9/I11 -> 0.0025599986
A10: ‫سپرده بانکی کوتاه مدت - گردشگري | C10: ‫132.9967.1270160.1 | E10: 1995670433 | G10: =E10/E11 -> 0.9997527 | I10: 8198377987 | K10: =I10/I11 -> 0.99744
A11: ‫جمع | E11: =SUM(E9:$E$10) -> 1996164089 | G11: =SUM(G9:$G$10) -> 1 | I11: =SUM(I9:$I$10) -> 8219419690 | K11: =SUM(K9:$K$10) -> 1

Sheet 6
A1: ‫سرمایه گذاری قابل معامله شاخصی بازار آشنا
A2: ‫صورت وضعیت درآمدها
A3: ‫برای ماه منتهی به 1404/05/31
A5: ‫3-2- سایر درآمدها:
C7: ='5'!E7 -> تغییرات طی مرداد ماه | E7: ='5'!I7 -> از ابتدای سال مالی تا 1404/05/31
A8: ‫سایر درآمدها | C8: ‫مبلغ | E8: ‫مبلغ
A9: ‫سهم آشنا | C9: 21572798 | E9: 140615461
A10: ‫جمع | C10: =SUM(C9:$C$9) -> 21572798 | E10: =SUM(E9:$E$9) -> 140615461

Sheet 7
A1: ‫سرمایه گذاری قابل معامله شاخصی بازار آشنا
A2: ‫صورت وضعیت درآمدها
A3: ‫برای ماه منتهی به 1404/05/31
A5: ‫درآمد سود سهام
C7: ‫اطلاعات مجمع | I7: تغییرات طی مرداد ماه | O7: ='3'!E6 -> از ابتدای سال مالی تا 1404/05/31
A8: ‫نام سهام | C8: ‫تاریخ تشکیل مجمع | E8: ‫تعداد سهام متعلقه در زمان مجمع | G8: ‫سود متعلق به هر سهم | I8: ‫جمع درآمد سود سهام | K8: ‫هزینه تنزیل | M8: ‫خالص درآمد سود سهام | O8: ‫جمع درآمد سود سهام | Q8: ‫هزینه تنزیل | S8: ‫خالص درآمد سود سهام
A9: ‫ارتباطات سیار | C9: ‫1404/03/21 | E9: 1000000 | G9: 637 | O9: 637000000 | Q9: 0 | S9: 637000000
A10: ‫اقتصاد نوين | C10: ‫1404/04/22 | E10: 5242039 | G10: 240 | O10: 1258089360 | Q10: 0 | S10: 1258089360
A11: ‫بانك تجارت | C11: ‫1404/04/31 | E11: 26466235 | G11: 11 | I11: 291128585 | K11: 0 | M11: 291128585 | O11: 291128585 | Q11: 0 | S11: 291128585
A12: ‫بانك ملت | C12: ‫1404/04/31 | E12: 20000000 | G12: 90 | I12: 1800000000 | K12: 0 | M12: 1800000000 | O12: 1800000000 | Q12: 0 | S12: 1800000000
A13: ‫بين المللي توسعه ص. معادن غدير | C13: ‫1403/10/15 | E13: 1700000 | G13: 560 | O13: 952000000 | Q13: 0 | S13: 952000000
A14: ‫توسعه نيشكر و صنايع جانبي | C14: ‫1403/12/20 | E14: 285750 | G14: 4400 | O14: 1257300000 | Q14: 0 | S14: 1257300000
A15: ‫توسعه‌معادن‌وفلزات‌ | C15: ‫1404/04/29 | E15: 3800000 | G15: 170 | O15: 646000000 | Q15: -80217157 | S15: 565782843
A16: ‫توليد انرژي برق شمس پاسارگاد | C16: ‫1403/12/22 | E16: 900000 | G16: 325 | O16: 292500000 | Q16: 0 | S16: 292500000
A17: ‫سرمايه گذاري غدير | C17: ‫1403/12/08 | E17: 4279048 | G17: 1170 | O17: 5006486160 | Q17: 0 | S17: 5006486160
A18: ‫سرمايه گذاري ملي ايران | C18: ‫1404/01/27 | E18: 1285714 | G18: 500 | O18: 642857000 | Q18: 0 | S18: 642857000
A19: ‫سيمان تهران | C19: ‫1404/04/28 | E19: 2000000 | G19: 1050 | O19: 2100000000 | Q19: -259663866 | S19: 1840336134
A20: ‫صبا فولاد خليج فارس | C20: ‫1404/01/31 | E20: 2400000 | G20: 560 | O20: 1344000000 | Q20: 0 | S20: 1344000000
A21: ‫صنايع الكترونيك ماديران | C21: ‫1404/04/17 | E21: 1500000 | G21: 150 | O21: 225000000 | Q21: -26510574 | S21: 198489426
A22: ‫صنايع غذايي رضوي | C22: ‫1404/04/28 | E22: 1875000 | G22: 300 | O22: 562500000 | Q22: -69552821 | S22: 492947179
A23: ‫صندوق بازنشستگي | C23: ‫1404/05/12 | E23: 650000 | G23: 2390 | I23: 1553500000 | K23: 0 | M23: 1553500000 | O23: 1553500000 | Q23: 0 | S23: 1553500000
A24: ‫فولاد مباركه | C24: ‫1404/05/13 | E24: 17000000 | G24: 280 | I24: 4760000000 | K24: -628252081 | M24: 4131747919 | O24: 4760000000 | Q24: -628252081 | S24: 4131747919
A25: ‫كاني كربن طبس | C25: ‫1404/03/28 | E25: 200000 | G25: 1480 | O25: 296000000 | Q25: -31681957 | S25: 264318043
A26: ‫مخابرات | C26: ‫1404/04/12 | E26: 29010652 | G26: 40 | O26: 1160426080 | Q26: -133624821 | S26: 1026801259
A27: ‫معدنكاران نسوز | C27: ‫1404/05/08 | E27: 175000 | G27: 1500 | I27: 262500000 | K27: -33966905 | M27: 228533095 | O27: 262500000 | Q27: -33966905 | S27: 228533095
A28: ‫ملي مس | C28: ‫1404/04/31 | E28: 12000000 | G28: 370 | I28: 4440000000 | K28: 0 | M28: 4440000000 | O28: 4440000000 | Q28: 0 | S28: 4440000000
A29: ‫نفت اصفهان | C29: ‫1404/04/30 | E29: 9250000 | G29: 360 | O29: 3330000000 | Q29: -415251799 | S29: 2914748201
A30: ‫نفت بندر عباس | C30: ‫1404/05/08 | E30: 1400000 | G30: 936 | I30: 1310400000 | K30: -169562791 | M30: 1140837209 | O30: 1310400000 | Q30: -169562791 | S30: 1140837209
A31: ‫نفت بهران | C31: ‫1404/04/30 | E31: 400000 | G31: 1050 | O31: 420000000 | Q31: -52374101 | S31: 367625899
A32: ‫نفت تبريز | C32: ‫1404/04/28 | E32: 650000 | G32: 1997 | O32: 1298050000 | Q32: -160503181 | S32: 1137546819
A33: ‫نفت تهران | C33: ‫1404/05/12 | E33: 5685981 | G33: 190 | I33: 1080336390 | K33: 0 | M33: 1080336390 | O33: 1080336390 | Q33: 0 | S33: 1080336390
A34: ‫نفت و گاز پارسیان | C34: ‫1403/10/19 | E34: 607000 | G34: 7240 | O34: 4394680000 | Q34: 0 | S34: 4394680000
A35: ‫پارس مينو | C35: ‫1404/03/03 | E35: 4850000 | G35: 390 | O35: 1891500000 | Q35: -176226708 | S35: 1715273292
A36: ‫پتروشيمي بوعلي سينا | C36: ‫1404/04/29 | E36: 219974 | G36: 8363 | O36: 1839640000 | Q36: -228437600 | S36: 1611202400
A37: ‫پتروشيمي جم | C37: ‫1404/04/28 | E37: 227029 | G37: 4200 | O37: 953521800 | Q37: -117902455 | S37: 835619345
A38: ‫پتروشيمي شيراز | C38: ‫1404/05/11 | E38: 500000 | G38: 4984 | I38: 2492000000 | K38: -326333333 | M38: 2165666667 | O38: 2492000000 | Q38: -326333333 | S38: 2165666667
A39: ‫پتروشيمي نوري | C39: ‫1404/05/08 | E39: 700001 | G39: 3400 | I39: 2380003400 | K39: 0 | M39: 2380003400 | O39: 2380003400 | Q39: 0 | S39: 2380003400
A40: ‫پتروشيمي پارس | C40: ‫1404/04/31 | E40: 5400000 | G40: 160 | I40: 864000000 | K40: 0 | M40: 864000000 | O40: 864000000 | Q40: 0 | S40: 864000000
A41: ‫پخش هجرت | C41: ‫1404/02/15 | E41: 350000 | G41: 5330 | O41: 1865500000 | Q41: -153601823 | S41: 1711898177
A42: ‫پست بانك ايران | C42: ‫1404/04/29 | E42: 2000000 | G42: 1624 | O42: 3248000000 | Q42: 0 | S42: 3248000000
...

Sheet 8
A1: ‫سرمایه گذاری قابل معامله شاخصی بازار آشنا
A2: ‫صورت وضعیت درآمدها
A3: ‫برای ماه منتهی به 1404/05/31
A5: ‫سود(زیان) حاصل از فروش اوراق بهادار
C7: ='10'!I7 -> تغییرات طی مرداد ماه | K7: ='10'!O7 -> از ابتدای سال مالی تا 1404/05/31
A8: ‫شرح | C8: ‫تعداد | E8: ‫خالص ارزش فروش | G8: ‫ارزش دفتری | I8: ‫سود و زیان ناشی از فروش | K8: ‫تعداد | M8: ‫خالص ارزش فروش | O8: ‫ارزش دفتری | Q8: ‫سود و زیان ناشی از فروش
A9: ‫آلومينيوم ايران | K9: 579887 | M9: 3249801158 | O9: 2839489099 | Q9: 410312059
A10: ‫اختيارخ اخابر-760-1404/05/22 | K10: 2000000 | M10: 59984551 | O10: 19989701 | Q10: 39994850
A11: ‫اختيارخ خساپا-3000-1403/12/22 | K11: 3400000 | M11: 204947225 | O11: 38968245 | Q11: 165978980
A12: ‫اختيارخ خساپا-3250-1403/12/22 | K12: 3400000 | M12: 204247405 | O12: 50960536 | Q12: 153286869
A13: ‫اختيارخ خساپا-500-1404/05/29 | C13: 2571000 | E13: 2570349 | G13: -651 | I13: 2571000 | K13: 2571000 | M13: 2570349 | O13: -651 | Q13: 2571000
A14: ‫اختيارخ خودرو-3750-1403/12/01 | K14: 542000 | M14: 275318095 | O14: 257445385 | Q14: 17872710
A15: ‫اختيارخ خودرو-3750-1404/01/06 | K15: 10050000 | M15: 974552024 | O15: 3574655304 | Q15: -2600103280
A16: ‫اختيارخ خودرو-382-1404/02/03 | K16: 3391000 | M16: 1506997858 | O16: 2494074992 | Q16: -987077134
A17: ‫اختيارخ خودرو-4000-1403/11/03 | K17: 3531000 | M17: 798637324 | O17: 145649675 | Q17: 652987649
A18: ‫اختيارخ خودرو-4000-1404/01/06 | K18: 4309000 | M18: 469382136 | O18: 612734884 | Q18: -143352748
A19: ‫اختيارخ خودرو-500-1404/07/02 | C19: 4000000 | E19: 87627444 | G19: 51990812 | I19: 35636632 | K19: 4000000 | M19: 87627444 | O19: 51990812 | Q19: 35636632
A20: ‫اختيارخ خودرو-500-1404/08/07 | C20: 5939000 | E20: 133806561 | G20: 133806561 | I20: 0 | K20: 5939000 | M20: 133806561 | O20: 133806561 | Q20: 0
A21: ‫اختيارخ خودرو-5000-1403/12/01 | K21: 7700000 | M21: 587094792 | O21: 256414819 | Q21: 330679973
A22: ‫اختيارخ خودرو-588-1404/02/03 | K22: 4000000 | M22: 329585143 | O22: 176973713 | Q22: 152611430
A23: ‫اختيارخ خودرو-600-1404/04/04 | K23: 29000000 | M23: 1008520372 | O23: 521874659 | Q23: 486645713
A24: ‫اختيارخ خودرو-647-1404/03/07 | K24: 10198800 | M24: 879216085 | O24: 428233453 | Q24: 450982632
A25: ‫اختيارخ خودرو-700-1404/03/07 | K25: 33996000 | M25: 1053604664 | O25: 237761921 | Q25: 815842743
A26: ‫اختيارخ خگستر-5500-1404/04/04 | K26: 2000000 | M26: 1659572560 | O26: 1016231267 | Q26: 643341293
A27: ‫اختيارخ ذوب-400-1404/06/18 | C27: 62444000 | E27: 62428094 | G27: 62428094 | I27: 0 | K27: 62444000 | M27: 62428094 | O27: 62428094 | Q27: 0
A28: ‫اختيارخ ذوب-500-1403/12/22 | K28: 14000000 | M28: 1232505640 | O28: 395766559 | Q28: 836739081
A29: ‫اختيارخ ذوب-700-1403/11/24 | K29: 1500000 | M29: 64903292 | O29: -351767500 | Q29: 416670792
A30: ‫اختيارخ شستا-1300-1404/06/12 | C30: 17000000 | E30: 33991330 | G30: 33991330 | I30: 0 | K30: 17000000 | M30: 33991330 | O30: 33991330 | Q30: 0
A31: ‫اختيارخ شستا-1400-1404/02/10 | K31: 10000000 | M31: 531873060 | O31: 2165796592 | Q31: -1633923532
A32: ‫اختيارخ شستا-1500-1404/01/20 | K32: 16214000 | M32: 903957236 | O32: 839388318 | Q32: 64568918
A33: ‫اختيارخ شستا-1500-1404/05/15 | K33: 4069000 | M33: 104698049 | O33: 28463378 | Q33: 76234671
A34: ‫اختيارخ شستا-1550-1403/11/10 | K34: 28000000 | M34: 2321433191 | O34: 1502932284 | Q34: 818500907
A35: ‫اختيارخ شستا-1600-1404/04/11 | K35: 20000000 | M35: 399897066 | O35: 19902127 | Q35: 379994939
A36: ‫اختيارخ شستا-1650-1403/12/08 | K36: 21751000 | M36: 1603768001 | O36: 750369242 | Q36: 853398759
A37: ‫اختيارخ شستا-1700-1404/04/11 | K37: 11000000 | M37: 207951504 | O37: 77180335 | Q37: 130771169
A38: ‫اختيارخ شستا-1800-1404/04/11 | K38: 1907000 | M38: 55298786 | O38: 13338215 | Q38: 41960571
A39: ‫اختيارخ شستا-2000-1404/03/13 | K39: 9543000 | M39: 688239801 | O39: 209822814 | Q39: 478416987
A40: ‫اختيارخ شستا-2200-1404/04/11 | K40: 40000000 | M40: 1978215683 | O40: 600645330 | Q40: 1377570353
A41: ‫اختيارخ شپنا-3873-1404/02/17 | K41: 5526640 | M41: 782593497 | O41: 591846803 | Q41: 190746694
A42: ‫اختيارخ شپنا-4930-1404/04/18 | K42: 1077780 | M42: 66146467 | O42: 1061042 | Q42: 65085425
...

Sheet 9
A1: ‫سرمایه گذاری قابل معامله شاخصی بازار آشنا
A2: ‫صورت وضعیت درآمدها
A3: ‫برای ماه منتهی به 1404/05/31
A5: ‫درآمد ناشی از تغییر قیمت اوراق بهادار
C7: ='8'!C7:I7 -> تغییرات طی مرداد ماه | K7: ='8'!K7:Q7 -> از ابتدای سال مالی تا 1404/05/31
A8: ‫شرح | C8: ‫تعداد | E8: ‫خالص ارزش فروش | G8: ‫ارزش دفتری | I8: ‫سود و زیان ناشی از تغییر قیمت | K8: ‫تعداد | M8: ‫خالص ارزش فروش | O8: ‫ارزش دفتری | Q8: ‫سود و زیان ناشی از تغییر قیمت
A9: ‫فولاد مباركه | C9: 14400000 | E9: 30489501600 | G9: 41025060229 | I9: -10535558629 | K9: 14400000 | M9: 30489501600 | O9: 60133581882 | Q9: -29644080282
A10: ‫سرمايه گذاري غدير | C10: 3200000 | E10: 24906916800 | G10: 29168273458 | I10: -4261356658 | K10: 3200000 | M10: 24906916800 | O10: 34304364647 | Q10: -9397447847
A11: ‫چادرملو | C11: 5802960 | E11: 10723515809 | G11: 12032949961 | I11: -1309434152 | K11: 5802960 | M11: 10723515809 | O11: 18106932355 | Q11: -7383416546
A12: ‫سرمايه گذاري تامين اجتماعي | C12: 16000000 | E12: 17479375200 | G12: 18247165939 | I12: -767790739 | K12: 16000000 | M12: 17479375200 | O12: 23452324642 | Q12: -5972949442
A13: ‫پتروشیمی تامین | C13: 1100000 | E13: 15767621100 | G13: 16466255762 | I13: -698634662 | K13: 1100000 | M13: 15767621100 | O13: 21578642442 | Q13: -5811021342
A14: ‫سيمان تهران | C14: 2500000 | E14: 18539032500 | G14: 22744014248 | I14: -4204981748 | K14: 2500000 | M14: 18539032500 | O14: 23171604024 | Q14: -4632571524
A15: ‫ملي مس | C15: 11000000 | E15: 59593297500 | G15: 74811066737 | I15: -15217769237 | K15: 11000000 | M15: 59593297500 | O15: 64088961893 | Q15: -4495664393
A16: ‫صندوق بازنشستگي | C16: 450000 | E16: 6316193700 | G16: 8426561850 | I16: -2110368150 | K16: 450000 | M16: 6316193700 | O16: 10261578150 | Q16: -3945384450
A17: ‫پتروشيمي شيراز | C17: 600000 | E17: 16652325600 | G17: 19840752954 | I17: -3188427354 | K17: 600000 | M17: 16652325600 | O17: 20490964280 | Q17: -3838638680
A18: ‫ايران خودرو | C18: 58000000 | E18: 22024171800 | G18: 27625567945 | I18: -5601396145 | K18: 58000000 | M18: 22024171800 | O18: 25684555317 | Q18: -3660383517
A19: ‫نفت و گاز پارسیان | C19: 350000 | E19: 17423708400 | G19: 18892417275 | I19: -1468708875 | K19: 350000 | M19: 17423708400 | O19: 21003779474 | Q19: -3580071074
A20: ‫گل گهر | C20: 1800000 | E20: 2970221400 | G20: -955121083 | I20: 3925342483 | K20: 1800000 | M20: 2970221400 | O20: 5880258489 | Q20: -2910037089
... A47: ‫پويا زركان آق دره | C47: 700000 | E47: 40741139250 | G47: 34078978062 | I47: 6662161188 | K47: 700000 | M47: 40741139250 | O47: 31964666269 | Q47: 8776472981
A48: ‫جمع | C48: 118808218 | E48: =SUM(E9:E47) -> 609581999134 | G48: =SUM(G9:G47) -> 696478726780 | I48: =SUM(I9:I47) -> -86896727646 | K48: =SUM(K9:K47) -> 118808218 | M48: =SUM(M9:M47) -> 609581999134 | O48: =SUM(O9:O47) -> 696104823924 | Q48: =SUM(Q9:Q47) -> -86522824790

Sheet 10
A1: ‫سرمایه گذاری قابل معامله شاخصی بازار آشنا
A2: ‫صورت وضعیت درآمدها
A3: ‫برای ماه منتهی به 1404/05/31
A5: ‫سود اوراق بهادار با درآمد ثابت و سپرده بانکی
I7: ='7'!I7:M7 -> تغییرات طی مرداد ماه | O7: ='7'!O7:S7 -> از ابتدای سال مالی تا 1404/05/31
A8: ‫شرح | C8: ‫تاریخ دریافت سود | E8: ‫تاریخ سررسید | G8: ‫نرخ سود علی الحساب | I8: ‫درآمد سود | K8: ‫هزینه تنزیل | M8: ‫خالص درآمد | O8: ‫درآمد سود | Q8: ‫هزینه تنزیل | S8: ‫خالص درآمد
A9: ‫كوتاه مدت-1.1270160.9967.132-گردشگري | C9: ‫1404/05/03 | E9: ‫- | G9: ‫23 | I9: 1995670433 | K9: -9656205 | M9: 1986014228 | O9: 8198377987 | Q9: -461576 | S9: 8197916411
A10: ‫كوتاه مدت-1.14938708.8100.415-پاسارگاد | C10: ‫1404/05/01 | E10: ‫- | G10: ‫0 | I10: 493656 | K10: 0 | M10: 493656 | O10: 21041703 | Q10: 0 | S10: 21041703
A11: ‫جمع | I11: =SUM(I9:$I$10) -> 1996164089 | K11: =SUM(K9:$K$10) -> -9656205 | M11: =SUM(M9:$M$10) -> 1986507884 | O11: =SUM(O9:$O$10) -> 8219419690 | Q11: =SUM(Q9:$Q$10) -> -461576 | S11: =SUM(S9:$S$10) -> 8218958114
