Workbook

Sheet  سهام
B1: صندوق سرمایه گذاری شاخص سی شرکت بزرگ فیروزه
B2: صورت وضعیت پرتفوی
B3: =AC6 -> برای ماه منتهی به 1404/09/30
B4: 1- سرمایه گذاری ها | AC4: 1404/08/30
B5: 1-1-سرمایه‌گذاری در سهام و حق تقدم سهام | AC5: 1404/09/30
D6: =AC4 -> 1404/08/30 | J6: تغییرات طی دوره | R6: =AC5 -> 1404/09/30 | AC6: برای ماه منتهی به 1404/09/30
B7: شرکت | D7: تعداد | F7: بهای تمام شده | H7: خالص ارزش فروش | J7: خرید طی دوره | N7: فروش طی دوره | R7: تعداد | T7: قیمت بازار هر سهم | V7: بهای تمام شده | X7: خالص ارزش فروش | Z7: درصد به کل دارایی‌ها | AC7: طی آذر ماه
J8: تعداد | L8: بهای تمام شده | N8: تعداد | P8: مبلغ فروش | AC8: از ابتدای سال مالی تا پایان آذر ماه
B9: ایران‌ خودرو | D9: 120000000 | F9: 59836542611 | H9: 63822806400 | I9: 124544524500 | J9: 0 | L9: 0 | N9: 0 | P9: 0 | R9: 120000000 | T9: 622 | V9: 59836542611 | X9: 74063032800 | Z9: =X9/$Z$84 -> 0.0072283204
B10: بانک پاسارگاد | D10: 1000 | F10: 1915216 | H10: 4718243.8 | I10: 91104682500 | J10: 0 | L10: 0 | N10: 0 | P10: 0 | R10: 1000 | T10: 5500 | V10: 1915216 | X10: 5457485 | Z10: =X10/$Z$84 -> 5.3263347e-07
B11: بانک تجارت | D11: 68000000 | F11: 32036253806 | H11: 31645474840 | I11: 6.0450666e+09 | J11: 400000 | L11: 187591990 | N11: -400000 | P11: 214453448 | R11: 68000000 | T11: 590 | V11: 32035402253 | X11: 39809872400 | Z11: =X11/$Z$84 -> 0.003885319
B12: بانک خاورمیانه | D12: 14000000 | F12: 34648837757 | H12: 35562956800 | I12: 3584544.3 | J12: 0 | L12: 0 | N12: 0 | P12: 0 | R12: 14000000 | T12: 2780 | V12: 34648837757 | X12: 38619148400 | Z12: =X12/$Z$84 -> 0.0037691081
B13: بانک ملت | D13: 341420817 | F13: 396644467027 | H13: 404505271097 | I13: 5785371000 | J13: 145000000 | L13: 203650090243 | N13: -15020817 | P13: 19999712144 | R13: 471400000 | T13: 1474 | V13: 582453738612 | X13: 689472458972 | Z13: =X13/$Z$84 -> 0.067290356
B14: بانک‌اقتصادنوین‌ | D14: 25000000 | F14: 94495873076 | H14: 108182236750 | I14: 187875450000 | J14: 0 | L14: 0 | N14: 0 | P14: 0 | R14: 25000000 | T14: 4939 | V14: 94495873076 | X14: 122520538250 | Z14: =X14/$Z$84 -> 0.011957621
B15: بیمه اتکایی ایران معین | D15: 232900 | F15: 394603131 | H15: 4.5988837e+08 | I15: 129972037500 | J15: 0 | L15: 0 | N15: 0 | P15: 0 | R15: 232900 | T15: 2270 | V15: 394603131 | X15: 5.2459628e+08 | Z15: =X15/$Z$84 -> 5.1198956e-05
B16: بین المللی توسعه ص. معادن غدیر | D16: 1000 | F16: 5411279 | H16: 3356849.4 | I16: 156455517600 | J16: 0 | L16: 0 | N16: 0 | P16: 0 | R16: 1000 | T16: 3955 | V16: 5411279 | X16: 3924427.9 | Z16: =X16/$Z$84 -> 3.8301189e-07
B17: پالایش نفت اصفهان | D17: 140400000 | F17: 537229668981 | H17: 729033866964 | I17: 5.882777e+08 | J17: 0 | L17: 0 | N17: -400000 | P17: 2080992714 | R17: 140000000 | T17: 6250 | V17: 535699100124 | X17: 868236250000 | Z17: =X17/$Z$84 -> 0.084737143
B18: پالایش نفت بندرعباس | D18: 97600000 | F18: 340353395163 | H18: 400068975312 | I18: 4419546.3 | J18: 39400000 | L18: 212767560873 | N18: 0 | P18: 0 | R18: 137000000 | T18: 6470 | V18: 553120956036 | X18: 879538205300 | Z18: =X18/$Z$84 -> 0.085840178
B19: پالایش نفت تهران | D19: 20000000 | F19: 49475705739 | H19: 61877957200 | I19: 654830437500 | J19: 0 | L19: 0 | N19: -2000000 | P19: 6058309710 | R19: 18000000 | T19: 3650 | V19: 44528135164 | X19: 65192139000 | Z19: =X19/$Z$84 -> 0.0063625489
B20: پتروشیمی بوعلی سینا | D20: 1000 | F20: 68624286 | H20: 46061173 | I20: 210340980000 | J20: 0 | L20: 0 | N20: 0 | P20: 0 | R20: 1000 | T20: 56790 | V20: 68624286 | X20: 56351013 | Z20: =X20/$Z$84 -> 5.4996827e-06
... B36: سرمایه گذاری پایا تدبیرپارسا | D36: 3250000 | F36: 4390650225 | H36: 3.4667433e+09 | I36: 67794210000 | J36: 0 | L36: 0 | N36: -3250000 | P36: 3519505944 | R36: 0 | T36: 0 | V36: 0 | X36: 0 | Z36: =X36/$Z$84 -> 0
B37: سرمایه گذاری تامین اجتماعی | D37: 304000000 | F37: 482394850099 | H37: 401797906560 | I37: 4413084975 | J37: 0 | L37: 0 | M37: 9102861790 | N37: -4000000 | P37: 5416935122 | R37: 300000000 | T37: 1715 | V37: 476047549439 | X37: 510522915000 | Z37: =X37/$Z$84 -> 0.04982544
B38: سرمایه گذاری سبحان | D38: 57000000 | F38: 128695497864 | H38: 128050458960 | I38: 614223495000 | J38: 1169302 | L38: 2805199480 | N38: -169302 | P38: 424090566 | R38: 58000000 | T38: 2700 | V38: 131117964007 | X38: 155389482000 | Z38: =X38/$Z$84 -> 0.015165527
B39: سرمایه گذاری صدرتامین | D39: 2000000 | F39: 23708180334 | H39: 18992047800 | I39: 72158089500 | J39: 12000000 | L39: 150078539520 | N39: 0 | P39: 0 | R39: 14000000 | T39: 13550 | V39: 173786719854 | X39: 188233619000 | Z39: =X39/$Z$84 -> 0.018371013
B40: سرمایه‌ گذاری‌ آتیه‌ دماوند | D40: 40800000 | F40: 163734617565 | H40: 178901518104 | I40: 266156887500 | J40: 254855 | L40: 1138778036 | N40: -1054855 | P40: 4625313552 | R40: 40000000 | T40: 5390 | V40: 160640153443 | X40: 213933412000 | Z40: =X40/$Z$84 -> 0.020879232
B41: سرمایه‌گذاری‌صندوق‌بازنشستگی‌ | D41: 10000000 | F41: 226006179166 | H41: 159259335000 | I41: 3.4124417e+11 | J41: 2000000 | L41: 37939278702 | N41: 0 | P41: 0 | R41: 12000000 | T41: 21000 | V41: 263945457868 | X41: 250052040000 | Z41: =X41/$Z$84 -> 0.024404297
B42: سرمایه‌گذاری‌غدیر(هلدینگ‌ | D42: 40000000 | F42: 399032730193 | H42: 446124592000 | I42: 484002945000 | J42: 863003 | L42: 12242079469 | N42: 0 | P42: 0 | R42: 40863003 | T42: 14200 | V42: 411274809662 | X42: 5.7576927e+11 | Z42: =X42/$Z$84 -> 0.056193281
B43: صنایع پتروشیمی خلیج فارس | D43: 88800000 | F43: 647362164575 | H43: 783329690640 | I43: 62923365000 | J43: 590132 | L43: 5826976356 | N43: -890132 | P43: 8496605070 | R43: 88500000 | T43: 10430 | V43: 646698425375 | X43: 915919784850 | Z43: =X43/$Z$84 -> 0.089390907
B44: فروشگاههای زنجیره ای افق کوروش | D44: 4000000 | F44: 100823299585 | H44: 104624948800 | I44: 50179644000 | J44: 0 | L44: 0 | N44: 0 | P44: 0 | R44: 4000000 | T44: 31150 | V44: 100823299585 | X44: 123636842000 | Z44: =X44/$Z$84 -> 0.012066569
B45: فولاد مبارکه اصفهان | D45: 76200000 | F45: 227508569626 | H45: 232125690180 | I45: 159048000000 | J45: 62200000 | L45: 218973222626 | N45: -800000 | P45: 2531742076 | R45: 137600000 | T45: 3874 | V45: 444078567408 | X45: 528941827648 | Z45: =X45/$Z$84 -> 0.051623068
B46: گروه س توسعه صنعتی ایران | D46: 60000000 | F46: 98042294767 | H46: 100735250400 | I46: 52485840000 | J46: 0 | L46: 0 | N46: 0 | P46: 0 | R46: 60000000 | T46: 1832 | V46: 98042294767 | X46: 109070318400 | Z46: =X46/$Z$84 -> 0.010644922
B47: گروه مالی صبا تامین | D47: 71080 | F47: 202526955 | H47: 2.2985907e+08 | I47: 151789446900 | J47: 0 | L47: 0 | N47: -71080 | P47: 227379995 | R47: 0 | T47: 0 | V47: 0 | X47: 0 | Z47: =X47/$Z$84 -> 0
B48: گروه مپنا (سهامی عام) | D48: 1000 | F48: 16436086 | H48: 13465104 | I48: 415115280000 | J48: 0 | L48: 0 | N48: 0 | P48: 0 | R48: 1000 | T48: 15200 | V48: 16436086 | X48: 15082504 | Z48: =X48/$Z$84 -> 1.4720052e-06
B49: نقل به صفحه بعد | C49: 0 | D49: =SUM(D9:D48) -> 1635993292 | E49: =AC48=SUM(#REF!) -> #REF! | F49: =SUM(F9:F48) -> 5162518829566 | G49: =SUM(#REF!) -> #REF! | H49: =SUM(H9:H48) -> 5.6190001e+12 | I49: =SUM(#REF!) -> #REF! | J49: =SUM(J9:J48) -> 294577292 | K49: =SUM(#REF!) -> #REF! | L49: =SUM(L9:L48) -> 1273227570791 | M49: =SUM(#REF!) -> #REF! | N49: =SUM(N9:N48) -> -61510786 | O49: =SUM(#REF!) -> #REF! | P49: =SUM(P9:P48) -> 298554556825 | Q49: =SUM(#REF!) -> #REF! | R49: =SUM(R9:R48) -> 1869059798 | S49: =SUM(#REF!) -> #REF! | T49: =SUM(T9:T48) -> 824722 | U49: =SUM(#REF!) -> #REF! | V49: =SUM(V9:V48) -> 6146321888574 | W49: =SUM(#REF!) -> #REF! | X49: =SUM(X9:X48) -> 8.073887e+12 | Y49: =SUM(#REF!) -> #REF! | Z49: =SUM(Z9:Z48) -> 0.78798612
B51: 1- سرمایه گذاری ها
B52: 1-1-سرمایه‌گذاری در سهام و حق تقدم سهام
D53: =D6 -> 1404/08/30 | J53: تغییرات طی دوره | R53: =R6 -> 1404/09/30
B54: شرکت | D54: تعداد | F54: بهای تمام شده | H54: خالص ارزش فروش | J54: خرید طی دوره | N54: فروش طی دوره | R54: تعداد | T54: قیمت بازار هر سهم | V54: بهای تمام شده | X54: خالص ارزش فروش | Z54: درصد به کل دارایی‌ها
J55: تعداد | L55: بهای تمام شده | N55: تعداد | P55: مبلغ فروش
B56: نقل از صفحه قبل | D56: =D49 -> 1635993292 | F56: =F49 -> 5162518829566 | H56: =H49 -> 5.6190001e+12 | J56: =J49 -> 294577292 | L56: =L49 -> 1273227570791 | N56: =N49 -> -61510786 | P56: =P49 -> 298554556825 | R56: =R49 -> 1869059798 | T56: =T49 -> 824722 | V56: =V49 -> 6146321888574 | X56: =X49 -> 8.073887e+12 | Z56: =Z49 -> 0.78798612
...

Sheet اوراق تبعی
B1: =' سهام'!B1:Z1 -> صندوق سرمایه گذاری شاخص سی شرکت بزرگ فیروزه
B2: صورت وضعیت پرتفوی
B3: =' سهام'!AC6 -> برای ماه منتهی به 1404/09/30
B4: اطلاعات آماری مرتبط با اوراق اختیار فروش تبعی خریداری شده توسط صندوق سرمایه گذاری:
D6: =' سهام'!AC4 -> 1404/08/30 | L6: =' سهام'!AC5 -> 1404/09/30
B7: نام سهام | D7: تعداد اوراق تبعی | F7: قیمت اعمال | H7: تاریخ اعمال | J7: نرخ سود مؤثر | L7: تعداد اوراق تبعی | N7: قیمت اعمال | P7: تاریخ اعمال | R7: نرخ سود مؤثر
D8: - | F8: - | H8: - | J8: 0 | L8: 0 | N8: - | P8: - | R8: 0
D9: =SUM(D8) -> 0 | F9: =SUM(F8) -> 0 | H9: ..... | J9: ..... | L9: =SUM(L8) -> 0 | N9: =SUM(N8) -> 0 | P9: ..... | R9: .....

Sheet تعدیل قیمت
A1: =اوراق!B1 -> صندوق سرمایه گذاری شاخص سی شرکت بزرگ فیروزه
A2: صورت وضعیت پرتفوی
A3: =' سهام'!AC6 -> برای ماه منتهی به 1404/09/30
A4: اوراق بهاداری که ارزش آنها در تاریخ گزارش تعدیل شده
A5: (بر اساس دستورالعمل نحوه تعیین قیمت خرید و فروش اوراق بهادار در صندوق های سرمایه گذاری)
C6: =' سهام'!AC5 -> 1404/09/30
A7: نام اوراق بهادار | C7: تعداد | E7: قیمت پایانی | G7: قیمت تعدیل شده | I7: درصد تعدیل | K7: خالص ارزش فروش تعدیل شده | M7: دلیل تعدیل
C9: - | E9: - | G9: - | I9: - | K9: - | M9: -
C10: - | E10: - | G10: - | I10: - | K10: - | M10: -

Sheet گواهی سپرده
A1: ='تعدیل قیمت'!A1:P1 -> صندوق سرمایه گذاری شاخص سی شرکت بزرگ فیروزه
A2: صورت وضعیت پرتفوی
A3: =' سهام'!AC6 -> برای ماه منتهی به 1404/09/30
A4: 4-1- سرمایه‌گذاری در گواهی سپرده‌ بانکی
K6: =' سهام'!AC4 -> 1404/08/30 | Q6: تغییرات طی دوره | W6: =' سهام'!AC5 -> 1404/09/30
A7: گواهی سپرده بانکی | C7: تاریخ سررسید | E7: نرخ سود علی الحساب | G7: نرخ شکست | I7: پذیرفته شده در بورس یا فرابورس | K7: تعداد | M7: بهای تمام شده | O7: خالص ارزش | Q7: خرید طی دوره | T7: فروش طی دوره | W7: تعداد | Y7: بهای تمام شده | AA7: خالص ارزش | AC7: درصد به کل
O8: فروش | Q8: تعداد | R8: بهای تمام شده | T8: تعداد | U8: مبلغ فروش | AA8: فروش | AC8: دارایی‌ها
A9: گواهی سپرده بانکی نزد بانک ..... | C9: ..... | E9: ..... | G9: ..... | I9: ..... | K9: ..... | M9: ..... | O9: ..... | Q9: ..... | R9: ..... | T9: ..... | U9: ..... | W9: ..... | Y9: ..... | AA9: ..... | AC9: .....
A10: جمع | C10: ..... | E10: ..... | G10: ..... | I10: ..... | K10: ..... | M10: ..... | O10: ..... | Q10: ..... | R10: ..... | T10: ..... | U10: ..... | W10: ..... | Y10: ..... | AA10: ..... | AC10: .....

Sheet اوراق
B1: =' سهام'!B1:Z1 -> صندوق سرمایه گذاری شاخص سی شرکت بزرگ فیروزه
B2: صورت وضعیت پرتفوی
B3: =' سهام'!AC6 -> برای ماه منتهی به 1404/09/30
B4: 2-1-سرمایه‌گذاری در اوراق بهادار با درآمد ثابت یا علی‌الحساب
B6: اطلاعات اوراق بهادار با درآمد ثابت | Q6: =' سهام'!AC4 -> 1404/08/30 | W6: تغییرات طی دوره | AE6: =' سهام'!AC5 -> 1404/09/30
B7: نام اوراق | D7: دارای مجوز از سازمان | F7: پذیرفته شده در بورس یا فرابورس | H7: تاریخ انتشار اوراق | J7: تاریخ سررسید | M7: نرخ سود اسمی | O7: نرخ سود مؤثر | Q7: تعداد | S7: بهای تمام شده | U7: خالص ارزش فروش | W7: خرید طی دوره | AA7: فروش طی دوره | AE7: تعداد | AG7: قیمت بازار هر ورقه | AI7: بهای تمام شده | AK7: خالص ارزش فروش | AM7: درصد به کل دارایی‌ها
W8: تعداد | Y8: بهای تمام شده | AA8: تعداد | AC8: مبلغ فروش
B9: جمع | M9: - | Q9: 0 | S9: 0 | U9: 0 | W9: 0 | Y9: 0 | AA9: 0 | AC9: 0 | AE9: 0 | AG9: 0 | AI9: 0 | AK9: 0 | AM9: 0

Sheet سپرده
B1: صندوق سرمایه گذاری شاخص سی شرکت بزرگ فیروزه
B2: صورت وضعیت پرتفوی
B3: =' سهام'!AC6 -> برای ماه منتهی به 1404/09/30
B4: 3-1- سرمایه‌گذاری در سپرده‌ بانکی | AA4: 1404/02/31
AA5: 1404/03/31
L6: تغییرات طی دوره | P6: =' سهام'!AC5 -> 1404/09/30 | AA6: برای ماه منتهی به 1404/03/31
B7: سپرده های بانکی | D7: نوع سپرده | F7: تاریخ افتتاح حساب | H7: نرخ سود علی الحساب | J7: مبلغ | L7: افزایش | N7: کاهش | P7: مبلغ | R7: درصد به کل دارایی‌ها | AA7: طی خرداد ماه
AA8: از ابتدای سال مالی تا پایان خرداد ماه
B9: حساب جاری بانک خاورمیانه | D9: حساب جاری | F9: 1393/04/25 | H9: 0 | J9: 50000000 | L9: 0 | N9: 0 | P9: 50000000 | R9: =P9/$R$18 -> 4.8798436e-06
B10: سپرده کوتاه مدت بانک خاورمیانه | D10: سپرده کوتاه مدت | F10: 1393/04/25 | H10: 0 | J10: 94173989 | L10: 1305321021907 | N10: 1305370782377 | P10: 44413519 | R10: =P10/$R$18 -> 4.3346206e-06
B11: سپرده کوتاه مدت بانک گردشگری | D11: سپرده کوتاه مدت | F11: 1402/06/19 | H11: 0 | J11: 206294231326 | L11: 938261524384 | N11: 1028867667920 | P11: 115688087790 | R11: =P11/$R$18 -> 0.011290796
B12: سپرده کوتاه مدت بانک صادرات | D12: سپرده کوتاه مدت | F12: 1404/08/01 | H12: 0 | J12: 1004110 | L12: 4126 | N12: 0 | P12: 1008236 | R12: =P12/$R$18 -> 9.8400681e-08
B13: سپرده کوتاه مدت بانک تجارت | D13: سپرده کوتاه مدت | F13: 1404/08/01 | H13: 0 | J13: 402500 | L13: 0 | N13: 0 | P13: 402500 | R13: =P13/$R$18 -> 3.9282741e-08
B14: سپرده جاری بانک گردشگری | D14: حساب جاری | F14: 1404/09/19 | H14: 0 | J14: 0 | L14: 5000000 | N14: 10000 | P14: 4990000 | R14: =P14/$R$18 -> 4.8700839e-07
B15: جمع | J15: =SUM(J9:J14) -> 206439811925 | L15: =SUM(L9:L14) -> 2243587550417 | N15: =SUM(N9:N14) -> 2334238460297 | P15: =SUM(P9:P14) -> 115788902045 | R15: =SUM(R9:R14) -> 0.011300635
R18: 10246229950860
R57: 1783
R74: 2083

Sheet درآمدها
A1: صندوق سرمایه گذاری شاخص سی شرکت بزرگ فیروزه
A2: =سپرده!B2 -> صورت وضعیت پرتفوی
A3: =سپرده!B3 -> برای ماه منتهی به 1404/09/30
AC4: 1404/02/31
B5: شرح | D5: یادداشت | F5: مبلغ | H5: درصد از کل درآمدها | J5: درصد از کل دارایی ها | AC5: برای ماه منتهی به 1404/03/31
B6: درآمد حاصل از سرمایه گذاری در سهام و حق تقدم سهام | D6: 1-2 | F6: ='درآمد سرمایه گذاری در سهام '!T127 -> 2981254227435 | H6: =F6/$H$12 -> 0.97575617 | J6: =F6/M8 -> 0.29096109 | AC6: طی خرداد ماه
B7: سود اوراق بهادار با درآمد ثابت و سپرده بانکی | D7: 3-2 | F7: ='درآمد سپرده بانکی'!J12 -> 22218972403 | H7: =F7/$H$12 -> 0.0072722075 | J7: =F7/M8 -> 0.0021685022
B8: سایر درآمدها | D8: 4-2 | F8: ='سایر درآمدها'!F8 -> 4226405839 | H8: =F8/$H$12 -> 0.0013832908 | J8: =F8/M8 -> 0.00041248399 | M8: 10246229950860
B9: جمع | F9: =SUM(F6:F8) -> 3007699605677 | H9: =SUM(H6:H8) -> 0.98441166 | J9: =SUM(J6:J8) -> 0.29354208
H12: 3055327072218
R57: 1783
R74: 2083

Sheet درآمد سرمایه گذاری در سهام 
B1: =درآمدها!A1 -> صندوق سرمایه گذاری شاخص سی شرکت بزرگ فیروزه
B2: صورت وضعیت درآمدها
B3: =' سهام'!AC6 -> برای ماه منتهی به 1404/09/30
AC4: 1404/02/31
B5: 1-2-درآمد حاصل از سرمایه گذاری در سهام و حق تقدم سهام: | AC5: 1404/03/31
AC6: برای ماه منتهی به 1404/03/31
D7: =' سهام'!AC7 -> طی آذر ماه | N7: =' سهام'!AC8 -> از ابتدای سال مالی تا پایان آذر ماه | AC7: طی خرداد ماه
B8: سهام | D8: درآمد سود سهام | F8: درآمد تغییر ارزش | H8: درآمد فروش | J8: جمع | N8: درآمد سود سهام | P8: درآمد تغییر ارزش | R8: درآمد فروش | T8: جمع | AC8: از ابتدای سال مالی تا پایان خرداد ماه
D10: یادداشت 2-1-1 | F10: یادداشت 2-1-2 | H10: یادداشت 2-1-3 | J10: مبلغ | L10: درصد از کل درآمد ها | N10: یادداشت 2-1-1 | P10: یادداشت 2-1-2 | R10: یادداشت 2-1-3 | T10: مبلغ | V10: درصد از کل درآمد ها
B11: گسترش نفت و گاز پارسیان | D11: 0 | F11: 55011127886 | H11: 134854901 | J11: =H11+F11+D11 -> 55145982787 | L11: =-J11/$G$136 -> -0.02875329 | N11: 0 | P11: 78304689379 | R11: 8615833784 | S11: -714562636 | T11: =N11+P11+R11 -> 86920523163 | U11: 11071728389 | V11: =T11/$X$12 -> 0.028910979
B12: پالایش نفت اصفهان | D12: 0 | F12: 140695819318 | H12: 587556432 | J12: =H12+F12+D12 -> 141283375750 | L12: =-J12/$G$136 -> -0.073665599 | N12: 54648000000 | P12: 345533551003 | R12: -2292453355 | S12: -4741243411 | T12: =N12+P12+R12 -> 397889097648 | U12: 11071728390 | V12: =T12/$X$12 -> 0.13234346 | X12: 3006488454242
B13: سرمایه گذاری سبحان | D13: 0 | F13: 24916556896 | H13: 41357229 | J13: =H13+F13+D13 -> 24957914125 | L13: =-J13/$G$136 -> -0.013013135 | N13: 11480000000 | P13: 24271517992 | R13: 2642430581 | S13: -3385001208 | T13: =N13+P13+R13 -> 38393948573 | U13: 11071728391 | V13: =T13/$X$12 -> 0.012770363
B14: پتروشیمی پارس | D14: 0 | F14: 1524171203 | H14: -1376254680 | J14: =H14+F14+D14 -> 147916523 | L14: =-J14/$G$136 -> -7.7124143e-05 | N14: 12000000000 | P14: -406139 | R14: -74811807393 | S14: -2880009787 | T14: =N14+P14+R14 -> -62812213532 | U14: 11071728392 | V14: =T14/$X$12 -> -0.020892218
B15: کشتیرانی دریای خزر | D15: 0 | F15: 0 | H15: 20642293424 | J15: =H15+F15+D15 -> 20642293424 | L15: =-J15/$G$136 -> -0.010762957 | N15: 0 | P15: 0 | R15: 20642293424 | S15: -664891573 | T15: =N15+P15+R15 -> 20642293424 | U15: 11071728393 | V15: =T15/$X$12 -> 0.0068659148
B16: توسعه‌معادن‌وفلزات‌ | D16: 0 | F16: 30966522276 | H16: 3112838586 | J16: =H16+F16+D16 -> 34079360862 | L16: =-J16/$G$136 -> -0.017769087 | N16: 2626384230 | P16: 66079505886 | R16: 31216116444 | S16: -2538727106 | T16: =N16+P16+R16 -> 99922006560 | U16: 11071728394 | V16: =T16/$X$12 -> 0.033235453
B17: ح .بیمه ایران - معین | D17: 0 | F17: 0 | H17: 41326305 | J17: =H17+F17+D17 -> 41326305 | L17: =-J17/$G$136 -> -2.1547666e-05 | N17: 0 | P17: 0 | R17: 41326305 | S17: -5759026841 | T17: =N17+P17+R17 -> 41326305 | U17: 11071728395 | V17: =T17/$X$12 -> 1.3745706e-05
B18: بانک ملت | D18: 0 | F18: 99493206888 | H18: 1823602887 | J18: =H18+F18+D18 -> 101316809775 | L18: =-J18/$G$136 -> -0.052826905 | N18: 3168000000 | P18: 98583210890 | R18: 21091202599 | S18: -2808202366 | T18: =N18+P18+R18 -> 122842413489 | U18: 11071728392 | V18: =T18/$X$12 -> 0.0408591
B19: کشتیرانی جمهوری اسلامی ایران | D19: 0 | F19: 43682722686 | H19: -4930261612 | J19: =H19+F19+D19 -> 38752461074 | L19: =-J19/$G$136 -> -0.020205656 | N19: 36750000000 | P19: 1582733229 | R19: -22758661311 | T19: =N19+P19+R19 -> 15574071918 | U19: 11071728393 | V19: =T19/$X$12 -> 0.0051801536
B20: توسعه سرمایه و صنعت غدیر | D20: 0 | F20: 0 | H20: -13490058810 | J20: =H20+F20+D20 -> -13490058810 | L20: =-J20/$G$136 -> 0.0070337593 | N20: 0 | P20: 0 | R20: -16706594194 | S20: 8828197833 | T20: =N20+P20+R20 -> -16706594194 | U20: 11071728394 | V20: =T20/$X$12 -> -0.0055568463
B21: پتروشیمی جم | D21: 0 | F21: 9732885855 | H21: -700412 | J21: =H21+F21+D21 -> 9732185443 | L21: =-J21/$G$136 -> -0.0050743923 | N21: 14534169683 | P21: 9709064670 | R21: -102060079441 | S21: -40082741567 | T21: =N21+P21+R21 -> -77816845088 | U21: 11071728395 | V21: =T21/$X$12 -> -0.025882968
B22: پویا | D22: 0 | F22: 0 | H22: 874503921 | J22: =H22+F22+D22 -> 874503921 | L22: =-J22/$G$136 -> -0.00045596911 | N22: 235000000 | P22: 0 | R22: 1290155549 | S22: 466959920 | T22: =N22+P22+R22 -> 1525155549 | U22: 11071728396 | V22: =T22/$X$12 -> 0.00050728801
B23: سرمایه‌ گذاری‌ آتیه‌ دماوند | D23: 0 | F23: 38126358018 | H23: 392071394 | J23: =H23+F23+D23 -> 38518429412 | L23: =-J23/$G$136 -> -0.020083631 | N23: 0 | P23: 53293258557 | R23: 655897105 | S23: -102059379029 | T23: =N23+P23+R23 -> 53949155662 | U23: 11071728398 | V23: =T23/$X$12 -> 0.017944242
B24: گروه مالی صبا تامین | D24: 0 | F24: 0 | H24: 24853040 | J24: =H24+F24+D24 -> 24853040 | L24: =-J24/$G$136 -> -1.2958454e-05 | N24: 0 | P24: 0 | R24: 23502326888 | S24: -11597631470 | T24: =N24+P24+R24 -> 23502326888 | U24: 11071728399 | V24: =T24/$X$12 -> 0.0078172018
B25: مبین انرژی خلیج فارس | D25: 0 | F25: 32893538566 | H25: 1061377754 | J25: =H25+F25+D25 -> 33954916320 | L25: =-J25/$G$136 -> -0.017704201 | N25: 22230000000 | P25: 59869747610 | R25: 56186623342 | S25: 52167321915 | T25: =N25+P25+R25 -> 138286370952 | U25: 11071728400 | V25: =T25/$X$12 -> 0.045995976
B26: معدنکاران نسوز | D26: 0 | F26: 0 | H26: 1468253632 | J26: =H26+F26+D26 -> 1468253632 | L26: =-J26/$G$136 -> -0.00076555209 | N26: 262500000 | P26: 0 | R26: 2340313737 | S26: -6964477628 | T26: =N26+P26+R26 -> 2602813737 | U26: 11071728401 | V26: =T26/$X$12 -> 0.00086573216
B27: صنایع پتروشیمی خلیج فارس | D27: 0 | F27: 133703049103 | H27: 1556673821 | J27: =H27+F27+D27 -> 135259722924 | L27: =-J27/$G$136 -> -0.070524848 | N27: 45900000000 | P27: 224826351729 | R27: 2218288310 | S27: -13571699443 | T27: =N27+P27+R27 -> 272944640039 | U27: 11071728402 | V27: =T27/$X$12 -> 0.090785195
B28: گروه مالی نماد غدیر(سهامی عام) | D28: 0 | F28: 0 | H28: 506290 | J28: =H28+F28+D28 -> 506290 | L28: =-J28/$G$136 -> -2.6398121e-07 | N28: 0 | P28: 0 | R28: 506290 | S28: 257545772 | T28: =N28+P28+R28 -> 506290 | U28: 11071728398 | V28: =T28/$X$12 -> 1.6839912e-07
B29: فولاد مبارکه اصفهان | D29: 0 | F29: 80248256339 | H29: 126400579 | J29: =H29+F29+D29 -> 80374656918 | L29: =-J29/$G$136 -> -0.0419076 | N29: 5600000000 | P29: 84645773988 | R29: -16338293696 | S29: 1026553445 | T29: =N29+P29+R29 -> 73907480292 | U29: 11071728399 | V29: =T29/$X$12 -> 0.024582659
B30: سرمایه گذاری پایا تدبیرپارسا | D30: 0 | F30: 0 | H30: -871144281 | J30: =H30+F30+D30 -> -871144281 | L30: =-J30/$G$136 -> 0.00045421738 | N30: 552500000 | P30: 0 | R30: -489193832 | S30: -1161777565 | T30: =N30+P30+R30 -> 63306168 | U30: -5155830316 | V30: =T30/$X$12 -> 2.1056515e-05
B31: تولیدی کوچین | D31: 0 | F31: 3301155489 | H31: 2711244205 | J31: =H31+F31+D31 -> 6012399694 | L31: =-J31/$G$136 -> -0.0031348842 | N31: 0 | P31: 3301155489 | R31: 2711244205 | S31: 599022178 | T31: =N31+P31+R31 -> 6012399694 | U31: -5155830315 | V31: =T31/$X$12 -> 0.001999808
... B34: ملی‌ صنایع‌ مس‌ ایران‌ | D34: 0 | F34: 238144225612 | H34: 1030701375 | J34: =H34+F34+D34 -> 239174926987 | L34: =-J34/$G$136 -> -0.12470656 | N34: 23680000000 | P34: 368504173586 | R34: 792083244 | S34: 8613312174 | T34: =N34+P34+R34 -> 392976256830 | U34: -5155830312 | V34: =T34/$X$12 -> 0.13070938
B35: نقل به صفحه بعد | D35: =SUM(D11:D34) -> 0 | F35: =SUM(F11:F34) -> 943870349354 | H35: =SUM(H11:H34) -> 16028860741 | J35: =SUM(J11:J34) -> 959899210095 | L35: =SUM(L11:L34) -> -0.50049449 | N35: =SUM(N11:N34) -> 249906553913 | P35: =SUM(P11:P34) -> 1440901337857 | R35: =SUM(R11:R34) -> -64999085333 | T35: =SUM(T11:T34) -> 1625808806437 | V35: =SUM(V11:V34) -> 0.54076669
B37: 1-2-درآمد حاصل از سرمایه گذاری در سهام و حق تقدم سهام:
D39: =D7 -> طی آذر ماه | N39: =N7 -> از ابتدای سال مالی تا پایان آذر ماه
B40: سهام | D40: درآمد سود سهام | F40: درآمد تغییر ارزش | H40: درآمد فروش | J40: جمع | N40: درآمد سود سهام | P40: درآمد تغییر ارزش | R40: درآمد فروش | T40: جمع
D42: یادداشت 2-1-1 | F42: یادداشت 2-1-2 | H42: یادداشت 2-1-3 | J42: مبلغ | L42: درصد از کل درآمد ها | N42: یادداشت 2-1-1 | P42: یادداشت 2-1-2 | R42: یادداشت 2-1-3 | T42: مبلغ | V42: درصد از کل درآمد ها
B43: نقل از صفحه قبل | D43: =D35 -> 0 | F43: =F35 -> 943870349354 | H43: =H35 -> 16028860741 | J43: =J35 -> 959899210095 | L43: =L35 -> -0.50049449 | N43: =N35 -> 249906553913 | P43: =P35 -> 1440901337857 | R43: =R35 -> -64999085333 | T43: =T35 -> 1625808806437 | V43: =V35 -> 0.54076669
B44: معدنی‌وصنعتی‌چادرملو | D44: 0 | F44: 4354817796 | H44: -964876445 | J44: =D44+F44+H44 -> 3389941351 | L44: =-J44/$G$136 -> -0.0017675261 | N44: 3040000000 | P44: 2412447287 | R44: 609965224 | S44: 2132299511 | T44: =N44+P44+R44 -> 6062412511 | U44: -5155830311 | V44: =T44/$X$12 -> 0.002016443
B45: تایدواترخاورمیانه | D45: 0 | F45: -9268093712 | H45: 14754383591 | J45: =D45+F45+H45 -> 5486289879 | L45: =-J45/$G$136 -> -0.0028605689 | N45: 0 | P45: 12358715934 | R45: 19827610330 | S45: 1644814375 | T45: =N45+P45+R45 -> 32186326264 | U45: -5155830310 | V45: =T45/$X$12 -> 0.010705621
B46: بانک تجارت | D46: 0 | F46: 8165249111 | H46: 26009906 | J46: =D46+F46+H46 -> 8191259017 | L46: =-J46/$G$136 -> -0.0042709484 | N46: 11000 | P46: 7774470231 | R46: -8605508431 | S46: -8875524087 | T46: =N46+P46+R46 -> -831027200 | U46: -803317139 | V46: =T46/$X$12 -> -0.00027641124
...

Sheet درآمد سود سهام
B1: =درآمدها!A1 -> صندوق سرمایه گذاری شاخص سی شرکت بزرگ فیروزه
B2: صورت وضعیت درآمدها
B3: =' سهام'!AC6 -> برای ماه منتهی به 1404/09/30
B4: 1-1-2-درآمد سود سهام | AG4: 1404/05/31
D5: اطلاعات مجمع | J5: =' سهام'!AC7 -> طی آذر ماه | P5: =' سهام'!AC8 -> از ابتدای سال مالی تا پایان آذر ماه | AE5: 1404/06/31
B6: نام سهام | D6: تاریخ مجمع | F6: تعداد سهام متعلقه در زمان مجمع | H6: سود متعلق به هر سهم | J6: جمع درآمد سود سهام | L6: هزینه تنزیل | N6: خالص درآمد سود سهام | P6: جمع درآمد سود سهام | R6: هزینه تنزیل | T6: خالص درآمد سود سهام | AC6: برای ماه منتهی به 1404/06/31
B7: گروه س توسعه صنعتی ایران | D7: 1404/09/17 | F7: 60000000 | H7: 330 | J7: 19800000000 | L7: 0 | N7: =J7+L7 -> 19800000000 | P7: 19800000000 | R7: 0 | T7: =P7+R7 -> 19800000000
B8: بانک‌اقتصادنوین‌ | D8: 1404/04/22 | F8: 36000000 | H8: 240 | J8: 0 | L8: 0 | N8: =J8+L8 -> 0 | P8: 8640000000 | R8: 0 | T8: =P8+R8 -> 8640000000
B9: گروه مپنا (سهامی عام) | D9: 1404/07/20 | F9: 1000 | H9: 620 | J9: 0 | L9: 0 | N9: =J9+L9 -> 0 | P9: 620000 | R9: -20530 | T9: =P9+R9 -> 599470
B10: سرمایه‌گذاری‌صندوق‌بازنشستگی‌ | D10: 1404/05/12 | F10: 14000000 | H10: 2390 | J10: 0 | L10: 0 | N10: =J10+L10 -> 0 | P10: 33460000000 | R10: 0 | T10: =P10+R10 -> 33460000000
B11: ملی‌ صنایع‌ مس‌ ایران‌ | D11: 1404/04/31 | F11: 64000000 | H11: 370 | J11: 0 | L11: 0 | N11: =J11+L11 -> 0 | P11: 23680000000 | R11: 0 | T11: =P11+R11 -> 23680000000
B12: سرمایه‌گذاری‌نیرو | D12: 1404/04/31 | F12: 10000000 | H12: 48 | J12: 0 | L12: 0 | N12: =J12+L12 -> 0 | P12: 480000000 | R12: 0 | T12: =P12+R12 -> 480000000
B13: گروه مدیریت سرمایه گذاری امید | D13: 1404/02/30 | F13: 1000 | H13: 2320 | J13: 0 | L13: 0 | N13: =J13+L13 -> 0 | P13: 2320000 | R13: 0 | T13: =P13+R13 -> 2320000
B14: کشتیرانی جمهوری اسلامی ایران | D14: 1404/07/15 | F14: 35000000 | H14: 1050 | J14: 0 | L14: 0 | N14: =J14+L14 -> 0 | P14: 36750000000 | R14: 0 | T14: =P14+R14 -> 36750000000
B15: توسعه‌معادن‌وفلزات‌ | D15: 1404/04/29 | F15: 15449319 | H15: 170 | J15: 0 | L15: 0 | N15: =J15+L15 -> 0 | P15: 2626384230 | R15: 0 | T15: =P15+R15 -> 2626384230
B16: پتروشیمی‌شیراز | D16: 1404/05/11 | F16: 6500000 | H16: 4984 | J16: 0 | L16: 0 | N16: =J16+L16 -> 0 | P16: 32396000000 | R16: 0 | T16: =P16+R16 -> 32396000000
B17: پالایش نفت تبریز | D17: 1404/04/28 | F17: 9000000 | H17: 1997 | J17: 0 | L17: 0 | N17: =J17+L17 -> 0 | P17: 17973000000 | R17: 0 | T17: =P17+R17 -> 17973000000 | AD17: 1
B18: پالایش نفت اصفهان | D18: 1404/04/30 | F18: 151800000 | H18: 360 | J18: 0 | L18: 0 | N18: =J18+L18 -> 0 | P18: 54648000000 | R18: 0 | T18: =P18+R18 -> 54648000000
B19: معدنی‌وصنعتی‌چادرملو | D19: 1404/04/23 | F19: 13383580 | H19: 380 | J19: 0 | L19: 0 | N19: =J19+L19 -> 0 | P19: 3040000000 | R19: 0 | T19: =P19+R19 -> 3040000000
B20: معدنی و صنعتی گل گهر | D20: 1404/04/23 | F20: 5600000 | H20: 310 | J20: 0 | L20: 0 | N20: =J20+L20 -> 0 | P20: 1736000000 | R20: 0 | T20: =P20+R20 -> 1736000000
B21: شهد ایران ‌ | D21: 1404/04/28 | F21: 6000000 | H21: 400 | J21: 0 | L21: 0 | N21: =J21+L21 -> 0 | P21: 2400000000 | R21: 0 | T21: =P21+R21 -> 2400000000
B22: فولاد مبارکه اصفهان | D22: 1404/05/13 | F22: 20000000 | H22: 280 | J22: 0 | L22: 0 | N22: =J22+L22 -> 0 | P22: 5600000000 | R22: 0 | T22: =P22+R22 -> 5600000000
B23: بانک ملت | D23: 1404/04/31 | F23: 35200000 | H23: 90 | J23: 0 | L23: 0 | N23: =J23+L23 -> 0 | P23: 3168000000 | R23: 0 | T23: =P23+R23 -> 3168000000
B24: بانک تجارت | D24: 1404/04/31 | F24: 1000 | H24: 11 | J24: 0 | L24: 0 | N24: =J24+L24 -> 0 | P24: 11000 | R24: 0 | T24: =P24+R24 -> 11000
B25: بانک صادرات ایران | D25: 1404/04/31 | F25: 100000000 | H25: 15 | J25: 0 | L25: 0 | N25: =J25+L25 -> 0 | P25: 1500000000 | R25: 0 | T25: =P25+R25 -> 1500000000
B26: پالایش نفت بندرعباس | D26: 1404/05/08 | F26: 24655240 | H26: 936 | J26: 0 | L26: 0 | N26: =J26+L26 -> 0 | P26: 23077304640 | R26: 0 | T26: =P26+R26 -> 23077304640
B27: پتروشیمی پردیس | D27: 1404/09/22 | F27: 1800000 | H27: 11000 | J27: 19800000000 | L27: -863760592 | N27: =J27+L27 -> 18936239408 | P27: 19800000000 | R27: -1328434505 | T27: =P27+R27 -> 18471565495
B28: پتروشیمی پردیس | D28: 1404/06/23 | F28: 1500000 | H28: 38000 | J28: 0 | L28: 0 | N28: =J28+L28 -> 0 | P28: 57000000000 | R28: 0 | T28: =P28+R28 -> 57000000000
B29: صنایع پتروشیمی خلیج فارس | D29: 1404/07/30 | F29: 90000000 | H29: 510 | J29: 0 | L29: 0 | N29: =J29+L29 -> 0 | P29: 45900000000 | R29: 0 | T29: =P29+R29 -> 45900000000
... B53: سرمایه گذاری پایا تدبیرپارسا | D53: 1404/08/18 | F53: 3250000 | H53: 170 | J53: 0 | L53: 0 | N53: =J53+L53 -> 0 | P53: 552500000 | R53: 0 | T53: =P53+R53 -> 552500000
B54: جمع | F54: =SUM(F7:F53) -> 1290662554 | J54: =SUM(J7:J53) -> 39600000000 | L54: =SUM(L7:L53) -> -863760592 | N54: =SUM(N7:N53) -> 38736239408 | P54: =SUM(P7:P53) -> 617571365503 | R54: =SUM(R7:R53) -> -4490745986 | T54: =SUM(T7:T53) -> 613080619517 | AB54: از ابتدای سال مالی تا پایان مهر ماه
R74: 2083

Sheet درآمد ناشی از تغییر قیمت اوراق 
B1: ='درآمد ناشی ازفروش'!B1:R1 -> صندوق سرمایه گذاری شاخص سی شرکت بزرگ فیروزه
B2: صورت وضعیت درآمدها
B3: =' سهام'!AC6 -> برای ماه منتهی به 1404/09/30
B4: 2-1-2-درآمد ناشی از تغییر قیمت اوراق بهادار | AC4: 1404/02/31
D5: =' سهام'!AC7 -> طی آذر ماه | L5: =' سهام'!AC8 -> از ابتدای سال مالی تا پایان آذر ماه | AC5: 1404/03/31
B6: شرح | D6: تعداد | F6: خالص ارزش فروش | H6: ارزش دفتری | J6: سود و زیان ناشی از تغییر قیمت | L6: تعداد | N6: خالص ارزش فروش | P6: ارزش دفتری | R6: سود و زیان ناشی از تغییر قیمت | AC6: برای ماه منتهی به 1404/03/31
B7: بیمه اتکایی ایران معین | D7: 232900 | F7: 524596280 | H7: -459888369 | J7: 64707911 | L7: 232900 | N7: 524596280 | P7: -522807947 | R7: 1788333 | AC7: طی خرداد ماه
B8: پتروشیمی بوعلی سینا | D8: 1000 | F8: 56351013 | H8: -46061173 | J8: 10289840 | L8: 1000 | N8: 56351013 | P8: -79176082 | R8: -22825068 | AC8: از ابتدای سال مالی تا پایان خرداد ماه
B9: ح.کشت و دام گلدشت نمونه اصفهان | D9: 1395395 | F9: 5021975380 | H9: -4088749185 | J9: 933226195 | L9: 1395395 | N9: 5021975380 | P9: -4615966660 | R9: 406008720
B10: بانک خاورمیانه | D10: 14000000 | F10: 38619148400 | H10: -35562956800 | J10: 3056191599 | L10: 14000000 | N10: 38619148400 | P10: -34648837757 | R10: 3970310642
B11: پالایش نفت تبریز | D11: 100000 | F11: 2634476850 | H11: -2087361792 | J11: 547115058 | L11: 100000 | N11: 2634476850 | P11: -2087361792 | R11: 547115058
B12: معدنی‌وصنعتی‌چادرملو | D12: 6000000 | F12: 18349056840 | H12: -13994239044 | J12: 4354817796 | L12: 6000000 | N12: 18349056840 | P12: -15936609552 | R12: 2412447287
B13: پتروشیمی پردیس | D13: 2000000 | F13: 784032217800 | H13: -618206254076 | J13: 165825963724 | L13: 2000000 | N13: 784032217800 | P13: -576774220176 | R13: 207257997624
B14: بین المللی توسعه ص. معادن غدیر | D14: 1000 | F14: 3924427 | H14: -3356849 | J14: 567578 | L14: 1000 | N14: 3924427 | P14: -3874804 | R14: 49623
B15: تایدواترخاورمیانه | D15: 7200000 | F15: 57940629840 | H15: -67208723552 | J15: -9268093712 | L15: 7200000 | N15: 57940629840 | P15: -45581913906 | R15: 12358715934
B16: کیمیا کالای رازی | D16: 267500 | F16: 7883337082 | H16: -7575228505 | J16: 308108577 | L16: 267500 | N16: 7883337082 | P16: -7575228505 | R16: 308108577
B17: کشت و دام گلدشت نمونه اصفهان | D17: 2700000 | F17: 13714461351 | H17: -10583881802 | J17: 3130579549 | L17: 2700000 | N17: 13714461351 | P17: -11635663561 | R17: 2078797790
B18: گروه مپنا (سهامی عام) | D18: 1000 | F18: 15082504 | H18: -13465103 | J18: 1617400 | L18: 1000 | N18: 15082504 | P18: -16437235 | R18: -1354731
B19: گسترش نفت و گاز پارسیان | D19: 3000000 | F19: 249962735700 | H19: -194951607814 | J19: 55011127886 | L19: 3000000 | N19: 249962735700 | P19: -171658046321 | R19: 78304689379
B20: پالایش نفت اصفهان | D20: 140000000 | F20: 868236250000 | H20: -727540430682 | J20: 140695819318 | L20: 140000000 | N20: 868236250000 | P20: -522702698997 | R20: 345533551003
... B38: گروه مدیریت سرمایه گذاری امید | D38: 1783 | F38: 10650688 | H38: -5292851 | J38: 5357837 | L38: 1783 | N38: 10650688 | P38: -8904512 | R38: 1746176
B39: نقل به صفحه بعد | D39: =SUM(D7:D38) -> 702820661 | F39: =SUM(F7:F38) -> 4876946099797 | H39: =SUM(H7:H38) -> -4081516528891 | J39: =SUM(J7:J38) -> 795429570896 | L39: =SUM(L7:L38) -> 702820661 | N39: =SUM(N7:N38) -> 4876946099797 | P39: =SUM(P7:P38) -> -3615521038232 | R39: =SUM(R7:R38) -> 1261425061561
B41: 2-1-2-درآمد ناشی از تغییر قیمت اوراق بهادار | AA41: 1404/02/31
D42: =D5 -> طی آذر ماه | L42: =L5 -> از ابتدای سال مالی تا پایان آذر ماه | AA42: 1404/03/31
B43: شرح | D43: تعداد | F43: خالص ارزش فروش | H43: ارزش دفتری | J43: سود و زیان ناشی از تغییر قیمت | L43: تعداد | N43: خالص ارزش فروش | P43: ارزش دفتری | R43: سود و زیان ناشی از تغییر قیمت | AA43: برای ماه منتهی به 1404/03/31
B44: نقل از صفحه قبل | D44: =D39 -> 702820661 | F44: =F39 -> 4876946099797 | H44: =H39 -> -4081516528891 | J44: =J39 -> 795429570896 | L44: =L39 -> 702820661 | N44: =N39 -> 4876946099797 | P44: =P39 -> -3615521038232 | R44: =R39 -> 1261425061561
B45: ایران خودرو دیزل | D45: 40000000 | F45: 52669691600 | H45: -53183846240 | J45: -514154640 | L45: 40000000 | N45: 52669691600 | P45: -53183846240 | R45: -514154640
B46: پالایش نفت بندرعباس | D46: 137000000 | F46: 879538205300 | H46: -612836536185 | J46: 266701669115 | L46: 137000000 | N46: 879538205300 | P46: -550309037976 | R46: 329229167324
B47: تولیدی کوچین | D47: 375000 | F47: 10083943875 | H47: -6782788386 | J47: 3301155489 | L47: 375000 | N47: 10083943875 | P47: -6782788386 | R47: 3301155489
B48: توسعه خدمات دریایی وبندری سینا | D48: 1000000 | F48: 13842166500 | H48: -13578102653 | J48: 264063846 | L48: 1000000 | N48: 13842166500 | P48: -13578102653 | R48: 264063846
B49: پتروشیمی جم | D49: 2000000 | F49: 120957713000 | H49: -111224827144 | J49: 9732885855 | L49: 2000000 | N49: 120957713000 | P49: -111248648329 | R49: 9709064670
B50: مخابرات ایران | D50: 1000 | F50: 586431 | H50: -470335 | J50: 116096 | L50: 1000 | N50: 586431 | P50: -483356 | R50: 103075
B51: سرمایه‌گذاری‌صندوق‌بازنشستگی‌ | D51: 12000000 | F51: 250052040000 | H51: -197198613702 | J51: 52853426298 | L51: 12000000 | N51: 250052040000 | P51: -275648177910 | R51: -25596137910
B52: پالایش نفت تهران | D52: 18000000 | F52: 65192139000 | H52: -56891965330 | J52: 8300173670 | L52: 18000000 | N52: 65192139000 | P52: -44873926802 | R52: 20318212198
B53: س. و توسعه صنایع لاستیک | D53: 562500 | F53: 5542448118 | H53: -5654078493 | J53: -111630374 | L53: 562500 | N53: 5542448118 | P53: -4998586413 | R53: 543861705
B54: ملی‌ صنایع‌ مس‌ ایران‌ | D54: 107985195 | F54: 1241873940840 | H54: -1003729715228 | J54: 238144225612 | L54: 107985195 | N54: 1241873940840 | P54: -873369767254 | R54: 368504173586
B55: سرمایه‌گذاری‌غدیر(هلدینگ‌ | D55: 40863003 | F55: 575769274212 | H55: -458366671469 | J55: 117402602743 | L55: 40863003 | N55: 575769274212 | P55: -400454614222 | R55: 175314659990
B56: کشت وصنعت و دامپروری پگاه فارس | D56: 360000 | F56: 4515225408 | H56: -4793854824 | J56: -278629416 | L56: 360000 | N56: 4515225408 | P56: -3620597726 | R56: 894627681
... B64: پتروشیمی‌شیراز | D64: 6000000 | F64: 268031972400 | H64: -213854030400 | J64: 54177941999 | L64: 6000000 | N64: 268031972400 | P64: -221563793094 | R64: 46468179305
B65: جمع | D65: =SUM(D44:D64) -> 2063368359 | F65: =SUM(F44:F64) -> 10024235910710 | H65: =SUM(H44:H64) -> -8183029994788 | J65: =SUM(J44:J64) -> 1841205915906 | L65: =SUM(L44:L64) -> 2063368359 | N65: =SUM(N44:N64) -> 10024235910710 | P65: =SUM(P44:P64) -> -7665427124002 | R65: =SUM(R44:R64) -> 2260225577601
...

Sheet درآمد ناشی ازفروش
B1: ='سود اوراق بهادار و سپرده بانکی'!B1:U1 -> صندوق سرمایه گذاری شاخص سی شرکت بزرگ فیروزه
B2: صورت وضعیت درآمدها
B3: =' سهام'!B3:Z3 -> برای ماه منتهی به 1404/09/30
B4: 3-1-2-سود(زیان) حاصل از فروش اوراق بهادار | AC4: 1404/04/31
D5: =' سهام'!AC7 -> طی آذر ماه | L5: =' سهام'!AC8 -> از ابتدای سال مالی تا پایان آذر ماه | AC5: 1404/05/31
B6: شرح | D6: تعداد | F6: خالص بهای فروش | H6: ارزش دفتری | J6: سود و زیان ناشی از فروش | L6: تعداد | N6: خالص ارزش فروش | P6: ارزش دفتری | R6: سود و زیان ناشی از فروش | Z6: برای ماه منتهی به 1404/05/31
B7: گسترش نفت و گاز پارسیان | D7: 15456 | F7: 1019237156 | H7: -884382255 | J7: 134854901 | L7: 3115456 | N7: 186760959138 | P7: -178145125354 | R7: 8615833784 | Z7: طی مرداد ماه
B8: پالایش نفت اصفهان | D8: 400000 | F8: 2080992714 | H8: -1493436282 | J8: 587556432 | L8: 18652817 | N8: 66740034992 | P8: -69032488347 | R8: -2292453355 | Z8: از ابتدای سال مالی تا پایان مرداد ماه
B9: سرمایه گذاری سبحان | D9: 169302 | F9: 424090566 | H9: -382733337 | J9: 41357229 | L9: 23344072 | N9: 51120926313 | P9: -48478495732 | R9: 2642430581
B10: پتروشیمی پارس | D10: 1499000 | F10: 4005654899 | H10: -5381909579 | J10: -1376254680 | L10: 83599000 | N10: 224668426760 | P10: -299480234153 | R10: -74811807393
B11: کشتیرانی دریای خزر | D11: 20000000 | F11: 72088004681 | H11: -51445711257 | J11: 20642293424 | L11: 20000000 | N11: 72088004681 | P11: -51445711257 | R11: 20642293424
B12: توسعه‌معادن‌وفلزات‌ | D12: 6400000 | F12: 13771250733 | H12: -10658412147 | J12: 3112838586 | L12: 194995378 | N12: 388875136319 | P12: -357659019875 | R12: 31216116444
B13: ح .بیمه ایران - معین | D13: 659600 | F13: 498429105 | H13: -457102800 | J13: 41326305 | L13: 659600 | N13: 498429105 | P13: -457102800 | R13: 41326305
B14: بانک ملت | D14: 15020817 | F14: 19999712144 | H14: -18176109257 | J14: 1823602887 | L14: 111420817 | N14: 205653849133 | P14: -184562646534 | R14: 21091202599
B15: کشتیرانی جمهوری اسلامی ایران | D15: 5000000 | F15: 32116725794 | H15: -37046987406 | J15: -4930261612 | L15: 24369697 | N15: 165260071662 | P15: -188018732973 | R15: -22758661311
B16: توسعه سرمایه و صنعت غدیر | D16: 6000000 | F16: 90749914656 | H16: -104239973466 | J16: -13490058810 | L16: 7000000 | N16: 104906708182 | P16: -121613302376 | R16: -16706594194
B17: پتروشیمی جم | D17: 1000 | F17: 54923913 | H17: -55624325 | J17: -700412 | L17: 4101912 | N17: 177576791309 | P17: -279636870750 | R17: -102060079441
B18: پویا | D18: 100000 | F18: 3476370721 | H18: -2601866800 | J18: 874503921 | L18: 200000 | N18: 6493889149 | P18: -5203733600 | R18: 1290155549
B19: سرمایه‌ گذاری‌ آتیه‌ دماوند | D19: 1054855 | F19: 4625313552 | H19: -4233242158 | J19: 392071394 | L19: 2254855 | N19: 9704863309 | P19: -9048966204 | R19: 655897105
B20: گروه مالی صبا تامین | D20: 71080 | F20: 227379995 | H20: -202526955 | J20: 24853040 | L20: 70000000 | N20: 222952069368 | P20: -199449742480 | R20: 23502326888
... B46: ایمن خودرو شرق | D46: 0 | F46: 0 | H46: 0 | J46: 0 | L46: 1750000 | N46: 6827446173 | P46: -4695146662 | R46: 2132299511
B47: نقل به صفحه بعد | D47: =SUM(D7:D46) -> 91891386 | F47: =SUM(F7:F46) -> 441044993525 | H47: =SUM(H7:H46) -> -412116342177 | J47: =SUM(J7:J46) -> 28928651348 | L47: =SUM(L7:L46) -> 1234768432 | N47: =SUM(N7:N46) -> 4222984550979 | P47: =SUM(P7:P46) -> -4249048262731 | R47: =SUM(R7:R46) -> -26063711752
B49: 3-1-2-سود(زیان) حاصل از فروش اوراق بهادار | Z49: 1404/02/31
D50: =D5 -> طی آذر ماه | L50: =L5 -> از ابتدای سال مالی تا پایان آذر ماه | Z50: 1404/03/31
B51: شرح | D51: تعداد | F51: خالص بهای فروش | H51: ارزش دفتری | J51: سود و زیان ناشی از فروش | L51: تعداد | N51: خالص ارزش فروش | P51: ارزش دفتری | R51: سود و زیان ناشی از فروش | X51: برای ماه منتهی به 1404/03/31
B52: نقل از صفحه قبل | D52: =D47 -> 91891386 | F52: =F47 -> 441044993525 | H52: =H47 -> -412116342177 | J52: =J47 -> 28928651348 | L52: =L47 -> 1234768432 | N52: =N47 -> 4222984550979 | P52: =P47 -> -4249048262731 | R52: =R47 -> -26063711752
B53: نورایستا پلاستیک | D53: 0 | F53: 0 | H53: 0 | J53: =F53+H53 -> 0 | L53: 225000 | N53: 4731339625 | P53: -3086525250 | R53: 1644814375
B54: مهرمام میهن | D54: 0 | F54: 0 | H54: 0 | J54: =F54+H54 -> 0 | L54: 1999999 | N54: 8638310933 | P54: -7151192124 | R54: 1487118809
B55: صنعتی مینو | D55: 0 | F55: 0 | H55: 0 | J55: =F55+H55 -> 0 | L55: 15297352 | N55: 124115112292 | P55: -120944002623 | R55: 3171109669
B56: گروه‌بهمن‌ | D56: 0 | F56: 0 | H56: 0 | J56: =F56+H56 -> 0 | L56: 25777644 | N56: 63229742834 | P56: -61292477531 | R56: 1937265303
B57: سرمایه گذاری جامی | D57: 0 | F57: 0 | H57: 0 | J57: =F57+H57 -> 0 | L57: 10000000 | N57: 14127514473 | P57: -12914583067 | R57: 1783
B58: گروه س توسعه صنعتی ایران | D58: 0 | F58: 0 | H58: 0 | J58: =F58+H58 -> 0 | L58: 33018562 | N58: 60477350165 | P58: -53566408497 | R58: 6910941668
B59: بیمه اتکایی ایران معین | D59: 0 | F59: 0 | H59: 0 | J59: =F59+H59 -> 0 | L59: 1062500 | N59: 2536492684 | P59: -2385072759 | R59: 151419925
B60: پتروشیمی بوعلی سینا | D60: 0 | F60: 0 | H60: 0 | J60: =F60+H60 -> 0 | L60: 9000 | N60: 743971783 | P60: -712584743 | R60: 31387040
B61: اقتصادی و خودکفایی آزادگان | D61: 0 | F61: 0 | H61: 0 | J61: =F61+H61 -> 0 | L61: 17003374 | N61: 93930456333 | P61: -115969359763 | R61: -22038903430
B62: توسعه نیشکر و صنایع جانبی | D62: 0 | F62: 0 | H62: 0 | J62: =F62+H62 -> 0 | L62: 285750 | N62: 16096789618 | P62: -13620187310 | R62: 2476602308
B63: بانک خاورمیانه | D63: 0 | F63: 0 | H63: 0 | J63: =F63+H63 -> 0 | L63: 45200000 | N63: 199311526542 | P63: -189463504064 | R63: 9848022478
B64: فجر انرژی خلیج فارس | D64: 0 | F64: 0 | H64: 0 | J64: =F64+H64 -> 0 | L64: 4100000 | N64: 47787732830 | P64: -50619014100 | R64: -2831281270
... B98: تولید انرژی برق شمس پاسارگاد | D98: 0 | F98: 0 | H98: 0 | J98: =F98+H98 -> 0 | L98: 900000 | N98: 3553314347 | P98: -2980062495 | R98: 573251852
B99: پتروشیمی پردیس | J99: =F99+H99 -> 0 | L99: 350629 | N99: 93332630138 | P99: -91302145481 | R99: 2030484657
...

Sheet درآمد سرمایه گذاری در اوراق بها
A1: صندوق سرمایه‌گذاری صندوق شاخص سی شرکت بزرگ فیروزه
A2: صورت وضعیت درآمدها
A3: =' سهام'!AC6 -> برای ماه منتهی به 1404/09/30
B4: 2-2-درآمد حاصل از سرمایه گذاری در اوراق بهادار با درآمد ثابت:
C6: =' سهام'!AC7 -> طی آذر ماه | M6: =' سهام'!AC8 -> از ابتدای سال مالی تا پایان آذر ماه
C7: درآمد سود اوراق | E7: درآمد تغییر ارزش | G7: درآمد فروش | I7: جمع | M7: درآمد سود اوراق | O7: درآمد تغییر ارزش | Q7: درآمد فروش | R7: جمع
C9: یادداشت 2-2-1 | E9: یادداشت 2-1-2 | G9: یادداشت 3-1-2 | I9: مبلغ | K9: درصد از کل دارائیها | M9: یادداشت 2-2-1 | O9: یادداشت 2-1-2 | Q9: یادداشت 3-1-2 | R9: مبلغ | S9: درصد از کل دارائیها
B10: - | C10: 0 | D10: 0 | E10: 0 | F10: 0 | G10: 0 | H10: 0 | I10: 0 | J10: 0 | K10: 0 | L10: 0 | M10: 0 | N10: 0 | O10: 0 | P10: 875280 | Q10: 0 | R10: 0 | S10: =R10/S14 -> 0
B11: جمع | C11: =SUM(C10:C10) -> 0 | E11: =SUM(E10:E10) -> 0 | G11: =SUM(G10:G10) -> 0 | I11: =SUM(I10:I10) -> 0 | K11: =SUM(K10:K10) -> 0 | M11: =SUM(M10:M10) -> 0 | O11: =SUM(O10:O10) -> 0 | Q11: =SUM(Q10:Q10) -> 0 | R11: =SUM(R10:R10) -> 0 | S11: =SUM(S10:S10) -> 0
K14: 2807555599778 | S14: 2807555599778

Sheet سود اوراق بهادار و سپرده بانکی
B1: ='درآمد سود سهام'!B1:T1 -> صندوق سرمایه گذاری شاخص سی شرکت بزرگ فیروزه
B2: صورت وضعیت درآمدها
B3: =' سهام'!AC6 -> برای ماه منتهی به 1404/09/30
B4: 1-2-2-سود اوراق بهادار با درآمد ثابت و سپرده بانکی | AC4: 1404/06/31
G5: ابتدای دوره | K5: =' سهام'!AC7 -> طی آذر ماه | Q5: =' سهام'!AC8 -> از ابتدای سال مالی تا پایان آذر ماه | AC5: 1404/07/30
B6: شرح | C6: تاریخ دریافت سود | D6: تاریخ سررسید | E6: نرخ سود علی الحساب | G6: درآمد سود | I6: هزینه تنزیل | K6: درآمد سود | M6: هزینه تنزیل | O6: خالص درآمد | Q6: درآمد سود | S6: هزینه تنزیل | U6: خالص درآمد | AC6: برای ماه منتهی به 1404/07/30
B7: سپرده کوتاه مدت بانک خاورمیانه مهستان | H7: 0 | J7: 176683 | K7: 14491 | M7: 0 | O7: =K7+M7 -> 14491 | Q7: 295543 | S7: 0 | U7: =Q7+S7 -> 295543 | AC7: طی مهر ماه
B8: سپرده کوتاه مدت بانک گردشگری سعادت آباد | K8: 1650666330 | M8: 0 | O8: =K8+M8 -> 1650666330 | Q8: 22218668624 | S8: 0 | U8: =Q8+S8 -> 22218668624
B9: سپرده کوتاه مدت بانک صادرات بلوار میرداماد | H9: 0 | J9: 2202729735 | K9: 4126 | M9: 0 | O9: =K9+M9 -> 4126 | Q9: 8236 | S9: 0 | U9: =Q9+S9 -> 8236 | AC9: از ابتدای سال مالی تا پایان مهر ماه
K10: =SUM(K7:K9) -> 1650684947 | O10: =SUM(O7:O9) -> 1650684947 | Q10: =SUM(Q7:Q9) -> 22218972403 | U10: =SUM(U7:U9) -> 22218972403
R57: 1783
R74: 2083

Sheet درآمد سپرده بانکی
B1: ='سود اوراق بهادار و سپرده بانکی'!B1:U1 -> صندوق سرمایه گذاری شاخص سی شرکت بزرگ فیروزه
B2: صورت وضعیت درآمدها
B3: =' سهام'!B3:Z3 -> برای ماه منتهی به 1404/09/30
B4: 3-2-درآمد حاصل از سرمایه گذاری در سپرده بانکی و گواهی سپرده: | AC4: 1404/02/31
AC5: 1404/03/31
B6: نام سپرده بانکی | F6: =' سهام'!AC7 -> طی آذر ماه | J6: =' سهام'!AC8 -> از ابتدای سال مالی تا پایان آذر ماه | AC6: برای ماه منتهی به 1404/03/31
B7: نام سپرده | F7: سود سپرده بانکی و گواهی سپرده | H7: درصد سود به میانگین سپرده | J7: سود سپرده بانکی و گواهی سپرده | L7: درصد سود به میانگین سپرده | AC7: طی خرداد ماه
F8: یادداشت 2-2-1 | J8: یادداشت 2-2-1 | AC8: از ابتدای سال مالی تا پایان خرداد ماه
B9: سپرده کوتاه مدت بانک خاورمیانه مهستان | F9: 14491 | H9: =F9/H14 -> 0.00028133069 | J9: 295543 | L9: =J9/درآمدها!F9 -> 9.826214e-08
B10: سپرده کوتاه مدت بانک گردشگری سعادت آباد | F10: 1650666330 | H10: =H14/F10 -> 0.031204839 | J10: 22218668624 | L10: =J10/درآمدها!F9 -> 0.0073872632
B11: سپرده کوتاه مدت بانک صادرات بلوار میرداماد | F11: 4126 | H11: =H15/F11 -> 0 | J11: 8236 | L11: =J11/درآمدها!F9 -> 2.7383054e-09
B12: جمع | F12: =SUM(F9:F11) -> 1650684947 | H12: =SUM(H9:H11) -> 0.03148617 | J12: =SUM(J9:J11) -> 22218972403 | L12: =SUM(L9:L11) -> 0.0073873642
H14: 51508777
R57: 1783
R74: 2083

Sheet Sheet1

Sheet سایر درآمدها
B1: ='درآمد سپرده بانکی'!B1:M1 -> صندوق سرمایه گذاری شاخص سی شرکت بزرگ فیروزه
B2: صورت وضعیت درآمدها
B3: =' سهام'!AC6 -> برای ماه منتهی به 1404/09/30
B4: 4-2-سایر درآمدها: | AC4: 1404/02/31
D5: =' سهام'!AC7 -> طی آذر ماه | F5: =' سهام'!AC8 -> از ابتدای سال مالی تا پایان آذر ماه | AC5: 1404/03/31
B6: سایر درآمدها | D6: 429246 | F6: 469031045 | AC6: برای ماه منتهی به 1404/03/31
B7: تعدیل کارمزد کارگزار | D7: -95463055 | F7: 3757374794
D8: =SUM(D6:D7) -> -95033809 | F8: =SUM(F6:F7) -> 4226405839
R57: 1783
R74: 2083
