Workbook

Sheet  سهام
B1: صندوق سرمایه گذاری شاخص سی شرکت بزرگ فیروزه
B2: صورت وضعیت پرتفوی
B3: =AC6 -> برای ماه منتهی به 1404/07/30
B4: 1- سرمایه گذاری ها | AC4: 1404/06/31
B5: 1-1-سرمایه‌گذاری در سهام و حق تقدم سهام | AC5: 1404/07/30
D6: =AC4 -> 1404/06/31 | J6: تغییرات طی دوره | R6: =AC5 -> 1404/07/30 | AC6: برای ماه منتهی به 1404/07/30
B7: شرکت | D7: تعداد | F7: بهای تمام شده | H7: خالص ارزش فروش | J7: خرید طی دوره | N7: فروش طی دوره | R7: تعداد | T7: قیمت بازار هر سهم | V7: بهای تمام شده | X7: خالص ارزش فروش | Z7: درصد به کل دارایی‌ها | AC7: طی مهر ماه
J8: تعداد | L8: بهای تمام شده | N8: تعداد | P8: مبلغ فروش | AC8: از ابتدای سال مالی تا پایان مهر ماه
B9: اقتصادی و خودکفایی آزادگان | D9: 14000000 | F9: 95486198330 | H9: 70418502000 | I9: 124544524500 | J9: 0 | L9: 0 | N9: -14000000 | P9: 71684704000 | R9: 0 | T9: 0 | V9: 0 | X9: 0 | Z9: =X9/$Z$69 -> 0
B10: ایران‌ خودرو | D10: 70000000 | F10: 35776968687 | H10: 27972567000 | I10: 91104682500 | J10: 49200000 | L10: 23641834149 | N10: 0 | P10: 0 | R10: 119200000 | T10: 532 | V10: 59418802836 | X10: 63037084320 | Z10: =X10/$Z$69 -> 0.008632879
B11: بانک پاسارگاد | D11: 1000 | F11: 1915216 | H11: 4291313.8 | I11: 6.0450666e+09 | J11: 0 | L11: 0 | N11: 0 | P11: 0 | R11: 1000 | T11: 5099 | V11: 1915216 | X11: 5068661 | Z11: =X11/$Z$69 -> 6.9414912e-07
B12: بانک تجارت | D12: 1000 | F12: 631914 | H12: 389667.6 | I12: 3584544.3 | J12: 0 | L12: 0 | N12: 0 | P12: 0 | R12: 1000 | T12: 468 | V12: 631914 | X12: 465215.4 | Z12: =X12/$Z$69 -> 6.3710883e-08
B13: بانک خاورمیانه | D13: 13600000 | F13: 33748888259 | H13: 30417930000 | I13: 5785371000 | J13: 2400000 | L13: 5849783461 | N13: -1000000 | P13: 2379415174 | R13: 15000000 | T13: 2529 | V13: 37123754740 | X13: 37709286750 | Z13: =X13/$Z$69 -> 0.0051642571
B14: بانک ملت | D14: 36390997 | F14: 30896154180 | H14: 3.6500041e+10 | I14: 187875450000 | J14: 134000000 | L14: 148357355295 | N14: -6400000 | P14: 7648489552 | R14: 163990997 | T14: 1224 | V14: 172520627569 | X14: 1.9953067e+11 | Z14: =X14/$Z$69 -> 0.027325568
B15: بانک‌اقتصادنوین‌ | D15: 30000000 | F15: 113395047697 | H15: 106224183000 | I15: 129972037500 | J15: 0 | L15: 0 | N15: 0 | P15: 0 | R15: 30000000 | T15: 4232 | V15: 113395047697 | X15: 126204588000 | Z15: =X15/$Z$69 -> 0.017283619
B16: بیمه اتکایی ایران معین | D16: 232900 | F16: 394603131 | H16: 4.338577e+08 | I16: 156455517600 | J16: 0 | L16: 0 | N16: 0 | P16: 0 | R16: 232900 | T16: 2020 | V16: 394603131 | X16: 4.6765877e+08 | Z16: =X16/$Z$69 -> 6.4045501e-05
B17: بین المللی توسعه ص. معادن غدیر | D17: 1000 | F17: 5411279 | H17: 2870816.4 | I17: 5.882777e+08 | J17: 0 | L17: 0 | N17: 0 | P17: 0 | R17: 1000 | T17: 3368 | V17: 5411279 | X17: 3347960.4 | Z17: =X17/$Z$69 -> 4.5850054e-07
D18: 140000000 | F18: 535146115145 | H18: 483744492000 | I18: 4419546.3 | J18: 0 | L18: 0 | N18: 0 | P18: 0 | R18: 140000000 | T18: 4900 | V18: 535146115145 | X18: 681918300000 | Z18: =X18/$Z$69 -> 0.093388174
B19: پالایش نفت بندرعباس | D19: 24500000 | F19: 244142660273 | H19: 248413095000 | I19: 654830437500 | J19: 8000000 | L19: 101193238160 | N19: -500000 | P19: 5892489043 | R19: 97600000 | T19: 4131 | V19: 340353395163 | X19: 400786645680 | Z19: =X19/$Z$69 -> 0.054887415
B20: پالایش نفت تبریز | D20: 10000000 | F20: 192794933347 | H20: 174952800000 | I20: 210340980000 | J20: 0 | L20: 0 | N20: 0 | P20: 0 | R20: 10000000 | T20: 23770 | V20: 192794933347 | X20: 236285685000 | Z20: =X20/$Z$69 -> 0.032359138
B21: پالایش نفت تهران | D21: 55000000 | F21: 136058190784 | H21: 118475849250 | I21: 190778076000 | J21: 0 | L21: 0 | N21: -35000000 | P21: 86160123469 | R21: 20000000 | T21: 2917 | V21: 49475705739 | X21: 57992877000 | Z21: =X21/$Z$69 -> 0.0079420788
B22: پتروشیمی بوعلی سینا | D22: 1000 | F22: 68624286 | H22: 47058327 | I22: 164435751000 | J22: 0 | L22: 0 | N22: 0 | P22: 0 | R22: 1000 | T22: 55550 | V22: 68624286 | X22: 55219478 | Z22: =X22/$Z$69 -> 7.5622639e-06
B23: پتروشیمی پارس | D23: 69940113 | F23: 200942238088 | H23: 1.6685753e+11 | I23: 74454345 | J23: 0 | L23: 0 | N23: -20740113 | P23: 57540140042 | R23: 49200000 | T23: 2808 | V23: 141354620263 | X23: 137331586080 | Z23: =X23/$Z$69 -> 0.018807453
B24: پتروشیمی پردیس | D24: 1550000 | F24: 383879335391 | H24: 388584085500 | I24: 276147090000 | J24: 0 | L24: 0 | N24: -50000 | P24: 14107271508 | R24: 1500000 | T24: 284900 | V24: 371496131018 | X24: 424807267500 | Z24: =X24/$Z$69 -> 0.058177021
B25: پتروشیمی جم | D25: 1000 | F25: 68078893 | H25: 35189370 | I25: 338593311000 | J25: 0 | L25: 0 | N25: 0 | P25: 0 | R25: 1000 | T25: 43200 | V25: 68078893 | X25: 42942960 | Z25: =X25/$Z$69 -> 5.8810045e-06
B26: پتروشیمی نوری | D26: 1000000 | F26: 30299649812 | H26: 34553178000 | I26: 280123290000 | J26: 0 | L26: 0 | N26: 0 | P26: 0 | R26: 1000000 | T26: 44790 | V26: 30299649812 | X26: 44523499500 | Z26: =X26/$Z$69 -> 0.0060974582
B27: پتروشیمی‌شیراز | D27: 6300000 | F27: 232841513410 | H27: 196329845250 | I27: 196321892850 | J27: 105319 | L27: 3820592343 | N27: -405319 | P27: 13961383517 | R27: 6000000 | T27: 36020 | V27: 221684251852 | X27: 214834086000 | Z27: =X27/$Z$69 -> 0.029421359
B28: پویا | D28: 100000 | F28: 2601866800 | H28: 2862864000 | I28: 234352257750 | J28: 0 | L28: 0 | N28: 0 | P28: 0 | R28: 100000 | T28: 30200 | V28: 2601866800 | X28: 3002031000 | Z28: =X28/$Z$69 -> 0.00041112578
B29: توسعه سرمایه و صنعت غدیر | D29: 7000000 | F29: 121613302376 | H29: 97903984500 | I29: 4622332.5 | J29: 0 | L29: 0 | N29: 0 | P29: 0 | R29: 7000000 | T29: 15190 | V29: 121613302376 | X29: 105697336500 | Z29: =X29/$Z$69 -> 0.014475167
B30: توسعه معادن وص.معدنی خاورمیانه | D30: 1000 | F30: 4947385 | H30: 3781366.2 | I30: 4.6052625e+10 | J30: 0 | L30: 0 | N30: 0 | P30: 0 | R30: 1000 | T30: 4293 | V30: 4947385 | X30: 4267456.7 | Z30: =X30/$Z$69 -> 5.8442483e-07
... B36: سرمایه گذاری تامین اجتماعی | D36: 337000000 | F36: 534760080551 | H36: 391608979650 | I36: 67794210000 | J36: 0 | L36: 0 | N36: -7000000 | P36: 9861866649 | R36: 330000000 | T36: 1243 | V36: 523652304396 | X36: 407749369500 | Z36: =X36/$Z$69 -> 0.055840955
B37: سرمایه گذاری سبحان | D37: 28000000 | F37: 58352955715 | H37: 60565478400 | I37: 4413084975 | J37: 0 | L37: 0 | M37: 9102861790 | N37: -3000000 | P37: 6320238252 | R37: 25000000 | T37: 2320 | V37: 52100853316 | X37: 57654900000 | Z37: =X37/$Z$69 -> 0.0078957931
B38: سرمایه گذاری صدرتامین | D38: 10000000 | F38: 118540901629 | H38: 92645460000 | I38: 614223495000 | J38: 0 | L38: 0 | N38: -8000000 | P38: 78327784276 | R38: 2000000 | T38: 11100 | V38: 23708180334 | X38: 22067910000 | Z38: =X38/$Z$69 -> 0.0030221829
B39: سرمایه‌گذاری‌صندوق‌بازنشستگی‌ | D39: 12900000 | F39: 291547971123 | H39: 169395066450 | I39: 72158089500 | J39: 0 | L39: 0 | N39: -900000 | P39: 13691571754 | R39: 12000000 | T39: 15300 | V39: 271207414995 | X39: 182507580000 | Z39: =X39/$Z$69 -> 0.024994269
B40: سرمایه‌گذاری‌غدیر(هلدینگ‌ | D40: 40000000 | F40: 399032730193 | H40: 337579380000 | I40: 266156887500 | J40: 0 | L40: 0 | N40: 0 | P40: 0 | R40: 40000000 | T40: 10080 | V40: 399032730193 | X40: 400800960000 | Z40: =X40/$Z$69 -> 0.054889376
B41: سرمایه‌گذاری‌نیرو | D41: 10000000 | F41: 56454832765 | H41: 48310830000 | I41: 3.4124417e+11 | J41: 0 | L41: 0 | N41: -10000000 | P41: 38860864777 | R41: 0 | T41: 0 | V41: 0 | X41: 0 | Z41: =X41/$Z$69 -> 0
B42: سیمان باقران | D42: 2035713 | F42: 103932356668 | H42: 121416030459 | I42: 484002945000 | J42: 0 | L42: 0 | N42: -2035713 | P42: 137755574821 | R42: 0 | T42: 0 | V42: 0 | X42: 0 | Z42: =X42/$Z$69 -> 0
B43: شمش طلا CD1GOB0001 | D43: 26228 | F43: 149809255586 | H43: 3.2753413e+11 | I43: 62923365000 | J43: 0 | L43: 0 | N43: -26228 | P43: 356337108208 | R43: 0 | T43: 0 | V43: 0 | X43: 0 | Z43: =X43/$Z$69 -> 0
B44: صنایع پتروشیمی خلیج فارس | D44: 40000000 | F44: 258409850710 | H44: 275948280000 | I44: 50179644000 | J44: 50922576 | L44: 404195810524 | N44: -922576 | P44: 7065476177 | R44: 90000000 | T44: 8260 | V44: 656110301933 | X44: 738976770000 | Z44: =X44/$Z$69 -> 0.10120229
B45: صنعتی مینو | D45: 3097352 | F45: 23803419669 | H45: 2.2260612e+10 | I45: 159048000000 | J45: 1200000 | L45: 9077399052 | N45: -4297352 | P45: 32192653049 | R45: 0 | T45: 0 | V45: 0 | X45: 0 | Z45: =X45/$Z$69 -> 0
...

Sheet اوراق تبعی
B1: =' سهام'!B1:Z1 -> صندوق سرمایه گذاری شاخص سی شرکت بزرگ فیروزه
B2: صورت وضعیت پرتفوی
B3: =' سهام'!AC6 -> برای ماه منتهی به 1404/07/30
B4: اطلاعات آماری مرتبط با اوراق اختیار فروش تبعی خریداری شده توسط صندوق سرمایه گذاری:
D6: =' سهام'!AC4 -> 1404/06/31 | L6: =' سهام'!AC5 -> 1404/07/30
B7: نام سهام | D7: تعداد اوراق تبعی | F7: قیمت اعمال | H7: تاریخ اعمال | J7: نرخ سود مؤثر | L7: تعداد اوراق تبعی | N7: قیمت اعمال | P7: تاریخ اعمال | R7: نرخ سود مؤثر
D8: - | F8: - | H8: - | J8: 0 | L8: 0 | N8: - | P8: - | R8: 0
D9: =SUM(D8) -> 0 | F9: =SUM(F8) -> 0 | H9: ..... | J9: ..... | L9: =SUM(L8) -> 0 | N9: =SUM(N8) -> 0 | P9: ..... | R9: .....

Sheet تعدیل قیمت
A1: =اوراق!B1 -> صندوق سرمایه گذاری شاخص سی شرکت بزرگ فیروزه
A2: صورت وضعیت پرتفوی
A3: =' سهام'!AC6 -> برای ماه منتهی به 1404/07/30
A4: اوراق بهاداری که ارزش آنها در تاریخ گزارش تعدیل شده
A5: (بر اساس دستورالعمل نحوه تعیین قیمت خرید و فروش اوراق بهادار در صندوق های سرمایه گذاری)
C6: =' سهام'!AC5 -> 1404/07/30
A7: نام اوراق بهادار | C7: تعداد | E7: قیمت پایانی | G7: قیمت تعدیل شده | I7: درصد تعدیل | K7: خالص ارزش فروش تعدیل شده | M7: دلیل تعدیل
C9: - | E9: - | G9: - | I9: - | K9: - | M9: -
C10: - | E10: - | G10: - | I10: - | K10: - | M10: -

Sheet گواهی سپرده
A1: ='تعدیل قیمت'!A1:P1 -> صندوق سرمایه گذاری شاخص سی شرکت بزرگ فیروزه
A2: صورت وضعیت پرتفوی
A3: =' سهام'!AC6 -> برای ماه منتهی به 1404/07/30
A4: 4-1- سرمایه‌گذاری در گواهی سپرده‌ بانکی
K6: =' سهام'!AC4 -> 1404/06/31 | Q6: تغییرات طی دوره | W6: =' سهام'!AC5 -> 1404/07/30
A7: گواهی سپرده بانکی | C7: تاریخ سررسید | E7: نرخ سود علی الحساب | G7: نرخ شکست | I7: پذیرفته شده در بورس یا فرابورس | K7: تعداد | M7: بهای تمام شده | O7: خالص ارزش | Q7: خرید طی دوره | T7: فروش طی دوره | W7: تعداد | Y7: بهای تمام شده | AA7: خالص ارزش | AC7: درصد به کل
O8: فروش | Q8: تعداد | R8: بهای تمام شده | T8: تعداد | U8: مبلغ فروش | AA8: فروش | AC8: دارایی‌ها
A9: گواهی سپرده بانکی نزد بانک ..... | C9: ..... | E9: ..... | G9: ..... | I9: ..... | K9: ..... | M9: ..... | O9: ..... | Q9: ..... | R9: ..... | T9: ..... | U9: ..... | W9: ..... | Y9: ..... | AA9: ..... | AC9: .....
A10: جمع | C10: ..... | E10: ..... | G10: ..... | I10: ..... | K10: ..... | M10: ..... | O10: ..... | Q10: ..... | R10: ..... | T10: ..... | U10: ..... | W10: ..... | Y10: ..... | AA10: ..... | AC10: .....

Sheet اوراق
B1: =' سهام'!B1:Z1 -> صندوق سرمایه گذاری شاخص سی شرکت بزرگ فیروزه
B2: صورت وضعیت پرتفوی
B3: =' سهام'!AC6 -> برای ماه منتهی به 1404/07/30
B4: 2-1-سرمایه‌گذاری در اوراق بهادار با درآمد ثابت یا علی‌الحساب
B6: اطلاعات اوراق بهادار با درآمد ثابت | Q6: =' سهام'!AC4 -> 1404/06/31 | W6: تغییرات طی دوره | AE6: =' سهام'!AC5 -> 1404/07/30
B7: نام اوراق | D7: دارای مجوز از سازمان | F7: پذیرفته شده در بورس یا فرابورس | H7: تاریخ انتشار اوراق | J7: تاریخ سررسید | M7: نرخ سود اسمی | O7: نرخ سود مؤثر | Q7: تعداد | S7: بهای تمام شده | U7: خالص ارزش فروش | W7: خرید طی دوره | AA7: فروش طی دوره | AE7: تعداد | AG7: قیمت بازار هر ورقه | AI7: بهای تمام شده | AK7: خالص ارزش فروش | AM7: درصد به کل دارایی‌ها
W8: تعداد | Y8: بهای تمام شده | AA8: تعداد | AC8: مبلغ فروش
B9: جمع | M9: - | Q9: 0 | S9: 0 | U9: 0 | W9: 0 | Y9: 0 | AA9: 0 | AC9: 0 | AE9: 0 | AG9: 0 | AI9: 0 | AK9: 0 | AM9: 0

Sheet سپرده
B1: صندوق سرمایه گذاری شاخص سی شرکت بزرگ فیروزه
B2: صورت وضعیت پرتفوی
B3: =' سهام'!AC6 -> برای ماه منتهی به 1404/07/30
B4: 3-1- سرمایه‌گذاری در سپرده‌ بانکی | AC4: 1404/02/31
AC5: 1404/03/31
D6: =' سهام'!AC4 -> 1404/06/31 | N6: تغییرات طی دوره | R6: =' سهام'!AC5 -> 1404/07/30 | AC6: برای ماه منتهی به 1404/03/31
B7: سپرده های بانکی | D7: شماره حساب | F7: نوع سپرده | H7: تاریخ افتتاح حساب | J7: نرخ سود علی الحساب | L7: مبلغ | N7: افزایش | P7: کاهش | R7: مبلغ | T7: درصد به کل دارایی‌ها | AC7: طی خرداد ماه
AC8: از ابتدای سال مالی تا پایان خرداد ماه
B9: حساب جاری بانک خاورمیانه مهستان | D9: 1005-11-040-00030030-1 | F9: حساب جاری | H9: 1393/04/25 | J9: 0 | L9: 50000000 | N9: 0 | P9: 0 | R9: 50000000 | T9: =R9/$T$14 -> 6.8474606e-06
B10: سپرده کوتاه مدت بانک خاورمیانه مهستان | D10: 1005-10-810-00030030-1 | F10: سپرده کوتاه مدت | H10: 1393/04/25 | J10: 0 | L10: 13911669 | N10: 3845901082506 | P10: 3845860637528 | R10: 54356647 | T10: =R10/$T$14 -> 7.4441e-06
B11: سپرده کوتاه مدت بانک گردشگری سعادت آباد | D11: 132.9967.1490777.1 | F11: سپرده کوتاه مدت | H11: 1402/06/19 | J11: 0 | L11: 473743783 | N11: 1480496691485 | P11: 1480930675000 | R11: 39760268 | T11: =R11/$T$14 -> 5.4451374e-06
B12: جمع | L12: =SUM(L9:L11) -> 537655452 | N12: =SUM(N9:N11) -> 5326397773991 | P12: =SUM(P9:P11) -> 5326791312528 | R12: =SUM(R9:R11) -> 144116915 | T12: =SUM(T9:T11) -> 1.9736698e-05
T14: 7301977015159

Sheet درآمدها
A1: صندوق سرمایه گذاری شاخص سی شرکت بزرگ فیروزه
A2: =سپرده!B2 -> صورت وضعیت پرتفوی
A3: =سپرده!B3 -> برای ماه منتهی به 1404/07/30
AC4: 1404/02/31
B5: شرح | D5: یادداشت | F5: مبلغ | H5: درصد از کل درآمدها | J5: درصد از کل دارایی ها | AC5: برای ماه منتهی به 1404/03/31
B6: درآمد حاصل از سرمایه گذاری در سهام و حق تقدم سهام | D6: 1-2 | F6: ='درآمد سرمایه گذاری در سهام '!T117 -> 824380889553 | H6: =F6/$H$12 -> 0.91226279 | J6: =F6/M8 -> 0.11289831 | AC6: طی خرداد ماه
B7: سود اوراق بهادار با درآمد ثابت و سپرده بانکی | D7: 3-2 | F7: ='درآمد سپرده بانکی'!J11 -> 19500124650 | H7: =F7/$H$12 -> 0.021578907 | J7: =F7/M8 -> 0.0026705267
B8: سایر درآمدها | D8: 4-2 | F8: ='سایر درآمدها'!F8 -> 4225976593 | H8: =F8/$H$12 -> 0.0046764806 | J8: =F8/M8 -> 0.00057874417 | M8: 7301977015159
B9: جمع | F9: =SUM(F6:F8) -> 848106990796 | H9: =SUM(H6:H8) -> 0.93851818 | J9: =SUM(J6:J8) -> 0.11614758
H12: 903666021073

Sheet درآمد سرمایه گذاری در سهام 
B1: =درآمدها!A1 -> صندوق سرمایه گذاری شاخص سی شرکت بزرگ فیروزه
B2: صورت وضعیت درآمدها
B3: =' سهام'!AC6 -> برای ماه منتهی به 1404/07/30
AC4: 1404/02/31
B5: 1-2-درآمد حاصل از سرمایه گذاری در سهام و حق تقدم سهام: | AC5: 1404/03/31
AC6: برای ماه منتهی به 1404/03/31
D7: =' سهام'!AC7 -> طی مهر ماه | N7: =' سهام'!AC8 -> از ابتدای سال مالی تا پایان مهر ماه | AC7: طی خرداد ماه
B8: سهام | D8: درآمد سود سهام | F8: درآمد تغییر ارزش | H8: درآمد فروش | J8: جمع | N8: درآمد سود سهام | P8: درآمد تغییر ارزش | R8: درآمد فروش | T8: جمع | AC8: از ابتدای سال مالی تا پایان خرداد ماه
D10: یادداشت 2-1-1 | F10: یادداشت 2-1-2 | H10: یادداشت 2-1-3 | J10: مبلغ | L10: درصد از کل درآمد ها | N10: یادداشت 2-1-1 | P10: یادداشت 2-1-2 | R10: یادداشت 2-1-3 | T10: مبلغ | V10: درصد از کل درآمد ها
B11: سرمایه‌گذاری‌صندوق‌بازنشستگی‌ | D11: 0 | F11: 34506314479 | H11: -7702229175 | J11: =H11+F11+D11 -> 26804085304 | L11: =-J11/$G$126 -> 0.03648363 | N11: 33460000000 | P11: -102743099037 | R11: -19299860645 | S11: -714562636 | T11: =N11+P11+R11 -> -88582959682 | U11: 11071728389 | V11: =T11/$X$12 -> -0.098026215
B12: شمش طلا CD1GOB0001 | D12: 0 | F12: 0 | H12: 91895554026 | J12: =H12+F12+D12 -> 91895554026 | L12: =-J12/$G$126 -> 0.12508106 | N12: 0 | P12: 0 | R12: 91895554026 | S12: -4741243411 | T12: =N12+P12+R12 -> 91895554026 | U12: 11071728390 | V12: =T12/$X$12 -> 0.10169194 | X12: 903666021073
B13: مبین انرژی خلیج فارس | D13: 0 | F13: 35063455505 | H13: 1043693046 | J13: =H13+F13+D13 -> 36107148551 | L13: =-J13/$G$126 -> 0.049146233 | N13: 22230000000 | P13: 36295544740 | R13: 53211014961 | S13: -3385001208 | T13: =N13+P13+R13 -> 111736559701 | U13: 11071728391 | V13: =T13/$X$12 -> 0.12364807
B14: صنایع پتروشیمی خلیج فارس | D14: 39350557839 | F14: 65917976946 | H14: -19821294 | J14: =H14+F14+D14 -> 105248713491 | L14: =-J14/$G$126 -> 0.14325634 | N14: 39350557839 | P14: 37416241612 | R14: -423765184 | S14: -2880009787 | T14: =N14+P14+R14 -> 76343034267 | U14: 11071728392 | V14: =T14/$X$12 -> 0.08448147
B15: فولاد مبارکه اصفهان | D15: 0 | F15: 28990816668 | H15: -5399783501 | J15: =H15+F15+D15 -> 23591033167 | L15: =-J15/$G$126 -> 0.032110274 | N15: 5600000000 | P15: -4567072112 | R15: -12135193293 | S15: -664891573 | T15: =N15+P15+R15 -> -11102265405 | U15: 11071728393 | V15: =T15/$X$12 -> -0.012285806
B16: پالایش نفت بندرعباس | D16: 0 | F16: 56104234159 | H16: 968567403 | J16: =H16+F16+D16 -> 57072801562 | L16: =-J16/$G$126 -> 0.077683044 | N16: 22491899048 | P16: 63245168576 | R16: 1330309687 | S16: -2538727106 | T16: =N16+P16+R16 -> 87067377311 | U16: 11071728394 | V16: =T16/$X$12 -> 0.096349066
B17: اقتصادی و خودکفایی آزادگان | D17: 0 | F17: 0 | H17: -23801494330 | J17: =H17+F17+D17 -> -23801494330 | L17: =-J17/$G$126 -> -0.032396737 | N17: 9013568521 | P17: 0 | R17: -22038903430 | S17: -5759026841 | T17: =N17+P17+R17 -> -13025334909 | U17: 11071728395 | V17: =T17/$X$12 -> -0.014413881
B18: بانک خاورمیانه | D18: 0 | F18: 3916490268 | H18: -95501806 | J18: =H18+F18+D18 -> 3820988462 | L18: =-J18/$G$126 -> 0.0052008314 | N18: 1500000000 | P18: 585532009 | R18: 9771719601 | S18: -2808202366 | T18: =N18+P18+R18 -> 11857251610 | U18: 11071728392 | V18: =T18/$X$12 -> 0.013121276
B19: سرمایه گذاری سبحان | D19: 11107223327 | F19: 3341523998 | H19: 68135853 | J19: =H19+F19+D19 -> 14516883178 | L19: =-J19/$G$126 -> 0.019759249 | N19: 11107223327 | P19: 5554046683 | R19: -596755720 | S19: 18700109240 | T19: =N19+P19+R19 -> 16064514290 | U19: 11071728393 | V19: =T19/$X$12 -> 0.017777048
B20: سیمان باقران | D20: 0 | F20: 0 | H20: 33823218153 | J20: =H20+F20+D20 -> 33823218153 | L20: =-J20/$G$126 -> 0.046037526 | N20: 0 | P20: 0 | R20: 33823218153 | S20: 8828197833 | T20: =N20+P20+R20 -> 33823218153 | U20: 11071728394 | V20: =T20/$X$12 -> 0.037428892
B21: معدنی‌وصنعتی‌چادرملو | D21: 0 | F21: 7500816264 | H21: -118411507 | J21: =H21+F21+D21 -> 7382404757 | L21: =-J21/$G$126 -> 0.010048353 | N21: 5051163390 | P21: -725656424 | R21: 1594153716 | S21: -40082741567 | T21: =N21+P21+R21 -> 5919660682 | U21: 11071728395 | V21: =T21/$X$12 -> 0.0065507173
B22: پتروشیمی پردیس | D22: 0 | F22: 49745408315 | H22: 585045192 | J22: =H22+F22+D22 -> 50330453507 | L22: =-J22/$G$126 -> 0.068505886 | N22: 55406125166 | P22: 19140478473 | R22: 2020709172 | S22: 466959920 | T22: =N22+P22+R22 -> 76567312811 | U22: 11071728396 | V22: =T22/$X$12 -> 0.084729658
B23: تایدواترخاورمیانه | D23: 0 | F23: 13308924562 | H23: 226949553 | J23: =H23+F23+D23 -> 13535874115 | L23: =-J23/$G$126 -> 0.018423976 | N23: 0 | P23: 13308924562 | R23: 226949553 | S23: -102059379029 | T23: =N23+P23+R23 -> 13535874115 | U23: 11071728398 | V23: =T23/$X$12 -> 0.014978846
B24: سرمایه‌گذاری‌نیرو | D24: 0 | F24: 0 | H24: -17593967988 | J24: =H24+F24+D24 -> -17593967988 | L24: =-J24/$G$126 -> -0.023947536 | N24: 480000000 | P24: 0 | R24: -17593967988 | S24: -11597631470 | T24: =N24+P24+R24 -> -17113967988 | U24: 11071728399 | V24: =T24/$X$12 -> -0.018938377
... B34: کشتیرانی جمهوری اسلامی ایران | D34: 35913654618 | F34: -2565905117 | H34: -8516276149 | J34: =H34+F34+D34 -> 24831473352 | L34: =-J34/$G$126 -> 0.033798664 | N34: 35913654618 | P34: -55579739338 | R34: -8831107891 | S34: 8613312174 | T34: =N34+P34+R34 -> -28497192611 | U34: -5155830312 | V34: =T34/$X$12 -> -0.031535094
B35: نقل به صفحه بعد | D35: =SUM(D11:D34) -> 140124812179 | F35: =SUM(F11:F34) -> 585249909205 | H35: =SUM(H11:H34) -> 75066087069 | J35: =SUM(J11:J34) -> 800440808453 | L35: =SUM(L11:L34) -> 1.0894976 | N35: =SUM(N11:N34) -> 370458196563 | P35: =SUM(P11:P34) -> 24921371727 | R35: =SUM(R11:R34) -> 112599651272 | T35: =SUM(T11:T34) -> 507979219562 | V35: =SUM(V11:V34) -> 0.56213159
B37: 1-2-درآمد حاصل از سرمایه گذاری در سهام و حق تقدم سهام:
D39: =D7 -> طی مهر ماه | N39: =N7 -> از ابتدای سال مالی تا پایان مهر ماه
B40: سهام | D40: درآمد سود سهام | F40: درآمد تغییر ارزش | H40: درآمد فروش | J40: جمع | N40: درآمد سود سهام | P40: درآمد تغییر ارزش | R40: درآمد فروش | T40: جمع
D42: یادداشت 2-1-1 | F42: یادداشت 2-1-2 | H42: یادداشت 2-1-3 | J42: مبلغ | L42: درصد از کل درآمد ها | N42: یادداشت 2-1-1 | P42: یادداشت 2-1-2 | R42: یادداشت 2-1-3 | T42: مبلغ | V42: درصد از کل درآمد ها
B43: نقل از صفحه قبل | D43: =D35 -> 140124812179 | F43: =F35 -> 585249909205 | H43: =H35 -> 75066087069 | J43: =J35 -> 800440808453 | L43: =L35 -> 1.0894976 | N43: =N35 -> 370458196563 | P43: =P35 -> 24921371727 | R43: =R35 -> 112599651272 | T43: =T35 -> 507979219562 | V43: =V35 -> 0.56213159
B44: سرمایه گذاری صدرتامین | D44: 0 | F44: 33538786297 | H44: -25788552021 | J44: =D44+F44+H44 -> 7750234276 | L44: =-J44/$G$126 -> 0.010549014 | N44: 19372738239 | P44: -3961174080 | R44: -65871293588 | S44: 2132299511 | T44: =N44+P44+R44 -> -50459729429 | U44: -5155830311 | V44: =T44/$X$12 -> -0.055838914
B45: پتروشیمی پارس | D45: 0 | F45: 44937977526 | H45: -16923777790 | J45: =D45+F45+H45 -> 28014199736 | L45: =-J45/$G$126 -> 0.038130743 | N45: 12000000000 | P45: -39312811066 | R45: -22682804631 | S45: 1644814375 | T45: =N45+P45+R45 -> -49995615697 | U45: -5155830310 | V45: =T45/$X$12 -> -0.055325324
B46: توسعه‌معادن‌وفلزات‌ | D46: 0 | F46: 48244237187 | H46: 15414195211 | J46: =D46+F46+H46 -> 63658432398 | L46: =-J46/$G$126 -> 0.086646891 | N46: 2573504011 | P46: 48243498617 | R46: 6538671124 | S46: -8875524087 | T46: =N46+P46+R46 -> 57355673752 | U46: -803317139 | V46: =T46/$X$12 -> 0.06346999
B47: صنعتی مینو | D47: 0 | F47: 0 | H47: -688165672 | J47: =D47+F47+H47 -> -688165672 | L47: =-J47/$G$126 -> -0.00093667742 | N47: 7300000000 | P47: 0 | R47: 3171109669 | S47: 1487118809 | T47: =N47+P47+R47 -> 10471109669 | U47: -38274340413 | V47: =T47/$X$12 -> 0.011587367
B48: جنرال مکانیک | D48: 0 | F48: 0 | H48: 0 | J48: =D48+F48+H48 -> 0 | L48: =-J48/$G$126 -> 0 | N48: 0 | P48: 0 | R48: -14922689397 | S48: 3859275341 | T48: =N48+P48+R48 -> -14922689397 | U48: 8687840 | V48: =T48/$X$12 -> -0.016513501
B49: پتروشیمی جم | D49: 0 | F49: 7753590 | H49: 0 | J49: =D49+F49+H49 -> 7753590 | L49: =-J49/$G$126 -> 1.0553582e-05 | N49: 14534167200 | P49: -25232694 | R49: -102059379029 | S49: 1937265303 | T49: =N49+P49+R49 -> -87550444523 | U49: -3013924119 | V49: =T49/$X$12 -> -0.09688363
B50: پویا | D50: 0 | F50: 139166999 | H50: 0 | J50: =D50+F50+H50 -> 139166999 | L50: =-J50/$G$126 -> 0.00018942326 | N50: 235000000 | P50: 400164199 | R50: 415651628 | S50: 1212931406 | T50: =N50+P50+R50 -> 1050815827 | U50: -5189228345 | V50: =T50/$X$12 -> 0.0011628365
B51: مخابرات ایران | D51: 0 | F51: 85488 | H51: 0 | J51: =D51+F51+H51 -> 85488 | L51: =-J51/$G$126 -> 1.163596e-07 | N51: 0 | P51: -13170 | R51: 5021464603 | S51: 6910941668 | T51: =N51+P51+R51 -> 5021451433 | U51: 3261876929 | V51: =T51/$X$12 -> 0.0055567558
B52: پتروشیمی مارون | D52: 0 | F52: 0 | H52: 0 | J52: =D52+F52+H52 -> 0 | L52: =-J52/$G$126 -> 0 | N52: 0 | P52: 0 | R52: -4485653237 | S52: 151419925 | T52: =N52+P52+R52 -> -4485653237 | U52: 2910175062 | V52: =T52/$X$12 -> -0.0049638397
B53: معدنکاران نسوز | D53: 0 | F53: 808908187 | H53: 0 | J53: =D53+F53+H53 -> 808908187 | L53: =-J53/$G$126 -> 0.0011010227 | N53: 262500000 | P53: 1200315357 | R53: 872060105 | S53: 31387040 | T53: =N53+P53+R53 -> 2334875462 | U53: 1401330331 | V53: =T53/$X$12 -> 0.0025837814
...

Sheet درآمد سود سهام
B1: =درآمدها!A1 -> صندوق سرمایه گذاری شاخص سی شرکت بزرگ فیروزه
B2: صورت وضعیت درآمدها
B3: =' سهام'!AC6 -> برای ماه منتهی به 1404/07/30
B4: 1-1-2-درآمد سود سهام | AK4: 1404/05/31
D5: اطلاعات مجمع | J5: =' سهام'!AC7 -> طی مهر ماه | P5: =' سهام'!AC8 -> از ابتدای سال مالی تا پایان مهر ماه | AI5: 1404/06/31
B6: نام سهام | D6: تاریخ مجمع | F6: تعداد سهام متعلقه در زمان مجمع | H6: سود متعلق به هر سهم | J6: جمع درآمد سود سهام | L6: هزینه تنزیل | N6: خالص درآمد سود سهام | P6: جمع درآمد سود سهام | R6: هزینه تنزیل | T6: خالص درآمد سود سهام | AI6: برای ماه منتهی به 1404/06/31
B7: بانک‌اقتصادنوین‌ | D7: 1404/04/22 | F7: 36000000 | H7: 240 | J7: 0 | L7: 0 | N7: 0 | P7: 8640000000 | R7: 0 | T7: =P7+R7 -> 8640000000
B8: گروه مپنا (سهامی عام) | D8: 1404/07/20 | F8: 1000 | H8: 620 | J8: 620000 | L8: -43439 | N8: 576561 | P8: 620000 | R8: -43439 | T8: =P8+R8 -> 576561
B9: سرمایه‌گذاری‌صندوق‌بازنشستگی‌ | D9: 1404/05/12 | F9: 14000000 | H9: 2390 | J9: 0 | L9: 0 | N9: 0 | P9: 33460000000 | R9: 0 | T9: =P9+R9 -> 33460000000
B10: ملی‌ صنایع‌ مس‌ ایران‌ | D10: 1404/04/31 | F10: 64000000 | H10: 370 | J10: 0 | L10: 0 | N10: 0 | P10: 23680000000 | R10: 0 | T10: =P10+R10 -> 23680000000
B11: سرمایه‌گذاری‌نیرو | D11: 1404/04/31 | F11: 10000000 | H11: 48 | J11: 0 | L11: 0 | N11: 0 | P11: 480000000 | R11: 0 | T11: =P11+R11 -> 480000000
B12: گروه مدیریت سرمایه گذاری امید | D12: 1404/02/30 | F12: 1000 | H12: 2320 | J12: 0 | L12: 0 | N12: 0 | P12: 2320000 | R12: 0 | T12: =P12+R12 -> 2320000
B13: کشتیرانی جمهوری اسلامی ایران | D13: 1404/07/15 | F13: 35000000 | H13: 1050 | J13: 36750000000 | L13: -836345382 | N13: 35913654618 | P13: 36750000000 | R13: -836345382 | T13: =P13+R13 -> 35913654618
B14: توسعه‌معادن‌وفلزات‌ | D14: 1404/04/29 | F14: 15449319 | H14: 170 | J14: 0 | L14: 0 | N14: 0 | P14: 2626384230 | R14: -52880219 | T14: =P14+R14 -> 2573504011
B15: پتروشیمی‌شیراز | D15: 1404/05/11 | F15: 6500000 | H15: 4984 | J15: 0 | L15: 0 | N15: 0 | P15: 32396000000 | R15: -307696065 | T15: =P15+R15 -> 32088303935
B16: پالایش نفت تبریز | D16: 1404/04/28 | F16: 9000000 | H16: 1997 | J16: 0 | L16: 0 | N16: 0 | P16: 17973000000 | R16: -182776271 | T16: =P16+R16 -> 17790223729
B17: پالایش نفت اصفهان | D17: 1404/04/30 | F17: 151800000 | H17: 360 | J17: 0 | L17: 0 | N17: 0 | P17: 54648000000 | R17: 0 | T17: =P17+R17 -> 54648000000 | AJ17: 1
B18: معدنی‌وصنعتی‌چادرملو | D18: 1404/04/23 | F18: 13383580 | H18: 380 | J18: 0 | L18: 0 | N18: 0 | P18: 5085760400 | R18: -34597010 | T18: =P18+R18 -> 5051163390
B19: معدنی و صنعتی گل گهر | D19: 1404/04/23 | F19: 5600000 | H19: 310 | J19: 0 | L19: 0 | N19: 0 | P19: 1736000000 | R19: -21142084 | T19: =P19+R19 -> 1714857916
B20: شهد ایران ‌ | D20: 1404/04/28 | F20: 6000000 | H20: 400 | J20: 0 | L20: 0 | N20: 0 | P20: 2400000000 | R20: 0 | T20: =P20+R20 -> 2400000000
B21: فولاد مبارکه اصفهان | D21: 1404/05/13 | F21: 20000000 | H21: 280 | J21: 0 | L21: 0 | N21: 0 | P21: 5600000000 | R21: 0 | T21: =P21+R21 -> 5600000000
B22: بانک ملت | D22: 1404/04/31 | F22: 35200000 | H22: 90 | J22: 0 | L22: 0 | N22: 0 | P22: 3168000000 | R22: 0 | T22: =P22+R22 -> 3168000000
B23: بانک تجارت | D23: 1404/04/31 | F23: 1000 | H23: 11 | J23: 0 | L23: 0 | N23: 0 | P23: 11000 | R23: 0 | T23: =P23+R23 -> 11000
B24: بانک صادرات ایران | D24: 1404/04/31 | F24: 100000000 | H24: 15 | J24: 0 | L24: 0 | N24: 0 | P24: 1500000000 | R24: 0 | T24: =P24+R24 -> 1500000000
B25: پالایش نفت بندرعباس | D25: 1404/05/08 | F25: 24655240 | H25: 936 | J25: 0 | L25: 0 | N25: 0 | P25: 23077304640 | R25: -585405592 | T25: =P25+R25 -> 22491899048
B26: پتروشیمی پردیس | D26: 1404/06/23 | F26: 1500000 | H26: 38000 | J26: 0 | L26: 0 | N26: 0 | P26: 57000000000 | R26: -1593874834 | T26: =P26+R26 -> 55406125166
B27: صنایع پتروشیمی خلیج فارس | D27: 1404/07/30 | F27: 90000000 | H27: 510 | J27: 45900000000 | L27: -6549442161 | N27: 39350557839 | P27: 45900000000 | R27: -6549442161 | T27: =P27+R27 -> 39350557839
B28: س. نفت و گاز و پتروشیمی تأمین | D28: 1404/06/26 | F28: 3800000 | H28: 2000 | J28: 0 | L28: 0 | N28: 0 | P28: 7600000000 | R28: 0 | T28: =P28+R28 -> 7600000000
B29: اقتصادی و خودکفایی آزادگان | D29: 1404/04/28 | F29: 14000000 | H29: 650 | J29: 0 | L29: 0 | N29: 0 | P29: 9100000000 | R29: -86431479 | T29: =P29+R29 -> 9013568521
... B50: پویا | D50: 1404/04/21 | F50: 100000 | H50: 2350 | J50: 0 | L50: 0 | N50: 0 | P50: 235000000 | R50: 0 | T50: =P50+R50 -> 235000000
B51: جمع | F51: =SUM(F7:F50) -> 1225612554 | J51: =SUM(J7:J50) -> 156830620000 | L51: =SUM(L7:L50) -> -16705231260 | N51: =SUM(N7:N50) -> 140125388740 | P51: =SUM(P7:P50) -> 579464625903 | R51: =SUM(R7:R50) -> -22436770139 | T51: =SUM(T7:T50) -> 557027855764 | AH51: از ابتدای سال مالی تا پایان مهر ماه
T54: =T51-'درآمد سرمایه گذاری در سهام '!N117 -> 0

Sheet درآمد ناشی از تغییر قیمت اوراق 
B1: ='درآمد ناشی ازفروش'!B1:R1 -> صندوق سرمایه گذاری شاخص سی شرکت بزرگ فیروزه
B2: صورت وضعیت درآمدها
B3: =' سهام'!AC6 -> برای ماه منتهی به 1404/07/30
B4: 2-1-2-درآمد ناشی از تغییر قیمت اوراق بهادار | AC4: 1404/02/31
D5: =' سهام'!AC7 -> طی مهر ماه | L5: =' سهام'!AC8 -> از ابتدای سال مالی تا پایان مهر ماه | AC5: 1404/03/31
B6: شرح | D6: تعداد | F6: خالص ارزش فروش | H6: ارزش دفتری | J6: سود و زیان ناشی از تغییر قیمت | L6: تعداد | N6: خالص ارزش فروش | P6: ارزش دفتری | R6: سود و زیان ناشی از تغییر قیمت | AC6: برای ماه منتهی به 1404/03/31
B7: کشت و دام گلدشت نمونه اصفهان | D7: 3000000 | F7: 16610575500 | H7: -11856521410 | J7: =F7+H7 -> 4754054090 | L7: 3000000 | N7: 16610575500 | P7: -18024621597 | R7: =N7+P7 -> -1414046097 | AC7: طی خرداد ماه
B8: گروه مپنا (سهامی عام) | D8: 1000 | F8: 13499199 | H8: -11640325 | J8: =F8+H8 -> 1858874 | L8: 1000 | N8: 13499199 | P8: -16437235 | R8: =N8+P8 -> -2938036 | AC8: از ابتدای سال مالی تا پایان خرداد ماه
B9: گسترش نفت و گاز پارسیان | D9: 3000000 | F9: 200907445500 | H9: -165035410140 | J9: =F9+H9 -> 35872035360 | L9: 3000000 | N9: 200907445500 | P9: -171542654628 | R9: =N9+P9 -> 29364790872
B10: پالایش نفت اصفهان | D10: 140000000 | F10: 681918300000 | H10: -483744492000 | J10: =F10+H10 -> 198173808000 | L10: 140000000 | N10: 681918300000 | P10: -522112581443 | R10: =N10+P10 -> 159805718557
B11: بانک ملت | D11: 163990997 | F11: 199530666695 | H11: -177781763886 | J11: 61958845030 | L11: 163990997 | N11: 199530666695 | P11: -181303122037 | R11: =N11+P11 -> 18227544658
B12: کشتیرانی جمهوری اسلامی ایران | D12: 30000000 | F12: 166702185000 | H12: -169268090117 | J12: =F12+H12 -> -2565905117 | L12: 30000000 | N12: 166702185000 | P12: -222281924338 | R12: =N12+P12 -> -55579739338
B13: توسعه سرمایه و صنعت غدیر | D13: 7000000 | F13: 105697336500 | H13: -97903984500 | J13: =F13+H13 -> 7793352000 | L13: 7000000 | N13: 105697336500 | P13: -121613302376 | R13: =N13+P13 -> -15915965876
B14: ایران‌ خودرو | D14: 119200000 | F14: 63037084320 | H14: -51614401149 | J14: =F14+H14 -> 11422683171 | L14: 119200000 | N14: 63037084320 | P14: -60338503525 | R14: =N14+P14 -> 2698580795
B15: سرمایه گذاری صدرتامین | D15: 2000000 | F15: 22067910000 | H15: 11470876297 | J15: =F15+H15 -> 33538786297 | L15: 2000000 | N15: 22067910000 | P15: -26029084080 | R15: =N15+P15 -> -3961174080
B16: بانک تجارت | D16: 1000 | F16: 465215 | H16: -389667 | J16: =F16+H16 -> 75548 | L16: 1000 | N16: 465215 | P16: -631828 | R16: =N16+P16 -> -166613
B17: معدنی و صنعتی گل گهر | D17: 1000 | F17: 2018915 | H17: -1646146 | J17: =F17+H17 -> 372769 | L17: 1000 | N17: 2018915 | P17: -2282542 | R17: =N17+P17 -> -263627
B18: سرمایه گذاری تامین اجتماعی | D18: 330000000 | F18: 407749369500 | H18: -380526821914 | J18: =F18+H18 -> 27222547586 | L18: 330000000 | N18: 407749369500 | P18: -522444578886 | R18: =N18+P18 -> -114695209386
B19: پتروشیمی‌شیراز | D19: 6000000 | F19: 214834086000 | H19: -185180792294 | J19: =F19+H19 -> 29653293706 | L19: 6000000 | N19: 214834086000 | P19: -221563793094 | R19: =N19+P19 -> -6729707094
B20: پتروشیمی جم | D20: 1000 | F20: 42942960 | H20: -35189370 | J20: =F20+H20 -> 7753590 | L20: 1000 | N20: 42942960 | P20: -68175654 | R20: =N20+P20 -> -25232694
B21: پویا | D21: 100000 | F21: 3002031000 | H21: -2862864000 | J21: =F21+H21 -> 139167000 | L21: 100000 | N21: 3002031000 | P21: -2601866800 | R21: =N21+P21 -> 400164200
B22: مخابرات ایران | D22: 1000 | F22: 470185 | H22: -384697 | J22: =F22+H22 -> 85488 | L22: 1000 | N22: 470185 | P22: -483356 | R22: =N22+P22 -> -13171
B23: سرمایه‌گذاری‌صندوق‌بازنشستگی‌ | D23: 12000000 | F23: 182507580000 | H23: -148001265521 | J23: =F23+H23 -> 34506314479 | L23: 12000000 | N23: 182507580000 | P23: -285250679037 | R23: =N23+P23 -> -102743099037
... B38: پالایش نفت تبریز | D38: 10000000 | F38: 236285685000 | H38: -174952800000 | J38: =F38+H38 -> 61332885000 | L38: 10000000 | N38: 236285685000 | P38: -190539440243 | R38: =N38+P38 -> 45746244757
B39: نقل به صفحه بعد | D39: =SUM(D7:D38) -> 1168760350 | F39: =SUM(F7:F38) -> 3353775110548 | H39: =SUM(H7:H38) -> -2737438182700 | J39: =SUM(J7:J38) -> 656546870069 | L39: =SUM(L7:L38) -> 1168760350 | N39: =SUM(N7:N38) -> 3353775110548 | P39: =SUM(P7:P38) -> -3354826985795 | R39: =SUM(R7:R38) -> -1051875247
B41: 2-1-2-درآمد ناشی از تغییر قیمت اوراق بهادار | AA41: 1404/02/31
D42: =D5 -> طی مهر ماه | L42: =L5 -> از ابتدای سال مالی تا پایان مهر ماه | AA42: 1404/03/31
B43: شرح | D43: تعداد | F43: خالص ارزش فروش | H43: ارزش دفتری | J43: سود و زیان ناشی از تغییر قیمت | L43: تعداد | N43: خالص ارزش فروش | P43: ارزش دفتری | R43: سود و زیان ناشی از تغییر قیمت | AA43: برای ماه منتهی به 1404/03/31
B44: نقل از صفحه قبل | D44: =D39 -> 1168760350 | F44: =F39 -> 3353775110548 | H44: =H39 -> -2737438182700 | J44: =J39 -> 656546870069 | L44: =L39 -> 1168760350 | N44: =N39 -> 3353775110548 | P44: =P39 -> -3354826985795 | R44: =R39 -> -1051875247
B45: سرمایه‌ گذاری‌ آتیه‌ دماوند | D45: 42000000 | F45: 172344412800 | H45: -168550341611 | J45: =F45+H45 -> 3794071189 | L45: 42000000 | N45: 172344412800 | P45: -168550341611 | R45: =N45+P45 -> 3794071189
B46: گروه مالی صبا تامین | D46: 70000000 | F46: 225102622500 | H46: -199449742480 | J46: =F46+H46 -> 25652880020 | L46: 70000000 | N46: 225102622500 | P46: -199449742480 | R46: =N46+P46 -> 25652880020
B47: مبین انرژی خلیج فارس | D47: 12000000 | F47: 153521082000 | H47: -118457626495 | J47: =F47+H47 -> 35063455505 | L47: 12000000 | N47: 153521082000 | P47: -117225537260 | R47: =N47+P47 -> 36295544740
B48: معدنکاران نسوز | D48: 175000 | F48: 8263040625 | H48: -7454132437 | J48: =F48+H48 -> 808908188 | L48: 175000 | N48: 8263040625 | P48: -7062725268 | R48: =N48+P48 -> 1200315357
B49: معدنی‌وصنعتی‌چادرملو | D49: 10000000 | F49: 25835359500 | H49: -18334543236 | J49: =F49+H49 -> 7500816264 | L49: 10000000 | N49: 25835359500 | P49: -26561015924 | R49: =N49+P49 -> -725656424
B50: پتروشیمی پردیس | D50: 1500000 | F50: 424807267500 | H50: -375061859184 | J50: =F50+H50 -> 49745408316 | L50: 1500000 | N50: 424807267500 | P50: -405666789026 | R50: =N50+P50 -> 19140478474
B51: بین المللی توسعه ص. معادن غدیر | D51: 1000 | F51: 3347960 | H51: -2870816 | J51: =F51+H51 -> 477144 | L51: 1000 | N51: 3347960 | P51: -3874804 | R51: =N51+P51 -> -526844
B52: تایدواترخاورمیانه | D52: 30000000 | F52: 201891555000 | H52: -188582630437 | J52: =F52+H52 -> 13308924563 | L52: 30000000 | N52: 201891555000 | P52: -188582630437 | R52: =N52+P52 -> 13308924563
B53: توسعه معادن وص.معدنی خاورمیانه | D53: 1000 | F53: 4267456 | H53: -3781366 | J53: =F53+H53 -> 486090 | L53: 1000 | N53: 4267456 | P53: -4876726 | R53: =N53+P53 -> -609270
B54: ایران‌ ترانسفو | D54: 5600000 | F54: 20791549800 | H54: -18490583894 | J54: =F54+H54 -> 2300965906 | L54: 5600000 | N54: 20791549800 | P54: -18490583894 | R54: =N54+P54 -> 2300965906
B55: پالایش نفت تهران | D55: 20000000 | F55: 57992877000 | H55: -31220991527 | J55: =F55+H55 -> 26771885473 | L55: 20000000 | N55: 57992877000 | P55: -49859918672 | R55: =N55+P55 -> 8132958328
...

Sheet درآمد ناشی ازفروش
B1: ='سود اوراق بهادار و سپرده بانکی'!B1:U1 -> صندوق سرمایه گذاری شاخص سی شرکت بزرگ فیروزه
B2: صورت وضعیت درآمدها
B3: =' سهام'!B3:Z3 -> برای ماه منتهی به 1404/07/30
B4: 3-1-2-سود(زیان) حاصل از فروش اوراق بهادار | AC4: 1404/04/31
D5: =' سهام'!AC7 -> طی مهر ماه | L5: =' سهام'!AC8 -> از ابتدای سال مالی تا پایان مهر ماه | AC5: 1404/05/31
B6: شرح | D6: تعداد | F6: خالص بهای فروش | H6: ارزش دفتری | J6: سود و زیان ناشی از فروش | L6: تعداد | N6: خالص ارزش فروش | P6: ارزش دفتری | R6: سود و زیان ناشی از فروش | Z6: برای ماه منتهی به 1404/05/31
B7: سرمایه‌گذاری‌صندوق‌بازنشستگی‌ | D7: 900000 | F7: 13691571754 | H7: -21393800929 | J7: =F7+H7 -> -7702229175 | L7: 2802865 | N7: 47326625398 | P7: -66626486043 | R7: -19299860645 | Z7: طی مرداد ماه
B8: شمش طلا CD1GOB0001 | D8: 26228 | F8: 356337108208 | H8: -264441554182 | J8: =F8+H8 -> 91895554026 | L8: 26228 | N8: 356337108208 | P8: -264441554182 | R8: 91895554026 | Z8: از ابتدای سال مالی تا پایان مرداد ماه
B9: مبین انرژی خلیج فارس | D9: 700000 | F9: 7881849379 | H9: -6838156333 | J9: =F9+H9 -> 1043693046 | L9: 18700000 | N9: 225789917894 | P9: -172578902933 | R9: 53211014961
B10: صنایع پتروشیمی خلیج فارس | D10: 922576 | F10: 7065476177 | H10: -7085297471 | J10: =F10+H10 -> -19821294 | L10: 13323322 | N10: 101045993049 | P10: -101469758233 | R10: -423765184
B11: فولاد مبارکه اصفهان | D11: 32000000 | F11: 87647971297 | H11: -93047754798 | J11: =F11+H11 -> -5399783501 | L11: 72600000 | N11: 240328360008 | P11: -252463553301 | R11: -12135193293
B12: پالایش نفت بندرعباس | D12: 500000 | F12: 5892489043 | H12: -4923921640 | J12: =F12+H12 -> 968567403 | L12: 4302565 | N12: 41425685971 | P12: -40095376284 | R12: 1330309687
B13: اقتصادی و خودکفایی آزادگان | D13: 14000000 | F13: 71684704000 | H13: -95486198330 | J13: =F13+H13 -> -23801494330 | L13: 17003374 | N13: 93930456333 | P13: -115969359763 | R13: -22038903430
B14: بانک خاورمیانه | D14: 1000000 | F14: 2379415174 | H14: -2474916980 | J14: =F14+H14 -> -95501806 | L14: 44200000 | N14: 196760306682 | P14: -186988587081 | R14: 9771719601
B15: سرمایه گذاری سبحان | D15: 3000000 | F15: 6320238252 | H15: -6252102399 | J15: =F15+H15 -> 68135853 | L15: 15174770 | N15: 30826733623 | P15: -31423489343 | R15: -596755720
B16: سیمان باقران | D16: 2035713 | F16: 137755574821 | H16: -103932356668 | J16: =F16+H16 -> 33823218153 | L16: 2035713 | N16: 137755574821 | P16: -103932356668 | R16: 33823218153
B17: معدنی‌وصنعتی‌چادرملو | D17: 383580 | F17: 900415942 | H17: -1018827449 | J17: =F17+H17 -> -118411507 | L17: 45383580 | N17: 122137553243 | P17: -120543399527 | R17: 1594153716
D18: 50000 | F18: 14107271508 | H18: -13522226316 | J18: =F18+H18 -> 585045192 | L18: 350000 | N18: 93152434018 | P18: -91131724846 | R18: 2020709172
B19: تایدواترخاورمیانه | D19: 1000000 | F19: 6513037236 | H19: -6286087683 | J19: =F19+H19 -> 226949553 | L19: 1000000 | N19: 6513037236 | P19: -6286087683 | R19: 226949553
B20: سرمایه‌گذاری‌نیرو | D20: 10000000 | F20: 38860864777 | H20: -56454832765 | J20: =F20+H20 -> -17593967988 | L20: 10000000 | N20: 38860864777 | P20: -56454832765 | R20: -17593967988
B21: ایران‌ ترانسفو | D21: 8400000 | F21: 29645764472 | H21: -27735875851 | J21: =F21+H21 -> 1909888621 | L21: 8400000 | N21: 29645764472 | P21: -27735875851 | R21: 1909888621
B22: پالایش نفت تهران | D22: 35000000 | F22: 86160123469 | H22: -87254857723 | J22: =F22+H22 -> -1094734254 | L22: 55000000 | N22: 132981669393 | P22: -135431083585 | R22: -2449414192
B23: ملی‌ صنایع‌ مس‌ ایران‌ | D23: 3951 | F23: 23608739 | H23: -27173852 | J23: =F23+H23 -> -3565113 | L23: 7315384 | N23: 43619362067 | P23: -50587404808 | R23: -6968042741
B24: سرمایه گذاری تامین اجتماعی | D24: 7000000 | F24: 9861866649 | H24: -11082157736 | J24: =F24+H24 -> -1220291087 | L24: 42714631 | N24: 52289922024 | P24: -67081912554 | R24: -14791990530
B25: پتروشیمی‌شیراز | D25: 405319 | F25: 13961383517 | H25: -14969645299 | J25: =F25+H25 -> -1008261782 | L25: 705319 | N25: 22304178782 | P25: -26078961990 | R25: -3774783208
B26: کشت و دام گلدشت نمونه اصفهان | D26: 3000000 | F26: 16714268686 | H26: -18024621590 | J26: =F26+H26 -> -1310352904 | L26: 11018459 | N26: 64169317239 | P26: -66194232779 | R26: -2024915540
B27: سرمایه گذاری توسعه گوهران امید | D27: 94429 | F27: 314925979 | H27: -324037299 | J27: =F27+H27 -> -9111320 | L27: 94429 | N27: 314925979 | P27: -324037299 | R27: -9111320
B28: گسترش نفت و گاز پارسیان | D28: 1599800 | F28: 103343959710 | H28: -91477979619 | J28: =F28+H28 -> 11865980091 | L28: 3100000 | N28: 185741721982 | P28: -177260743099 | R28: 8480978883
B29: بانک ملت | D29: 6400000 | F29: 7648489552 | H29: -7075632211 | J29: =F29+H29 -> 572857341 | L29: 96000000 | N29: 185184855704 | P29: -165911889123 | R29: 19272966581
B30: کشتیرانی جمهوری اسلامی ایران | D30: 5000000 | F30: 28530711234 | H30: -37046987383 | J30: =F30+H30 -> -8516276149 | L30: 14369697 | N30: 105093650294 | P30: -113924758185 | R30: -8831107891
... B42: کانی کربن طبس | D42: 0 | F42: 0 | H42: 0 | J42: =F42+H42 -> 0 | L42: 250000 | N42: 3710544265 | P42: -3436927875 | R42: 273616390
B43: نقل به صفحه بعد | D43: =SUM(D7:D42) -> 241460061 | F43: =SUM(F7:F42) -> 1361410801049 | H43: =SUM(H7:H42) -> -1314331014252 | J43: =SUM(J7:J42) -> 47079786797 | L43: =SUM(L7:L42) -> 746630990 | N43: =SUM(N7:N42) -> 3703229336253 | P43: =SUM(P7:P42) -> -3759779949105 | R43: =SUM(R7:R42) -> -56550612852
B45: 3-1-2-سود(زیان) حاصل از فروش اوراق بهادار | Z45: 1404/02/31
D46: =D5 -> طی مهر ماه | L46: =L5 -> از ابتدای سال مالی تا پایان مهر ماه | Z46: 1404/03/31
B47: شرح | D47: تعداد | F47: خالص بهای فروش | H47: ارزش دفتری | J47: سود و زیان ناشی از فروش | L47: تعداد | N47: خالص ارزش فروش | P47: ارزش دفتری | R47: سود و زیان ناشی از فروش | X47: برای ماه منتهی به 1404/03/31
B48: نقل از صفحه قبل | D48: =D43 -> 241460061 | F48: =F43 -> 1361410801049 | H48: =H43 -> -1314331014252 | J48: =J43 -> 47079786797 | L48: =L43 -> 746630990 | N48: =N43 -> 3703229336253 | P48: =P43 -> -3759779949105 | R48: =R43 -> -56550612852
B49: شرکت قند بیستون | D49: 0 | F49: 0 | H49: 0 | J49: =F49+H49 -> 0 | L49: 358251 | N49: 6944992773 | P49: 6981910383 | R49: -36917610
B50: بانک‌اقتصادنوین‌ | D50: 0 | F50: 0 | H50: 0 | J50: =F50+H50 -> 0 | L50: 3250000 | N50: 4772600674 | P50: 4390650225 | R50: 381950449
B51: ایمن خودرو شرق | D51: 0 | F51: 0 | H51: 0 | J51: =F51+H51 -> 0 | L51: 4110000 | N51: 69935875826 | P51: 67901304925 | R51: 2034570901
B52: نورایستا پلاستیک | D52: 0 | F52: 0 | H52: 0 | J52: =F52+H52 -> 0 | L52: 8075370 | N52: 10863602652 | P52: 13421679968 | R52: -2558077316
...

Sheet درآمد سرمایه گذاری در اوراق بها
A1: صندوق سرمایه‌گذاری صندوق شاخص سی شرکت بزرگ فیروزه
A2: صورت وضعیت درآمدها
A3: =' سهام'!AC6 -> برای ماه منتهی به 1404/07/30
B4: 2-2-درآمد حاصل از سرمایه گذاری در اوراق بهادار با درآمد ثابت:
C6: =' سهام'!AC7 -> طی مهر ماه | M6: =' سهام'!AC8 -> از ابتدای سال مالی تا پایان مهر ماه
C7: درآمد سود اوراق | E7: درآمد تغییر ارزش | G7: درآمد فروش | I7: جمع | M7: درآمد سود اوراق | O7: درآمد تغییر ارزش | Q7: درآمد فروش | R7: جمع
C9: یادداشت 2-2-1 | E9: یادداشت 2-1-2 | G9: یادداشت 3-1-2 | I9: مبلغ | K9: درصد از کل دارائیها | M9: یادداشت 2-2-1 | O9: یادداشت 2-1-2 | Q9: یادداشت 3-1-2 | R9: مبلغ | S9: درصد از کل دارائیها
B10: - | C10: 0 | D10: 0 | E10: 0 | F10: 0 | G10: 0 | H10: 0 | I10: 0 | J10: 0 | K10: 0 | L10: 0 | M10: 0 | N10: 0 | O10: 0 | P10: 875280 | Q10: 0 | R10: 0 | S10: =R10/S14 -> 0
B11: جمع | C11: =SUM(C10:C10) -> 0 | E11: =SUM(E10:E10) -> 0 | G11: =SUM(G10:G10) -> 0 | I11: =SUM(I10:I10) -> 0 | K11: =SUM(K10:K10) -> 0 | M11: =SUM(M10:M10) -> 0 | O11: =SUM(O10:O10) -> 0 | Q11: =SUM(Q10:Q10) -> 0 | R11: =SUM(R10:R10) -> 0 | S11: =SUM(S10:S10) -> 0
K14: 2807555599778 | S14: 2807555599778

Sheet سود اوراق بهادار و سپرده بانکی
B1: ='درآمد سود سهام'!B1:T1 -> صندوق سرمایه گذاری شاخص سی شرکت بزرگ فیروزه
B2: صورت وضعیت درآمدها
B3: =' سهام'!AC6 -> برای ماه منتهی به 1404/07/30
B4: 1-2-2-سود اوراق بهادار با درآمد ثابت و سپرده بانکی | AC4: 1404/06/31
G5: ابتدای دوره | K5: =' سهام'!AC7 -> طی مهر ماه | Q5: =' سهام'!AC8 -> از ابتدای سال مالی تا پایان مهر ماه | AC5: 1404/07/30
B6: شرح | C6: تاریخ دریافت سود | D6: تاریخ سررسید | E6: نرخ سود علی الحساب | G6: درآمد سود | I6: هزینه تنزیل | K6: درآمد سود | M6: هزینه تنزیل | O6: خالص درآمد | Q6: درآمد سود | S6: هزینه تنزیل | U6: خالص درآمد | AC6: برای ماه منتهی به 1404/07/30
B7: سپرده کوتاه مدت بانک خاورمیانه مهستان | H7: 0 | J7: 176683 | K7: 20096 | M7: 0 | O7: =K7+M7 -> 20096 | Q7: 104340 | S7: 0 | U7: =Q7+S7 -> 104340 | AC7: طی مهر ماه
B8: سپرده کوتاه مدت بانک گردشگری سعادت آباد | H8: 0 | J8: 2202729735 | K8: 3971033781 | M8: 0 | O8: =K8+M8 -> 3971033781 | Q8: 19500020310 | S8: 0 | U8: =Q8+S8 -> 19500020310 | AC8: از ابتدای سال مالی تا پایان مهر ماه
K9: =SUM(K7:K8) -> 3971053877 | O9: =SUM(O7:O8) -> 3971053877 | Q9: =SUM(Q7:Q8) -> 19500124650 | U9: =SUM(U7:U8) -> 19500124650

Sheet درآمد سپرده بانکی
B1: ='سود اوراق بهادار و سپرده بانکی'!B1:U1 -> صندوق سرمایه گذاری شاخص سی شرکت بزرگ فیروزه
B2: صورت وضعیت درآمدها
B3: =' سهام'!B3:Z3 -> برای ماه منتهی به 1404/07/30
B4: 3-2-درآمد حاصل از سرمایه گذاری در سپرده بانکی و گواهی سپرده: | AC4: 1404/02/31
AC5: 1404/03/31
B6: نام سپرده بانکی | F6: =' سهام'!AC7 -> طی مهر ماه | J6: =' سهام'!AC8 -> از ابتدای سال مالی تا پایان مهر ماه | AC6: برای ماه منتهی به 1404/03/31
B7: نام سپرده | D7: شماره حساب | F7: سود سپرده بانکی و گواهی سپرده | H7: درصد سود به میانگین سپرده | J7: سود سپرده بانکی و گواهی سپرده | L7: درصد سود به میانگین سپرده | AC7: طی خرداد ماه
F8: یادداشت 2-2-1 | J8: یادداشت 2-2-1 | AC8: از ابتدای سال مالی تا پایان خرداد ماه
B9: سپرده کوتاه مدت بانک خاورمیانه مهستان | D9: 1005-10-810-00030030-1 | F9: 20096 | H9: 0 | J9: 104340 | L9: 0
B10: سپرده کوتاه مدت بانک گردشگری سعادت آباد | D10: 132.9967.1490777.1 | F10: 3971033781 | H10: 0 | J10: 19500020310 | L10: 0
B11: جمع | F11: =SUM(F9:F10) -> 3971053877 | H11: =SUM(H9:H9) -> 0 | J11: =SUM(J9:J10) -> 19500124650 | L11: =SUM(L9:L9) -> 0

Sheet Sheet1

Sheet سایر درآمدها
B1: ='درآمد سپرده بانکی'!B1:M1 -> صندوق سرمایه گذاری شاخص سی شرکت بزرگ فیروزه
B2: صورت وضعیت درآمدها
B3: =' سهام'!AC6 -> برای ماه منتهی به 1404/07/30
B4: 4-2-سایر درآمدها: | AC4: 1404/02/31
D5: =' سهام'!AC7 -> طی مهر ماه | F5: =' سهام'!AC8 -> از ابتدای سال مالی تا پایان مهر ماه | AC5: 1404/03/31
B6: سایر درآمدها | D6: 2664 | F6: 468601799 | AC6: برای ماه منتهی به 1404/03/31
B7: تعدیل کارمزد کارگزار | D7: 104737469 | F7: 3757374794
D8: =SUM(D6:D7) -> 104740133 | F8: =SUM(F6:F7) -> 4225976593
