Workbook

Sheet  سهام
B1: صندوق سرمایه گذاری شاخص سی شرکت بزرگ فیروزه
B2: صورت وضعیت پرتفوی
B3: =AC6 -> برای ماه منتهی به 1405/04/31
B4: 1- سرمایه گذاری ها | AC4: 1405/03/31
B5: 1-1-سرمایه‌گذاری در سهام و حق تقدم سهام | AC5: 1405/04/31
D6: =AC4 -> 1405/03/31 | J6: تغییرات طی دوره | R6: =AC5 -> 1405/04/31 | AC6: برای ماه منتهی به 1405/04/31
B7: شرکت | D7: تعداد | F7: بهای تمام شده | H7: خالص ارزش فروش | J7: خرید طی دوره | N7: فروش طی دوره | R7: تعداد | T7: قیمت بازار هر سهم | V7: بهای تمام شده | X7: خالص ارزش فروش | Z7: درصد به کل دارایی‌ها | AC7: طی تیر ماه
J8: تعداد | L8: بهای تمام شده | N8: تعداد | P8: مبلغ فروش | AC8: از ابتدای سال مالی تا پایان تیر ماه
B9: آلومینیوم‌ایران‌ | D9: 14000000 | F9: 87506491301 | H9: 141557238200 | J9: 0 | L9: 0 | N9: -14000000 | P9: 149825239849 | R9: 0 | T9: 0 | V9: 0 | X9: 0 | Z9: =X9/$Z$80 -> 0
B10: ایران خودرو دیزل | D10: 72662416 | F10: 99060136044 | H10: 1.0166204e+11 | J10: 0 | L10: 0 | N10: -72662416 | P10: 107268224021 | R10: 0 | T10: 0 | V10: 0 | X10: 0 | Z10: =X10/$Z$80 -> 0
B11: ایران‌ خودرو | D11: 753200000 | F11: 362402577489 | H11: 430489592064 | J11: 0 | L11: 0 | N11: -553200000 | P11: 310640779856 | R11: 200000000 | T11: 504 | V11: 96230105555 | X11: 100020816000 | Z11: =X11/$Z$80 -> 0.0073281248
B12: بانک پاسارگاد | D12: 1000 | F12: 1915216 | H12: 10061618 | J12: 0 | L12: 0 | N12: 0 | P12: 0 | R12: 1000 | T12: 8600 | V12: 1915216 | X12: 8533522 | Z12: =X12/$Z$80 -> 6.25217e-07
B13: بانک تجارت | D13: 333200000 | F13: 186591341771 | H13: 212260841688 | J13: 0 | L13: 0 | N13: -253200000 | P13: 164039287526 | R13: 80000000 | T13: 528 | V13: 44799841988 | X13: 41913484800 | Z13: =X13/$Z$80 -> 0.0030708333
B14: بانک ملت | D14: 1372355188 | F14: 1526550668574 | H14: 1.8056764e+12 | J14: 0 | L14: 0 | N14: -702355188 | P14: 862327857433 | R14: 670000000 | T14: 1118 | V14: 745280053458 | X14: 743269766200 | Z14: =X14/$Z$80 -> 0.054456401
B15: بانک‌اقتصادنوین‌ | D15: 60000000 | F15: 100530477997 | H15: 214151711400 | J15: 11283274 | L15: 0 | N15: -10000000 | P15: 35742240264 | R15: 61283274 | T15: 2785 | V15: 83775398362 | X15: 1.6935461e+11 | Z15: =X15/$Z$80 -> 0.012407934
B16: بین المللی توسعه ص. معادن غدیر | D16: 1000 | F16: 5411279 | H16: 3313189.5 | J16: 0 | L16: 0 | N16: 0 | P16: 0 | R16: 1000 | T16: 3160 | V16: 5411279 | X16: 3135573.2 | Z16: =X16/$Z$80 -> 2.297309e-07
B17: پالایش نفت اصفهان | D17: 120600000 | F17: 396729813026 | H17: 1096156699920 | J17: 0 | L17: 0 | N17: -60600000 | P17: 602710217327 | R17: 60000000 | T17: 9420 | V17: 197378016384 | X17: 560831004000 | Z17: =X17/$Z$80 -> 0.041089843
B18: پالایش نفت بندرعباس | D18: 81708586 | F18: 354491575881 | H18: 9.3968218e+11 | J18: 0 | L18: 0 | N18: -21708586 | P18: 262257952234 | R18: 60000000 | T18: 11080 | V18: 260309174270 | X18: 659661096000 | Z18: =X18/$Z$80 -> 0.048330728
B19: پالایش نفت تبریز | D19: 1000 | F19: 20873618 | H19: 43243127 | J19: 0 | L19: 0 | N19: 0 | P19: 0 | R19: 1000 | T19: 38960 | V19: 20873618 | X19: 38658839 | Z19: =X19/$Z$80 -> 2.8323784e-06
B20: پالایش نفت تهران | D20: 50000000 | F20: 148963424259 | H20: 256997930000 | J20: 0 | L20: 0 | N20: 0 | P20: 0 | R20: 50000000 | T20: 4760 | V20: 148963424259 | X20: 236160260000 | Z20: =X20/$Z$80 -> 0.017302517
... B36: ح . معدنی‌وصنعتی‌چادرملو | D36: 119 | F36: 166957 | H36: 102257.39 | J36: 0 | L36: 0 | N36: -119 | P36: 114609 | R36: 0 | T36: 0 | V36: 0 | X36: 0 | Z36: =X36/$Z$80 -> 0
B37: رهیاب پیام گستران | D37: 585000 | F37: 3927629043 | H37: 3.8317349e+09 | J37: 0 | L37: 0 | M37: 9102861790 | N37: 0 | P37: 0 | R37: 585000 | T37: 6187 | V37: 3927629043 | X37: 3.5914171e+09 | Z37: =X37/$Z$80 -> 0.00026312875
B38: س. نفت و گاز و پتروشیمی تأمین | D38: 5000000 | F38: 99981901348 | H38: 127903603000 | J38: 0 | L38: 0 | N38: 0 | P38: 0 | R38: 5000000 | T38: 26920 | V38: 99981901348 | X38: 133559542000 | Z38: =X38/$Z$80 -> 0.009785373
B39: سایپا | D39: 668000000 | F39: 386793419604 | H39: 377816725200 | J39: 0 | L39: 0 | N39: -668000000 | P39: 374761805019 | R39: 0 | T39: 0 | V39: 0 | X39: 0 | Z39: =X39/$Z$80 -> 0
B40: سرمایه گذاری تامین اجتماعی | D40: 660800000 | F40: 1234969619642 | H40: 1343512940784 | J40: 0 | L40: 0 | N40: -60800000 | P40: 131156464299 | R40: 600000000 | T40: 2178 | V40: 1121340453668 | X40: 1296698436000 | Z40: =X40/$Z$80 -> 0.095003904
B41: سرمایه گذاری خوارزمی | D41: 294982360 | F41: 1227799962434 | H41: 1.413166e+12 | J41: 0 | L41: 0 | N41: -15000000 | P41: 74165148336 | R41: 279982360 | T41: 5470 | V41: 1165365722529 | X41: 1.519665e+12 | Z41: =X41/$Z$80 -> 0.11133977
B42: سرمایه گذاری سبحان | D42: 89880000 | F42: 128191324192 | H42: 169897858578 | J42: 0 | L42: 0 | N42: -59880000 | P42: 118034724781 | R42: 30000000 | T42: 2073 | V42: 42787491384 | X42: 61709271300 | Z42: =X42/$Z$80 -> 0.0045211913
B43: سرمایه گذاری صدرتامین | D43: 20714814 | F43: 234457900705 | H43: 2.9269876e+11 | J43: 5000000 | L43: 80768776078 | N43: -300000 | P43: 4188950950 | R43: 25414814 | T43: 16400 | V43: 311831166198 | X43: 4.1358106e+11 | Z43: =X43/$Z$80 -> 0.030301429
B44: سرمایه‌ گذاری‌ آتیه‌ دماوند | D44: 19617870 | F44: 79587328846 | H44: 1.1017883e+11 | J44: 0 | L44: 0 | N44: -19617870 | P44: 99998611256 | R44: 0 | T44: 0 | V44: 0 | X44: 0 | Z44: =X44/$Z$80 -> 0
B45: سرمایه‌گذاری‌صندوق‌بازنشستگی‌ | D45: 1000000 | F45: 21678525535 | H45: 16868590000 | J45: 0 | L45: 0 | N45: -999000 | P45: 16630010355 | R45: 1000 | T45: 14930 | V45: 21678521 | X45: 14814591 | Z45: =X45/$Z$80 -> 1.0854058e-06
B46: سرمایه‌گذاری‌غدیر(هلدینگ‌ | D46: 44000000 | F46: 470498994928 | H46: 656207996400 | J46: 0 | L46: 0 | N46: -14000000 | P46: 196390026792 | R46: 30000000 | T46: 13710 | V46: 320794769231 | X46: 408120651000 | Z46: =X46/$Z$80 -> 0.029901366
B47: صنایع پتروشیمی خلیج فارس | D47: 50000000 | F47: 365366342037 | H47: 623145560000 | J47: 0 | L47: 0 | N47: -11000000 | P47: 123400084740 | R47: 39000000 | T47: 10400 | V47: 284985746797 | X47: 402464712000 | Z47: =X47/$Z$80 -> 0.029486978
B48: فروشگاههای زنجیره ای افق کوروش | D48: 2000000 | F48: 50411649795 | H48: 120560805000 | J48: 0 | L48: 0 | N48: -1998956 | P48: 97293807383 | R48: 1044 | T48: 61770 | V48: 26314878 | X48: 63989389 | Z48: =X48/$Z$80 -> 4.6882464e-06
B49: نقل به صفحه بعد | C49: 0 | D49: =SUM(D9:D48) -> 5320660299 | E49: =AC48=SUM(#REF!) -> #REF! | F49: =SUM(F9:F48) -> 10473633849472 | G49: =SUM(#REF!) -> #REF! | H49: =SUM(H9:H48) -> 1.3542691e+13 | J49: =SUM(J9:J48) -> 16283274 | K49: =SUM(#REF!) -> #REF! | L49: =SUM(L9:L48) -> 80768776078 | M49: =SUM(#REF!) -> #REF! | N49: =SUM(N9:N48) -> -2572923437 | O49: =SUM(#REF!) -> #REF! | P49: =SUM(P9:P48) -> 3906826714583 | Q49: =SUM(#REF!) -> #REF! | R49: =SUM(R9:R48) -> 2740420136 | S49: =SUM(#REF!) -> #REF! | T49: =SUM(T9:T48) -> 501852 | U49: =SUM(#REF!) -> #REF! | V49: =SUM(V9:V48) -> 7585163803536 | W49: =SUM(#REF!) -> #REF! | X49: =SUM(X9:X48) -> 9.2784076e+12 | Y49: =SUM(#REF!) -> #REF! | Z49: =SUM(Z9:Z48) -> 0.67979178
B51: 1- سرمایه گذاری ها
B52: 1-1-سرمایه‌گذاری در سهام و حق تقدم سهام
D53: =D6 -> 1405/03/31 | J53: تغییرات طی دوره | R53: =R6 -> 1405/04/31
B54: شرکت | D54: تعداد | F54: بهای تمام شده | H54: خالص ارزش فروش | J54: خرید طی دوره | N54: فروش طی دوره | R54: تعداد | T54: قیمت بازار هر سهم | V54: بهای تمام شده | X54: خالص ارزش فروش | Z54: درصد به کل دارایی‌ها
J55: تعداد | L55: بهای تمام شده | N55: تعداد | P55: مبلغ فروش
B56: نقل از صفحه قبل | D56: =D49 -> 5320660299 | F56: =F49 -> 10473633849472 | H56: =H49 -> 1.3542691e+13 | J56: =J49 -> 16283274 | L56: =L49 -> 80768776078 | N56: =N49 -> -2572923437 | P56: =P49 -> 3906826714583 | R56: =R49 -> 2740420136 | T56: =T49 -> 501852 | V56: =V49 -> 7585163803536 | X56: =X49 -> 9.2784076e+12 | Z56: =Z49 -> 0.67979178
...

Sheet اوراق تبعی
B1: =' سهام'!B1:Z1 -> صندوق سرمایه گذاری شاخص سی شرکت بزرگ فیروزه
B2: صورت وضعیت پرتفوی
B3: =' سهام'!AC6 -> برای ماه منتهی به 1405/04/31
B4: اطلاعات آماری مرتبط با اوراق اختیار فروش تبعی خریداری شده توسط صندوق سرمایه گذاری:
D6: =' سهام'!AC4 -> 1405/03/31 | L6: =' سهام'!AC5 -> 1405/04/31
B7: نام سهام | D7: تعداد اوراق تبعی | F7: قیمت اعمال | H7: تاریخ اعمال | J7: نرخ سود مؤثر | L7: تعداد اوراق تبعی | N7: قیمت اعمال | P7: تاریخ اعمال | R7: نرخ سود مؤثر
D8: - | F8: - | H8: - | J8: 0 | L8: 0 | N8: - | P8: - | R8: 0
D9: =SUM(D8) -> 0 | F9: =SUM(F8) -> 0 | H9: ..... | J9: ..... | L9: =SUM(L8) -> 0 | N9: =SUM(N8) -> 0 | P9: ..... | R9: .....

Sheet تعدیل قیمت
A1: =اوراق!B1 -> صندوق سرمایه گذاری شاخص سی شرکت بزرگ فیروزه
A2: صورت وضعیت پرتفوی
A3: =' سهام'!AC6 -> برای ماه منتهی به 1405/04/31
A4: اوراق بهاداری که ارزش آنها در تاریخ گزارش تعدیل شده
A5: (بر اساس دستورالعمل نحوه تعیین قیمت خرید و فروش اوراق بهادار در صندوق های سرمایه گذاری)
C6: =' سهام'!AC5 -> 1405/04/31
A7: نام اوراق بهادار | C7: تعداد | E7: قیمت پایانی | G7: قیمت تعدیل شده | I7: درصد تعدیل | K7: خالص ارزش فروش تعدیل شده | M7: دلیل تعدیل
C9: - | E9: - | G9: - | I9: - | K9: - | M9: -
C10: - | E10: - | G10: - | I10: - | K10: - | M10: -

Sheet گواهی سپرده
A1: ='تعدیل قیمت'!A1:P1 -> صندوق سرمایه گذاری شاخص سی شرکت بزرگ فیروزه
A2: صورت وضعیت پرتفوی
A3: =' سهام'!AC6 -> برای ماه منتهی به 1405/04/31
A4: 4-1- سرمایه‌گذاری در گواهی سپرده‌ بانکی
K6: =' سهام'!AC4 -> 1405/03/31 | Q6: تغییرات طی دوره | W6: =' سهام'!AC5 -> 1405/04/31
A7: گواهی سپرده بانکی | C7: تاریخ سررسید | E7: نرخ سود علی الحساب | G7: نرخ شکست | I7: پذیرفته شده در بورس یا فرابورس | K7: تعداد | M7: بهای تمام شده | O7: خالص ارزش | Q7: خرید طی دوره | T7: فروش طی دوره | W7: تعداد | Y7: بهای تمام شده | AA7: خالص ارزش | AC7: درصد به کل
O8: فروش | Q8: تعداد | R8: بهای تمام شده | T8: تعداد | U8: مبلغ فروش | AA8: فروش | AC8: دارایی‌ها
A9: گواهی سپرده بانکی نزد بانک ..... | C9: ..... | E9: ..... | G9: ..... | I9: ..... | K9: ..... | M9: ..... | O9: ..... | Q9: ..... | R9: ..... | T9: ..... | U9: ..... | W9: ..... | Y9: ..... | AA9: ..... | AC9: .....
A10: جمع | C10: ..... | E10: ..... | G10: ..... | I10: ..... | K10: ..... | M10: ..... | O10: ..... | Q10: ..... | R10: ..... | T10: ..... | U10: ..... | W10: ..... | Y10: ..... | AA10: ..... | AC10: .....

Sheet اوراق
B1: =' سهام'!B1:Z1 -> صندوق سرمایه گذاری شاخص سی شرکت بزرگ فیروزه
B2: صورت وضعیت پرتفوی
B3: =' سهام'!AC6 -> برای ماه منتهی به 1405/04/31
B4: 2-1-سرمایه‌گذاری در اوراق بهادار با درآمد ثابت یا علی‌الحساب
B6: اطلاعات اوراق بهادار با درآمد ثابت | Q6: =' سهام'!AC4 -> 1405/03/31 | W6: تغییرات طی دوره | AE6: =' سهام'!AC5 -> 1405/04/31
B7: نام اوراق | D7: دارای مجوز از سازمان | F7: پذیرفته شده در بورس یا فرابورس | H7: تاریخ انتشار اوراق | J7: تاریخ سررسید | M7: نرخ سود اسمی | O7: نرخ سود مؤثر | Q7: تعداد | S7: بهای تمام شده | U7: خالص ارزش فروش | W7: خرید طی دوره | AA7: فروش طی دوره | AE7: تعداد | AG7: قیمت بازار هر ورقه | AI7: بهای تمام شده | AK7: خالص ارزش فروش | AM7: درصد به کل دارایی‌ها
W8: تعداد | Y8: بهای تمام شده | AA8: تعداد | AC8: مبلغ فروش
B9: جمع | M9: - | Q9: 0 | S9: 0 | U9: 0 | W9: 0 | Y9: 0 | AA9: 0 | AC9: 0 | AE9: 0 | AG9: 0 | AI9: 0 | AK9: 0 | AM9: 0

Sheet سپرده
B1: صندوق سرمایه گذاری شاخص سی شرکت بزرگ فیروزه
B2: صورت وضعیت پرتفوی
B3: =' سهام'!AC6 -> برای ماه منتهی به 1405/04/31
B4: 3-1- سرمایه‌گذاری در سپرده‌ بانکی | AA4: 1404/02/31
AA5: 1404/03/31
L6: تغییرات طی دوره | P6: =' سهام'!AC5 -> 1405/04/31 | AA6: برای ماه منتهی به 1404/03/31
B7: سپرده های بانکی | D7: نوع سپرده | F7: تاریخ افتتاح حساب | H7: نرخ سود علی الحساب | J7: مبلغ | L7: افزایش | N7: کاهش | P7: مبلغ | R7: درصد به کل دارایی‌ها | AA7: طی خرداد ماه
AA8: از ابتدای سال مالی تا پایان خرداد ماه
B9: حساب جاری بانک خاورمیانه مهستان | D9: حساب جاری | F9: 1393/04/25 | H9: 0 | J9: 50000000 | L9: 0 | N9: 0 | P9: 50000000 | R9: =P9/$R$20 -> 3.6632999e-06
B10: سپرده کوتاه مدت بانک خاورمیانه مهستان | D10: سپرده کوتاه مدت | F10: 1393/04/25 | H10: 0 | J10: 48598023 | L10: 206375 | N10: 0 | P10: 48804398 | R10: =P10/$R$20 -> 3.5757029e-06
B11: سپرده کوتاه مدت بانک گردشگری سعادت آباد | D11: سپرده کوتاه مدت | F11: 1402/06/19 | H11: 0 | J11: 285121957760 | L11: 840788683254 | N11: 1125910541014 | P11: 100000 | R11: =P11/$R$20 -> 7.3265997e-09
B12: سپرده کوتاه مدت بانک صادرات بلوار میرداماد | D12: سپرده کوتاه مدت | F12: 1404/08/01 | H12: 0 | J12: 394772 | L12: 0 | N12: 0 | P12: 394772 | R12: =P12/$R$20 -> 2.8923364e-08
B13: سپرده کوتاه مدت بانک تجارت مطهری دریای نور | D13: سپرده کوتاه مدت | F13: 1404/08/01 | H13: 0 | J13: 402500 | L13: 0 | N13: 0 | P13: 402500 | R13: =P13/$R$20 -> 2.9489564e-08
B14: حساب جاری بانک گردشگری سعادت آباد | D14: حساب جاری | F14: 1404/09/19 | H14: 0 | J14: 54421918 | L14: 5071673261454 | N14: 5071714295661 | P14: 13387711 | R14: =P14/$R$20 -> 9.80864e-07
B15: سپرده کوتاه مدت بانک خاورمیانه نیاوران | D15: سپرده کوتاه مدت | F15: 1404/10/15 | J15: 58296027 | L15: 247558 | N15: 0 | P15: 58543585 | R15: =P15/$R$20 -> 4.2892541e-06
B16: سپرده کوتاه مدت بانک گردشگری سعادت آباد | D16: سپرده کوتاه مدت | F16: 1405/04/23 | H16: 0 | J16: 0 | L16: 211494222228 | N16: 83015750000 | P16: 128478472228 | R16: =P16/$R$20 -> 0.0094131034
B17: جمع | J17: =SUM(J9:J16) -> 285334071000 | L17: =SUM(L9:L16) -> 6123956620869 | N17: =SUM(N9:N16) -> 6280640586675 | P17: =SUM(P9:P16) -> 128650105194 | R17: =SUM(R9:R16) -> 0.0094256782
R20: 13648896332220
R59: 1783
R76: 2083

Sheet درآمدها
A1: صندوق سرمایه گذاری شاخص سی شرکت بزرگ فیروزه
A2: =سپرده!B2 -> صورت وضعیت پرتفوی
A3: =سپرده!B3 -> برای ماه منتهی به 1405/04/31
AC4: 1404/02/31
B5: شرح | D5: یادداشت | F5: مبلغ | H5: درصد از کل درآمدها | J5: درصد از کل دارایی ها | AC5: برای ماه منتهی به 1404/03/31
B6: درآمد حاصل از سرمایه گذاری در سهام و حق تقدم سهام | D6: 1-2 | F6: ='درآمد سرمایه گذاری در سهام '!T96 -> 3033094641653 | H6: =F6/$M$9 -> 0.85582391 | J6: =F6/سپرده!R20 -> 0.2222227 | AC6: طی خرداد ماه
B7: سود اوراق بهادار با درآمد ثابت و سپرده بانکی | D7: 3-2 | F7: ='درآمد سپرده بانکی'!J13 -> 33450709959 | H7: =F7/$M$9 -> 0.0094385176 | J7: =F7/سپرده!R20 -> 0.0024507996
B8: سایر درآمد ها | D8: 4-2 | F8: ='سایر درآمدها'!F8 -> 15752436690 | H8: =F8/$M$9 -> 0.0044447383 | J8: =F8/سپرده!R20 -> 0.001154118 | M8: 18341274631176
B9: جمع | F9: =SUM(F6:F8) -> 3082297788302 | H9: =SUM(H6:H8) -> 0.86970716 | J9: =SUM(J6:J8) -> 0.22582762 | M9: 3544063938478
R57: 1783
R74: 2083

Sheet تعدیل قیمت 
B1: صندوق سرمایه گذاری شاخص سی شرکت بزرگ فیروزه
B2: صورت وضعیت پرتفوی
B3: =' سهام'!AC6 -> برای ماه منتهی به 1405/04/31
B4: اوراق بهاداری که ارزش آنها در تاریخ گذشته تعدیل شده
B5: (بر اساس دستورالعمل نحوه تعیین قیمت خرید و فروش اوراق بهادار در صندوق های سرمایه گذاری )
B7: =' سهام'!AC5 -> 1405/04/31
B8: نام اوراق بهادار | D8: تعداد | F8: قیمت پایانی | H8: قیمت تعدیل شده | J8: درصد تعدیل | L8: خالص ارزش فروش تعدیل شده | N8: دلایل تعدیل
B10: فولاد مبارکه اصفهان | D10: 12900000 | F10: 2610 | H10: -40 | J10: -0.4 | L10: 20201400000 | N10: بسته بودن سهم
B11: مبین انرژی خلیج فارس | D11: 10000000 | F11: 13260 | H11: -40 | J11: -0.4 | L11: 79560000000 | N11: بسته بودن سهم
B12: جمع | D12: =SUM(D10:D11) -> 22900000 | F12: =SUM(F10:F11) -> 15870 | L12: =SUM(L10:L11) -> 99761400000

Sheet درآمد سرمایه گذاری در سهام 
B1: =درآمدها!A1 -> صندوق سرمایه گذاری شاخص سی شرکت بزرگ فیروزه
B2: صورت وضعیت درآمدها
B3: =' سهام'!AC6 -> برای ماه منتهی به 1405/04/31
AC4: 1404/02/31
B5: 1-2-درآمد حاصل از سرمایه گذاری در سهام و حق تقدم سهام: | AC5: 1404/03/31
AC6: برای ماه منتهی به 1404/03/31
D7: =' سهام'!AC7 -> طی تیر ماه | N7: =' سهام'!AC8 -> از ابتدای سال مالی تا پایان تیر ماه | AC7: طی خرداد ماه
B8: سهام | D8: درآمد سود سهام | F8: درآمد تغییر ارزش | H8: درآمد فروش | J8: جمع | N8: درآمد سود سهام | P8: درآمد تغییر ارزش | R8: درآمد فروش | T8: جمع | AC8: از ابتدای سال مالی تا پایان خرداد ماه
D10: یادداشت 2-1-1 | F10: یادداشت 2-1-2 | H10: یادداشت 2-1-3 | J10: مبلغ | L10: درصد از کل درآمد ها | N10: یادداشت 2-1-1 | P10: یادداشت 2-1-2 | R10: یادداشت 2-1-3 | T10: مبلغ | V10: درصد از کل درآمد ها
B11: سرمایه‌گذاری‌ سپه‌ | D11: 0 | F11: -13553823960 | H11: -298493988 | J11: =H11+F11+D11 -> -13852317948 | L11: =J11/$X$12 -> 0.013395434 | N11: 0 | P11: -13553823960 | R11: -298493988 | S11: -714562636 | T11: =N11+P11+R11 -> -13852317948 | U11: 11071728389 | V11: =T11/درآمدها!$F$9 -> -0.004494153
B12: پتروشیمی جم | D12: 3859365 | F12: 443643919 | H12: -613813908 | J12: =H12+F12+D12 -> -166310624 | L12: =J12/$X$12 -> 0.00016082528 | N12: 3859365 | P12: -7838931 | R12: -613813908 | S12: -4741243411 | T12: =N12+P12+R12 -> -617793474 | U12: 11071728390 | V12: =T12/درآمدها!$F$9 -> -0.00020043277 | X12: -1034107475059
B13: سرمایه‌گذاری‌صندوق‌بازنشستگی‌ | D13: 1578378 | F13: -11966779 | H13: -211798274 | J13: =H13+F13+D13 -> -222186675 | L13: =J13/$X$12 -> 0.0002148584 | N13: 1578378 | P13: -2044071 | R13: -14030982045 | S13: -3385001208 | T13: =N13+P13+R13 -> -14031447738 | U13: 11071728391 | V13: =T13/درآمدها!$F$9 -> -0.0045522687
B14: سرمایه گذاری خوارزمی | D14: 0 | F14: 164797569564 | H14: 15866603233 | J14: =H14+F14+D14 -> 180664172797 | L14: =J14/$X$12 -> -0.17470541 | N14: 0 | P14: 431494037317 | R14: 15873961915 | S14: -2880009787 | T14: =N14+P14+R14 -> 447367999232 | U14: 11071728392 | V14: =T14/درآمدها!$F$9 -> 0.14514107
B15: کشت و صنعت هلال | D15: 239516645 | F15: 590081924 | H15: 604976897 | J15: =H15+F15+D15 -> 1434575466 | L15: =J15/$X$12 -> -0.0013872595 | N15: 239516645 | P15: 608084099 | R15: 604976897 | S15: -664891573 | T15: =N15+P15+R15 -> 1452577641 | U15: 11071728393 | V15: =T15/درآمدها!$F$9 -> 0.00047126454
B16: تراکتورسازی‌ایران‌ | D16: 18191242756 | F16: -20500200521 | H16: 325265293 | J16: =H16+F16+D16 -> -1983692472 | L16: =J16/$X$12 -> 0.0019182653 | N16: 18191242756 | P16: -9587967329 | R16: 325265293 | S16: -2538727106 | T16: =N16+P16+R16 -> 8928540720 | U16: 11071728394 | V16: =T16/درآمدها!$F$9 -> 0.0028967158
B17: ح . سرمایه‌گذاری‌ سپه‌ | D17: 0 | F17: 0 | H17: 0 | J17: =H17+F17+D17 -> 0 | L17: =J17/$X$12 -> 0 | N17: 0 | P17: 0 | R17: 0 | S17: -5759026841 | T17: =N17+P17+R17 -> 0 | U17: 11071728395 | V17: =T17/درآمدها!$F$9 -> 0
B18: پالایش نفت اصفهان | D18: 38086956522 | F18: -221663860853 | H18: 289048382260 | J18: =H18+F18+D18 -> 105471477929 | L18: =J18/$X$12 -> -0.10199276 | N18: 38086956522 | P18: 250274731584 | R18: 289057834716 | S18: -2808202366 | T18: =N18+P18+R18 -> 577419522822 | U18: 11071728392 | V18: =T18/درآمدها!$F$9 -> 0.18733411
B19: ملی‌ صنایع‌ مس‌ ایران‌ | D19: 0 | F19: -304302830194 | H19: 55680128071 | J19: =H19+F19+D19 -> -248622702123 | L19: =J19/$X$12 -> 0.2404225 | N19: 0 | P19: 806312701795 | R19: 55680128071 | T19: =N19+P19+R19 -> 861992829866 | U19: 11071728393 | V19: =T19/درآمدها!$F$9 -> 0.27965917
B20: گروه توسعه مالی فیروزه | D20: 0 | F20: 7510669540 | H20: -26881204 | J20: =H20+F20+D20 -> 7483788336 | L20: =J20/$X$12 -> -0.0072369541 | N20: 0 | P20: 7511332145 | R20: -26881204 | S20: 8828197833 | T20: =N20+P20+R20 -> 7484450941 | U20: 11071728394 | V20: =T20/درآمدها!$F$9 -> 0.002428205
B21: ح . معدنی و صنعتی گل گهر | D21: 0 | F21: 0 | H21: -40290 | J21: =H21+F21+D21 -> -40290 | L21: =J21/$X$12 -> 3.8961134e-08 | N21: 0 | P21: 0 | R21: -40290 | S21: -40082741567 | T21: =N21+P21+R21 -> -40290 | U21: 11071728395 | V21: =T21/درآمدها!$F$9 -> -1.3071417e-08
B22: سرمایه‌گذاری‌غدیر(هلدینگ‌ | D22: 0 | F22: -56292325972 | H22: 4595007364 | J22: =H22+F22+D22 -> -51697318608 | L22: =J22/$X$12 -> 0.049992211 | N22: 0 | P22: -2868676358 | R22: 4595007364 | S22: 466959920 | T22: =N22+P22+R22 -> 1726331006 | U22: 11071728396 | V22: =T22/درآمدها!$F$9 -> 0.00056007924
B23: سرمایه‌ گذاری‌ آتیه‌ دماوند | D23: 0 | F23: 0 | H23: 15067476485 | J23: =H23+F23+D23 -> 15067476485 | L23: =J23/$X$12 -> -0.014570513 | N23: 2942680500 | P23: 0 | R23: 35527447451 | S23: -102059379029 | T23: =N23+P23+R23 -> 38470127951 | U23: 11071728398 | V23: =T23/درآمدها!$F$9 -> 0.01248099
B24: سرمایه گذاری سبحان | D24: 0 | F24: -14547194177 | H24: 24393331680 | J24: =H24+F24+D24 -> 9846137503 | L24: =J24/$X$12 -> -0.009521387 | N24: 0 | P24: 14794745711 | R24: 24287398136 | S24: -11597631470 | T24: =N24+P24+R24 -> 39082143847 | U24: 11071728399 | V24: =T24/درآمدها!$F$9 -> 0.012679548
B25: بانک‌اقتصادنوین‌ | D25: 5404230317 | F25: -24144287628 | H25: 15089425196 | J25: =H25+F25+D25 -> -3650632115 | L25: =J25/$X$12 -> 0.0035302251 | N25: 5404230317 | P25: 66090533186 | R25: 15089425196 | S25: 52167321915 | T25: =N25+P25+R25 -> 86584188699 | U25: 11071728400 | V25: =T25/درآمدها!$F$9 -> 0.028090793
B26: بانک ملت | D26: 0 | F26: -301292909838 | H26: 101214167413 | J26: =H26+F26+D26 -> -200078742425 | L26: =J26/$X$12 -> 0.19347964 | N26: 0 | P26: 17218074944 | R26: 134058810652 | S26: -6964477628 | T26: =N26+P26+R26 -> 151276885596 | U26: 11071728401 | V26: =T26/درآمدها!$F$9 -> 0.049079257
B27: ایران‌ خودرو | D27: 0 | F27: -66298911938 | H27: 46470915730 | J27: =H27+F27+D27 -> -19827996208 | L27: =J27/$X$12 -> 0.019174019 | N27: 0 | P27: 4514719093 | R27: 46591278625 | S27: -13571699443 | T27: =N27+P27+R27 -> 51105997718 | U27: 11071728402 | V27: =T27/درآمدها!$F$9 -> 0.016580487
B28: سرمایه گذاری صدرتامین | D28: 0 | F28: 43597598438 | H28: 704875168 | J28: =H28+F28+D28 -> 44302473606 | L28: =J28/$X$12 -> -0.042841266 | N28: 0 | P28: 95723089796 | R28: 704865319 | S28: 257545772 | T28: =N28+P28+R28 -> 96427955115 | U28: 11071728398 | V28: =T28/درآمدها!$F$9 -> 0.031284438
B29: صنایع پتروشیمی خلیج فارس | D29: 0 | F29: -106073663022 | H29: 8792899762 | J29: =H29+F29+D29 -> -97280763260 | L29: =J29/$X$12 -> 0.094072198 | N29: 0 | P29: -3869853020 | R29: 39781757177 | S29: 1026553445 | T29: =N29+P29+R29 -> 35911904157 | U29: 11071728399 | V29: =T29/درآمدها!$F$9 -> 0.011651017
B30: ح . معدنی‌وصنعتی‌چادرملو | D30: 0 | F30: 0 | H30: -52348 | J30: =H30+F30+D30 -> -52348 | L30: =J30/$X$12 -> 5.0621431e-08 | N30: 0 | P30: 0 | R30: -52348 | S30: -1161777565 | T30: =N30+P30+R30 -> -52348 | U30: -5155830316 | V30: =T30/درآمدها!$F$9 -> -1.6983434e-08
B31: ایران خودرو دیزل | D31: 0 | F31: 0 | H31: 29543631120 | J31: =H31+F31+D31 -> 29543631120 | L31: =J31/$X$12 -> -0.028569208 | N31: 0 | P31: 0 | R31: 31998464469 | S31: 599022178 | T31: =N31+P31+R31 -> 31998464469 | U31: -5155830315 | V31: =T31/درآمدها!$F$9 -> 0.010381367
... B33: پتروشیمی پردیس | D33: 0 | F33: -108775416080 | H33: -11698273966 | J33: =H33+F33+D33 -> -120473690046 | L33: =J33/$X$12 -> 0.11650016 | N33: 0 | P33: -114398808624 | R33: -11693683903 | S33: 28553005 | T33: =N33+P33+R33 -> -126092492527 | U33: -5155830313 | V33: =T33/درآمدها!$F$9 -> -0.040908602
B34: تایدواترخاورمیانه | D34: 20054945055 | F34: -15081313275 | H34: 2219621667 | J34: =H34+F34+D34 -> 7193253447 | L34: =J34/$X$12 -> -0.0069560018 | N34: 20054945055 | P34: 31281311752 | R34: 2230615539 | T34: =N34+P34+R34 -> 53566872346 | V34: =T34/درآمدها!$F$9 -> 0.017378876
B35: پتروشیمی خراسان | D35: 0 | F35: 0 | H35: 4347276722 | J35: =H35+F35+D35 -> 4347276722 | L35: =J35/$X$12 -> -0.0042038926 | N35: 1624750000 | P35: 0 | R35: 4347975638 | T35: =N35+P35+R35 -> 5972725638 | V35: =T35/درآمدها!$F$9 -> 0.001937751
B36: توسعه‌معادن‌وفلزات‌ | D36: 44060886714 | F36: -90245857358 | H36: -1310606077 | J36: =H36+F36+D36 -> -47495576721 | L36: =J36/$X$12 -> 0.045929053 | N36: 44060886714 | P36: -119703573039 | R36: -1264363845 | T36: =N36+P36+R36 -> -76907050170 | V36: =T36/درآمدها!$F$9 -> -0.024951207
B37: آلومینیوم‌ایران‌ | D37: 0 | F37: 0 | H37: 72448025249 | J37: =H37+F37+D37 -> 72448025249 | L37: =J37/$X$12 -> -0.070058506 | N37: 0 | P37: 0 | R37: 72448025249 | T37: =N37+P37+R37 -> 72448025249 | V37: =T37/درآمدها!$F$9 -> 0.023504551
B38: بانک تجارت | D38: 0 | F38: -51771129250 | H38: 45463059888 | J38: =H38+F38+D38 -> -6308069362 | L38: =J38/$X$12 -> 0.0061000133 | N38: 0 | P38: 4448641908 | R38: 45483546616 | T38: =N38+P38+R38 -> 49932188524 | V38: =T38/درآمدها!$F$9 -> 0.016199664
B39: سرمایه گذاری تامین اجتماعی | D39: 0 | F39: 67832426531 | H39: 16509532983 | J39: =H39+F39+D39 -> 84341959514 | L39: =J39/$X$12 -> -0.081560149 | N39: 0 | P39: 165314245410 | R39: 16509532983 | T39: =N39+P39+R39 -> 181823778393 | V39: =T39/درآمدها!$F$9 -> 0.058989686
B40: پتروشیمی‌شیراز | D40: 0 | F40: -27256136976 | H40: 562837263 | J40: =H40+F40+D40 -> -26693299713 | L40: =J40/$X$12 -> 0.025812887 | N40: 61067191060 | P40: -85793737891 | R40: 432957341 | T40: =N40+P40+R40 -> -24293589490 | V40: =T40/درآمدها!$F$9 -> -0.0078816491
B41: فروشگاههای زنجیره ای افق کوروش | D41: 7285030759 | F41: -56052768343 | H41: 32849760115 | J41: =H41+F41+D41 -> -15917977469 | L41: =J41/$X$12 -> 0.015392962 | N41: 7285030759 | P41: 30332056 | R41: 32849760115 | T41: =N41+P41+R41 -> 40165122930 | V41: =T41/درآمدها!$F$9 -> 0.013030903
B42: سایپا | D42: 0 | F42: 0 | H42: 234334906 | J42: =H42+F42+D42 -> 234334906 | L42: =J42/$X$12 -> -0.00022660595 | N42: 0 | P42: 0 | R42: 234334906 | T42: =N42+P42+R42 -> 234334906 | V42: =T42/درآمدها!$F$9 -> 7.6026044e-05
...

Sheet درآمد سود سهام
B1: =درآمدها!A1 -> صندوق سرمایه گذاری شاخص سی شرکت بزرگ فیروزه
B2: صورت وضعیت درآمدها
B3: =' سهام'!AC6 -> برای ماه منتهی به 1405/04/31
B4: 1-1-2-درآمد سود سهام | AG4: 1404/05/31
D5: اطلاعات مجمع | J5: =' سهام'!AC7 -> طی تیر ماه | P5: =' سهام'!AC8 -> از ابتدای سال مالی تا پایان تیر ماه | AE5: 1404/06/31
B6: نام سهام | D6: تاریخ مجمع | F6: تعداد سهام متعلقه در زمان مجمع | H6: سود متعلق به هر سهم | J6: جمع درآمد سود سهام | L6: هزینه تنزیل | N6: خالص درآمد سود سهام | P6: جمع درآمد سود سهام | R6: هزینه تنزیل | T6: خالص درآمد سود سهام | AC6: برای ماه منتهی به 1404/06/31
B7: سرمایه‌ گذاری‌ آتیه‌ دماوند | D7: 1405/03/31 | F7: 19617870 | H7: 150 | J7: 0 | L7: 0 | N7: 0 | P7: 2942680500 | R7: 0 | T7: 2942680500
B8: تایدواترخاورمیانه | D8: 1405/04/29 | F8: 25000000 | H8: 850 | J8: 21250000000 | L8: -1195054945 | N8: 20054945055 | P8: 21250000000 | R8: -1195054945 | T8: 20054945055
B9: مخابرات ایران | D9: 1405/04/23 | F9: 1000 | H9: 47 | J9: 47000 | L9: -3265 | N9: 43735 | P9: 47000 | R9: -3265 | T9: 43735
B10: بانک‌اقتصادنوین‌ | D10: 1405/04/30 | F10: 50000000 | H10: 126 | J10: 6300000000 | L10: -895769683 | N10: 5404230317 | P10: 6300000000 | R10: -895769683 | T10: 5404230317
B11: سرمایه‌گذاری‌صندوق‌بازنشستگی‌ | D11: 1405/04/30 | F11: 1000 | H11: 1840 | J11: 1840000 | L11: -261622 | N11: 1578378 | P11: 1840000 | R11: -261622 | T11: 1578378
B12: تراکتورسازی‌ایران‌ | D12: 1405/04/17 | F12: 90000000 | H12: 215 | J12: 19350000000 | L12: -1158757244 | N12: 18191242756 | P12: 19350000000 | R12: -1158757244 | T12: 18191242756
B13: گروه مدیریت سرمایه گذاری امید | D13: 1405/04/22 | F13: 999 | H13: 2650 | J13: 2647350 | L13: -92736 | N13: 2554614 | P13: 2647350 | R13: -92736 | T13: 2554614
B14: توسعه‌معادن‌وفلزات‌ | D14: 1405/04/20 | F14: 379999999 | H14: 120 | J14: 45599999880 | L14: -1539113166 | N14: 44060886714 | P14: 45599999880 | R14: -1539113166 | T14: 44060886714
B15: پتروشیمی‌شیراز | D15: 1405/03/27 | F15: 9442434 | H15: 6928 | J15: 0 | L15: 0 | N15: 0 | P15: 65417182752 | R15: -4349991692 | T15: 61067191060
B16: پالایش نفت تبریز | D16: 1405/04/22 | F16: 1000 | H16: 4795 | J16: 4795000 | L16: -307372 | N16: 4487628 | P16: 4795000 | R16: -307372 | T16: 4487628
B17: پالایش نفت اصفهان | D17: 1405/04/30 | F17: 60000000 | H17: 740 | J17: 44400000000 | L17: -6313043478 | N17: 38086956522 | P17: 44400000000 | R17: -6313043478 | T17: 38086956522
B18: معدنی‌وصنعتی‌چادرملو | D18: 1405/02/31 | F18: 1092 | H18: 200 | J18: 0 | L18: 0 | N18: 0 | P18: 218400 | R18: -8759 | T18: 209641
... B32: رهیاب پیام گستران | D32: 1405/04/31 | F32: 585000 | H32: 414 | J32: 242190000 | L32: -34557939 | N32: 207632061 | P32: 242190000 | R32: -34557939 | T32: 207632061
B33: جمع | F33: =SUM(F7:F32) -> 821651178 | J33: =SUM(J7:J32) -> 178618825910 | L33: =SUM(L7:L32) -> -13772472531 | N33: =SUM(N7:N32) -> 164846353379 | P33: =SUM(P7:P32) -> 249363631281 | R33: =SUM(R7:R32) -> -18129017129 | T33: =SUM(T7:T32) -> 231234614152 | AB33: از ابتدای سال مالی تا پایان مهر ماه
L36: =J33+L33-N33 -> 0

Sheet درآمد ناشی از تغییر قیمت اوراق 
B1: ='درآمد ناشی ازفروش'!B1:R1 -> صندوق سرمایه گذاری شاخص سی شرکت بزرگ فیروزه
B2: صورت وضعیت درآمدها
B3: =' سهام'!AC6 -> برای ماه منتهی به 1405/04/31
B4: 2-1-2-درآمد ناشی از تغییر قیمت اوراق بهادار | AB4: 1404/02/31
D5: =' سهام'!AC7 -> طی تیر ماه | L5: =' سهام'!AC8 -> از ابتدای سال مالی تا پایان تیر ماه | AB5: 1404/03/31
B6: شرح | D6: تعداد | F6: خالص ارزش فروش | H6: ارزش دفتری | J6: سود و زیان ناشی از تغییر قیمت | L6: تعداد | N6: خالص ارزش فروش | P6: ارزش دفتری | R6: سود و زیان ناشی از تغییر قیمت | AB6: برای ماه منتهی به 1404/03/31
B7: گروه مپنا (سهامی عام) | D7: 1000 | F7: 20599525 | H7: -17642560 | J7: =F7+H7 -> 2956965 | L7: 1000 | N7: 20599525 | P7: -12413297 | R7: =N7+P7 -> 8186228 | AB7: طی خرداد ماه
B8: ح . سرمایه گذاری صدرتامین | D8: 2400000 | F8: 36674299200 | H8: -27910570560 | J8: =F8+H8 -> 8763728640 | L8: 2400000 | N8: 36674299200 | P8: -21259186297 | R8: =N8+P8 -> 15415112903 | AB8: از ابتدای سال مالی تا پایان خرداد ماه
B9: پالایش نفت تهران | D9: 50000000 | F9: 236160260000 | H9: -256997930000 | J9: =F9+H9 -> -20837670000 | L9: 50000000 | N9: 236160260000 | P9: -153404941940 | R9: =N9+P9 -> 82755318060
B10: ملی‌ صنایع‌ مس‌ ایران‌ | D10: 205714285 | F10: 3046756519249 | H10: -3351059349444 | J10: =F10+H10 -> -304302830195 | L10: 205714285 | N10: 3046756519249 | P10: -2240443817454 | R10: =N10+P10 -> 806312701795
B11: گروه توسعه مالی فیروزه | D11: 20000000 | F11: 91685748000 | H11: -84175078459 | J11: =F11+H11 -> 7510669541 | L11: 20000000 | N11: 91685748000 | P11: -84174415854 | R11: =N11+P11 -> 7511332146
B12: سرمایه‌گذاری‌غدیر(هلدینگ‌ | D12: 30000000 | F12: 408120651000 | H12: -464412976972 | J12: =F12+H12 -> -56292325972 | L12: 30000000 | N12: 408120651000 | P12: -410989327358 | R12: =N12+P12 -> -2868676358
B13: صنایع پتروشیمی خلیج فارس | D13: 39000000 | F13: 402464712000 | H13: -508538375022 | J13: =F13+H13 -> -106073663022 | L13: 39000000 | N13: 402464712000 | P13: -406334565020 | R13: =N13+P13 -> -3869853020
B14: س. نفت و گاز و پتروشیمی تأمین | D14: 5000000 | F14: 133559542000 | H14: -127903603000 | J14: =F14+H14 -> 5655939000 | L14: 5000000 | N14: 133559542000 | P14: -96924889103 | R14: =N14+P14 -> 36634652897
B15: گروه مدیریت سرمایه گذاری امید | D15: 1782 | F15: 8664303 | H15: -10874584 | J15: =F15+H15 -> -2210281 | L15: 1782 | N15: 8664303 | P15: -9583780 | R15: =N15+P15 -> -919477
B16: بانک تجارت | D16: 80000000 | F16: 41913484800 | H16: -93684614050 | J16: =F16+H16 -> -51771129250 | L16: 80000000 | N16: 41913484800 | P16: -37464842891 | R16: =N16+P16 -> 4448641909
B17: معدنی و صنعتی گل گهر | D17: 1068 | F17: 2273151 | H17: -2169296 | J17: =F17+H17 -> 103855 | L17: 1068 | N17: 2273151 | P17: -1966004 | R17: =N17+P17 -> 307147
B18: سرمایه گذاری تامین اجتماعی | D18: 600000000 | F18: 1296698436000 | H18: -1228866009468 | J18: =F18+H18 -> 67832426532 | L18: 600000000 | N18: 1296698436000 | P18: -1131384190589 | R18: =N18+P18 -> 165314245411
B19: پتروشیمی‌شیراز | D19: 9000000 | F19: 548417706300 | H19: -575673843276 | J19: =F19+H19 -> -27256136976 | L19: 9000000 | N19: 548417706300 | P19: -634211444191 | R19: =N19+P19 -> -85793737891
B20: سرمایه‌گذاری‌ سپه‌ | D20: 23000000 | F20: 98135503000 | H20: -111689326960 | J20: =F20+H20 -> -13553823960 | L20: 23000000 | N20: 98135503000 | P20: -111689326960 | R20: =N20+P20 -> -13553823960
... B37: سرمایه گذاری صدرتامین | D37: 25414814 | F37: 413581062799 | H37: -369983464361 | J37: =F37+H37 -> 43597598438 | L37: 25414814 | N37: 413581062799 | P37: -317857973003 | R37: =N37+P37 -> 95723089796
B38: نقل به صفحه بعد | D38: =SUM(D7:D37) -> 2576231709 | F38: =SUM(F7:F37) -> 10339459701276 | H38: =SUM(H7:H37) -> -11246919435913 | J38: =SUM(J7:J37) -> -907459734637 | L38: =SUM(L7:L37) -> 2576231709 | N38: =SUM(N7:N37) -> 10339459701276 | P38: =SUM(P7:P37) -> -8560275212612 | R38: =SUM(R7:R37) -> 1779184488664
B40: 2-1-2-درآمد ناشی از تغییر قیمت اوراق بهادار | Z40: 1404/02/31
D41: =D5 -> طی تیر ماه | L41: =L5 -> از ابتدای سال مالی تا پایان تیر ماه | Z41: 1404/03/31
B42: شرح | D42: تعداد | F42: خالص ارزش فروش | H42: ارزش دفتری | J42: سود و زیان ناشی از تغییر قیمت | L42: تعداد | N42: خالص ارزش فروش | P42: ارزش دفتری | R42: سود و زیان ناشی از تغییر قیمت | Z42: برای ماه منتهی به 1404/03/31
B43: نقل از صفحه قبل | D43: =D38 -> 2576231709 | F43: =F38 -> 10339459701276 | H43: =H38 -> -11246919435913 | J43: =J38 -> -907459734637 | L43: =L38 -> 2576231709 | N43: =N38 -> 10339459701276 | P43: =P38 -> -8560275212612 | R43: =R38 -> 1779184488664
B44: معدنی‌وصنعتی‌چادرملو | D44: 1092 | F44: 2276557 | H44: -2600541 | J44: =H44+F44 -> -323984 | L44: 1092 | N44: 2276557 | P44: -2298833 | R44: =N44+P44 -> -22276
B45: پتروشیمی پردیس | D45: 45000000 | F45: 467508010500 | H45: -576283426580 | J45: =H45+F45 -> -108775416080 | L45: 45000000 | N45: 467508010500 | P45: -581906819124 | R45: =N45+P45 -> -114398808624
B46: بین المللی توسعه ص. معادن غدیر | D46: 1000 | F46: 3135573 | H46: -3313189 | J46: =H46+F46 -> -177616 | L46: 1000 | N46: 3135573 | P46: -2745611 | R46: =N46+P46 -> 389962
B47: تایدواترخاورمیانه | D47: 25000000 | F47: 184066085000 | H47: -199147398275 | J47: =H47+F47 -> -15081313275 | L47: 25000000 | N47: 184066085000 | P47: -152784773247 | R47: =N47+P47 -> 31281311753
B48: فروشگاههای زنجیره ای افق کوروش | D48: 1044 | F48: 63989388 | H48: -56116757732 | J48: =H48+F48 -> -56052768344 | L48: 1044 | N48: 63989388 | P48: -33657332 | R48: =N48+P48 -> 30332056
B49: بانک پاسارگاد | D49: 1000 | F49: 8533522 | H49: -10061617 | J49: =H49+F49 -> -1528095 | L49: 1000 | N49: 8533522 | P49: -5586480 | R49: =N49+P49 -> 2947042
B50: فولاد مبارکه اصفهان | D50: 12900000 | F50: 20045243178 | H50: -20045243178 | J50: =H50+F50 -> 0 | L50: 12900000 | N50: 20045243178 | P50: -33408738630 | R50: =N50+P50 -> -13363495452
B51: پتروشیمی اروند | D51: 2700000 | F51: 119140866630 | H51: -178644321720 | J51: =H51+F51 -> -59503455090 | L51: 2700000 | N51: 119140866630 | P51: -203490878141 | R51: =N51+P51 -> -84350011511
B52: سرمایه گذاری سبحان | D52: 30000000 | F52: 61709271300 | H52: -76256465477 | J52: =H52+F52 -> -14547194177 | L52: 30000000 | N52: 61709271300 | P52: -46914525589 | R52: =N52+P52 -> 14794745711
B53: پتروشیمی نوری | D53: 5000000 | F53: 238690548500 | H53: -203688224250 | J53: =H53+F53 -> 35002324250 | L53: 5000000 | N53: 238690548500 | P53: -277305387181 | R53: =N53+P53 -> -38614838681
B54: بانک‌اقتصادنوین‌ | D54: 61283274 | F54: 169354608703 | H54: -193498896332 | J54: =H54+F54 -> -24144287629 | L54: 61283274 | N54: 169354608703 | P54: -103264075517 | R54: =N54+P54 -> 66090533186
B55: پتروشیمی پارس | D55: 1147 | F55: 2143105 | H55: -3109381 | J55: =H55+F55 -> -966276 | L55: 1147 | N55: 2143105 | P55: -2718819 | R55: =N55+P55 -> -575714
... B59: مبین انرژی خلیج فارس | D59: 10000000 | F59: 78945001200 | H59: -88470793200 | J59: =H59+F59 -> -9525792000 | L59: 10000000 | N59: 78945001200 | P59: -147451322000 | R59: =N59+P59 -> -68506320800
B60: جمع | D60: =SUM(D43:D59) -> 3268165363 | F60: =SUM(F43:F59) -> 13203750830554 | H60: =SUM(H43:H59) -> -14590390414880 | J60: =SUM(J43:J59) -> -1386639584326 | L60: =SUM(L43:L59) -> 3268165363 | N60: =SUM(N43:N59) -> 13203750830554 | P60: =SUM(P43:P59) -> -11475293905088 | R60: =SUM(R43:R59) -> 1728456925466
...

Sheet درآمد ناشی ازفروش
B1: ='سود اوراق بهادار و سپرده بانکی'!B1:U1 -> صندوق سرمایه گذاری شاخص سی شرکت بزرگ فیروزه
B2: صورت وضعیت درآمدها
B3: =' سهام'!B3:Z3 -> برای ماه منتهی به 1405/04/31
B4: 3-1-2-سود(زیان) حاصل از فروش اوراق بهادار | AC4: 1404/04/31
D5: =' سهام'!AC7 -> طی تیر ماه | L5: =' سهام'!AC8 -> از ابتدای سال مالی تا پایان تیر ماه | AC5: 1404/05/31
B6: شرح | D6: تعداد | F6: خالص بهای فروش | H6: ارزش دفتری | J6: سود و زیان ناشی از فروش | L6: تعداد | N6: خالص ارزش فروش | P6: ارزش دفتری | R6: سود و زیان ناشی از فروش | Z6: برای ماه منتهی به 1404/05/31
B7: سرمایه‌گذاری‌ سپه‌ | D7: 600000 | F7: 2615140627 | H7: -2913634615 | J7: -298493988 | L7: 600000 | N7: 2615140627 | P7: -2913634615 | R7: =P7+N7 -> -298493988
B8: پتروشیمی جم | D8: 99000 | F8: 3688867268 | H8: -4302681176 | J8: -613813908 | L8: 99000 | N8: 3688867268 | P8: -4302681176 | R8: =P8+N8 -> -613813908
B9: سرمایه‌گذاری‌صندوق‌بازنشستگی‌ | D9: 999000 | F9: 16630010355 | H9: -16841808629 | J9: -211798274 | L9: 13999000 | N9: 221973501492 | P9: -236004483537 | R9: =P9+N9 -> -14030982045
B10: سرمایه گذاری خوارزمی | D10: 15000000 | F10: 74165148336 | H10: -58298545103 | J10: 15866603233 | L10: 15014493 | N10: 74228835073 | P10: -58354873158 | R10: =P10+N10 -> 15873961915
B11: کشت و صنعت هلال | D11: 125000 | F11: 5389880247 | H11: -4784903350 | J11: 604976897 | L11: 125000 | N11: 5389880247 | P11: -4784903350 | R11: =P11+N11 -> 604976897
B12: تراکتورسازی‌ایران‌ | D12: 18000000 | F12: 43919753152 | H12: -43594487859 | J12: 325265293 | L12: 18000000 | N12: 43919753152 | P12: -43594487859 | R12: =P12+N12 -> 325265293
B13: ح . سرمایه‌گذاری‌ سپه‌ | D13: 23600000 | F13: 91002961575 | H13: -91002961575 | J13: 0 | L13: 23600000 | N13: 91002961575 | P13: -91002961575 | R13: =P13+N13 -> 0
B14: پالایش نفت اصفهان | D14: 60600000 | F14: 602710217327 | H14: -313661835067 | J14: 289048382260 | L14: 60660440 | N14: 603029455899 | P14: -313971621183 | R14: =P14+N14 -> 289057834716
B15: ملی‌ صنایع‌ مس‌ ایران‌ | D15: 9500000 | F15: 197574903177 | H15: -141894775106 | J15: 55680128071 | L15: 9500000 | N15: 197574903177 | P15: -141894775106 | R15: =P15+N15 -> 55680128071
B16: گروه توسعه مالی فیروزه | D16: 1301101 | F16: 5449089631 | H16: -5475970835 | J16: -26881204 | L16: 1301101 | N16: 5449089631 | P16: -5475970835 | R16: =P16+N16 -> -26881204
B17: ح . معدنی و صنعتی گل گهر | D17: 111 | F17: 107895 | H17: -148185 | J17: -40290 | L17: 111 | N17: 107895 | P17: -148185 | R17: =P17+N17 -> -40290
B18: سرمایه‌گذاری‌غدیر(هلدینگ‌ | D18: 14000000 | F18: 196390026792 | H18: -191795019428 | J18: 4595007364 | L18: 14000000 | N18: 196390026792 | P18: -191795019428 | R18: =P18+N18 -> 4595007364
... B28: نشاسته و گلوکز آردینه | D28: 500000 | F28: 13543500950 | H28: -13803569294 | J28: -260068344 | L28: 500000 | N28: 13543500950 | P28: -13803569294 | R28: =P28+N28 -> -260068344
B29: پتروشیمی پردیس | D29: 5600000 | F29: 60716796494 | H29: -72415070460 | J29: -11698273966 | L29: 5607435 | N29: 60817530494 | P29: -72511214397 | R29: =P29+N29 -> -11693683903 | Z29: طی مرداد ماه
B30: تایدواترخاورمیانه | D30: 800000 | F30: 7108734412 | H30: -4889112745 | J30: 2219621667 | L30: 882353 | N30: 7623019663 | P30: -5392404124 | R30: =P30+N30 -> 2230615539
B31: پتروشیمی خراسان | D31: 335000 | F31: 16234274413 | H31: -11886997691 | J31: 4347276722 | L31: 335212 | N31: 16242495847 | P31: -11894520209 | R31: =P31+N31 -> 4347975638
B32: توسعه‌معادن‌وفلزات‌ | D32: 8400000 | F32: 17888603965 | H32: -19199210042 | J32: -1310606077 | L32: 8615749 | N32: 18290254437 | P32: -19554618282 | R32: =P32+N32 -> -1264363845
B33: آلومینیوم‌ایران‌ | D33: 14000000 | F33: 149825239849 | H33: -77377214600 | J33: 72448025249 | L33: 14000000 | N33: 149825239849 | P33: -77377214600 | R33: =P33+N33 -> 72448025249
B34: بانک تجارت | D34: 253200000 | F34: 164039287526 | H34: -118576227638 | J34: 45463059888 | L34: 254126441 | N34: 164405370607 | P34: -118921823991 | R34: =P34+N34 -> 45483546616
B35: سرمایه گذاری تامین اجتماعی | D35: 60800000 | F35: 131156464299 | H35: -114646931316 | J35: 16509532983 | L35: 60800000 | N35: 131156464299 | P35: -114646931316 | R35: =P35+N35 -> 16509532983
B36: پتروشیمی‌شیراز | D36: 367191 | F36: 26438029954 | H36: -25875192691 | J36: 562837263 | L36: 442434 | N36: 31610369096 | P36: -31177411755 | R36: =P36+N36 -> 432957341
B37: فروشگاههای زنجیره ای افق کوروش | D37: 1998956 | F37: 97293807383 | H37: -64444047268 | J37: 32849760115 | L37: 1998956 | N37: 97293807383 | P37: -64444047268 | R37: =P37+N37 -> 32849760115
B38: سایپا | D38: 668000000 | F38: 374761805019 | H38: -374527470113 | J38: 234334906 | L38: 668000000 | N38: 374761805019 | P38: -374527470113 | R38: =P38+N38 -> 234334906
B39: پالایش نفت بندرعباس | D39: 21708586 | F39: 262257952234 | H39: -149493003710 | J39: 112764948524 | L39: 30000000 | N39: 357304174363 | P39: -206590613990 | R39: =P39+N39 -> 150713560373
B40: ح . سرمایه گذاری صدرتامین | D40: 0 | F40: 0 | H40: 0 | J40: 0 | L40: 88889 | N40: 833094748 | P40: -787378253 | R40: =P40+N40 -> 45716495
B41: بیمه اتکایی ایران معین | D41: 0 | F41: 0 | H41: 0 | J41: 0 | L41: 232900 | N41: 462048552 | P41: -459195070 | R41: =P41+N41 -> 2853482
... B52: ح.سرمایه گذاری خوارزمی | D52: 0 | F52: 0 | H52: 0 | J52: 0 | L52: 190000000 | N52: 647162323018 | P52: -647162323018 | R52: =P52+N52 -> 0
B53: تولیدی کوچین | D53: 0 | F53: 0 | H53: 0 | J53: 0 | L53: 1475169 | N53: 16827652536 | P53: -10269781860 | R53: =P53+N53 -> 6557870676 | Z53: از ابتدای سال مالی تا پایان مرداد ماه
B54: جمع | D54: =SUM(D7:D53) -> 2608549538 | F54: =SUM(F7:F53) -> 4222402190790 | H54: =SUM(H7:H53) -> -3342025736200 | J54: =SUM(J7:J53) -> 880376454590 | L54: =SUM(L7:L53) -> 3040791581 | N54: =SUM(N7:N53) -> 6025560350886 | P54: =SUM(P7:P53) -> -4952157248851 | R54: =SUM(R7:R53) -> 1073403102035
B56: 3-1-2-سود(زیان) حاصل از فروش اوراق بهادار | Z56: 1404/02/31
D57: =D5 -> طی تیر ماه | L57: =L5 -> از ابتدای سال مالی تا پایان تیر ماه | Z57: 1404/03/31
B58: شرح | D58: تعداد | F58: خالص بهای فروش | H58: ارزش دفتری | J58: سود و زیان ناشی از فروش | L58: تعداد | N58: خالص ارزش فروش | P58: ارزش دفتری | R58: سود و زیان ناشی از فروش | X58: برای ماه منتهی به 1404/03/31
B59: نقل از صفحه قبل | D59: =D54 -> 2608549538 | F59: =F54 -> 4222402190790 | H59: =H54 -> -3342025736200 | J59: =J54 -> 880376454590 | L59: =L54 -> 3040791581 | N59: =N54 -> 6025560350886 | P59: =P54 -> -4952157248851 | R59: =R54 -> 1073403102035
B60: جمع | D60: =SUM(D59:D59) -> 2608549538 | F60: =SUM(F59:F59) -> 4222402190790 | H60: =SUM(H59:H59) -> -3342025736200 | J60: =SUM(J59:J59) -> 880376454590 | L60: =SUM(L59:L59) -> 3040791581 | N60: =SUM(N59:N59) -> 6025560350886 | P60: =SUM(P59:P59) -> -4952157248851 | R60: =SUM(R59:R59) -> 1073403102035

Sheet درآمد سرمایه گذاری در اوراق بها
A1: صندوق سرمایه‌گذاری صندوق شاخص سی شرکت بزرگ فیروزه
A2: صورت وضعیت درآمدها
A3: =' سهام'!AC6 -> برای ماه منتهی به 1405/04/31
B4: 2-2-درآمد حاصل از سرمایه گذاری در اوراق بهادار با درآمد ثابت:
C6: =' سهام'!AC7 -> طی تیر ماه | M6: =' سهام'!AC8 -> از ابتدای سال مالی تا پایان تیر ماه
C7: درآمد سود اوراق | E7: درآمد تغییر ارزش | G7: درآمد فروش | I7: جمع | M7: درآمد سود اوراق | O7: درآمد تغییر ارزش | Q7: درآمد فروش | R7: جمع
C9: یادداشت 2-2-1 | E9: یادداشت 2-1-2 | G9: یادداشت 3-1-2 | I9: مبلغ | K9: درصد از کل دارائیها | M9: یادداشت 2-2-1 | O9: یادداشت 2-1-2 | Q9: یادداشت 3-1-2 | R9: مبلغ | S9: درصد از کل دارائیها
B10: - | C10: 0 | D10: 0 | E10: 0 | F10: 0 | G10: 0 | H10: 0 | I10: 0 | J10: 0 | K10: 0 | L10: 0 | M10: 0 | N10: 0 | O10: 0 | P10: 875280 | Q10: 0 | R10: 0 | S10: =R10/S14 -> 0
B11: جمع | C11: =SUM(C10:C10) -> 0 | E11: =SUM(E10:E10) -> 0 | G11: =SUM(G10:G10) -> 0 | I11: =SUM(I10:I10) -> 0 | K11: =SUM(K10:K10) -> 0 | M11: =SUM(M10:M10) -> 0 | O11: =SUM(O10:O10) -> 0 | Q11: =SUM(Q10:Q10) -> 0 | R11: =SUM(R10:R10) -> 0 | S11: =SUM(S10:S10) -> 0
K14: 2807555599778 | S14: 2807555599778

Sheet سود اوراق بهادار و سپرده بانکی
B1: ='درآمد سود سهام'!B1:T1 -> صندوق سرمایه گذاری شاخص سی شرکت بزرگ فیروزه
B2: صورت وضعیت درآمدها
B3: =' سهام'!AC6 -> برای ماه منتهی به 1405/04/31
B4: 1-2-2-سود اوراق بهادار با درآمد ثابت و سپرده بانکی | AC4: 1404/06/31
G5: ابتدای دوره | K5: =' سهام'!AC7 -> طی تیر ماه | Q5: =' سهام'!AC8 -> از ابتدای سال مالی تا پایان تیر ماه | AC5: 1404/07/30
B6: شرح | C6: تاریخ دریافت سود | D6: تاریخ سررسید | E6: نرخ سود علی الحساب | G6: درآمد سود | I6: هزینه تنزیل | K6: درآمد سود | M6: هزینه تنزیل | O6: خالص درآمد | Q6: درآمد سود | S6: هزینه تنزیل | U6: خالص درآمد | AC6: برای ماه منتهی به 1404/07/30
B7: سپرده کوتاه مدت بانک خاورمیانه مهستان | H7: 0 | J7: 176683 | K7: 206375 | M7: 0 | O7: 206375 | Q7: 834143 | S7: 0 | U7: 834143 | AC7: طی مهر ماه
B8: سپرده کوتاه مدت بانک گردشگری سعادت آباد | K8: 12467836653 | M8: 0 | O8: 12467836653 | Q8: 33446410899 | S8: 0 | U8: 33446410899
B9: سپرده کوتاه مدت بانک صادرات بلوار میرداماد | K9: 0 | M9: 0 | O9: 0 | Q9: 4055 | S9: 0 | U9: 4055
B10: سپرده کوتاه مدت بانک خاورمیانه نیاوران | H10: 0 | J10: 2202729735 | K10: 247558 | M10: 0 | O10: 247558 | Q10: 3460862 | S10: 0 | U10: 3460862 | AC10: از ابتدای سال مالی تا پایان مهر ماه
K11: =SUM(K7:K10) -> 12468290586 | O11: =SUM(O7:O10) -> 12468290586 | Q11: =SUM(Q7:Q10) -> 33450709959 | U11: =SUM(U7:U10) -> 33450709959
R58: 1783
R75: 2083

Sheet درآمد سپرده بانکی
B1: ='سود اوراق بهادار و سپرده بانکی'!B1:U1 -> صندوق سرمایه گذاری شاخص سی شرکت بزرگ فیروزه
B2: صورت وضعیت درآمدها
B3: =' سهام'!B3:Z3 -> برای ماه منتهی به 1405/04/31
B4: 3-2-درآمد حاصل از سرمایه گذاری در سپرده بانکی و گواهی سپرده:
B6: نام سپرده بانکی | F6: =' سهام'!AC7 -> طی تیر ماه | J6: =' سهام'!AC8 -> از ابتدای سال مالی تا پایان تیر ماه
B7: نام سپرده | F7: سود سپرده بانکی و گواهی سپرده | H7: درصد سود به میانگین سپرده | J7: سود سپرده بانکی و گواهی سپرده | L7: درصد سود به میانگین سپرده
F8: یادداشت 2-2-1 | J8: یادداشت 2-2-1
B9: سپرده کوتاه مدت بانک خاورمیانه مهستان | F9: 206375 | H9: =F9/L18 -> 9.3955323e-07 | J9: 834143 | L9: =J9/L18 -> 3.7975615e-06
B10: سپرده کوتاه مدت بانک گردشگری سعادت آباد | F10: 12467836653 | H10: =F10/L18 -> 0.056761702 | J10: 33446410899 | L10: =J10/L18 -> 0.15226982
B11: سپرده کوتاه مدت بانک صادرات بلوار میرداماد | F11: 0 | H11: =F11/L18 -> 0 | J11: 4055 | L11: =J11/L18 -> 1.8460997e-08
B12: سپرده کوتاه مدت بانک خاورمیانه نیاوران | F12: 247558 | H12: =F12/L18 -> 1.127045e-06 | J12: 3460862 | L12: =J12/L18 -> 1.5756095e-05
B13: جمع | F13: =SUM(F9:F12) -> 12468290586 | H13: =SUM(H9:H12) -> 0.056763768 | J13: =SUM(J9:J12) -> 33450709959 | L13: =SUM(L9:L12) -> 0.15228939
J18: 6809220361173 | L18: =J18/31 -> 2.1965227e+11
R58: 1783
R75: 2083

Sheet Sheet1

Sheet سایر درآمدها
B1: ='درآمد سپرده بانکی'!B1:M1 -> صندوق سرمایه گذاری شاخص سی شرکت بزرگ فیروزه
B2: صورت وضعیت درآمدها
B3: =' سهام'!AC6 -> برای ماه منتهی به 1405/04/31
B4: 4-2-سایر درآمدها:
D5: =' سهام'!AC7 -> طی تیر ماه | F5: =' سهام'!AC8 -> از ابتدای سال مالی تا پایان تیر ماه
B6: سایر درآمدها | D6: -11178 | F6: 2383197
B7: تعدیل کارمزد کارگزار | D7: 6203755572 | F7: 15750053493
D8: =SUM(D6:D7) -> 6203744394 | F8: =SUM(F6:F7) -> 15752436690
R57: 1783
R74: 2083
