Workbook

Sheet  سهام
B1: صندوق سرمایه گذاری شاخص سی شرکت بزرگ فیروزه
B2: صورت وضعیت پرتفوی
B3: =AC6 -> برای ماه منتهی به 1404/12/29
B4: 1- سرمایه گذاری ها | AC4: 1404/11/30
B5: 1-1-سرمایه‌گذاری در سهام و حق تقدم سهام | AC5: 1404/12/29
D6: =AC4 -> 1404/11/30 | J6: تغییرات طی دوره | R6: =AC5 -> 1404/12/29 | AC6: برای ماه منتهی به 1404/12/29
B7: شرکت | D7: تعداد | F7: بهای تمام شده | H7: خالص ارزش فروش | J7: خرید طی دوره | N7: فروش طی دوره | R7: تعداد | T7: قیمت بازار هر سهم | V7: بهای تمام شده | X7: خالص ارزش فروش | Z7: درصد به کل دارایی‌ها | AC7: طی اسفند ماه
J8: تعداد | L8: بهای تمام شده | N8: تعداد | P8: مبلغ فروش | AC8: از ابتدای سال مالی تا پایان اسفند ماه
B9: آلومینیوم‌ایران‌ | D9: 14600000 | F9: 91256769500 | H9: 85763880640 | J9: 0 | L9: 0 | N9: -600000 | P9: 3299342676 | R9: 14000000 | T9: 5570 | V9: 87506491301 | X9: 77377214600 | Z9: =X9/$Z$78 -> 0.0081689962
B10: آلیاژ گستر هامون | D10: 837500 | F10: 3566757144 | H10: 3.7121937e+09 | J10: 0 | L10: 0 | N10: 0 | P10: 0 | R10: 837500 | T10: 4153 | V10: 3566757144 | X10: 3.4512515e+09 | Z10: =X10/$Z$78 -> 0.00036436127
B11: ایران خودرو دیزل | D11: 80000000 | F11: 109063410216 | H11: 92717708800 | J11: 0 | L11: 0 | N11: 0 | P11: 0 | R11: 80000000 | T11: 1078 | V11: 109063410216 | X11: 85573364800 | Z11: =X11/$Z$78 -> 0.0090342938
B12: ایران‌ خودرو | D12: 100000000 | F12: 49863785508 | H12: 49811954000 | J12: 0 | L12: 0 | N12: 0 | P12: 0 | R12: 100000000 | T12: 475 | V12: 49863785508 | X12: 47132825000 | Z12: =X12/$Z$78 -> 0.0049759851
B13: بانک پاسارگاد | D13: 1000 | F13: 1915216 | H13: 5070499.7 | J13: 0 | L13: 0 | N13: 0 | P13: 0 | R13: 1000 | T13: 5630 | V13: 1915216 | X13: 5586480.1 | Z13: =X13/$Z$78 -> 5.8978518e-07
B14: بانک تجارت | D14: 200000000 | F14: 110857944356 | H14: 80770778000 | J14: 0 | L14: 0 | N14: 0 | P14: 0 | R14: 200000000 | T14: 404 | V14: 110857944356 | X14: 80175416000 | Z14: =X14/$Z$78 -> 0.0084644125
B15: بانک ملت | D15: 600000000 | F15: 785782978665 | H15: 748370034000 | J15: 232067064 | L15: 0 | N15: -50000000 | P15: 59614787916 | R15: 782067064 | T15: 873 | V15: 720301063770 | X15: 6.7746693e+11 | Z15: =X15/$Z$78 -> 0.071522667
B16: بانک‌اقتصادنوین‌ | D16: 58000000 | F16: 93098147252 | H16: 112916356920 | J16: 0 | L16: 0 | N16: 0 | P16: 0 | R16: 58000000 | T16: 2024 | V16: 93098147252 | X16: 116484559840 | Z16: =X16/$Z$78 -> 0.012297702
B17: بیمه اتکایی ایران معین | D17: 232900 | F17: 394603131 | H17: 4.5965727e+08 | J17: 0 | L17: 0 | N17: 0 | P17: 0 | R17: 232900 | T17: 1987 | V17: 394603131 | X17: 4.5919507e+08 | Z17: =X17/$Z$78 -> 4.8478907e-05
B18: بین المللی توسعه ص. معادن غدیر | D18: 1000 | F18: 5411279 | H18: 2808124.1 | J18: 0 | L18: 0 | N18: 0 | P18: 0 | R18: 1000 | T18: 2767 | V18: 5411279 | X18: 2745611.1 | Z18: =X18/$Z$78 -> 2.8986423e-07
B19: پالایش نفت اصفهان | D19: 100000000 | F19: 382642214429 | H19: 628106910000 | J19: 0 | L19: 0 | N19: 0 | P19: 0 | R19: 100000000 | T19: 6150 | V19: 382642214429 | X19: 610246050000 | Z19: =X19/$Z$78 -> 0.064425912
B20: پالایش نفت بندرعباس | D20: 135000000 | F20: 585695642002 | H20: 1010031633000 | J20: 0 | L20: 0 | N20: -45000000 | P20: 310010475599 | R20: 90000000 | T20: 6940 | V20: 390463761385 | X20: 619771842000 | Z20: =X20/$Z$78 -> 0.065431585
... B36: سایپا | D36: 160000000 | F36: 93100332246 | H36: 81763048000 | J36: 0 | L36: 0 | N36: -10000000 | P36: 5063484125 | R36: 150000000 | T36: 504 | V36: 87281561491 | X36: 75015612000 | Z36: =X36/$Z$78 -> 0.0079196731
B37: سرمایه گذاری تامین اجتماعی | D37: 300000000 | F37: 476047549439 | H37: 490280607000 | J37: 0 | L37: 0 | M37: 9102861790 | N37: -20000000 | P37: 31946035695 | R37: 280000000 | T37: 1639 | V37: 444311046137 | X37: 455372548400 | Z37: =X37/$Z$78 -> 0.048075349
B38: سرمایه گذاری خوارزمی | D38: 99982360 | F38: 371522240327 | H38: 3.0288659e+11 | J38: 0 | L38: 0 | N38: 0 | P38: 0 | R38: 99982360 | T38: 2925 | V38: 371522240327 | X38: 2.9018778e+11 | Z38: =X38/$Z$78 -> 0.030636187
B39: سرمایه گذاری سبحان | D39: 96000000 | F39: 136919972432 | H39: 152793703680 | J39: 0 | L39: 0 | N39: 0 | P39: 0 | R39: 96000000 | T39: 1576 | V39: 136919972432 | X39: 150126481920 | Z39: =X39/$Z$78 -> 0.015849403
B40: سرمایه گذاری صدرتامین | D40: 10000000 | F40: 124133371320 | H40: 133460315000 | J40: 414815 | L40: 0 | N40: -3000000 | P40: 38880071391 | R40: 7414815 | T40: 9927 | V40: 66922514585 | X40: 7.3037887e+10 | Z40: =X40/$Z$78 -> 0.0077108775
B41: سرمایه‌ گذاری‌ آتیه‌ دماوند | D41: 35000000 | F41: 141990772138 | H41: 154164028550 | J41: 0 | L41: 0 | N41: -1000000 | P41: 4145415462 | R41: 34000000 | T41: 4363 | V41: 137933892936 | X41: 147195316340 | Z41: =X41/$Z$78 -> 0.015539949
B42: سرمایه‌گذاری‌صندوق‌بازنشستگی‌ | D42: 18000000 | F42: 390213459868 | H42: 318816351000 | J42: 0 | L42: 0 | N42: -4000000 | P42: 66088837645 | R42: 14000000 | T42: 16990 | V42: 303499357672 | X42: 236021342200 | Z42: =X42/$Z$78 -> 0.024917638
B43: سرمایه‌گذاری‌غدیر(هلدینگ‌ | D43: 40000000 | F43: 406715712142 | H43: 595362000000 | J43: 0 | L43: 0 | N43: 0 | P43: 0 | R43: 40000000 | T43: 13580 | V43: 406715712142 | X43: 539001064000 | Z43: =X43/$Z$78 -> 0.056904318
B44: صنایع پتروشیمی خلیج فارس | D44: 88000000 | F44: 643044761954 | H44: 943053408000 | J44: 0 | L44: 0 | N44: -8000000 | P44: 80986843843 | R44: 80000000 | T44: 10500 | V44: 584586147232 | X44: 833506800000 | Z44: =X44/$Z$78 -> 0.087996368
B45: فروشگاههای زنجیره ای افق کوروش | D45: 4000000 | F45: 100823299585 | H45: 137846148400 | J45: 0 | L45: 0 | N45: -2000000 | P45: 65601330928 | R45: 2000000 | T45: 32490 | V45: 50411649795 | X45: 64477704600 | Z45: =X45/$Z$78 -> 0.0068071476
B46: فولاد مبارکه اصفهان | D46: 10000000 | F46: 34912740601 | H46: 33439499000 | J46: 2900000 | L46: 0 | N46: 0 | P46: 0 | R46: 12900000 | T46: 2610 | V46: 34912740601 | X46: 33408738630 | Z46: =X46/$Z$78 -> 0.003527083
B47: گروه س توسعه صنعتی ایران | D47: 60000000 | F47: 98042294767 | H47: 90554560200 | J47: 0 | L47: 0 | N47: 0 | P47: 0 | R47: 60000000 | T47: 1455 | V47: 98042294767 | X47: 86625171000 | Z47: =X47/$Z$78 -> 0.0091453368
B48: گروه صنعتی درپاد تبریز | D48: 375000 | F48: 3137744212 | H48: 4.1191608e+09 | J48: 0 | L48: 0 | N48: 0 | P48: 0 | R48: 375000 | T48: 9830 | V48: 3137744212 | X48: 3.6577553e+09 | Z48: =X48/$Z$78 -> 0.00038616263
B49: نقل به صفحه بعد | C49: 0 | D49: =SUM(D9:D48) -> 2373206641 | E49: =AC48=SUM(#REF!) -> #REF! | F49: =SUM(F9:F48) -> 6683381235705 | G49: =SUM(#REF!) -> #REF! | H49: =SUM(H9:H48) -> 8.0655695e+12 | J49: =SUM(J9:J48) -> 305233390 | K49: =SUM(#REF!) -> #REF! | L49: =SUM(L9:L48) -> 0 | M49: =SUM(#REF!) -> #REF! | N49: =SUM(N9:N48) -> -199788752 | O49: =SUM(#REF!) -> #REF! | P49: =SUM(P9:P48) -> 780173717359 | Q49: =SUM(#REF!) -> #REF! | R49: =SUM(R9:R48) -> 2478651279 | S49: =SUM(#REF!) -> #REF! | T49: =SUM(T9:T48) -> 459250 | U49: =SUM(#REF!) -> #REF! | V49: =SUM(V9:V48) -> 6018253749016 | W49: =SUM(#REF!) -> #REF! | X49: =SUM(X9:X48) -> 6.9559425e+12 | Y49: =SUM(#REF!) -> #REF! | Z49: =SUM(Z9:Z48) -> 0.73436434
B51: 1- سرمایه گذاری ها
B52: 1-1-سرمایه‌گذاری در سهام و حق تقدم سهام
D53: =D6 -> 1404/11/30 | J53: تغییرات طی دوره | R53: =R6 -> 1404/12/29
B54: شرکت | D54: تعداد | F54: بهای تمام شده | H54: خالص ارزش فروش | J54: خرید طی دوره | N54: فروش طی دوره | R54: تعداد | T54: قیمت بازار هر سهم | V54: بهای تمام شده | X54: خالص ارزش فروش | Z54: درصد به کل دارایی‌ها
J55: تعداد | L55: بهای تمام شده | N55: تعداد | P55: مبلغ فروش
B56: نقل از صفحه قبل | D56: =D49 -> 2373206641 | F56: =F49 -> 6683381235705 | H56: =H49 -> 8.0655695e+12 | J56: =J49 -> 305233390 | L56: =L49 -> 0 | N56: =N49 -> -199788752 | P56: =P49 -> 780173717359 | R56: =R49 -> 2478651279 | T56: =T49 -> 459250 | V56: =V49 -> 6018253749016 | X56: =X49 -> 6.9559425e+12 | Z56: =Z49 -> 0.73436434
...

Sheet اوراق تبعی
B1: =' سهام'!B1:Z1 -> صندوق سرمایه گذاری شاخص سی شرکت بزرگ فیروزه
B2: صورت وضعیت پرتفوی
B3: =' سهام'!AC6 -> برای ماه منتهی به 1404/12/29
B4: اطلاعات آماری مرتبط با اوراق اختیار فروش تبعی خریداری شده توسط صندوق سرمایه گذاری:
D6: =' سهام'!AC4 -> 1404/11/30 | L6: =' سهام'!AC5 -> 1404/12/29
B7: نام سهام | D7: تعداد اوراق تبعی | F7: قیمت اعمال | H7: تاریخ اعمال | J7: نرخ سود مؤثر | L7: تعداد اوراق تبعی | N7: قیمت اعمال | P7: تاریخ اعمال | R7: نرخ سود مؤثر
D8: - | F8: - | H8: - | J8: 0 | L8: 0 | N8: - | P8: - | R8: 0
D9: =SUM(D8) -> 0 | F9: =SUM(F8) -> 0 | H9: ..... | J9: ..... | L9: =SUM(L8) -> 0 | N9: =SUM(N8) -> 0 | P9: ..... | R9: .....

Sheet تعدیل قیمت
A1: =اوراق!B1 -> صندوق سرمایه گذاری شاخص سی شرکت بزرگ فیروزه
A2: صورت وضعیت پرتفوی
A3: =' سهام'!AC6 -> برای ماه منتهی به 1404/12/29
A4: اوراق بهاداری که ارزش آنها در تاریخ گزارش تعدیل شده
A5: (بر اساس دستورالعمل نحوه تعیین قیمت خرید و فروش اوراق بهادار در صندوق های سرمایه گذاری)
C6: =' سهام'!AC5 -> 1404/12/29
A7: نام اوراق بهادار | C7: تعداد | E7: قیمت پایانی | G7: قیمت تعدیل شده | I7: درصد تعدیل | K7: خالص ارزش فروش تعدیل شده | M7: دلیل تعدیل
C9: - | E9: - | G9: - | I9: - | K9: - | M9: -
C10: - | E10: - | G10: - | I10: - | K10: - | M10: -

Sheet گواهی سپرده
A1: ='تعدیل قیمت'!A1:P1 -> صندوق سرمایه گذاری شاخص سی شرکت بزرگ فیروزه
A2: صورت وضعیت پرتفوی
A3: =' سهام'!AC6 -> برای ماه منتهی به 1404/12/29
A4: 4-1- سرمایه‌گذاری در گواهی سپرده‌ بانکی
K6: =' سهام'!AC4 -> 1404/11/30 | Q6: تغییرات طی دوره | W6: =' سهام'!AC5 -> 1404/12/29
A7: گواهی سپرده بانکی | C7: تاریخ سررسید | E7: نرخ سود علی الحساب | G7: نرخ شکست | I7: پذیرفته شده در بورس یا فرابورس | K7: تعداد | M7: بهای تمام شده | O7: خالص ارزش | Q7: خرید طی دوره | T7: فروش طی دوره | W7: تعداد | Y7: بهای تمام شده | AA7: خالص ارزش | AC7: درصد به کل
O8: فروش | Q8: تعداد | R8: بهای تمام شده | T8: تعداد | U8: مبلغ فروش | AA8: فروش | AC8: دارایی‌ها
A9: گواهی سپرده بانکی نزد بانک ..... | C9: ..... | E9: ..... | G9: ..... | I9: ..... | K9: ..... | M9: ..... | O9: ..... | Q9: ..... | R9: ..... | T9: ..... | U9: ..... | W9: ..... | Y9: ..... | AA9: ..... | AC9: .....
A10: جمع | C10: ..... | E10: ..... | G10: ..... | I10: ..... | K10: ..... | M10: ..... | O10: ..... | Q10: ..... | R10: ..... | T10: ..... | U10: ..... | W10: ..... | Y10: ..... | AA10: ..... | AC10: .....

Sheet اوراق
B1: =' سهام'!B1:Z1 -> صندوق سرمایه گذاری شاخص سی شرکت بزرگ فیروزه
B2: صورت وضعیت پرتفوی
B3: =' سهام'!AC6 -> برای ماه منتهی به 1404/12/29
B4: 2-1-سرمایه‌گذاری در اوراق بهادار با درآمد ثابت یا علی‌الحساب
B6: اطلاعات اوراق بهادار با درآمد ثابت | Q6: =' سهام'!AC4 -> 1404/11/30 | W6: تغییرات طی دوره | AE6: =' سهام'!AC5 -> 1404/12/29
B7: نام اوراق | D7: دارای مجوز از سازمان | F7: پذیرفته شده در بورس یا فرابورس | H7: تاریخ انتشار اوراق | J7: تاریخ سررسید | M7: نرخ سود اسمی | O7: نرخ سود مؤثر | Q7: تعداد | S7: بهای تمام شده | U7: خالص ارزش فروش | W7: خرید طی دوره | AA7: فروش طی دوره | AE7: تعداد | AG7: قیمت بازار هر ورقه | AI7: بهای تمام شده | AK7: خالص ارزش فروش | AM7: درصد به کل دارایی‌ها
W8: تعداد | Y8: بهای تمام شده | AA8: تعداد | AC8: مبلغ فروش
B9: جمع | M9: - | Q9: 0 | S9: 0 | U9: 0 | W9: 0 | Y9: 0 | AA9: 0 | AC9: 0 | AE9: 0 | AG9: 0 | AI9: 0 | AK9: 0 | AM9: 0

Sheet سپرده
B1: صندوق سرمایه گذاری شاخص سی شرکت بزرگ فیروزه
B2: صورت وضعیت پرتفوی
B3: =' سهام'!AC6 -> برای ماه منتهی به 1404/12/29
B4: 3-1- سرمایه‌گذاری در سپرده‌ بانکی | AA4: 1404/02/31
AA5: 1404/03/31
L6: تغییرات طی دوره | P6: =' سهام'!AC5 -> 1404/12/29 | AA6: برای ماه منتهی به 1404/03/31
B7: سپرده های بانکی | D7: نوع سپرده | F7: تاریخ افتتاح حساب | H7: نرخ سود علی الحساب | J7: مبلغ | L7: افزایش | N7: کاهش | P7: مبلغ | R7: درصد به کل دارایی‌ها | AA7: طی خرداد ماه
AA8: از ابتدای سال مالی تا پایان خرداد ماه
B9: حساب جاری بانک خاورمیانه مهستان | D9: حساب جاری | F9: 1393/04/25 | H9: 0 | J9: 50000000 | L9: 0 | N9: 0 | P9: 50000000 | R9: =P9/$R$19 -> 5.2786833e-06
B10: سپرده کوتاه مدت بانک خاورمیانه مهستان | D10: سپرده کوتاه مدت | F10: 1393/04/25 | H10: 0 | J10: 51046468 | L10: 202787 | N10: 0 | P10: 51249255 | R10: =P10/$R$19 -> 5.4105717e-06
B11: سپرده کوتاه مدت بانک گردشگری سعادت آباد | D11: سپرده کوتاه مدت | F11: 1402/06/19 | H11: 0 | J11: 40845741103 | L11: 337843597532 | N11: 164161350000 | P11: 214527988635 | R11: =P11/$R$19 -> 0.022648506
B12: سپرده کوتاه مدت بانک صادرات بلوار میرداماد | D12: سپرده کوتاه مدت | F12: 1404/08/01 | H12: 0 | J12: 1016539 | L12: 4178 | N12: 0 | P12: 1020717 | R12: =P12/$R$19 -> 1.0776083e-07
B13: سپرده کوتاه مدت بانک تجارت مطهری دریای نور | D13: سپرده کوتاه مدت | F13: 1404/08/01 | H13: 0 | J13: 402500 | L13: 0 | N13: 0 | P13: 402500 | R13: =P13/$R$19 -> 4.24934e-08
B14: حساب جاری بانک گردشگری سعادت آباد | D14: حساب جاری | F14: 1404/09/19 | H14: 0 | J14: 4990000 | L14: 0 | N14: 0 | P14: 4990000 | R14: =P14/$R$19 -> 5.2681259e-07
B15: سپرده کوتاه مدت بانک خاورمیانه نیاوران | D15: سپرده کوتاه مدت | F15: 1404/10/15 | H15: 0 | J15: 34956421 | L15: 1083298235971 | N15: 1082959775000 | P15: 373417392 | R15: =P15/$R$19 -> 3.9423043e-05
B16: جمع | J16: =SUM(J9:J15) -> 40988153031 | L16: =SUM(L9:L15) -> 1421142040468 | N16: =SUM(N9:N15) -> 1247121125000 | P16: =SUM(P9:P15) -> 215009068499 | R16: =SUM(R9:R15) -> 0.022699295
R19: 9472059129644
R58: 1783
R75: 2083

Sheet درآمدها
A1: صندوق سرمایه گذاری شاخص سی شرکت بزرگ فیروزه
A2: =سپرده!B2 -> صورت وضعیت پرتفوی
A3: =سپرده!B3 -> برای ماه منتهی به 1404/12/29
AC4: 1404/02/31
B5: شرح | D5: یادداشت | F5: مبلغ | H5: درصد از کل درآمدها | J5: درصد از کل دارایی ها | AC5: برای ماه منتهی به 1404/03/31
B6: درآمد حاصل از سرمایه گذاری در سهام و حق تقدم سهام | D6: 1-2 | F6: ='درآمد سرمایه گذاری در سهام '!T138 -> 3146274350526 | H6: =F6/$M$9 -> 0.96562967 | J6: =F6/M8 -> 0.33216372 | AC6: طی خرداد ماه
B7: سود اوراق بهادار با درآمد ثابت و سپرده بانکی | D7: 3-2 | F7: ='درآمد سپرده بانکی'!J13 -> 40104137325 | H7: =F7/$M$9 -> 0.012308445 | J7: =F7/M8 -> 0.0042339408
B8: سایر درآمد ها | D8: 4-2 | F8: ='سایر درآمدها'!F8 -> 4225972993 | H8: =F8/$M$9 -> 0.0012970023 | J8: =F8/M8 -> 0.00044615146 | M8: 9472059129644
B9: جمع | F9: =SUM(F6:F8) -> 3190604460844 | H9: =SUM(H6:H8) -> 0.97923512 | J9: =SUM(J6:J8) -> 0.33684381 | M9: 3258261873610
R57: 1783
R74: 2083

Sheet درآمد سرمایه گذاری در سهام 
B1: =درآمدها!A1 -> صندوق سرمایه گذاری شاخص سی شرکت بزرگ فیروزه
B2: صورت وضعیت درآمدها
B3: =' سهام'!AC6 -> برای ماه منتهی به 1404/12/29
AC4: 1404/02/31
B5: 1-2-درآمد حاصل از سرمایه گذاری در سهام و حق تقدم سهام: | AC5: 1404/03/31
AC6: برای ماه منتهی به 1404/03/31
D7: =' سهام'!AC7 -> طی اسفند ماه | N7: =' سهام'!AC8 -> از ابتدای سال مالی تا پایان اسفند ماه | AC7: طی خرداد ماه
B8: سهام | D8: درآمد سود سهام | F8: درآمد تغییر ارزش | H8: درآمد فروش | J8: جمع | N8: درآمد سود سهام | P8: درآمد تغییر ارزش | R8: درآمد فروش | T8: جمع | AC8: از ابتدای سال مالی تا پایان خرداد ماه
D10: یادداشت 2-1-1 | F10: یادداشت 2-1-2 | H10: یادداشت 2-1-3 | J10: مبلغ | L10: درصد از کل درآمد ها | N10: یادداشت 2-1-1 | P10: یادداشت 2-1-2 | R10: یادداشت 2-1-3 | T10: مبلغ | V10: درصد از کل درآمد ها
B11: ملی‌ صنایع‌ مس‌ ایران‌ | D11: 0 | F11: 7121831584 | H11: 11990308089 | J11: =H11+F11+D11 -> 19112139673 | L11: =J11/$X$12 -> 0.0034914938 | N11: 23680000000 | P11: 629692818414 | R11: 19871878477 | S11: -714562636 | T11: =N11+P11+R11 -> 673244696891 | U11: 11071728389 | V11: =T11/درآمدها!$F$9 -> 0.21100851
B12: صنایع پتروشیمی خلیج فارس | D12: 0 | F12: -47074885225 | H12: 18515121068 | J12: =H12+F12+D12 -> -28559764157 | L12: =J12/$X$12 -> -0.0052174295 | N12: 45900000000 | P12: 208789572336 | R12: 22196330575 | S12: -4741243411 | T12: =N12+P12+R12 -> 276885902911 | U12: 11071728390 | V12: =T12/درآمدها!$F$9 -> 0.086781645 | X12: 5473914764504
B13: پالایش نفت بندرعباس | D13: 0 | F13: -195861736417 | H13: 115612421016 | J13: =H13+F13+D13 -> -80249315401 | L13: =J13/$X$12 -> -0.014660315 | N13: 23077304640 | P13: 230975732765 | R13: 168022523573 | S13: -3385001208 | T13: =N13+P13+R13 -> 422075560978 | U13: 11071728391 | V13: =T13/درآمدها!$F$9 -> 0.13228702
B14: بانک ملت | D14: 0 | F14: -4718984285 | H14: -6569330274 | J14: =H14+F14+D14 -> -11288314559 | L14: =J14/$X$12 -> -0.0020622014 | N14: 3168000000 | P14: -50558368564 | R14: 14648159800 | S14: -2880009787 | T14: =N14+P14+R14 -> -32742208764 | U14: 11071728392 | V14: =T14/درآمدها!$F$9 -> -0.010262071
B15: کشتیرانی جمهوری اسلامی ایران | D15: 0 | F15: 11115777845 | H15: -8166726128 | J15: =H15+F15+D15 -> 2949051717 | L15: =J15/$X$12 -> 0.00053874637 | N15: 36750000000 | P15: -31356401587 | R15: -34502495456 | S15: -664891573 | T15: =N15+P15+R15 -> -29108897043 | U15: 11071728393 | V15: =T15/درآمدها!$F$9 -> -0.0091233174
B16: سرمایه گذاری صدرتامین | D16: 0 | F16: -2714234340 | H16: 1142723479 | J16: =H16+F16+D16 -> -1571510861 | L16: =J16/$X$12 -> -0.00028709085 | N16: 22000000000 | P16: 4954920944 | R16: -48838077114 | S16: -2538727106 | T16: =N16+P16+R16 -> -21883156170 | U16: 11071728394 | V16: =T16/درآمدها!$F$9 -> -0.0068586239
B17: فروشگاههای زنجیره ای افق کوروش | D17: 0 | F17: -22957017489 | H17: 15189904617 | J17: =H17+F17+D17 -> -7767112872 | L17: =J17/$X$12 -> -0.001418932 | N17: 1160000 | P17: 14066278296 | R17: 15402180994 | S17: -5759026841 | T17: =N17+P17+R17 -> 29469619290 | U17: 11071728395 | V17: =T17/درآمدها!$F$9 -> 0.009236375
B18: سایپا | D18: 0 | F18: -929691495 | H18: -754260380 | J18: =H18+F18+D18 -> -1683951875 | L18: =J18/$X$12 -> -0.0003076321 | N18: 0 | P18: -12250555707 | R18: -1292934009 | S18: -2808202366 | T18: =N18+P18+R18 -> -13543489716 | U18: 11071728392 | V18: =T18/درآمدها!$F$9 -> -0.0042448037
B19: گسترش نفت و گاز پارسیان | D19: 0 | F19: -13265469100 | H19: 5574942382 | J19: =H19+F19+D19 -> -7690526718 | L19: =J19/$X$12 -> -0.0014049409 | N19: 26100000000 | P19: 61824771540 | R19: 17940618053 | T19: =N19+P19+R19 -> 105865389593 | U19: 11071728393 | V19: =T19/درآمدها!$F$9 -> 0.033180355
B20: توسعه‌معادن‌وفلزات‌ | D20: 0 | F20: -13693086297 | H20: 8281055392 | J20: =H20+F20+D20 -> -5412030905 | L20: =J20/$X$12 -> -0.00098869477 | N20: 2626384230 | P20: 30019579 | R20: 68505149451 | S20: 8828197833 | T20: =N20+P20+R20 -> 71161553260 | U20: 11071728394 | V20: =T20/درآمدها!$F$9 -> 0.022303471
B21: کارخانجات تولیدی نیروترانسفو | D21: 0 | F21: -1481233999 | H21: 831302920 | J21: =H21+F21+D21 -> -649931079 | L21: =J21/$X$12 -> -0.00011873241 | N21: 0 | P21: 498886690 | R21: 831302920 | S21: -40082741567 | T21: =N21+P21+R21 -> 1330189610 | U21: 11071728395 | V21: =T21/درآمدها!$F$9 -> 0.00041690834
B22: سرمایه‌گذاری‌صندوق‌بازنشستگی‌ | D22: 0 | F22: 6519697841 | H22: -23225868997 | J22: =H22+F22+D22 -> -16706171156 | L22: =J22/$X$12 -> -0.0030519604 | N22: 33460000000 | P22: -76580131068 | R22: -57791373786 | S22: 466959920 | T22: =N22+P22+R22 -> -100911504854 | U22: 11071728396 | V22: =T22/درآمدها!$F$9 -> -0.031627708
B23: سرمایه‌ گذاری‌ آتیه‌ دماوند | D23: 0 | F23: -2911833008 | H23: 88536260 | J23: =H23+F23+D23 -> -2823296748 | L23: =J23/$X$12 -> -0.00051577287 | N23: 0 | P23: 9261423403 | R23: 8129586581 | S23: -102059379029 | T23: =N23+P23+R23 -> 17391009984 | U23: 11071728398 | V23: =T23/درآمدها!$F$9 -> 0.0054506944
B24: مبین انرژی خلیج فارس | D24: 0 | F24: -6159314136 | H24: 2591693351 | J24: =H24+F24+D24 -> -3567620785 | L24: =J24/$X$12 -> -0.00065174942 | N24: 22230000000 | P24: 29939728467 | R24: 76947894058 | S24: -11597631470 | T24: =N24+P24+R24 -> 129117622525 | U24: 11071728399 | V24: =T24/درآمدها!$F$9 -> 0.040468076
B25: آلومینیوم‌ایران‌ | D25: 0 | F25: -4636387841 | H25: -450935523 | J25: =H25+F25+D25 -> -5087323364 | L25: =J25/$X$12 -> -0.0009293757 | N25: 0 | P25: -10129276701 | R25: -771626388 | S25: 52167321915 | T25: =N25+P25+R25 -> -10900903089 | U25: 11071728400 | V25: =T25/درآمدها!$F$9 -> -0.0034165636
B26: سرمایه گذاری تامین اجتماعی | D26: 0 | F26: -3244750775 | H26: 282727870 | J26: =H26+F26+D26 -> -2962022905 | L26: =J26/$X$12 -> -0.00054111601 | N26: 62700000000 | P26: 12086239076 | R26: -23107113555 | S26: -6964477628 | T26: =N26+P26+R26 -> 51679125521 | U26: 11071728401 | V26: =T26/درآمدها!$F$9 -> 0.016197284
B27: کشت و دام گلدشت نمونه اصفهان | D27: 0 | F27: 0 | H27: 0 | J27: =H27+F27+D27 -> 0 | L27: =J27/$X$12 -> 0 | N27: 5600000000 | P27: 0 | R27: 600423215 | S27: -13571699443 | T27: =N27+P27+R27 -> 6200423215 | U27: 11071728402 | V27: =T27/درآمدها!$F$9 -> 0.0019433381
B28: اخشان خراسان | D28: 0 | F28: 0 | H28: 0 | J28: =H28+F28+D28 -> 0 | L28: =J28/$X$12 -> 0 | N28: 0 | P28: 0 | R28: 257545772 | S28: 257545772 | T28: =N28+P28+R28 -> 257545772 | U28: 11071728398 | V28: =T28/درآمدها!$F$9 -> 8.0720056e-05
B29: سرمایه گذاری توسعه گوهران امید | D29: 0 | F29: 0 | H29: 0 | J29: =H29+F29+D29 -> 0 | L29: =J29/$X$12 -> 0 | N29: 0 | P29: 0 | R29: -9111320 | S29: 1026553445 | T29: =N29+P29+R29 -> -9111320 | U29: 11071728399 | V29: =T29/درآمدها!$F$9 -> -2.8556721e-06
B30: گروه مپنا (سهامی عام) | D30: 0 | F30: -238144 | H30: 0 | J30: =H30+F30+D30 -> -238144 | L30: =J30/$X$12 -> -4.3505244e-08 | N30: 620000 | P30: -4023937 | R30: -4741243411 | S30: -1161777565 | T30: =N30+P30+R30 -> -4744647348 | U30: -5155830316 | V30: =T30/درآمدها!$F$9 -> -0.0014870685
B31: پالایش نفت تهران | D31: 0 | F31: -12250518271 | H31: 0 | J31: =H31+F31+D31 -> -12250518271 | L31: =J31/$X$12 -> -0.0022379812 | N31: 10640000000 | P31: 7174739266 | R31: -1377096352 | S31: 599022178 | T31: =N31+P31+R31 -> 16437642914 | U31: -5155830315 | V31: =T31/درآمدها!$F$9 -> 0.0051518899
... B33: ح . معدنی و صنعتی گل گهر | D33: 0 | F33: 0 | H33: 0 | J33: =H33+F33+D33 -> 0 | L33: =J33/$X$12 -> 0 | N33: 0 | P33: 0 | R33: -2044819416 | S33: 28553005 | T33: =N33+P33+R33 -> -2044819416 | U33: -5155830313 | V33: =T33/درآمدها!$F$9 -> -0.00064088778
B34: شهد ایران ‌ | D34: 0 | F34: 0 | H34: 0 | J34: =H34+F34+D34 -> 0 | L34: =J34/$X$12 -> 0 | N34: 2400000000 | P34: 0 | R34: -6440726392 | T34: =N34+P34+R34 -> -4040726392 | V34: =T34/درآمدها!$F$9 -> -0.0012664454
B35: سرمایه‌گذاری‌غدیر(هلدینگ‌ | D35: 60000000000 | F35: -56360936000 | H35: 0 | J35: =H35+F35+D35 -> 3639064000 | L35: =J35/$X$12 -> 0.000664801 | N35: 60000000000 | P35: 142589097255 | R35: 6416000523 | T35: =N35+P35+R35 -> 209005097778 | V35: =T35/درآمدها!$F$9 -> 0.065506427
B36: کشت وصنعت و دامپروری پگاه فارس | D36: 0 | F36: -389366748 | H36: 0 | J36: =H36+F36+D36 -> -389366748 | L36: =J36/$X$12 -> -7.1131314e-05 | N36: 0 | P36: 244492377 | R36: 1176011000 | T36: =N36+P36+R36 -> 1420503377 | V36: =T36/درآمدها!$F$9 -> 0.0004452145
B37: گروه مالی نماد غدیر(سهامی عام) | D37: 0 | F37: 0 | H37: 0 | J37: =H37+F37+D37 -> 0 | L37: =J37/$X$12 -> 0 | N37: 0 | P37: 0 | R37: 506290 | T37: =N37+P37+R37 -> 506290 | V37: =T37/درآمدها!$F$9 -> 1.5868153e-07
B38: سیمان‌ تهران‌ | D38: 0 | F38: 0 | H38: 0 | J38: =H38+F38+D38 -> 0 | L38: =J38/$X$12 -> 0 | N38: 0 | P38: 0 | R38: 24578982239 | T38: =N38+P38+R38 -> 24578982239 | V38: =T38/درآمدها!$F$9 -> 0.0077035504
B39: نیان باتری خاوران | D39: 0 | F39: -247844239 | H39: 0 | J39: =H39+F39+D39 -> -247844239 | L39: =J39/$X$12 -> -4.5277329e-05 | N39: 0 | P39: -315176170 | R39: 1295097720 | T39: =N39+P39+R39 -> 979921550 | V39: =T39/درآمدها!$F$9 -> 0.00030712724
B40: فولاد مبارکه اصفهان | D40: 0 | F40: -30760370 | H40: 0 | J40: =H40+F40+D40 -> -30760370 | L40: =J40/$X$12 -> -5.6194463e-06 | N40: 5600000000 | P40: -1516077837 | R40: 71201598286 | T40: =N40+P40+R40 -> 75285520449 | V40: =T40/درآمدها!$F$9 -> 0.023596006
B41: کانی کربن طبس | D41: 0 | F41: 0 | H41: 0 | J41: =H41+F41+D41 -> 0 | L41: =J41/$X$12 -> 0 | N41: 0 | P41: 0 | R41: 273616390 | T41: =N41+P41+R41 -> 273616390 | V41: =T41/درآمدها!$F$9 -> 8.5756913e-05 | X41: =L41/$X$12 -> 0
B42: س. نفت و گاز و پتروشیمی تأمین | D42: 0 | F42: -3472945000 | H42: 0 | J42: =H42+F42+D42 -> -3472945000 | L42: =J42/$X$12 -> -0.00063445361 | N42: 7600000000 | P42: -3303566903 | R42: -1160756855 | T42: =N42+P42+R42 -> 3135676242 | V42: =T42/درآمدها!$F$9 -> 0.00098278438
...

Sheet درآمد سود سهام
B1: =درآمدها!A1 -> صندوق سرمایه گذاری شاخص سی شرکت بزرگ فیروزه
B2: صورت وضعیت درآمدها
B3: =' سهام'!AC6 -> برای ماه منتهی به 1404/12/29
B4: 1-1-2-درآمد سود سهام | AG4: 1404/05/31
D5: اطلاعات مجمع | J5: =' سهام'!AC7 -> طی اسفند ماه | P5: =' سهام'!AC8 -> از ابتدای سال مالی تا پایان اسفند ماه | AE5: 1404/06/31
B6: نام سهام | D6: تاریخ مجمع | F6: تعداد سهام متعلقه در زمان مجمع | H6: سود متعلق به هر سهم | J6: جمع درآمد سود سهام | L6: هزینه تنزیل | N6: خالص درآمد سود سهام | P6: جمع درآمد سود سهام | R6: هزینه تنزیل | T6: خالص درآمد سود سهام | AC6: برای ماه منتهی به 1404/06/31
B7: گروه س توسعه صنعتی ایران | D7: 1404/09/17 | F7: 60000000 | H7: 330 | J7: 0 | L7: 0 | N7: 0 | P7: 19800000000 | R7: 0 | T7: =P7+R7 -> 19800000000
B8: بانک‌اقتصادنوین‌ | D8: 1404/04/22 | F8: 36000000 | H8: 240 | J8: 0 | L8: 0 | N8: 0 | P8: 8640000000 | R8: 0 | T8: =P8+R8 -> 8640000000
B9: گروه مپنا (سهامی عام) | D9: 1404/07/20 | F9: 1000 | H9: 620 | J9: 0 | L9: 0 | N9: 0 | P9: 620000 | R9: 0 | T9: =P9+R9 -> 620000
B10: سرمایه‌گذاری‌صندوق‌بازنشستگی‌ | D10: 1404/05/12 | F10: 14000000 | H10: 2390 | J10: 0 | L10: 0 | N10: 0 | P10: 33460000000 | R10: 0 | T10: =P10+R10 -> 33460000000
B11: سرمایه‌گذاری‌غدیر(هلدینگ‌ | D11: 1404/12/10 | F11: 40000000 | H11: 1500 | J11: 60000000000 | L11: 0 | N11: 60000000000 | P11: 60000000000 | R11: 0 | T11: =P11+R11 -> 60000000000
B12: ملی‌ صنایع‌ مس‌ ایران‌ | D12: 1404/04/31 | F12: 64000000 | H12: 370 | J12: 0 | L12: 0 | N12: 0 | P12: 23680000000 | R12: 0 | T12: =P12+R12 -> 23680000000
B13: سرمایه‌گذاری‌نیرو | D13: 1404/04/31 | F13: 10000000 | H13: 48 | J13: 0 | L13: 0 | N13: 0 | P13: 480000000 | R13: 0 | T13: =P13+R13 -> 480000000
B14: گروه مدیریت سرمایه گذاری امید | D14: 1404/02/30 | F14: 1000 | H14: 2320 | J14: 0 | L14: 0 | N14: 0 | P14: 2320000 | R14: 0 | T14: =P14+R14 -> 2320000
B15: کشتیرانی جمهوری اسلامی ایران | D15: 1404/07/15 | F15: 35000000 | H15: 1050 | J15: 0 | L15: 0 | N15: 0 | P15: 36750000000 | R15: 0 | T15: =P15+R15 -> 36750000000
B16: توسعه‌معادن‌وفلزات‌ | D16: 1404/04/29 | F16: 15449319 | H16: 170 | J16: 0 | L16: 0 | N16: 0 | P16: 2626384230 | R16: 0 | T16: =P16+R16 -> 2626384230
B17: پتروشیمی‌شیراز | D17: 1404/05/11 | F17: 6500000 | H17: 4984 | J17: 0 | L17: 0 | N17: 0 | P17: 32396000000 | R17: 0 | T17: =P17+R17 -> 32396000000 | AD17: 1
B18: پالایش نفت تبریز | D18: 1404/04/28 | F18: 9000000 | H18: 1997 | J18: 0 | L18: 0 | N18: 0 | P18: 17973000000 | R18: 0 | T18: =P18+R18 -> 17973000000
B19: پالایش نفت اصفهان | D19: 1404/04/30 | F19: 151800000 | H19: 360 | J19: 0 | L19: 0 | N19: 0 | P19: 54648000000 | R19: 0 | T19: =P19+R19 -> 54648000000
B20: معدنی‌وصنعتی‌چادرملو | D20: 1404/04/23 | F20: 13383580 | H20: 380 | J20: 0 | L20: 0 | N20: 0 | P20: 3040000000 | R20: 0 | T20: =P20+R20 -> 3040000000
B21: معدنی و صنعتی گل گهر | D21: 1404/04/23 | F21: 5600000 | H21: 310 | J21: 0 | L21: 0 | N21: 0 | P21: 1736000000 | R21: 0 | T21: =P21+R21 -> 1736000000
B22: شهد ایران ‌ | D22: 1404/04/28 | F22: 6000000 | H22: 400 | J22: 0 | L22: 0 | N22: 0 | P22: 2400000000 | R22: 0 | T22: =P22+R22 -> 2400000000
B23: فولاد مبارکه اصفهان | D23: 1404/05/13 | F23: 20000000 | H23: 280 | J23: 0 | L23: 0 | N23: 0 | P23: 5600000000 | R23: 0 | T23: =P23+R23 -> 5600000000
B24: بانک ملت | D24: 1404/04/31 | F24: 35200000 | H24: 90 | J24: 0 | L24: 0 | N24: 0 | P24: 3168000000 | R24: 0 | T24: =P24+R24 -> 3168000000
B25: بانک تجارت | D25: 1404/04/31 | F25: 1000 | H25: 11 | J25: 0 | L25: 0 | N25: 0 | P25: 11000 | R25: 0 | T25: =P25+R25 -> 11000
B26: بانک صادرات ایران | D26: 1404/04/31 | F26: 100000000 | H26: 15 | J26: 0 | L26: 0 | N26: 0 | P26: 1500000000 | R26: 0 | T26: =P26+R26 -> 1500000000
B27: پالایش نفت بندرعباس | D27: 1404/05/08 | F27: 24655240 | H27: 936 | J27: 0 | L27: 0 | N27: 0 | P27: 23077304640 | R27: 0 | T27: =P27+R27 -> 23077304640
B28: گسترش نفت و گاز پارسیان | D28: 1404/10/23 | F28: 3000000 | H28: 8700 | J28: 0 | L28: 0 | N28: 0 | P28: 26100000000 | R28: 0 | T28: =P28+R28 -> 26100000000
B29: پتروشیمی پردیس | D29: 1404/09/22 | F29: 1800000 | H29: 11000 | J29: 0 | L29: 0 | N29: 0 | P29: 19800000000 | R29: 0 | T29: =P29+R29 -> 19800000000
... B56: سرمایه گذاری پایا تدبیرپارسا | D56: 1404/08/18 | F56: 3250000 | H56: 170 | J56: 0 | L56: 0 | N56: 0 | P56: 552500000 | R56: 0 | T56: =P56+R56 -> 552500000
B57: جمع | F57: =SUM(F7:F56) -> 1333663554 | J57: =SUM(J7:J56) -> 60000000000 | L57: =SUM(L7:L56) -> 0 | N57: =SUM(N7:N56) -> 60000000000 | P57: =SUM(P7:P56) -> 703671705503 | R57: =SUM(R7:R56) -> -12127 | T57: =SUM(T7:T56) -> 703671693376 | AB57: از ابتدای سال مالی تا پایان مهر ماه

Sheet درآمد ناشی از تغییر قیمت اوراق 
B1: ='درآمد ناشی ازفروش'!B1:R1 -> صندوق سرمایه گذاری شاخص سی شرکت بزرگ فیروزه
B2: صورت وضعیت درآمدها
B3: =' سهام'!AC6 -> برای ماه منتهی به 1404/12/29
B4: 2-1-2-درآمد ناشی از تغییر قیمت اوراق بهادار | AB4: 1404/02/31
D5: =' سهام'!AC7 -> طی اسفند ماه | L5: =' سهام'!AC8 -> از ابتدای سال مالی تا پایان اسفند ماه | AB5: 1404/03/31
B6: شرح | D6: تعداد | F6: خالص ارزش فروش | H6: ارزش دفتری | J6: سود و زیان ناشی از تغییر قیمت | L6: تعداد | N6: خالص ارزش فروش | P6: ارزش دفتری | R6: سود و زیان ناشی از تغییر قیمت | AB6: برای ماه منتهی به 1404/03/31
B7: پتروشیمی جم | D7: 100000 | F7: 4346142600 | H7: -4645808140 | J7: -299665540 | L7: 100000 | N7: 4346142600 | P7: -5636945479 | R7: -1290802879 | AB7: طی خرداد ماه
B8: مخابرات ایران | D8: 1000 | F8: 419730 | H8: -400877 | J8: 18853 | L8: 1000 | N8: 419730 | P8: -483356 | R8: -63625 | AB8: از ابتدای سال مالی تا پایان خرداد ماه
B9: سرمایه‌گذاری‌صندوق‌بازنشستگی‌ | D9: 14000000 | F9: 236021342200 | H9: -229501644358 | J9: 6519697841 | L9: 14000000 | N9: 236021342200 | P9: -312601473268 | R9: -76580131068
B10: سرمایه گذاری خوارزمی | D10: 99982360 | F10: 290187776844 | H10: -302886592378 | J10: -12698815533 | L10: 99982360 | N10: 290187776844 | P10: -371522240327 | R10: -81334463482
B11: سرمایه گذاری سبحان | D11: 96000000 | F11: 150126481920 | H11: -152793703680 | J11: -2667221760 | L11: 96000000 | N11: 150126481920 | P11: -136919972432 | R11: 13206509487
B12: پتروشیمی نوری | D12: 2000000 | F12: 90495024000 | H12: -91566675600 | J12: -1071651600 | L12: 2000000 | N12: 90495024000 | P12: -87540671134 | R12: 2954352865
B13: بانک‌اقتصادنوین‌ | D13: 58000000 | F13: 116484559840 | H13: -112916356920 | J13: 3568202919 | L13: 58000000 | N13: 116484559840 | P13: -93098147252 | R13: 23386412588
B14: معدنی‌وصنعتی‌چادرملو | D14: 1000 | F14: 2465790 | H14: -2496551 | J14: -30760 | L14: 1000 | N14: 2465790 | P14: -2656100 | R14: -190309
B15: پتروشیمی پردیس | D15: 50607435 | F15: 654418033521 | H15: -678165939230 | J15: -23747905708 | L15: 50607435 | N15: 654418033521 | P15: -483153100152 | R15: 171264933369
B16: بین المللی توسعه ص. معادن غدیر | D16: 1000 | F16: 2745611 | H16: -2808124 | J16: -62512 | L16: 1000 | N16: 2745611 | P16: -3874804 | R16: -1129192
B17: تایدواترخاورمیانه | D17: 25882353 | F17: 158177177371 | H17: -162533826000 | J17: -4356648628 | L17: 25882353 | N17: 158177177371 | P17: -198421146000 | R17: -40243968628
B18: کیمیا کالای رازی | D18: 133750 | F18: 5023304858 | H18: -5122841942 | J18: -99537083 | L18: 133750 | N18: 5023304858 | P18: -3787614251 | R18: 1235690607
B19: پتروشیمی خراسان | D19: 335212 | F19: 11894520209 | H19: -12990173162 | J19: -1095652952 | L19: 335212 | N19: 11894520209 | P19: -12087758820 | R19: -193238610
B20: آلیاژ گستر هامون | D20: 837500 | F20: 3451251497 | H20: -3712193700 | J20: -260942202 | L20: 837500 | N20: 3451251497 | P20: -3566757144 | R20: -115505646
... B37: مبین انرژی خلیج فارس | D37: 10000000 | F37: 147451322000 | H37: -153610636136 | J37: -6159314136 | L37: 10000000 | N37: 147451322000 | P37: -117511593532 | R37: 29939728467
B38: نقل به صفحه بعد | D38: =SUM(D7:D37) -> 1907600457 | F38: =SUM(F7:F37) -> 4715286110930 | H38: =SUM(H7:H37) -> -4796849519958 | J38: =SUM(J7:J37) -> -81563409019 | L38: =SUM(L7:L37) -> 1907600457 | N38: =SUM(N7:N37) -> 4715286110930 | P38: =SUM(P7:P37) -> -4334371698543 | R38: =SUM(R7:R37) -> 380914412393
B40: 2-1-2-درآمد ناشی از تغییر قیمت اوراق بهادار | Z40: 1404/02/31
D41: =D5 -> طی اسفند ماه | L41: =L5 -> از ابتدای سال مالی تا پایان اسفند ماه | Z41: 1404/03/31
B42: شرح | D42: تعداد | F42: خالص ارزش فروش | H42: ارزش دفتری | J42: سود و زیان ناشی از تغییر قیمت | L42: تعداد | N42: خالص ارزش فروش | P42: ارزش دفتری | R42: سود و زیان ناشی از تغییر قیمت | Z42: برای ماه منتهی به 1404/03/31
B43: نقل از صفحه قبل | D43: =D38 -> 1907600457 | F43: =F38 -> 4715286110930 | H43: =H38 -> -4796849519958 | J43: =J38 -> -81563409019 | L43: =L38 -> 1907600457 | N43: =N38 -> 4715286110930 | P43: =P38 -> -4334371698543 | R43: =R38 -> 380914412393
B44: گروه صنعتی درپاد تبریز | D44: 375000 | F44: 3657755287 | H44: -4119160837 | J44: -461405549 | L44: 375000 | N44: 3657755287 | P44: -3137744212 | R44: 520011075
B45: پتروشیمی پارس | D45: 1000 | F45: 2718819 | H45: -2798201 | J45: -79381 | L45: 1000 | N45: 2718819 | P45: -3590334 | R45: -871514
B46: توسعه‌معادن‌وفلزات‌ | D46: 211248 | F46: 429501243 | H46: -14122587541 | J46: -13693086297 | L46: 211248 | N46: 429501243 | P46: -399481664 | R46: 30019579
B47: کارخانجات تولیدی نیروترانسفو | D47: 750000 | F47: 6556424025 | H47: -8037658024 | J47: -1481233999 | L47: 750000 | N47: 6556424025 | P47: -6057537334 | R47: 498886690
B48: گروه س توسعه صنعتی ایران | D48: 60000000 | F48: 86625171000 | H48: -90554560200 | J48: -3929389200 | L48: 60000000 | N48: 86625171000 | P48: -98042294767 | R48: -11417123767
B49: فروشگاههای زنجیره ای افق کوروش | D49: 2000000 | F49: 64477704600 | H49: -87434722089 | J49: -22957017489 | L49: 2000000 | N49: 64477704600 | P49: -50411426304 | R49: 14066278296
B50: بانک پاسارگاد | D50: 1000 | F50: 5586480 | H50: -5070499 | J50: 515981 | L50: 1000 | N50: 5586480 | P50: -1846946 | R50: 3739534
B51: سایپا | D51: 150000000 | F51: 75015612000 | H51: -75945303495 | J51: -929691495 | L51: 150000000 | N51: 75015612000 | P51: -87266167707 | R51: -12250555707
B52: گروه مپنا (سهامی عام) | D52: 1000 | F52: 12413297 | H52: -12651442 | J52: -238144 | L52: 1000 | N52: 12413297 | P52: -16437235 | R52: -4023937
B53: ح . سرمایه گذاری صدرتامین | D53: 2488889 | F53: 22046564550 | H53: -19970845336 | J53: 2075719214 | L53: 2488889 | N53: 22046564550 | P53: -19970845336 | R53: 2075719214
B54: پالایش نفت تهران | D54: 84661723 | F54: 259750534128 | H54: -272001052400 | J54: -12250518271 | L54: 84661723 | N54: 259750534128 | P54: -252575794862 | R54: 7174739266
B55: س. و توسعه صنایع لاستیک | D55: 562500 | F55: 4632660562 | H55: -4906154981 | J55: -273494418 | L55: 562500 | N55: 4632660562 | P55: -4998586413 | R55: -365925850
... B66: تولیدی کوچین | D66: 1475169 | F66: 10269781860 | H66: -10269781860 | J66: 0 | L66: 1475169 | N66: 10269781860 | P66: -6782788386 | R66: 3486993470
B67: جمع | D67: =SUM(D43:D66) -> 2650647268 | F67: =SUM(F43:F66) -> 9256398187042 | H67: =SUM(H43:H66) -> -9695322589949 | J67: =SUM(J43:J66) -> -438924402907 | L67: =SUM(L43:L66) -> 2650647268 | N67: =SUM(N43:N66) -> 9256398187042 | P67: =SUM(P43:P66) -> -7687998357220 | R67: =SUM(R43:R66) -> 1568399829822
...

Sheet درآمد ناشی ازفروش
B1: ='سود اوراق بهادار و سپرده بانکی'!B1:U1 -> صندوق سرمایه گذاری شاخص سی شرکت بزرگ فیروزه
B2: صورت وضعیت درآمدها
B3: =' سهام'!B3:Z3 -> برای ماه منتهی به 1404/12/29
B4: 3-1-2-سود(زیان) حاصل از فروش اوراق بهادار | AC4: 1404/04/31
D5: =' سهام'!AC7 -> طی اسفند ماه | L5: =' سهام'!AC8 -> از ابتدای سال مالی تا پایان اسفند ماه | AC5: 1404/05/31
B6: شرح | D6: تعداد | F6: خالص بهای فروش | H6: ارزش دفتری | J6: سود و زیان ناشی از فروش | L6: تعداد | N6: خالص ارزش فروش | P6: ارزش دفتری | R6: سود و زیان ناشی از فروش | Z6: برای ماه منتهی به 1404/05/31
B7: ملی‌ صنایع‌ مس‌ ایران‌ | D7: 3000000 | F7: 38461404674 | H7: -26471096585 | J7: 11990308089 | L7: 17591474 | N7: 150801587174 | P7: -130929708697 | R7: 19871878477 | Z7: طی مرداد ماه
B8: صنایع پتروشیمی خلیج فارس | D8: 8000000 | F8: 80986843843 | H8: -62471722775 | J8: 18515121068 | L8: 23913454 | N8: 206336365887 | P8: -184140035312 | R8: 22196330575 | Z8: از ابتدای سال مالی تا پایان مرداد ماه
B9: پالایش نفت بندرعباس | D9: 45000000 | F9: 310010475599 | H9: -194398054583 | J9: 115612421016 | L9: 65302565 | N9: 469513545378 | P9: -301491021805 | R9: 168022523573
B10: بانک ملت | D10: 50000000 | F10: 59614787916 | H10: -66184118190 | J10: -6569330274 | L10: 161995581 | N10: 266134677584 | P10: -251486517784 | R10: 14648159800
B11: کشتیرانی جمهوری اسلامی ایران | D11: 4000000 | F11: 21623573118 | H11: -29790299246 | J11: -8166726128 | L11: 30369697 | N11: 198201686378 | P11: -232704181834 | R11: -34502495456
B12: سرمایه گذاری صدرتامین | D12: 3000000 | F12: 38880071391 | H12: -37737347912 | J12: 1142723479 | L12: 26265446 | N12: 289948275134 | P12: -338786352248 | R12: -48838077114
B13: فروشگاههای زنجیره ای افق کوروش | D13: 2000000 | F13: 65601330928 | H13: -50411426311 | J13: 15189904617 | L13: 2309853 | N13: 73623673142 | P13: -58221492148 | R13: 15402180994
B14: سایپا | D14: 10000000 | F14: 5063484125 | H14: -5817744505 | J14: -754260380 | L14: 187231921 | N14: 78787363715 | P14: -80080297724 | R14: -1292934009
B15: گسترش نفت و گاز پارسیان | D15: 700000 | F15: 18926123762 | H15: -13351181380 | J15: 5574942382 | L15: 4115456 | N15: 215158859668 | P15: -197218241615 | R15: 17940618053
B16: توسعه‌معادن‌وفلزات‌ | D16: 56188752 | F16: 114537092079 | H16: -106256036687 | J16: 8281055392 | L16: 284784130 | N16: 595959663752 | P16: -527454514301 | R16: 68505149451
B17: کارخانجات تولیدی نیروترانسفو | D17: 750000 | F17: 6888840246 | H17: -6057537326 | J17: 831302920 | L17: 750000 | N17: 6888840246 | P17: -6057537326 | R17: 831302920
B18: سرمایه‌گذاری‌صندوق‌بازنشستگی‌ | D18: 4000000 | F18: 66088837645 | H18: -89314706642 | J18: -23225868997 | L18: 8802865 | N18: 145691598728 | P18: -203482972514 | R18: -57791373786
B19: سرمایه‌ گذاری‌ آتیه‌ دماوند | D19: 1000000 | F19: 4145415462 | H19: -4056879202 | J19: 88536260 | L19: 9254855 | N19: 45576707212 | P19: -37447120631 | R19: 8129586581
B20: مبین انرژی خلیج فارس | D20: 1000000 | F20: 14342852715 | H20: -11751159364 | J20: 2591693351 | L20: 23700000 | N20: 303271141095 | P20: -226323247037 | R20: 76947894058
... B58: سیمان‌ شرق‌ | D58: 0 | F58: 0 | H58: 0 | J58: 0 | L58: 10177909 | N58: 151231461978 | P58: -126328323943 | R58: 24903138035
B59: نقل به صفحه بعد | D59: =SUM(D7:D58) -> 209238752 | F59: =SUM(F7:F58) -> 880416511874 | H59: =SUM(H7:H58) -> -739482896732 | J59: =SUM(J7:J58) -> 140933615142 | L59: =SUM(L7:L58) -> 1914110472 | N59: =SUM(N7:N58) -> 6075272510280 | P59: =SUM(P7:P58) -> -5718828720283 | R59: =SUM(R7:R58) -> 356443789997
B61: 3-1-2-سود(زیان) حاصل از فروش اوراق بهادار | Z61: 1404/02/31
D62: =D5 -> طی اسفند ماه | L62: =L5 -> از ابتدای سال مالی تا پایان اسفند ماه | Z62: 1404/03/31
B63: شرح | D63: تعداد | F63: خالص بهای فروش | H63: ارزش دفتری | J63: سود و زیان ناشی از فروش | L63: تعداد | N63: خالص ارزش فروش | P63: ارزش دفتری | R63: سود و زیان ناشی از فروش | X63: برای ماه منتهی به 1404/03/31
B64: نقل از صفحه قبل | D64: =D59 -> 209238752 | F64: =F59 -> 880416511874 | H64: =H59 -> -739482896732 | J64: =J59 -> 140933615142 | L64: =L59 -> 1914110472 | N64: =N59 -> 6075272510280 | P64: =P59 -> -5718828720283 | R64: =R59 -> 356443789997
B65: گسترش‌سرمایه‌گذاری‌ایران‌خودرو | D65: 0 | F65: 0 | H65: 0 | J65: 0 | L65: 15571100 | N65: 91315510092 | P65: -95651473345 | R65: -4335963253
B66: ح.سرمایه گذاری خوارزمی | D66: 0 | F66: 0 | H66: 0 | J66: 0 | L66: 14973541 | N66: 31073136051 | P66: -41851047095 | R66: -10777911044
B67: مدیریت نیروگاهی ایرانیان مپنا | D67: 0 | F67: 0 | H67: 0 | J67: 0 | L67: 800000 | N67: 14710482899 | P67: -10680073200 | R67: 4030409699
B68: بانک پاسارگاد | D68: 0 | F68: 0 | H68: 0 | J68: 0 | L68: 144364 | N68: 363956344 | P68: -266632352 | R68: 97323992
B69: س. صنایع‌شیمیایی‌ایران | D69: 0 | F69: 0 | H69: 0 | J69: 0 | L69: 29167090 | N69: 169466517260 | P69: -140253073100 | R69: 29213444160
B70: سرمایه‌گذاری‌نیرو | D70: 0 | F70: 0 | H70: 0 | J70: 0 | L70: 10000000 | N70: 38860864777 | P70: -56454832765 | R70: -17593967988
B71: صنایع پتروشیمی کرمانشاه | D71: 0 | F71: 0 | H71: 0 | J71: 0 | L71: 100000 | N71: 4115321807 | P71: -3787915314 | R71: 327406493
B72: شیر و گوشت زاگرس شهرکرد | D72: 0 | F72: 0 | H72: 0 | J72: 0 | L72: 9100000 | N72: 123917346802 | P72: -132769794012 | R72: -8852447210
B73: توسعه معادن وص.معدنی خاورمیانه | D73: 0 | F73: 0 | H73: 0 | J73: 0 | L73: 364998 | N73: 1669452833 | P73: -1779995754 | R73: -110542921
B74: ایران‌ ترانسفو | D74: 0 | F74: 0 | H74: 0 | J74: 0 | L74: 14000000 | N74: 49376310474 | P74: -46226459745 | R74: 3149850729
B75: توسعه ساختمان سپهر تهران | D75: 0 | F75: 0 | H75: 0 | J75: 0 | L75: 866 | N75: 2950834 | P75: -2892418 | R75: 58416
B76: تولیدی برنا باطری | D76: 0 | F76: 0 | H76: 0 | J76: 0 | L76: 1000000 | N76: 7418294945 | P76: -6391741500 | R76: 1026553445
... B118: پتروشیمی‌شیراز | D118: 0 | F118: 0 | H118: 0 | J118: 0 | L118: 705319 | N118: 22304178782 | P118: -26078961990 | R118: -3774783208
B119: جمع | D119: =SUM(D64:D118) -> 209238752 | F119: =SUM(F64:F118) -> 880416511874 | H119: =SUM(H64:H118) -> -739482896732 | J119: =SUM(J64:J118) -> 140933615142 | L119: =SUM(L64:L118) -> 2864794413 | N119: =SUM(N64:N118) -> 11014154949193 | P119: =SUM(P64:P118) -> -10139952121864 | R119: =SUM(R64:R118) -> 874202827328

Sheet درآمد سرمایه گذاری در اوراق بها
A1: صندوق سرمایه‌گذاری صندوق شاخص سی شرکت بزرگ فیروزه
A2: صورت وضعیت درآمدها
A3: =' سهام'!AC6 -> برای ماه منتهی به 1404/12/29
B4: 2-2-درآمد حاصل از سرمایه گذاری در اوراق بهادار با درآمد ثابت:
C6: =' سهام'!AC7 -> طی اسفند ماه | M6: =' سهام'!AC8 -> از ابتدای سال مالی تا پایان اسفند ماه
C7: درآمد سود اوراق | E7: درآمد تغییر ارزش | G7: درآمد فروش | I7: جمع | M7: درآمد سود اوراق | O7: درآمد تغییر ارزش | Q7: درآمد فروش | R7: جمع
C9: یادداشت 2-2-1 | E9: یادداشت 2-1-2 | G9: یادداشت 3-1-2 | I9: مبلغ | K9: درصد از کل دارائیها | M9: یادداشت 2-2-1 | O9: یادداشت 2-1-2 | Q9: یادداشت 3-1-2 | R9: مبلغ | S9: درصد از کل دارائیها
B10: - | C10: 0 | D10: 0 | E10: 0 | F10: 0 | G10: 0 | H10: 0 | I10: 0 | J10: 0 | K10: 0 | L10: 0 | M10: 0 | N10: 0 | O10: 0 | P10: 875280 | Q10: 0 | R10: 0 | S10: =R10/S14 -> 0
B11: جمع | C11: =SUM(C10:C10) -> 0 | E11: =SUM(E10:E10) -> 0 | G11: =SUM(G10:G10) -> 0 | I11: =SUM(I10:I10) -> 0 | K11: =SUM(K10:K10) -> 0 | M11: =SUM(M10:M10) -> 0 | O11: =SUM(O10:O10) -> 0 | Q11: =SUM(Q10:Q10) -> 0 | R11: =SUM(R10:R10) -> 0 | S11: =SUM(S10:S10) -> 0
K14: 2807555599778 | S14: 2807555599778

Sheet سود اوراق بهادار و سپرده بانکی
B1: ='درآمد سود سهام'!B1:T1 -> صندوق سرمایه گذاری شاخص سی شرکت بزرگ فیروزه
B2: صورت وضعیت درآمدها
B3: =' سهام'!AC6 -> برای ماه منتهی به 1404/12/29
B4: 1-2-2-سود اوراق بهادار با درآمد ثابت و سپرده بانکی | AC4: 1404/06/31
G5: ابتدای دوره | K5: =' سهام'!AC7 -> طی اسفند ماه | Q5: =' سهام'!AC8 -> از ابتدای سال مالی تا پایان اسفند ماه | AC5: 1404/07/30
B6: شرح | C6: تاریخ دریافت سود | D6: تاریخ سررسید | E6: نرخ سود علی الحساب | G6: درآمد سود | I6: هزینه تنزیل | K6: درآمد سود | M6: هزینه تنزیل | O6: خالص درآمد | Q6: درآمد سود | S6: هزینه تنزیل | U6: خالص درآمد | AC6: برای ماه منتهی به 1404/07/30
B7: سپرده کوتاه مدت بانک خاورمیانه مهستان | H7: 0 | J7: 176683 | K7: 202787 | M7: 0 | O7: =K7+M7 -> 202787 | Q7: 871858 | S7: 0 | U7: =Q7+S7 -> 871858 | AC7: طی مهر ماه
B8: سپرده کوتاه مدت بانک گردشگری سعادت آباد | K8: 3158597532 | M8: 0 | O8: =K8+M8 -> 3158597532 | Q8: 40103031576 | S8: 0 | U8: =Q8+S8 -> 40103031576
B9: سپرده کوتاه مدت بانک صادرات بلوار میرداماد | K9: 4178 | M9: 0 | O9: =K9+M9 -> 4178 | Q9: 20717 | S9: 0 | U9: =Q9+S9 -> 20717
B10: سپرده کوتاه مدت بانک خاورمیانه نیاوران | H10: 0 | J10: 2202729735 | K10: 138867 | M10: 0 | O10: =K10+M10 -> 138867 | Q10: 213174 | S10: 0 | U10: =Q10+S10 -> 213174 | AC10: از ابتدای سال مالی تا پایان مهر ماه
K11: =SUM(K7:K10) -> 3158943364 | O11: =SUM(O7:O10) -> 3158943364 | Q11: =SUM(Q7:Q10) -> 40104137325 | U11: =SUM(U7:U10) -> 40104137325
R58: 1783
R75: 2083

Sheet درآمد سپرده بانکی
B1: ='سود اوراق بهادار و سپرده بانکی'!B1:U1 -> صندوق سرمایه گذاری شاخص سی شرکت بزرگ فیروزه
B2: صورت وضعیت درآمدها
B3: =' سهام'!B3:Z3 -> برای ماه منتهی به 1404/12/29
B4: 3-2-درآمد حاصل از سرمایه گذاری در سپرده بانکی و گواهی سپرده: | AC4: 1404/02/31
AC5: 1404/03/31
B6: نام سپرده بانکی | F6: =' سهام'!AC7 -> طی اسفند ماه | J6: =' سهام'!AC8 -> از ابتدای سال مالی تا پایان اسفند ماه | AC6: برای ماه منتهی به 1404/03/31
B7: نام سپرده | F7: سود سپرده بانکی و گواهی سپرده | H7: درصد سود به میانگین سپرده | J7: سود سپرده بانکی و گواهی سپرده | L7: درصد سود به میانگین سپرده | AC7: طی خرداد ماه
F8: یادداشت 2-2-1 | J8: یادداشت 2-2-1 | AC8: از ابتدای سال مالی تا پایان خرداد ماه
B9: سپرده کوتاه مدت بانک خاورمیانه مهستان | F9: 202787 | H9: =F9/H16 -> 0.0039369407 | J9: 871858 | L9: =J9/درآمدها!F9 -> 2.7325794e-07
B10: سپرده کوتاه مدت بانک گردشگری سعادت آباد | F10: 3158597532 | H10: =H16/F10 -> 0.016307483 | J10: 40103031576 | L10: =J10/درآمدها!F9 -> 0.012569102
B11: سپرده کوتاه مدت بانک صادرات بلوار میرداماد | F11: 4178 | H11: =H17/F11 -> 0 | J11: 20717 | L11: =J11/درآمدها!F9 -> 6.493127e-09
B12: سپرده کوتاه مدت بانک خاورمیانه نیاوران | F12: 138867 | H12: =H17/F12 -> 0 | J12: 213174 | L12: =J12/درآمدها!F9 -> 6.6813045e-08
B13: جمع | F13: =SUM(F9:F12) -> 3158943364 | H13: =SUM(H9:H12) -> 0.020244424 | J13: =SUM(J9:J12) -> 40104137325 | L13: =SUM(L9:L12) -> 0.012569448
F16: =F13-F15 -> 3158943364 | H16: 51508777 | J16: =J13-J15 -> 40104137325
R58: 1783
R75: 2083

Sheet Sheet1

Sheet سایر درآمدها
B1: ='درآمد سپرده بانکی'!B1:M1 -> صندوق سرمایه گذاری شاخص سی شرکت بزرگ فیروزه
B2: صورت وضعیت درآمدها
B3: =' سهام'!AC6 -> برای ماه منتهی به 1404/12/29
B4: 4-2-سایر درآمدها: | AC4: 1404/02/31
D5: =' سهام'!AC7 -> طی اسفند ماه | F5: =' سهام'!AC8 -> از ابتدای سال مالی تا پایان اسفند ماه | AC5: 1404/03/31
B6: سایر درآمدها | D6: -670150 | F6: 468598199 | AC6: برای ماه منتهی به 1404/03/31
B7: تعدیل کارمزد کارگزار | D7: 0 | F7: 3757374794
D8: =SUM(D6:D7) -> -670150 | F8: =SUM(F6:F7) -> 4225972993
R57: 1783
R74: 2083
