Workbook

Sheet  سهام
B1: صندوق سرمایه گذاری شاخص سی شرکت بزرگ فیروزه
B2: صورت وضعیت پرتفوی
B3: =AC6 -> برای ماه منتهی به 1405/05/31
B4: 1- سرمایه گذاری ها | AC4: 1405/04/31
B5: 1-1-سرمایه‌گذاری در سهام و حق تقدم سهام | AC5: 1405/05/31
D6: =AC4 -> 1405/04/31 | J6: تغییرات طی دوره | R6: =AC5 -> 1405/05/31 | AC6: برای ماه منتهی به 1405/05/31
B7: شرکت | D7: تعداد | F7: بهای تمام شده | H7: خالص ارزش فروش | J7: خرید طی دوره | N7: فروش طی دوره | R7: تعداد | T7: قیمت بازار هر سهم | V7: بهای تمام شده | X7: خالص ارزش فروش | Z7: درصد به کل دارایی‌ها | AC7: طی مرداد ماه
J8: تعداد | L8: بهای تمام شده | N8: تعداد | P8: مبلغ فروش | AC8: از ابتدای سال مالی تا پایان مرداد ماه
B9: ایران‌ خودرو | D9: 200000000 | F9: 96230105555 | H9: 100020816000 | J9: 0 | L9: 0 | N9: 0 | P9: 0 | R9: 200000000 | T9: 647 | V9: 96230105555 | X9: 128399738000 | Z9: =X9/$Z$71 -> 0.0081365589
B10: بانک پاسارگاد | D10: 1000 | F10: 1915216 | H10: 8533522 | J10: 0 | L10: 0 | N10: 0 | P10: 0 | R10: 1000 | T10: 10890 | V10: 1915216 | X10: 10805820 | Z10: =X10/$Z$71 -> 6.8475368e-07
B11: بانک تجارت | D11: 80000000 | F11: 44799841988 | H11: 41913484800 | J11: 0 | L11: 0 | N11: -30000000 | P11: 17037134491 | R11: 50000000 | T11: 850 | V11: 27999901246 | X11: 42171475000 | Z11: =X11/$Z$71 -> 0.0026723628
B12: بانک ملت | D12: 670000000 | F12: 745280053458 | H12: 743269766200 | J12: 0 | L12: 0 | N12: -170000000 | P12: 214152596688 | R12: 500000000 | T12: 1369 | V12: 556179144373 | X12: 679208815000 | Z12: =X12/$Z$71 -> 0.043040762
B13: بانک‌اقتصادنوین‌ | D13: 61283274 | F13: 83775398362 | H13: 1.6935461e+11 | J13: 0 | L13: 0 | N13: -1 | P13: 1 | R13: 61283273 | T13: 3390 | V13: 83775396995 | X13: 2.0614439e+11 | Z13: =X13/$Z$71 -> 0.013063157
B14: بین المللی توسعه ص. معادن غدیر | D14: 1000 | F14: 5411279 | H14: 3135573.2 | J14: 0 | L14: 0 | N14: 0 | P14: 0 | R14: 1000 | T14: 4790 | V14: 5411279 | X14: 4752973.3 | Z14: =X14/$Z$71 -> 3.0119101e-07
B15: پالایش نفت اصفهان | D15: 60000000 | F15: 197378016384 | H15: 560831004000 | J15: 0 | L15: 0 | N15: -5000000 | P15: 49200655432 | R15: 55000000 | T15: 11300 | V15: 180929848351 | X15: 616695805000 | Z15: =X15/$Z$71 -> 0.039079377
B16: پالایش نفت بندرعباس | D16: 60000000 | F16: 260309174270 | H16: 659661096000 | J16: 0 | L16: 0 | N16: -10000000 | P16: 120034356745 | R16: 50000000 | T16: 12050 | V16: 216924311880 | X16: 597842675000 | Z16: =X16/$Z$71 -> 0.037884673
B17: پالایش نفت تبریز | D17: 1000 | F17: 20873618 | H17: 38658839 | J17: 0 | L17: 0 | N17: 0 | P17: 0 | R17: 1000 | T17: 46050 | V17: 20873618 | X17: 45694034 | Z17: =X17/$Z$71 -> 2.8955837e-06
B18: پالایش نفت تهران | D18: 50000000 | F18: 148963424259 | H18: 236160260000 | J18: 0 | L18: 0 | N18: -20000000 | P18: 94195395579 | R18: 30000000 | T18: 5470 | V18: 89378054551 | X18: 162831507000 | Z18: =X18/$Z$71 -> 0.010318465
B19: پتروشیمی اروند | D19: 2700000 | F19: 203490878141 | H19: 119140866630 | J19: 0 | L19: 0 | N19: -2700000 | P19: 118055390380 | R19: 0 | T19: 0 | V19: 0 | X19: 0 | Z19: =X19/$Z$71 -> 0
B20: پتروشیمی بوعلی سینا | D20: 1400 | F20: 68624286 | H20: 35951927 | J20: 28600 | L20: 1118869243 | N20: 0 | P20: 0 | R20: 30000 | T20: 38140 | V20: 1187493529 | X20: 1135355334 | Z20: =X20/$Z$71 -> 7.1946296e-05
... B36: سرمایه گذاری صدرتامین | D36: 25414814 | F36: 311831166198 | H36: 4.1358106e+11 | J36: 1400000 | L36: 23854465076 | N36: -3400000 | P36: 71085640391 | R36: 23414814 | T36: 20900 | V36: 293122175634 | X36: 4.8558679e+11 | Z36: =X36/$Z$71 -> 0.030771133
B37: سرمایه‌گذاری‌ سپه‌ | D37: 23000000 | F37: 111689326960 | H37: 98135503000 | J37: 0 | L37: 0 | M37: 9102861790 | N37: -8000000 | P37: 39569278324 | R37: 15000000 | T37: 5910 | V37: 72840865405 | X37: 87964735500 | Z37: =X37/$Z$71 -> 0.0055742345
B38: سرمایه‌گذاری‌صندوق‌بازنشستگی‌ | D38: 1000 | F38: 21678521 | H38: 14814591 | J38: 0 | L38: 0 | N38: 0 | P38: 0 | R38: 1000 | T38: 18260 | V38: 21678521 | X38: 18118850 | Z38: =X38/$Z$71 -> 1.1481728e-06
B39: سرمایه‌گذاری‌غدیر(هلدینگ‌ | D39: 30000000 | F39: 320794769231 | H39: 408120651000 | J39: 0 | L39: 0 | N39: 0 | P39: 0 | R39: 30000000 | T39: 18970 | V39: 320794769231 | X39: 564700857000 | Z39: =X39/$Z$71 -> 0.03578451
B40: صنایع پتروشیمی خلیج فارس | D40: 39000000 | F40: 284985746797 | H40: 402464712000 | J40: 9500000 | L40: 0 | N40: -9000000 | P40: 84250330858 | R40: 39500000 | T40: 9590 | V40: 230911528183 | X40: 375876837350 | Z40: =X40/$Z$71 -> 0.023818927
B41: فروشگاههای زنجیره ای افق کوروش | D41: 1044 | F41: 26314878 | H41: 63989389 | J41: 500 | L41: 31565961 | N41: -544 | P41: 34123834 | R41: 1000 | T41: 72140 | V41: 37487590 | X41: 71582358 | Z41: =X41/$Z$71 -> 4.5361001e-06
B42: فولاد مبارکه اصفهان | D42: 12900000 | F42: 34912740601 | H42: 20045243178 | J42: 0 | L42: 0 | N42: -5900000 | P42: 13805341002 | R42: 7000000 | T42: 2533 | V42: 18944898001 | X42: 17593939370 | Z42: =X42/$Z$71 -> 0.0011149098
B43: گروه توسعه مالی فیروزه | D43: 20000000 | F43: 84174415854 | H43: 91685748000 | J43: 12600000 | L43: 58119700695 | N43: 0 | P43: 0 | R43: 32600000 | T43: 5010 | V43: 142294116549 | X43: 162063490020 | Z43: =X43/$Z$71 -> 0.010269796
B44: گروه س توسعه صنعتی ایران | D44: 60000000 | F44: 98042294767 | H44: 116155126200 | J44: 0 | L44: 0 | N44: 0 | P44: 0 | R44: 60000000 | T44: 3043 | V44: 98042294767 | X44: 181168656600 | Z44: =X44/$Z$71 -> 0.011480471
B45: گروه مپنا (سهامی عام) | D45: 1000 | F45: 16436086 | H45: 20599525 | J45: 0 | L45: 0 | N45: 0 | P45: 0 | R45: 1000 | T45: 29420 | V45: 16436086 | X45: 29192583 | Z45: =X45/$Z$71 -> 1.8499039e-06
B46: گروه مدیریت سرمایه گذاری امید | D46: 1782 | F46: 8899545 | H46: 8664303.2 | J46: 0 | L46: 0 | N46: 0 | P46: 0 | R46: 1782 | T46: 5270 | V46: 8899545 | X46: 9318546.5 | Z46: =X46/$Z$71 -> 5.9050667e-07
B47: گسترش سوخت سبززاگرس(سهامی عام) | D47: 170000000 | F47: 174126065194 | H47: 155191028000 | J47: 10000000 | L47: 10732426662 | N47: 0 | P47: 0 | R47: 180000000 | T47: 1332 | V47: 184858491856 | X47: 237906655200 | Z47: =X47/$Z$71 -> 0.015075899
B48: گسترش نفت و گاز پارسیان | D48: 8000000 | F48: 147918055705 | H48: 185832325600 | J48: 0 | L48: 0 | N48: -2000000 | P48: 53000967586 | R48: 6000000 | T48: 29470 | V48: 110938541779 | X48: 175453181400 | Z48: =X48/$Z$71 -> 0.011118287
B49: نقل به صفحه بعد | C49: 0 | D49: =SUM(D9:D48) -> 3034322918 | E49: =AC48=SUM(#REF!) -> #REF! | F49: =SUM(F9:F48) -> 8236052038248 | G49: =SUM(#REF!) -> #REF! | H49: =SUM(H9:H48) -> 9.9454818e+12 | J49: =SUM(J9:J48) -> 67945593 | K49: =SUM(#REF!) -> #REF! | L49: =SUM(L9:L48) -> 576105006913 | M49: =SUM(#REF!) -> #REF! | N49: =SUM(N9:N48) -> -546237545 | O49: =SUM(#REF!) -> #REF! | P49: =SUM(P9:P48) -> 2481285161109 | Q49: =SUM(#REF!) -> #REF! | R49: =SUM(R9:R48) -> 2556030966 | S49: =SUM(#REF!) -> #REF! | T49: =SUM(T9:T48) -> 604171 | U49: =SUM(#REF!) -> #REF! | V49: =SUM(V9:V48) -> 6641891784831 | W49: =SUM(#REF!) -> #REF! | X49: =SUM(X9:X48) -> 1.0481274e+13 | Y49: =SUM(#REF!) -> #REF! | Z49: =SUM(Z9:Z48) -> 0.66418754
B51: 1- سرمایه گذاری ها
B52: 1-1-سرمایه‌گذاری در سهام و حق تقدم سهام
D53: =D6 -> 1405/04/31 | J53: تغییرات طی دوره | R53: =R6 -> 1405/05/31
B54: شرکت | D54: تعداد | F54: بهای تمام شده | H54: خالص ارزش فروش | J54: خرید طی دوره | N54: فروش طی دوره | R54: تعداد | T54: قیمت بازار هر سهم | V54: بهای تمام شده | X54: خالص ارزش فروش | Z54: درصد به کل دارایی‌ها
J55: تعداد | L55: بهای تمام شده | N55: تعداد | P55: مبلغ فروش
B56: نقل از صفحه قبل | D56: =D49 -> 3034322918 | F56: =F49 -> 8236052038248 | H56: =H49 -> 9.9454818e+12 | J56: =J49 -> 67945593 | L56: =L49 -> 576105006913 | N56: =N49 -> -546237545 | P56: =P49 -> 2481285161109 | R56: =R49 -> 2556030966 | T56: =T49 -> 604171 | V56: =V49 -> 6641891784831 | X56: =X49 -> 1.0481274e+13 | Z56: =Z49 -> 0.66418754
...

Sheet اوراق تبعی
B1: =' سهام'!B1:Z1 -> صندوق سرمایه گذاری شاخص سی شرکت بزرگ فیروزه
B2: صورت وضعیت پرتفوی
B3: =' سهام'!AC6 -> برای ماه منتهی به 1405/05/31
B4: اطلاعات آماری مرتبط با اوراق اختیار فروش تبعی خریداری شده توسط صندوق سرمایه گذاری:
D6: =' سهام'!AC4 -> 1405/04/31 | L6: =' سهام'!AC5 -> 1405/05/31
B7: نام سهام | D7: تعداد اوراق تبعی | F7: قیمت اعمال | H7: تاریخ اعمال | J7: نرخ سود مؤثر | L7: تعداد اوراق تبعی | N7: قیمت اعمال | P7: تاریخ اعمال | R7: نرخ سود مؤثر
D8: - | F8: - | H8: - | J8: 0 | L8: 0 | N8: - | P8: - | R8: 0
D9: =SUM(D8) -> 0 | F9: =SUM(F8) -> 0 | H9: ..... | J9: ..... | L9: =SUM(L8) -> 0 | N9: =SUM(N8) -> 0 | P9: ..... | R9: .....

Sheet تعدیل قیمت
A1: =اوراق!B1 -> صندوق سرمایه گذاری شاخص سی شرکت بزرگ فیروزه
A2: صورت وضعیت پرتفوی
A3: =' سهام'!AC6 -> برای ماه منتهی به 1405/05/31
A4: اوراق بهاداری که ارزش آنها در تاریخ گزارش تعدیل شده
A5: (بر اساس دستورالعمل نحوه تعیین قیمت خرید و فروش اوراق بهادار در صندوق های سرمایه گذاری)
C6: =' سهام'!AC5 -> 1405/05/31
A7: نام اوراق بهادار | C7: تعداد | E7: قیمت پایانی | G7: قیمت تعدیل شده | I7: درصد تعدیل | K7: خالص ارزش فروش تعدیل شده | M7: دلیل تعدیل
C9: - | E9: - | G9: - | I9: - | K9: - | M9: -
C10: - | E10: - | G10: - | I10: - | K10: - | M10: -

Sheet گواهی سپرده
A1: ='تعدیل قیمت'!A1:P1 -> صندوق سرمایه گذاری شاخص سی شرکت بزرگ فیروزه
A2: صورت وضعیت پرتفوی
A3: =' سهام'!AC6 -> برای ماه منتهی به 1405/05/31
A4: 4-1- سرمایه‌گذاری در گواهی سپرده‌ بانکی
K6: =' سهام'!AC4 -> 1405/04/31 | Q6: تغییرات طی دوره | W6: =' سهام'!AC5 -> 1405/05/31
A7: گواهی سپرده بانکی | C7: تاریخ سررسید | E7: نرخ سود علی الحساب | G7: نرخ شکست | I7: پذیرفته شده در بورس یا فرابورس | K7: تعداد | M7: بهای تمام شده | O7: خالص ارزش | Q7: خرید طی دوره | T7: فروش طی دوره | W7: تعداد | Y7: بهای تمام شده | AA7: خالص ارزش | AC7: درصد به کل
O8: فروش | Q8: تعداد | R8: بهای تمام شده | T8: تعداد | U8: مبلغ فروش | AA8: فروش | AC8: دارایی‌ها
A9: گواهی سپرده بانکی نزد بانک ..... | C9: ..... | E9: ..... | G9: ..... | I9: ..... | K9: ..... | M9: ..... | O9: ..... | Q9: ..... | R9: ..... | T9: ..... | U9: ..... | W9: ..... | Y9: ..... | AA9: ..... | AC9: .....
A10: جمع | C10: ..... | E10: ..... | G10: ..... | I10: ..... | K10: ..... | M10: ..... | O10: ..... | Q10: ..... | R10: ..... | T10: ..... | U10: ..... | W10: ..... | Y10: ..... | AA10: ..... | AC10: .....

Sheet اوراق
B1: =' سهام'!B1:Z1 -> صندوق سرمایه گذاری شاخص سی شرکت بزرگ فیروزه
B2: صورت وضعیت پرتفوی
B3: =' سهام'!AC6 -> برای ماه منتهی به 1405/05/31
B4: 2-1-سرمایه‌گذاری در اوراق بهادار با درآمد ثابت یا علی‌الحساب
B6: اطلاعات اوراق بهادار با درآمد ثابت | Q6: =' سهام'!AC4 -> 1405/04/31 | W6: تغییرات طی دوره | AE6: =' سهام'!AC5 -> 1405/05/31
B7: نام اوراق | D7: دارای مجوز از سازمان | F7: پذیرفته شده در بورس یا فرابورس | H7: تاریخ انتشار اوراق | J7: تاریخ سررسید | M7: نرخ سود اسمی | O7: نرخ سود مؤثر | Q7: تعداد | S7: بهای تمام شده | U7: خالص ارزش فروش | W7: خرید طی دوره | AA7: فروش طی دوره | AE7: تعداد | AG7: قیمت بازار هر ورقه | AI7: بهای تمام شده | AK7: خالص ارزش فروش | AM7: درصد به کل دارایی‌ها
W8: تعداد | Y8: بهای تمام شده | AA8: تعداد | AC8: مبلغ فروش
B9: جمع | M9: - | Q9: 0 | S9: 0 | U9: 0 | W9: 0 | Y9: 0 | AA9: 0 | AC9: 0 | AE9: 0 | AG9: 0 | AI9: 0 | AK9: 0 | AM9: 0

Sheet سپرده
B1: صندوق سرمایه گذاری شاخص سی شرکت بزرگ فیروزه
B2: صورت وضعیت پرتفوی
B3: =' سهام'!AC6 -> برای ماه منتهی به 1405/05/31
B4: 3-1- سرمایه‌گذاری در سپرده‌ بانکی | AA4: 1404/02/31
AA5: 1404/03/31
L6: تغییرات طی دوره | P6: =' سهام'!AC5 -> 1405/05/31 | AA6: برای ماه منتهی به 1404/03/31
B7: سپرده های بانکی | D7: نوع سپرده | F7: تاریخ افتتاح حساب | H7: نرخ سود علی الحساب | J7: مبلغ | L7: افزایش | N7: کاهش | P7: مبلغ | R7: درصد به کل دارایی‌ها | AA7: طی خرداد ماه
AA8: از ابتدای سال مالی تا پایان خرداد ماه
B9: حساب جاری بانک خاورمیانه مهستان | D9: حساب جاری | F9: 1393/04/25 | H9: 0 | J9: 50000000 | L9: 0 | N9: 0 | P9: 50000000 | R9: =P9/$R$20 -> 3.1684484e-06
B10: سپرده کوتاه مدت بانک خاورمیانه مهستان | D10: سپرده کوتاه مدت | F10: 1393/04/25 | H10: 0 | J10: 48804398 | L10: 320096 | N10: 0 | P10: 49124494 | R10: =P10/$R$20 -> 3.1129685e-06
B11: سپرده کوتاه مدت بانک گردشگری سعادت آباد | D11: سپرده کوتاه مدت | F11: 1402/06/19 | H11: 0 | J11: 100000 | L11: 0 | N11: 0 | P11: 100000 | R11: =P11/$R$20 -> 6.3368968e-09
B12: سپرده کوتاه مدت بانک صادرات بلوار میرداماد | D12: سپرده کوتاه مدت | F12: 1404/08/01 | H12: 0 | J12: 394772 | L12: 0 | N12: 0 | P12: 394772 | R12: =P12/$R$20 -> 2.5016294e-08
B13: سپرده کوتاه مدت بانک تجارت مطهری دریای نور | D13: سپرده کوتاه مدت | F13: 1404/08/01 | H13: 0 | J13: 402500 | L13: 0 | N13: 0 | P13: 402500 | R13: =P13/$R$20 -> 2.550601e-08
B14: حساب جاری بانک گردشگری سعادت آباد | D14: حساب جاری | F14: 1404/09/19 | H14: 0 | J14: 13387711 | L14: 2958606709854 | N14: 2956358738853 | P14: 2261358712 | R14: =P14/$R$20 -> 0.00014329997
B15: سپرده کوتاه مدت بانک خاورمیانه نیاوران | D15: سپرده کوتاه مدت | F15: 1404/10/15 | J15: 58543585 | L15: 268825 | N15: 0 | P15: 58812410 | R15: =P15/$R$20 -> 3.7268817e-06
B16: سپرده کوتاه مدت بانک گردشگری سعادت آباد | D16: سپرده کوتاه مدت | F16: 1405/04/23 | H16: 0 | J16: 128478472228 | L16: 1691117261266 | N16: 1774536000000 | P16: 45059733494 | R16: =P16/$R$20 -> 0.0028553888
B17: جمع | J17: =SUM(J9:J16) -> 128650105194 | L17: =SUM(L9:L16) -> 4649724560041 | N17: =SUM(N9:N16) -> 4730894738853 | P17: =SUM(P9:P16) -> 47479926382 | R17: =SUM(R9:R16) -> 0.0030087539
R20: 15780594719071
R59: 1783
R76: 2083

Sheet درآمدها
A1: صندوق سرمایه گذاری شاخص سی شرکت بزرگ فیروزه
A2: =سپرده!B2 -> صورت وضعیت پرتفوی
A3: =سپرده!B3 -> برای ماه منتهی به 1405/05/31
AC4: 1404/02/31
B5: شرح | D5: یادداشت | F5: مبلغ | H5: درصد از کل درآمدها | J5: درصد از کل دارایی ها | AC5: برای ماه منتهی به 1404/03/31
B6: درآمد حاصل از سرمایه گذاری در سهام و حق تقدم سهام | D6: 1-2 | F6: ='درآمد سرمایه گذاری در سهام '!T96 -> 6572106406529 | H6: =F6/$M$9 -> 0.98235582 | J6: =F6/سپرده!R20 -> 0.4164676 | AC6: طی خرداد ماه
B7: سود اوراق بهادار با درآمد ثابت و سپرده بانکی | D7: 3-2 | F7: ='درآمد سپرده بانکی'!J14 -> 39514153638 | H7: =F7/$M$9 -> 0.0059063193 | J7: =F7/سپرده!R20 -> 0.0025039711
B8: سایر درآمد ها | D8: 4-2 | F8: ='سایر درآمدها'!F8 -> 8978495485 | H8: =F8/$M$9 -> 0.0013420472 | J8: =F8/سپرده!R20 -> 0.00056895799
B9: جمع | F9: =SUM(F6:F8) -> 6620599055652 | H9: =SUM(H6:H8) -> 0.98960418 | J9: =SUM(J6:J8) -> 0.41954053 | M9: 6690148616502
R57: 1783
R74: 2083

Sheet تعدیل قیمت 
B1: صندوق سرمایه گذاری شاخص سی شرکت بزرگ فیروزه
B2: صورت وضعیت پرتفوی
B3: =' سهام'!AC6 -> برای ماه منتهی به 1405/05/31
B4: اوراق بهاداری که ارزش آنها در تاریخ گذشته تعدیل شده
B5: (بر اساس دستورالعمل نحوه تعیین قیمت خرید و فروش اوراق بهادار در صندوق های سرمایه گذاری )
B7: =' سهام'!AC5 -> 1405/05/31
B8: نام اوراق بهادار | D8: تعداد | F8: قیمت پایانی | H8: قیمت تعدیل شده | J8: درصد تعدیل | L8: خالص ارزش فروش تعدیل شده | N8: دلایل تعدیل
B10: مبین انرژی خلیج فارس | D10: 10000000 | F10: 13260 | H10: -40 | J10: -0.4 | L10: 79560000000 | N10: بسته بودن سهم
B11: جمع | D11: =SUM(D10:D10) -> 10000000 | F11: =SUM(F10:F10) -> 13260 | L11: =SUM(L10:L10) -> 79560000000

Sheet درآمد سرمایه گذاری در سهام 
B1: =درآمدها!A1 -> صندوق سرمایه گذاری شاخص سی شرکت بزرگ فیروزه
B2: صورت وضعیت درآمدها
B3: =' سهام'!AC6 -> برای ماه منتهی به 1405/05/31
AC4: 1404/02/31
B5: 1-2-درآمد حاصل از سرمایه گذاری در سهام و حق تقدم سهام: | AC5: 1404/03/31
AC6: برای ماه منتهی به 1404/03/31
D7: =' سهام'!AC7 -> طی مرداد ماه | N7: =' سهام'!AC8 -> از ابتدای سال مالی تا پایان مرداد ماه | AC7: طی خرداد ماه
B8: سهام | D8: درآمد سود سهام | F8: درآمد تغییر ارزش | H8: درآمد فروش | J8: جمع | N8: درآمد سود سهام | P8: درآمد تغییر ارزش | R8: درآمد فروش | T8: جمع | AC8: از ابتدای سال مالی تا پایان خرداد ماه
D10: یادداشت 2-1-1 | F10: یادداشت 2-1-2 | H10: یادداشت 2-1-3 | J10: مبلغ | L10: درصد از کل درآمد ها | N10: یادداشت 2-1-1 | P10: یادداشت 2-1-2 | R10: یادداشت 2-1-3 | T10: مبلغ | V10: درصد از کل درآمد ها
B11: سرمایه‌گذاری‌ سپه‌ | D11: 0 | F11: 28677694055 | H11: 720816769 | J11: =H11+F11+D11 -> 29398510824 | L11: =J11/$X$12 -> -0.028428874 | N11: 0 | P11: 15123870094 | R11: 422322781 | S11: -714562636 | T11: =N11+P11+R11 -> 15546192875 | U11: 11071728389 | V11: =T11/درآمدها!$F$9 -> 0.002348155
B12: تراکتورسازی‌ایران‌ | D12: 0 | F12: 0 | H12: 20646905854 | J12: =H12+F12+D12 -> 20646905854 | L12: =J12/$X$12 -> -0.019965919 | N12: 18561760841 | P12: 0 | R12: 20972171147 | S12: -4741243411 | T12: =N12+P12+R12 -> 39533931988 | U12: 11071728390 | V12: =T12/درآمدها!$F$9 -> 0.0059713527 | X12: -1034107475059
B13: گسترش نفت و گاز پارسیان | D13: 0 | F13: 43223281172 | H13: -601457786 | J13: =H13+F13+D13 -> 42621823386 | L13: =J13/$X$12 -> -0.041216048 | N13: 0 | P13: 14645905171 | R13: -601457786 | S13: -3385001208 | T13: =N13+P13+R13 -> 14044447385 | U13: 11071728391 | V13: =T13/درآمدها!$F$9 -> 0.0021213258
B14: پالایش نفت اصفهان | D14: 0 | F14: 81744490357 | H14: 23320966074 | J14: =H14+F14+D14 -> 105065456431 | L14: =J14/$X$12 -> -0.10160013 | N14: 43918699187 | P14: 332019221942 | R14: 312378800790 | S14: -2880009787 | T14: =N14+P14+R14 -> 688316721919 | U14: 11071728392 | V14: =T14/درآمدها!$F$9 -> 0.10396593
B15: پالایش نفت تهران | D15: 13786229508 | F15: -11966776231 | H15: 32833418810 | J15: =H15+F15+D15 -> 34652872087 | L15: =J15/$X$12 -> -0.033509933 | N15: 13786229508 | P15: 70788541829 | R15: 101087660665 | S15: -664891573 | T15: =N15+P15+R15 -> 185662432002 | U15: 11071728393 | V15: =T15/درآمدها!$F$9 -> 0.028043147
B16: پتروشیمی اروند | D16: 0 | F16: 0 | H16: -85435487761 | J16: =H16+F16+D16 -> -85435487761 | L16: =J16/$X$12 -> 0.08261761 | N16: 15348475016 | P16: 0 | R16: -85435487761 | S16: -2538727106 | T16: =N16+P16+R16 -> -70087012745 | U16: 11071728394 | V16: =T16/درآمدها!$F$9 -> -0.010586204
B17: سرمایه گذاری سبحان | D17: 0 | F17: 0 | H17: 39097524261 | J17: =H17+F17+D17 -> 39097524261 | L17: =J17/$X$12 -> -0.037807989 | N17: 0 | P17: 0 | R17: 63384922397 | S17: -5759026841 | T17: =N17+P17+R17 -> 63384922397 | U17: 11071728395 | V17: =T17/درآمدها!$F$9 -> 0.0095738953
B18: پتروشیمی نوری | D18: 18951449764 | F18: 34432135811 | H18: -163326352 | J18: =H18+F18+D18 -> 53220259223 | L18: =J18/$X$12 -> -0.051464921 | N18: 18951449764 | P18: -4182702869 | R18: -163326352 | S18: -2808202366 | T18: =N18+P18+R18 -> 14605420543 | U18: 11071728392 | V18: =T18/درآمدها!$F$9 -> 0.0022060572
B19: بانک‌اقتصادنوین‌ | D19: 0 | F19: 36789778668 | H19: -1684 | J19: =H19+F19+D19 -> 36789776984 | L19: =J19/$X$12 -> -0.035576357 | N19: 6300000000 | P19: 102880311854 | R19: 15089423512 | T19: =N19+P19+R19 -> 124269735366 | U19: 11071728393 | V19: =T19/درآمدها!$F$9 -> 0.018770165
B20: بانک ملت | D20: 30820000000 | F20: 120161119737 | H20: 29930525750 | J20: =H20+F20+D20 -> 180911645487 | L20: =J20/$X$12 -> -0.17494472 | N20: 30820000000 | P20: 137379194683 | R20: 163989336402 | S20: 8828197833 | T20: =N20+P20+R20 -> 332188531085 | U20: 11071728394 | V20: =T20/درآمدها!$F$9 -> 0.050174996
B21: کشتیرانی جمهوری اسلامی ایران | D21: 0 | F21: 10210458298 | H21: 7009354657 | J21: =H21+F21+D21 -> 17219812955 | L21: =J21/$X$12 -> -0.01665186 | N21: 0 | P21: 34679836499 | R21: 7009354657 | S21: -40082741567 | T21: =N21+P21+R21 -> 41689191156 | U21: 11071728395 | V21: =T21/درآمدها!$F$9 -> 0.0062968911
B22: سرمایه گذاری صدرتامین | D22: 0 | F22: 91478885743 | H22: 27758012267 | J22: =H22+F22+D22 -> 119236898010 | L22: =J22/$X$12 -> -0.11530416 | N22: 0 | P22: 187201975539 | R22: 28462877586 | S22: 466959920 | T22: =N22+P22+R22 -> 215664853125 | U22: 11071728396 | V22: =T22/درآمدها!$F$9 -> 0.032574825
B23: صنایع پتروشیمی خلیج فارس | D23: 0 | F23: 50511504233 | H23: 7150951974 | J23: =H23+F23+D23 -> 57662456207 | L23: =J23/$X$12 -> -0.055760603 | N23: 0 | P23: 46641651213 | R23: 46932709151 | S23: -102059379029 | T23: =N23+P23+R23 -> 93574360364 | U23: 11071728398 | V23: =T23/درآمدها!$F$9 -> 0.014133821
B24: فولاد مبارکه اصفهان | D24: 689201597 | F24: 12828661922 | H24: -1474624728 | J24: =H24+F24+D24 -> 12043238791 | L24: =J24/$X$12 -> -0.011646022 | N24: 689201597 | P24: -534833530 | R24: -1474624728 | S24: -11597631470 | T24: =N24+P24+R24 -> -1320256661 | U24: 11071728399 | V24: =T24/درآمدها!$F$9 -> -0.0001994165
B25: معدنی‌وصنعتی‌چادرملو | D25: 0 | F25: -4735 | H25: 25552975 | J25: =H25+F25+D25 -> 25548240 | L25: =J25/$X$12 -> -2.4705595e-05 | N25: 218400 | P25: -27011 | R25: 25552975 | S25: 52167321915 | T25: =N25+P25+R25 -> 25744364 | U25: 11071728400 | V25: =T25/درآمدها!$F$9 -> 3.8885249e-06
B26: پتروشیمی پردیس | D26: 0 | F26: 114396286210 | H26: -117475673367 | J26: =H26+F26+D26 -> -3079387157 | L26: =J26/$X$12 -> 0.0029778212 | N26: 0 | P26: -2522413 | R26: -129169357270 | S26: -6964477628 | T26: =N26+P26+R26 -> -129171879683 | U26: 11071728401 | V26: =T26/درآمدها!$F$9 -> -0.019510603
B27: تایدواترخاورمیانه | D27: 0 | F27: -7446986289 | H27: 7080234791 | J27: =H27+F27+D27 -> -366751498 | L27: =J27/$X$12 -> 0.00035465511 | N27: 20465039578 | P27: 23834325463 | R27: 9310850330 | S27: -13571699443 | T27: =N27+P27+R27 -> 53610215371 | U27: 11071728402 | V27: =T27/درآمدها!$F$9 -> 0.0080974871
B28: پتروشیمی پارس | D28: 0 | F28: 755071 | H28: 72385445 | J28: =H28+F28+D28 -> 73140516 | L28: =J28/$X$12 -> -7.0728157e-05 | N28: 504680 | P28: 179357 | R28: 72385445 | S28: 257545772 | T28: =N28+P28+R28 -> 73069482 | U28: 11071728398 | V28: =T28/درآمدها!$F$9 -> 1.1036687e-05
B29: توسعه‌معادن‌وفلزات‌ | D29: 0 | F29: 265626415475 | H29: -2225314265 | J29: =H29+F29+D29 -> 263401101210 | L29: =J29/$X$12 -> -0.25471347 | N29: 44983783665 | P29: 145922842435 | R29: -3489678110 | S29: 1026553445 | T29: =N29+P29+R29 -> 187416947990 | U29: 11071728399 | V29: =T29/درآمدها!$F$9 -> 0.028308156
B30: بانک تجارت | D30: 720000000 | F30: 14307306280 | H30: 2987818411 | J30: =H30+F30+D30 -> 18015124691 | L30: =J30/$X$12 -> -0.01742094 | N30: 720000000 | P30: 18755948189 | R30: 48471365027 | S30: -1161777565 | T30: =N30+P30+R30 -> 67947313216 | U30: -5155830316 | V30: =T30/درآمدها!$F$9 -> 0.010263016
B31: پتروشیمی‌شیراز | D31: 0 | F31: 85784066332 | H31: -89285395392 | J31: =H31+F31+D31 -> -3501329060 | L31: =J31/$X$12 -> 0.0033858464 | N31: 62302078811 | P31: -9671558 | R31: -88852438051 | S31: 599022178 | T31: =N31+P31+R31 -> -26560030798 | U31: -5155830315 | V31: =T31/درآمدها!$F$9 -> -0.0040117262
... B33: پالایش نفت بندرعباس | D33: 56034215623 | F33: 7045117023 | H33: 51170818721 | J33: =H33+F33+D33 -> 114250151367 | L33: =J33/$X$12 -> -0.11048189 | N33: 56034215623 | P33: 253524985014 | R33: 201884379094 | S33: 28553005 | T33: =N33+P33+R33 -> 511443579731 | U33: -5155830313 | V33: =T33/درآمدها!$F$9 -> 0.077250348
B34: پتروشیمی جم | D34: 0 | F34: 11450795 | H34: 0 | J34: =H34+F34+D34 -> 11450795 | L34: =J34/$X$12 -> -1.1073119e-05 | N34: 4166000 | P34: 3611864 | R34: -613813908 | T34: =N34+P34+R34 -> -606036044 | V34: =T34/درآمدها!$F$9 -> -9.1537947e-05
B35: سرمایه‌گذاری‌صندوق‌بازنشستگی‌ | D35: 0 | F35: 3304259 | H35: 0 | J35: =H35+F35+D35 -> 3304259 | L35: =J35/$X$12 -> -3.1952762e-06 | N35: 1840000 | P35: 1260187 | R35: -14030982045 | T35: =N35+P35+R35 -> -14027881858 | V35: =T35/درآمدها!$F$9 -> -0.0021188237
B36: سرمایه گذاری خوارزمی | D36: 0 | F36: 597302354837 | H36: 0 | J36: =H36+F36+D36 -> 597302354837 | L36: =J36/$X$12 -> -0.57760182 | N36: 0 | P36: 1028796392154 | R36: 15873961915 | T36: =N36+P36+R36 -> 1044670354069 | V36: =T36/درآمدها!$F$9 -> 0.15779091
B37: ح . سرمایه گذاری صدرتامین | D37: 0 | F37: 10716516000 | H37: 0 | J37: =H37+F37+D37 -> 10716516000 | L37: =J37/$X$12 -> -0.010363058 | N37: 0 | P37: 26131628903 | R37: 45716495 | T37: =N37+P37+R37 -> 26177345398 | V37: =T37/درآمدها!$F$9 -> 0.003953924
B38: بیمه اتکایی ایران معین | D38: 0 | F38: 0 | H38: 0 | J38: =H38+F38+D38 -> 0 | L38: =J38/$X$12 -> 0 | N38: 0 | P38: 0 | R38: 2853482 | T38: =N38+P38+R38 -> 2853482 | V38: =T38/درآمدها!$F$9 -> 4.3100058e-07
B39: کشت و صنعت هلال | D39: 0 | F39: 664820899 | H39: 0 | J39: =H39+F39+D39 -> 664820899 | L39: =J39/$X$12 -> -0.00064289343 | N39: 244366427 | P39: 1272905000 | R39: 604976897 | T39: =N39+P39+R39 -> 2122248324 | V39: =T39/درآمدها!$F$9 -> 0.00032055231
B40: ح . سرمایه‌گذاری‌ سپه‌ | D40: 0 | F40: 0 | H40: 0 | J40: =H40+F40+D40 -> 0 | L40: =J40/$X$12 -> 0 | N40: 0 | P40: 0 | R40: 0 | T40: =N40+P40+R40 -> 0 | V40: =T40/درآمدها!$F$9 -> 0
B41: س. و توسعه صنایع لاستیک | D41: 0 | F41: 0 | H41: 0 | J41: =H41+F41+D41 -> 0 | L41: =J41/$X$12 -> 0 | N41: 0 | P41: 0 | R41: 287383164 | T41: =N41+P41+R41 -> 287383164 | V41: =T41/درآمدها!$F$9 -> 4.3407426e-05
B42: ملی‌ صنایع‌ مس‌ ایران‌ | D42: 66096579477 | F42: 882632667107 | H42: 0 | J42: =H42+F42+D42 -> 948729246584 | L42: =J42/$X$12 -> -0.91743776 | N42: 66096579477 | P42: 1688945368902 | R42: 55680128071 | T42: =N42+P42+R42 -> 1810722076450 | V42: =T42/درآمدها!$F$9 -> 0.27349822
...

Sheet درآمد سود سهام
B1: =درآمدها!A1 -> صندوق سرمایه گذاری شاخص سی شرکت بزرگ فیروزه
B2: صورت وضعیت درآمدها
B3: =' سهام'!AC6 -> برای ماه منتهی به 1405/05/31
B4: 1-1-2-درآمد سود سهام | AG4: 1404/05/31
D5: اطلاعات مجمع | J5: =' سهام'!AC7 -> طی مرداد ماه | P5: =' سهام'!AC8 -> از ابتدای سال مالی تا پایان مرداد ماه | AE5: 1404/06/31
B6: نام سهام | D6: تاریخ مجمع | F6: تعداد سهام متعلقه در زمان مجمع | H6: سود متعلق به هر سهم | J6: جمع درآمد سود سهام | L6: هزینه تنزیل | N6: خالص درآمد سود سهام | P6: جمع درآمد سود سهام | R6: هزینه تنزیل | T6: خالص درآمد سود سهام | AC6: برای ماه منتهی به 1404/06/31
B7: سرمایه‌ گذاری‌ آتیه‌ دماوند | D7: 1405/03/31 | F7: 19617870 | H7: 150 | J7: 0 | L7: 0 | N7: 0 | P7: 2942680500 | R7: 0 | T7: 2942680500
B8: تایدواترخاورمیانه | D8: 1405/04/29 | F8: 25000000 | H8: 850 | J8: 0 | L8: 0 | N8: 0 | P8: 21250000000 | R8: -784960422 | T8: 20465039578
B9: مخابرات ایران | D9: 1405/04/23 | F9: 1000 | H9: 47 | J9: 0 | L9: 0 | N9: 0 | P9: 47000 | R9: -2384 | T9: 44616
B10: بانک‌اقتصادنوین‌ | D10: 1405/04/30 | F10: 50000000 | H10: 126 | J10: 0 | L10: 0 | N10: 0 | P10: 6300000000 | R10: 0 | T10: 6300000000
B11: سرمایه‌گذاری‌صندوق‌بازنشستگی‌ | D11: 1405/04/30 | F11: 1000 | H11: 1840 | J11: 0 | L11: 0 | N11: 0 | P11: 1840000 | R11: 0 | T11: 1840000
B12: ملی‌ صنایع‌ مس‌ ایران‌ | D12: 1405/04/31 | F12: 150000000 | H12: 450 | J12: 67500000000 | L12: -1403420523 | N12: 66096579477 | P12: 67500000000 | R12: -1403420523 | T12: 66096579477
B13: تراکتورسازی‌ایران‌ | D13: 1405/04/17 | F13: 90000000 | H13: 215 | J13: 0 | L13: 0 | N13: 0 | P13: 19350000000 | R13: -788239159 | T13: 18561760841
B14: گروه مدیریت سرمایه گذاری امید | D14: 1405/04/22 | F14: 999 | H14: 2650 | J14: 0 | L14: 0 | N14: 0 | P14: 2647350 | R14: -39299 | T14: 2608051
B15: توسعه‌معادن‌وفلزات‌ | D15: 1405/04/20 | F15: 379999999 | H15: 120 | J15: 0 | L15: 0 | N15: 0 | P15: 45599999880 | R15: -616216215 | T15: 44983783665
B16: پتروشیمی‌شیراز | D16: 1405/03/27 | F16: 9442434 | H16: 6928 | J16: 0 | L16: 0 | N16: 0 | P16: 65417182752 | R16: -3115103941 | T16: 62302078811
B17: پالایش نفت تبریز | D17: 1405/04/22 | F17: 1000 | H17: 4795 | J17: 0 | L17: 0 | N17: 0 | P17: 4795000 | R17: -216387 | T17: 4578613
B18: پالایش نفت اصفهان | D18: 1405/04/30 | F18: 60000000 | H18: 740 | J18: 0 | L18: 0 | N18: 0 | P18: 44400000000 | R18: -481300813 | T18: 43918699187
... B39: رهیاب پیام گستران | D39: 1405/04/31 | F39: 585000 | H39: 414 | J39: 0 | L39: 0 | N39: 0 | P39: 242190000 | R39: -13176140 | T39: 229013860
B40: جمع | F40: =SUM(F7:F39) -> 1819551178 | J40: =SUM(J7:J39) -> 192849500000 | L40: =SUM(L7:L39) -> -5751824031 | N40: =SUM(N7:N39) -> 187097675969 | P40: =SUM(P7:P39) -> 442213131281 | R40: =SUM(R7:R39) -> -13420850653 | T40: =SUM(T7:T39) -> 428792280628 | AB40: از ابتدای سال مالی تا پایان مهر ماه

Sheet درآمد ناشی از تغییر قیمت اوراق 
B1: ='درآمد ناشی ازفروش'!B1:R1 -> صندوق سرمایه گذاری شاخص سی شرکت بزرگ فیروزه
B2: صورت وضعیت درآمدها
B3: =' سهام'!AC6 -> برای ماه منتهی به 1405/05/31
B4: 2-1-2-درآمد ناشی از تغییر قیمت اوراق بهادار | AB4: 1404/02/31
D5: =' سهام'!AC7 -> طی مرداد ماه | L5: =' سهام'!AC8 -> از ابتدای سال مالی تا پایان مرداد ماه | AB5: 1404/03/31
B6: شرح | D6: تعداد | F6: خالص ارزش فروش | H6: ارزش دفتری | J6: سود و زیان ناشی از تغییر قیمت | L6: تعداد | N6: خالص ارزش فروش | P6: ارزش دفتری | R6: سود و زیان ناشی از تغییر قیمت | AB6: برای ماه منتهی به 1404/03/31
B7: گروه مپنا (سهامی عام) | D7: 1000 | F7: 29192583 | H7: -20599525 | J7: =F7+H7 -> 8593058 | L7: 1000 | N7: 29192583 | P7: -12413297 | R7: =N7+P7 -> 16779286 | AB7: طی خرداد ماه
B8: ح . سرمایه گذاری صدرتامین | D8: 2400000 | F8: 47390815200 | H8: -36674299200 | J8: =F8+H8 -> 10716516000 | L8: 2400000 | N8: 47390815200 | P8: -21259186297 | R8: =N8+P8 -> 26131628903 | AB8: از ابتدای سال مالی تا پایان خرداد ماه
B9: توسعه معادن وص.معدنی خاورمیانه | D9: 1000 | F9: 6876431 | H9: -5606325 | J9: =F9+H9 -> 1270106 | L9: 1000 | N9: 6876431 | P9: -5300706 | R9: =N9+P9 -> 1575725
B10: کشت و صنعت هلال | D10: 125000 | F10: 6057808350 | H10: -5392987450 | J10: =F10+H10 -> 664820900 | L10: 125000 | N10: 6057808350 | P10: -4784903350 | R10: =N10+P10 -> 1272905000
B11: پالایش نفت تهران | D11: 30000000 | F11: 162831507000 | H11: -174798283231 | J11: =F11+H11 -> -11966776231 | L11: 30000000 | N11: 162831507000 | P11: -92042965171 | R11: =N11+P11 -> 70788541829
B12: ملی‌ صنایع‌ مس‌ ایران‌ | D12: 205714285 | F12: 3929389186356 | H12: -3046756519249 | J12: =F12+H12 -> 882632667107 | L12: 205714285 | N12: 3929389186356 | P12: -2240443817454 | R12: =N12+P12 -> 1688945368902
B13: گروه توسعه مالی فیروزه | D13: 32600000 | F13: 162063490020 | H13: -149805448695 | J13: =F13+H13 -> 12258041325 | L13: 32600000 | N13: 162063490020 | P13: -142294116549 | R13: =N13+P13 -> 19769373471
B14: سرمایه‌گذاری‌غدیر(هلدینگ‌ | D14: 30000000 | F14: 564700857000 | H14: -408120651000 | J14: =F14+H14 -> 156580206000 | L14: 30000000 | N14: 564700857000 | P14: -410989327358 | R14: =N14+P14 -> 153711529642
B15: پتروشیمی نوری | D15: 7760000 | F15: 264803522728 | H15: -230371386916 | J15: =F15+H15 -> 34432135812 | L15: 7760000 | N15: 264803522728 | P15: -268986225597 | R15: =N15+P15 -> -4182702869
B16: بانک‌اقتصادنوین‌ | D16: 61283273 | F16: 206144385686 | H16: -169354607018 | J16: =F16+H16 -> 36789778668 | L16: 61283273 | N16: 206144385686 | P16: -103264073832 | R16: =N16+P16 -> 102880311854
B17: صنایع پتروشیمی خلیج فارس | D17: 39500000 | F17: 375876837350 | H17: -325365333116 | J17: =F17+H17 -> 50511504234 | L17: 39500000 | N17: 375876837350 | P17: -329235186136 | R17: =N17+P17 -> 46641651214
B18: فولاد مبارکه اصفهان | D18: 7000000 | F18: 17593939370 | H18: -4765277448 | J18: =F18+H18 -> 12828661922 | L18: 7000000 | N18: 17593939370 | P18: -18128772900 | R18: =N18+P18 -> -534833530
B19: س. نفت و گاز و پتروشیمی تأمین | D19: 15400000 | F19: 578231450720 | H19: -492094743480 | J19: =F19+H19 -> 86136707240 | L19: 15400000 | N19: 578231450720 | P19: -455460090583 | R19: =N19+P19 -> 122771360137
B20: گروه مدیریت سرمایه گذاری امید | D20: 1782 | F20: 9318546 | H20: -8664303 | J20: =F20+H20 -> 654243 | L20: 1782 | N20: 9318546 | P20: -9583780 | R20: =N20+P20 -> -265234
... B37: گسترش سوخت سبززاگرس(سهامی عام) | D37: 180000000 | F37: 237906655200 | H37: -165923454662 | J37: =F37+H37 -> 71983200538 | L37: 180000000 | N37: 237906655200 | P37: -184858491856 | R37: =N37+P37 -> 53048163344
B38: نقل به صفحه بعد | D38: =SUM(D7:D37) -> 1328453437 | F38: =SUM(F7:F37) -> 10699891018348 | H38: =SUM(H7:H37) -> -8274720585655 | J38: =SUM(J7:J37) -> 2425170432693 | L38: =SUM(L7:L37) -> 1328453437 | N38: =SUM(N7:N37) -> 10699891018348 | P38: =SUM(P7:P37) -> -6856377884476 | R38: =SUM(R7:R37) -> 3843513133872
B40: 2-1-2-درآمد ناشی از تغییر قیمت اوراق بهادار | Z40: 1404/02/31
D41: =D5 -> طی مرداد ماه | L41: =L5 -> از ابتدای سال مالی تا پایان مرداد ماه | Z41: 1404/03/31
B42: شرح | D42: تعداد | F42: خالص ارزش فروش | H42: ارزش دفتری | J42: سود و زیان ناشی از تغییر قیمت | L42: تعداد | N42: خالص ارزش فروش | P42: ارزش دفتری | R42: سود و زیان ناشی از تغییر قیمت | Z42: برای ماه منتهی به 1404/03/31
B43: نقل از صفحه قبل | D43: =D38 -> 1328453437 | F43: =F38 -> 10699891018348 | H43: =H38 -> -8274720585655 | J43: =J38 -> 2425170432693 | L43: =L38 -> 1328453437 | N43: =N38 -> 10699891018348 | P43: =P38 -> -6856377884476 | R43: =R38 -> 3843513133872
B44: بانک ملت | D44: 500000000 | F44: 679208815000 | H44: -559047695262 | J44: =H44+F44 -> 120161119738 | L44: 500000000 | N44: 679208815000 | P44: -541829620317 | R44: =N44+P44 -> 137379194683
B45: کشتیرانی جمهوری اسلامی ایران | D45: 15000000 | F45: 120263124000 | H45: -110052665701 | J45: =H45+F45 -> 10210458299 | L45: 15000000 | N45: 120263124000 | P45: -85583287501 | R45: =N45+P45 -> 34679836499
B46: ایران‌ خودرو | D46: 200000000 | F46: 128399738000 | H46: -100020816000 | J46: =H46+F46 -> 28378922000 | L46: 200000000 | N46: 128399738000 | P46: -95506096906 | R46: =N46+P46 -> 32893641094
B47: سرمایه گذاری صدرتامین | D47: 23414814 | F47: 485586785494 | H47: -394107899751 | J47: =H47+F47 -> 91478885743 | L47: 23414814 | N47: 485586785494 | P47: -298384809955 | R47: =N47+P47 -> 187201975539
B48: معدنی‌وصنعتی‌چادرملو | D48: 1000 | F48: 2467775 | H48: -2472511 | J48: =H48+F48 -> -4736 | L48: 1000 | N48: 2467775 | P48: -2494787 | R48: =N48+P48 -> -27012
B49: پتروشیمی پردیس | D49: 1000 | F49: 10408912 | H49: 114385877298 | J49: =H49+F49 -> 114396286210 | L49: 1000 | N49: 10408912 | P49: -12931326 | R49: =N49+P49 -> -2522414
B50: بین المللی توسعه ص. معادن غدیر | D50: 1000 | F50: 4752973 | H50: -3135573 | J50: =H50+F50 -> 1617400 | L50: 1000 | N50: 4752973 | P50: -2745611 | R50: =N50+P50 -> 2007362
B51: تایدواترخاورمیانه | D51: 20000000 | F51: 146062144000 | H51: -153509130289 | J51: =H51+F51 -> -7446986289 | L51: 20000000 | N51: 146062144000 | P51: -122227818536 | R51: =N51+P51 -> 23834325464
B52: بانک تجارت | D52: 50000000 | F52: 42171475000 | H52: -27864168720 | J52: =H52+F52 -> 14307306280 | L52: 50000000 | N52: 42171475000 | P52: -23415526811 | R52: =N52+P52 -> 18755948189
B53: معدنی و صنعتی گل گهر | D53: 1000000 | F53: 2766448760 | H53: -2828163214 | J53: =H53+F53 -> -61714454 | L53: 1000000 | N53: 2766448760 | P53: -2827856067 | R53: =N53+P53 -> -61407307
B54: سرمایه گذاری تامین اجتماعی | D54: 600000000 | F54: 1716428646000 | H54: -1296698436000 | J54: =H54+F54 -> 419730210000 | L54: 600000000 | N54: 1716428646000 | P54: -1131384190589 | R54: =N54+P54 -> 585044455411
B55: پتروشیمی‌شیراز | D55: 1000 | F55: 60796382 | H55: 85723269950 | J55: =H55+F55 -> 85784066332 | L55: 1000 | N55: 60796382 | P55: -70467941 | R55: =N55+P55 -> -9671559
B56: پالایش نفت بندرعباس | D56: 50000000 | F56: 597842675000 | H56: -590797557976 | J56: =H56+F56 -> 7045117024 | L56: 50000000 | N56: 597842675000 | P56: -344317689986 | R56: =N56+P56 -> 253524985014
B57: جمع | D57: =SUM(D43:D56) -> 2787872251 | F57: =SUM(F43:F56) -> 14618699295644 | H57: =SUM(H43:H56) -> -11309543579404 | J57: =SUM(J43:J56) -> 3309155716240 | L57: =SUM(L43:L56) -> 2787872251 | N57: =SUM(N43:N56) -> 14618699295644 | P57: =SUM(P43:P56) -> -9501943420809 | R57: =SUM(R43:R56) -> 5116755874835
...

Sheet درآمد ناشی ازفروش
B1: ='سود اوراق بهادار و سپرده بانکی'!B1:U1 -> صندوق سرمایه گذاری شاخص سی شرکت بزرگ فیروزه
B2: صورت وضعیت درآمدها
B3: =' سهام'!B3:Z3 -> برای ماه منتهی به 1405/05/31
B4: 3-1-2-سود(زیان) حاصل از فروش اوراق بهادار | AC4: 1404/04/31
D5: =' سهام'!AC7 -> طی مرداد ماه | L5: =' سهام'!AC8 -> از ابتدای سال مالی تا پایان مرداد ماه | AC5: 1404/05/31
B6: شرح | D6: تعداد | F6: خالص بهای فروش | H6: ارزش دفتری | J6: سود و زیان ناشی از فروش | L6: تعداد | N6: خالص ارزش فروش | P6: ارزش دفتری | R6: سود و زیان ناشی از فروش | Z6: برای ماه منتهی به 1404/05/31
B7: سرمایه‌گذاری‌ سپه‌ | D7: 8000000 | F7: 39569278324 | H7: -38848461555 | J7: 720816769 | L7: 8600000 | N7: 42184418951 | P7: -41762096170 | R7: 422322781
B8: تراکتورسازی‌ایران‌ | D8: 80000000 | F8: 214400185183 | H8: -193753279329 | J8: 20646905854 | L8: 98000000 | N8: 258319938335 | P8: -237347767188 | R8: 20972171147
B9: گسترش نفت و گاز پارسیان | D9: 2000000 | F9: 53000967586 | H9: -53602425372 | J9: -601457786 | L9: 2000000 | N9: 53000967586 | P9: -53602425372 | R9: -601457786
B10: پالایش نفت اصفهان | D10: 5000000 | F10: 49200655432 | H10: -25879689358 | J10: 23320966074 | L10: 65660440 | N10: 652230111331 | P10: -339851310541 | R10: 312378800790
B11: پالایش نفت تهران | D11: 20000000 | F11: 94195395579 | H11: -61361976769 | J11: 32833418810 | L11: 54661723 | N11: 268795229622 | P11: -167707568957 | R11: 101087660665
B12: پتروشیمی اروند | D12: 2700000 | F12: 118055390380 | H12: -203490878141 | J12: -85435487761 | L12: 2700000 | N12: 118055390380 | P12: -203490878141 | R12: -85435487761
B13: سرمایه گذاری سبحان | D13: 30000000 | F13: 86012049850 | H13: -46914525589 | J13: 39097524261 | L13: 96000000 | N13: 213511404317 | P13: -150126481920 | R13: 63384922397
B14: پتروشیمی نوری | D14: 240000 | F14: 8155835232 | H14: -8319161584 | J14: -163326352 | L14: 240000 | N14: 8155835232 | P14: -8319161584 | R14: -163326352
B15: بانک‌اقتصادنوین‌ | D15: 1 | F15: 1 | H15: -1685 | J15: -1684 | L15: 10000001 | N15: 35742240265 | P15: -20652816753 | R15: 15089423512
B16: بانک ملت | D16: 170000000 | F16: 214152596688 | H16: -184222070938 | J16: 29930525750 | L16: 992467064 | N16: 1239470861484 | P16: -1075481525082 | R16: 163989336402
B17: کشتیرانی جمهوری اسلامی ایران | D17: 3000000 | F17: 24126012156 | H17: -17116657499 | J17: 7009354657 | L17: 3000000 | N17: 24126012156 | P17: -17116657499 | R17: 7009354657
B18: سرمایه گذاری صدرتامین | D18: 3400000 | F18: 71085640391 | H18: -43327628124 | J18: 27758012267 | L18: 3700001 | N18: 75274591342 | P18: -46811713756 | R18: 28462877586
... B28: فروشگاههای زنجیره ای افق کوروش | D28: 544 | F28: 34123834 | H28: -22980227 | J28: 11143607 | L28: 1999500 | N28: 97327931217 | P28: -64467027495 | R28: 32860903722
B29: پالایش نفت بندرعباس | D29: 10000000 | F29: 120034356745 | H29: -68863538024 | J29: 51170818721 | L29: 40000000 | N29: 477338531108 | P29: -275454152014 | R29: 201884379094 | Z29: طی مرداد ماه
B30: پتروشیمی جم | D30: 0 | F30: 0 | H30: 0 | J30: 0 | L30: 99000 | N30: 3688867268 | P30: -4302681176 | R30: -613813908
B31: سرمایه‌گذاری‌صندوق‌بازنشستگی‌ | D31: 0 | F31: 0 | H31: 0 | J31: 0 | L31: 13999000 | N31: 221973501492 | P31: -236004483537 | R31: -14030982045
B32: سرمایه گذاری خوارزمی | D32: 0 | F32: 0 | H32: 0 | J32: 0 | L32: 15014493 | N32: 74228835073 | P32: -58354873158 | R32: 15873961915
B33: ح . سرمایه گذاری صدرتامین | D33: 0 | F33: 0 | H33: 0 | J33: 0 | L33: 88889 | N33: 833094748 | P33: -787378253 | R33: 45716495
B34: بیمه اتکایی ایران معین | D34: 0 | F34: 0 | H34: 0 | J34: 0 | L34: 232900 | N34: 462048552 | P34: -459195070 | R34: 2853482
B35: کشت و صنعت هلال | D35: 0 | F35: 0 | H35: 0 | J35: 0 | L35: 125000 | N35: 5389880247 | P35: -4784903350 | R35: 604976897
B36: ح . سرمایه‌گذاری‌ سپه‌ | D36: 0 | F36: 0 | H36: 0 | J36: 0 | L36: 23600000 | N36: 91002961575 | P36: -91002961575 | R36: 0
B37: س. و توسعه صنایع لاستیک | D37: 0 | F37: 0 | H37: 0 | J37: 0 | L37: 562500 | N37: 4920043726 | P37: -4632660562 | R37: 287383164
B38: ملی‌ صنایع‌ مس‌ ایران‌ | D38: 0 | F38: 0 | H38: 0 | J38: 0 | L38: 9500000 | N38: 197574903177 | P38: -141894775106 | R38: 55680128071
B39: گروه توسعه مالی فیروزه | D39: 0 | F39: 0 | H39: 0 | J39: 0 | L39: 1301101 | N39: 5449089631 | P39: -5475970835 | R39: -26881204
B40: ح . معدنی و صنعتی گل گهر | D40: 0 | F40: 0 | H40: 0 | J40: 0 | L40: 111 | N40: 107895 | P40: -148185 | R40: -40290
B41: سرمایه‌گذاری‌غدیر(هلدینگ‌ | D41: 0 | F41: 0 | H41: 0 | J41: 0 | L41: 14000000 | N41: 196390026792 | P41: -191795019428 | R41: 4595007364
... B59: سایپا | D59: 0 | F59: 0 | H59: 0 | J59: 0 | L59: 668000000 | N59: 374761805019 | P59: -374527470113 | R59: 234334906
B60: تولیدی کوچین | D60: 0 | F60: 0 | H60: 0 | J60: 0 | L60: 1475169 | N60: 16827652536 | P60: -10269781860 | R60: 6557870676 | Z60: از ابتدای سال مالی تا پایان مرداد ماه
B61: جمع | D61: =SUM(D7:D60) -> 550236545 | F61: =SUM(F7:F60) -> 2507929019565 | H61: =SUM(H7:H60) -> -2554773870534 | J61: =SUM(J7:J60) -> -46844850969 | L61: =SUM(L7:L60) -> 3591028126 | N61: =SUM(N7:N60) -> 8533489370451 | P61: =SUM(P7:P60) -> -7506931119385 | R61: =SUM(R7:R60) -> 1026558251066
B63: 3-1-2-سود(زیان) حاصل از فروش اوراق بهادار | Z63: 1404/02/31
D64: =D5 -> طی مرداد ماه | L64: =L5 -> از ابتدای سال مالی تا پایان مرداد ماه | Z64: 1404/03/31
B65: شرح | D65: تعداد | F65: خالص بهای فروش | H65: ارزش دفتری | J65: سود و زیان ناشی از فروش | L65: تعداد | N65: خالص ارزش فروش | P65: ارزش دفتری | R65: سود و زیان ناشی از فروش | X65: برای ماه منتهی به 1404/03/31
B66: نقل از صفحه قبل | D66: =D61 -> 550236545 | F66: =F61 -> 2507929019565 | H66: =H61 -> -2554773870534 | J66: =J61 -> -46844850969 | L66: =L61 -> 3591028126 | N66: =N61 -> 8533489370451 | P66: =P61 -> -7506931119385 | R66: =R61 -> 1026558251066
B67: جمع | D67: =SUM(D66:D66) -> 550236545 | F67: =SUM(F66:F66) -> 2507929019565 | H67: =SUM(H66:H66) -> -2554773870534 | J67: =SUM(J66:J66) -> -46844850969 | L67: =SUM(L66:L66) -> 3591028126 | N67: =SUM(N66:N66) -> 8533489370451 | P67: =SUM(P66:P66) -> -7506931119385 | R67: =SUM(R66:R66) -> 1026558251066

Sheet سود اوراق بهادار و سپرده بانکی
B1: ='درآمد سود سهام'!B1:T1 -> صندوق سرمایه گذاری شاخص سی شرکت بزرگ فیروزه
B2: صورت وضعیت درآمدها
B3: =' سهام'!AC6 -> برای ماه منتهی به 1405/05/31
B4: 1-2-2-سود اوراق بهادار با درآمد ثابت و سپرده بانکی | AC4: 1404/06/31
G5: ابتدای دوره | K5: =' سهام'!AC7 -> طی مرداد ماه | Q5: =' سهام'!AC8 -> از ابتدای سال مالی تا پایان مرداد ماه | AC5: 1404/07/30
B6: شرح | C6: تاریخ دریافت سود | D6: تاریخ سررسید | E6: نرخ سود علی الحساب | G6: درآمد سود | I6: هزینه تنزیل | K6: درآمد سود | M6: هزینه تنزیل | O6: خالص درآمد | Q6: درآمد سود | S6: هزینه تنزیل | U6: خالص درآمد | AC6: برای ماه منتهی به 1404/07/30
B7: سپرده کوتاه مدت بانک خاورمیانه مهستان | H7: 0 | J7: 176683 | K7: 320096 | M7: 0 | O7: 320096 | Q7: 1154239 | S7: 0 | U7: 1154239 | AC7: طی مهر ماه
B8: سپرده کوتاه مدت بانک گردشگری سعادت آباد | K8: 0 | M8: 0 | O8: 0 | Q8: 33446410899 | S8: 0 | U8: 33446410899
B9: سپرده کوتاه مدت بانک صادرات بلوار میرداماد | K9: 0 | M9: 0 | O9: 0 | Q9: 4055 | S9: 0 | U9: 4055
B10: سپرده کوتاه مدت بانک خاورمیانه نیاوران | K10: 268825 | O10: 268825 | Q10: 3729687 | U10: 3729687
B11: سپرده کوتاه مدت بانک گردشگری سعادت آباد | H11: 0 | J11: 2202729735 | K11: 6062854758 | M11: 0 | O11: 6062854758 | Q11: 6062854758 | S11: 0 | U11: 6062854758 | AC11: از ابتدای سال مالی تا پایان مهر ماه
K12: =SUM(K7:K11) -> 6063443679 | O12: =SUM(O7:O11) -> 6063443679 | Q12: =SUM(Q7:Q11) -> 39514153638 | U12: =SUM(U7:U11) -> 39514153638
R59: 1783
R76: 2083

Sheet درآمد سرمایه گذاری در اوراق بها
A1: صندوق سرمایه‌گذاری صندوق شاخص سی شرکت بزرگ فیروزه
A2: صورت وضعیت درآمدها
A3: =' سهام'!AC6 -> برای ماه منتهی به 1405/05/31
B4: 2-2-درآمد حاصل از سرمایه گذاری در اوراق بهادار با درآمد ثابت:
C6: =' سهام'!AC7 -> طی مرداد ماه | M6: =' سهام'!AC8 -> از ابتدای سال مالی تا پایان مرداد ماه
C7: درآمد سود اوراق | E7: درآمد تغییر ارزش | G7: درآمد فروش | I7: جمع | M7: درآمد سود اوراق | O7: درآمد تغییر ارزش | Q7: درآمد فروش | R7: جمع
C9: یادداشت 2-2-1 | E9: یادداشت 2-1-2 | G9: یادداشت 3-1-2 | I9: مبلغ | K9: درصد از کل دارائیها | M9: یادداشت 2-2-1 | O9: یادداشت 2-1-2 | Q9: یادداشت 3-1-2 | R9: مبلغ | S9: درصد از کل دارائیها
B10: - | C10: 0 | D10: 0 | E10: 0 | F10: 0 | G10: 0 | H10: 0 | I10: 0 | J10: 0 | K10: 0 | L10: 0 | M10: 0 | N10: 0 | O10: 0 | P10: 875280 | Q10: 0 | R10: 0 | S10: =R10/S14 -> 0
B11: جمع | C11: =SUM(C10:C10) -> 0 | E11: =SUM(E10:E10) -> 0 | G11: =SUM(G10:G10) -> 0 | I11: =SUM(I10:I10) -> 0 | K11: =SUM(K10:K10) -> 0 | M11: =SUM(M10:M10) -> 0 | O11: =SUM(O10:O10) -> 0 | Q11: =SUM(Q10:Q10) -> 0 | R11: =SUM(R10:R10) -> 0 | S11: =SUM(S10:S10) -> 0
K14: 2807555599778 | S14: 2807555599778

Sheet درآمد سپرده بانکی
B1: ='سود اوراق بهادار و سپرده بانکی'!B1:U1 -> صندوق سرمایه گذاری شاخص سی شرکت بزرگ فیروزه
B2: صورت وضعیت درآمدها
B3: =' سهام'!B3:Z3 -> برای ماه منتهی به 1405/05/31
B4: 3-2-درآمد حاصل از سرمایه گذاری در سپرده بانکی و گواهی سپرده:
B6: نام سپرده بانکی | F6: =' سهام'!AC7 -> طی مرداد ماه | J6: =' سهام'!AC8 -> از ابتدای سال مالی تا پایان مرداد ماه
B7: نام سپرده | F7: سود سپرده بانکی و گواهی سپرده | H7: درصد سود به میانگین سپرده | J7: سود سپرده بانکی و گواهی سپرده | L7: درصد سود به میانگین سپرده
F8: یادداشت 2-2-1 | J8: یادداشت 2-2-1
B9: سپرده کوتاه مدت بانک خاورمیانه مهستان | F9: 320096 | H9: =F9/L29 -> 1.4572852e-06 | J9: 1154239 | L9: =J9/L29 -> 5.2548467e-06
B10: سپرده کوتاه مدت بانک گردشگری سعادت آباد | F10: 0 | H10: =F10/L29 -> 0 | J10: 33446410899 | L10: =J10/L29 -> 0.15226982
B11: سپرده کوتاه مدت بانک صادرات بلوار میرداماد | F11: 0 | H11: =F11/L29 -> 0 | J11: 4055 | L11: =J11/L29 -> 1.8460997e-08
B12: سپرده کوتاه مدت بانک خاورمیانه نیاوران | F12: 268825 | H12: =F12/L29 -> 1.2238663e-06 | J12: 3729687 | L12: =J12/L29 -> 1.6979961e-05
B13: سپرده کوتاه مدت بانک گردشگری سعادت آباد | F13: 6062854758 | H13: =F13/L29 -> 0.027602058 | J13: 6062854758 | L13: =J13/L29 -> 0.027602058
B14: جمع | F14: =SUM(F9:F13) -> 6063443679 | H14: =SUM(H9:H13) -> 0.027604739 | J14: =SUM(J9:J13) -> 39514153638 | L14: =SUM(L9:L13) -> 0.17989413
J29: 6809220361173 | L29: =J29/31 -> 2.1965227e+11
R69: 1783
R86: 2083

Sheet Sheet1

Sheet سایر درآمدها
B1: ='درآمد سپرده بانکی'!B1:M1 -> صندوق سرمایه گذاری شاخص سی شرکت بزرگ فیروزه
B2: صورت وضعیت درآمدها
B3: =' سهام'!AC6 -> برای ماه منتهی به 1405/05/31
B4: 4-2-سایر درآمدها:
D5: =' سهام'!AC7 -> طی مرداد ماه | F5: =' سهام'!AC8 -> از ابتدای سال مالی تا پایان مرداد ماه
B6: سایر درآمدها | D6: -1262 | F6: 2381935
B7: تعدیل کارمزد کارگزار | D7: -6773939943 | F7: 8976113550
D8: =SUM(D6:D7) -> -6773941205 | F8: =SUM(F6:F7) -> 8978495485
R57: 1783
R74: 2083
