Workbook

Sheet  سهام
B1: صندوق سرمایه گذاری شاخص سی شرکت بزرگ فیروزه
B2: صورت وضعیت پرتفوی
B3: =AC6 -> برای ماه منتهی به 1405/03/31
B4: 1- سرمایه گذاری ها | AC4: 1405/02/31
B5: 1-1-سرمایه‌گذاری در سهام و حق تقدم سهام | AC5: 1405/03/31
D6: =AC4 -> 1405/02/31 | J6: تغییرات طی دوره | R6: =AC5 -> 1405/03/31 | AC6: برای ماه منتهی به 1405/03/31
B7: شرکت | D7: تعداد | F7: بهای تمام شده | H7: خالص ارزش فروش | J7: خرید طی دوره | N7: فروش طی دوره | R7: تعداد | T7: قیمت بازار هر سهم | V7: بهای تمام شده | X7: خالص ارزش فروش | Z7: درصد به کل دارایی‌ها | AC7: طی خرداد ماه
J8: تعداد | L8: بهای تمام شده | N8: تعداد | P8: مبلغ فروش | AC8: از ابتدای سال مالی تا پایان خرداد ماه
B9: آلومینیوم‌ایران‌ | D9: 14000000 | F9: 87506491301 | H9: 81961502000 | J9: 0 | L9: 0 | N9: 0 | P9: 0 | R9: 14000000 | T9: 10190 | V9: 87506491301 | X9: 141557238200 | Z9: =X9/$Z$90 -> 0.0077179608
B10: آلیاژ گستر هامون | D10: 837500 | F10: 3566757144 | H10: 3423827635 | J10: 0 | L10: 0 | N10: -837500 | P10: 3673905921 | R10: 0 | T10: 0 | V10: 0 | X10: 0 | Z10: =X10/$Z$90 -> 0
B11: ایران خودرو دیزل | D11: 80000000 | F11: 109063410216 | H11: 81763048000 | J11: 0 | L11: 0 | N11: -7337584 | P11: 10303605248 | R11: 72662416 | T11: 1410 | V11: 99060136044 | X11: 1.0166204e+11 | Z11: =X11/$Z$90 -> 0.0055428011
B12: ایران‌ خودرو | D12: 100000000 | F12: 49863785508 | H12: 45743647000 | J12: 654400000 | L12: 313116172614 | N12: -1200000 | P12: 693399477 | R12: 753200000 | T12: 576 | V12: 362402577489 | X12: 430489592064 | Z12: =X12/$Z$90 -> 0.023471084
B13: بانک پاسارگاد | D13: 1000 | F13: 1915216 | H13: 5844470.3 | J13: 0 | L13: 0 | N13: 0 | P13: 0 | R13: 1000 | T13: 10140 | V13: 1915216 | X13: 10061618 | Z13: =X13/$Z$90 -> 5.4857789e-07
B14: بانک تجارت | D14: 214926440 | F14: 110857943840 | H14: 8.2533578e+10 | J14: 119200000 | L14: 76211250882 | N14: -926440 | P14: 366083080 | R14: 333200000 | T14: 642 | V14: 186591341771 | X14: 212260841688 | Z14: =X14/$Z$90 -> 0.011572851 | AB14: 0
B15: بانک ملت | D15: 782067055 | F15: 720301055481 | H15: 7.302364e+11 | J15: 710400000 | L15: 939844213875 | N15: -120111867 | P15: 162990407354 | R15: 1372355188 | T15: 1326 | V15: 1526550668574 | X15: 1.8056764e+12 | Z15: =X15/$Z$90 -> 0.098448794
B16: بانک‌اقتصادنوین‌ | D16: 58000000 | F16: 93098147252 | H16: 123505862360 | J16: 2000000 | L16: 7432330745 | N16: 0 | P16: 0 | R16: 60000000 | T16: 3597 | V16: 100530477997 | X16: 214151711400 | Z16: =X16/$Z$90 -> 0.011675945
B17: بیمه اتکایی ایران معین | D17: 232900 | F17: 394603131 | H17: 4.3146311e+08 | J17: 0 | L17: 0 | N17: -232900 | P17: 462048552 | R17: 0 | T17: 0 | V17: 0 | X17: 0 | Z17: =X17/$Z$90 -> 0
B18: بین المللی توسعه ص. معادن غدیر | D18: 1000 | F18: 5411279 | H18: 2732711.6 | J18: 0 | L18: 0 | N18: 0 | P18: 0 | R18: 1000 | T18: 3339 | V18: 5411279 | X18: 3313189.5 | Z18: =X18/$Z$90 -> 1.8064118e-07
B19: پالایش نفت اصفهان | D19: 119060440 | F19: 382642214429 | H19: 6.1196573e+11 | J19: 1600000 | L19: 14281843599 | N19: -60440 | P19: 319238572 | R19: 120600000 | T19: 9160 | V19: 396729813026 | X19: 1096156699920 | Z19: =X19/$Z$90 -> 0.059764478
B20: پالایش نفت بندرعباس | D20: 90000000 | F20: 390463761385 | H20: 619771842000 | J20: 0 | L20: 0 | N20: -8291414 | P20: 95046222129 | R20: 81708586 | T20: 11590 | V20: 354491575881 | X20: 9.3968218e+11 | Z20: =X20/$Z$90 -> 0.0512332
B21: پالایش نفت تبریز | D21: 1000 | F21: 20873618 | H21: 25689870 | J21: 0 | L21: 0 | N21: 0 | P21: 0 | R21: 1000 | T21: 43580 | V21: 20873618 | X21: 43243127 | Z21: =X21/$Z$90 -> 2.3576947e-06
B22: پالایش نفت تهران | D22: 84661723 | F22: 252230003224 | H22: 2.5975053e+11 | J22: 0 | L22: 0 | N22: -34661723 | P22: 174599834043 | R22: 50000000 | T22: 5180 | V22: 148963424259 | X22: 256997930000 | Z22: =X22/$Z$90 -> 0.014011999
B23: پتروشیمی بوعلی سینا | D23: 1400 | F23: 68624286 | H23: 23838017 | J23: 0 | L23: 0 | N23: 0 | P23: 0 | R23: 1400 | T23: 30400 | V23: 68624286 | X23: 42231011 | Z23: =X23/$Z$90 -> 2.3025123e-06
B24: پتروشیمی پارس | D24: 1000 | F24: 2873060 | H24: 1903173.9 | J24: 0 | L24: 0 | N24: 0 | P24: 0 | R24: 1147 | T24: 2732 | V24: 2873060 | X24: 3109381.2 | Z24: =X24/$Z$90 -> 1.6952918e-07
B25: پتروشیمی پردیس | D25: 50607433 | F25: 467681242627 | H25: 4.5809261e+11 | J25: 0 | L25: 0 | N25: -7433 | P25: 100733998 | R25: 50600000 | T25: 12920 | V25: 467612551637 | X25: 648698497040 | Z25: =X25/$Z$90 -> 0.035368234
B26: پتروشیمی جم | D26: 100000 | F26: 5636941092 | H26: 3042299820 | J26: 0 | L26: 0 | N26: 0 | P26: 0 | R26: 100000 | T26: 39250 | V26: 5636941092 | X26: 3894659750 | Z26: =X26/$Z$90 -> 0.00021234401
... B36: ح . معدنی و صنعتی گل گهر | D36: 111 | F36: 148185 | H36: 80293.496 | J36: 0 | L36: 0 | N36: 0 | P36: 0 | R36: 111 | T36: 1008 | V36: 148185 | X36: 111023.11 | Z36: =X36/$Z$90 -> 6.0531838e-09
B37: ح . معدنی‌وصنعتی‌چادرملو | D37: 119 | F37: 166957 | H37: 114419.65 | J37: 0 | L37: 0 | M37: 9102861790 | N37: 0 | P37: 0 | R37: 119 | T37: 866 | V37: 166957 | X37: 102257.39 | Z37: =X37/$Z$90 -> 5.575261e-09
B38: س. نفت و گاز و پتروشیمی تأمین | D38: 5000000 | F38: 97418382725 | H38: 65881766650 | J38: 400000 | L38: 10562070731 | N38: -400000 | P38: 10234194759 | R38: 5000000 | T38: 25780 | V38: 99981901348 | X38: 127903603000 | Z38: =X38/$Z$90 -> 0.0069735395
B39: س. و توسعه صنایع لاستیک | D39: 562500 | F39: 4998586413 | H39: 4.5377747e+09 | J39: 0 | L39: 0 | N39: -562500 | P39: 4920043726 | R39: 0 | T39: 0 | V39: 0 | X39: 0 | Z39: =X39/$Z$90 -> 0
B40: سایپا | D40: 150000000 | F40: 87281561491 | H40: 73229526000 | J40: 518000000 | L40: 299511858113 | N40: 0 | P40: 0 | R40: 668000000 | T40: 570 | V40: 386793419604 | X40: 377816725200 | Z40: =X40/$Z$90 -> 0.020599262
B41: سرمایه گذاری تامین اجتماعی | D41: 280000000 | F41: 444311046137 | H41: 444536960000 | J41: 380800000 | L41: 790658573505 | N41: 0 | P41: 0 | R41: 660800000 | T41: 2049 | V41: 1234969619642 | X41: 1343512940784 | Z41: =X41/$Z$90 -> 0.073250795
B42: سرمایه گذاری خوارزمی | D42: 99982360 | F42: 371522240327 | H42: 2.9008857e+11 | J42: 5014493 | L42: 19175723052 | N42: -14493 | P42: 63686737 | R42: 294982360 | T42: 4828 | V42: 1227799962434 | X42: 1.413166e+12 | Z42: =X42/$Z$90 -> 0.077048405
B43: سرمایه گذاری سبحان | D43: 92400000 | F43: 131785473469 | H43: 116119999842 | J43: 0 | L43: 0 | N43: -2520000 | P43: 4126799095 | R43: 89880000 | T43: 1905 | V43: 128191324192 | X43: 169897858578 | Z43: =X43/$Z$90 -> 0.0092631435
B44: سرمایه گذاری صدرتامین | D44: 7414814 | F44: 66922505559 | H44: 7.3574975e+10 | J44: 13300000 | L44: 167535395146 | N44: 0 | P44: 0 | R44: 20714814 | T44: 14240 | V44: 234457900705 | X44: 2.9269876e+11 | Z44: =X44/$Z$90 -> 0.015958475
B45: سرمایه‌ گذاری‌ آتیه‌ دماوند | D45: 34000000 | F45: 137933892936 | H45: 143787861160 | J45: 0 | L45: 0 | N45: -14382130 | P45: 82724152535 | R45: 19617870 | T45: 5660 | V45: 79587328846 | X45: 1.1017883e+11 | Z45: =X45/$Z$90 -> 0.0060071521
B46: سرمایه‌گذاری‌صندوق‌بازنشستگی‌ | D46: 6800000 | F46: 147413973728 | H46: 107554129840 | J46: 0 | L46: 0 | N46: -5800000 | P46: 90959387096 | R46: 1000000 | T46: 17000 | V46: 21678525535 | X46: 16868590000 | Z46: =X46/$Z$90 -> 0.00091970653
B47: سرمایه‌گذاری‌غدیر(هلدینگ‌ | D47: 40000000 | F47: 406715712142 | H47: 377300744800 | J47: 4000000 | L47: 63783282786 | N47: 0 | P47: 0 | R47: 44000000 | T47: 15030 | V47: 470498994928 | X47: 656207996400 | Z47: =X47/$Z$90 -> 0.035777666
B48: صنایع پتروشیمی خلیج فارس | D48: 80000000 | F48: 584586147232 | H48: 416753400000 | J48: 0 | L48: 0 | N48: -30000000 | P48: 343553907417 | R48: 50000000 | T48: 12560 | V48: 365366342037 | X48: 623145560000 | Z48: =X48/$Z$90 -> 0.033975041
B49: نقل به صفحه بعد | C49: 0 | D49: =SUM(D9:D48) -> 2429112002 | E49: =AC48=SUM(#REF!) -> #REF! | F49: =SUM(F9:F48) -> 5690500543679 | G49: =SUM(#REF!) -> #REF! | H49: =SUM(H9:H48) -> 5.7354597e+12 | J49: =SUM(J9:J48) -> 2803961427 | K49: =SUM(#REF!) -> #REF! | L49: =SUM(L9:L48) -> 4080519994824 | M49: =SUM(#REF!) -> #REF! | N49: =SUM(N9:N48) -> -229298277 | O49: =SUM(#REF!) -> #REF! | P49: =SUM(P9:P48) -> 1008910248314 | Q49: =SUM(#REF!) -> #REF! | R49: =SUM(R9:R48) -> 5193775299 | S49: =SUM(#REF!) -> #REF! | T49: =SUM(T9:T48) -> 474529 | U49: =SUM(#REF!) -> #REF! | V49: =SUM(V9:V48) -> 9887452963730 | W49: =SUM(#REF!) -> #REF! | X49: =SUM(X9:X48) -> 1.289571e+13 | Y49: =SUM(#REF!) -> #REF! | Z49: =SUM(Z9:Z48) -> 0.7030978
...

Sheet اوراق تبعی
B1: =' سهام'!B1:Z1 -> صندوق سرمایه گذاری شاخص سی شرکت بزرگ فیروزه
B2: صورت وضعیت پرتفوی
B3: =' سهام'!AC6 -> برای ماه منتهی به 1405/03/31
B4: اطلاعات آماری مرتبط با اوراق اختیار فروش تبعی خریداری شده توسط صندوق سرمایه گذاری:
D6: =' سهام'!AC4 -> 1405/02/31 | L6: =' سهام'!AC5 -> 1405/03/31
B7: نام سهام | D7: تعداد اوراق تبعی | F7: قیمت اعمال | H7: تاریخ اعمال | J7: نرخ سود مؤثر | L7: تعداد اوراق تبعی | N7: قیمت اعمال | P7: تاریخ اعمال | R7: نرخ سود مؤثر
D8: - | F8: - | H8: - | J8: 0 | L8: 0 | N8: - | P8: - | R8: 0
D9: =SUM(D8) -> 0 | F9: =SUM(F8) -> 0 | H9: ..... | J9: ..... | L9: =SUM(L8) -> 0 | N9: =SUM(N8) -> 0 | P9: ..... | R9: .....

Sheet تعدیل قیمت
A1: =اوراق!B1 -> صندوق سرمایه گذاری شاخص سی شرکت بزرگ فیروزه
A2: صورت وضعیت پرتفوی
A3: =' سهام'!AC6 -> برای ماه منتهی به 1405/03/31
A4: اوراق بهاداری که ارزش آنها در تاریخ گزارش تعدیل شده
A5: (بر اساس دستورالعمل نحوه تعیین قیمت خرید و فروش اوراق بهادار در صندوق های سرمایه گذاری)
C6: =' سهام'!AC5 -> 1405/03/31
A7: نام اوراق بهادار | C7: تعداد | E7: قیمت پایانی | G7: قیمت تعدیل شده | I7: درصد تعدیل | K7: خالص ارزش فروش تعدیل شده | M7: دلیل تعدیل
C9: - | E9: - | G9: - | I9: - | K9: - | M9: -
C10: - | E10: - | G10: - | I10: - | K10: - | M10: -

Sheet گواهی سپرده
A1: ='تعدیل قیمت'!A1:P1 -> صندوق سرمایه گذاری شاخص سی شرکت بزرگ فیروزه
A2: صورت وضعیت پرتفوی
A3: =' سهام'!AC6 -> برای ماه منتهی به 1405/03/31
A4: 4-1- سرمایه‌گذاری در گواهی سپرده‌ بانکی
K6: =' سهام'!AC4 -> 1405/02/31 | Q6: تغییرات طی دوره | W6: =' سهام'!AC5 -> 1405/03/31
A7: گواهی سپرده بانکی | C7: تاریخ سررسید | E7: نرخ سود علی الحساب | G7: نرخ شکست | I7: پذیرفته شده در بورس یا فرابورس | K7: تعداد | M7: بهای تمام شده | O7: خالص ارزش | Q7: خرید طی دوره | T7: فروش طی دوره | W7: تعداد | Y7: بهای تمام شده | AA7: خالص ارزش | AC7: درصد به کل
O8: فروش | Q8: تعداد | R8: بهای تمام شده | T8: تعداد | U8: مبلغ فروش | AA8: فروش | AC8: دارایی‌ها
A9: گواهی سپرده بانکی نزد بانک ..... | C9: ..... | E9: ..... | G9: ..... | I9: ..... | K9: ..... | M9: ..... | O9: ..... | Q9: ..... | R9: ..... | T9: ..... | U9: ..... | W9: ..... | Y9: ..... | AA9: ..... | AC9: .....
A10: جمع | C10: ..... | E10: ..... | G10: ..... | I10: ..... | K10: ..... | M10: ..... | O10: ..... | Q10: ..... | R10: ..... | T10: ..... | U10: ..... | W10: ..... | Y10: ..... | AA10: ..... | AC10: .....

Sheet اوراق
B1: =' سهام'!B1:Z1 -> صندوق سرمایه گذاری شاخص سی شرکت بزرگ فیروزه
B2: صورت وضعیت پرتفوی
B3: =' سهام'!AC6 -> برای ماه منتهی به 1405/03/31
B4: 2-1-سرمایه‌گذاری در اوراق بهادار با درآمد ثابت یا علی‌الحساب
B6: اطلاعات اوراق بهادار با درآمد ثابت | Q6: =' سهام'!AC4 -> 1405/02/31 | W6: تغییرات طی دوره | AE6: =' سهام'!AC5 -> 1405/03/31
B7: نام اوراق | D7: دارای مجوز از سازمان | F7: پذیرفته شده در بورس یا فرابورس | H7: تاریخ انتشار اوراق | J7: تاریخ سررسید | M7: نرخ سود اسمی | O7: نرخ سود مؤثر | Q7: تعداد | S7: بهای تمام شده | U7: خالص ارزش فروش | W7: خرید طی دوره | AA7: فروش طی دوره | AE7: تعداد | AG7: قیمت بازار هر ورقه | AI7: بهای تمام شده | AK7: خالص ارزش فروش | AM7: درصد به کل دارایی‌ها
W8: تعداد | Y8: بهای تمام شده | AA8: تعداد | AC8: مبلغ فروش
B9: جمع | M9: - | Q9: 0 | S9: 0 | U9: 0 | W9: 0 | Y9: 0 | AA9: 0 | AC9: 0 | AE9: 0 | AG9: 0 | AI9: 0 | AK9: 0 | AM9: 0

Sheet سپرده
B1: صندوق سرمایه گذاری شاخص سی شرکت بزرگ فیروزه
B2: صورت وضعیت پرتفوی
B3: =' سهام'!AC6 -> برای ماه منتهی به 1405/03/31
B4: 3-1- سرمایه‌گذاری در سپرده‌ بانکی | AA4: 1404/02/31
AA5: 1404/03/31
L6: تغییرات طی دوره | P6: =' سهام'!AC5 -> 1405/03/31 | AA6: برای ماه منتهی به 1404/03/31
B7: سپرده های بانکی | D7: نوع سپرده | F7: تاریخ افتتاح حساب | H7: نرخ سود علی الحساب | J7: مبلغ | L7: افزایش | N7: کاهش | P7: مبلغ | R7: درصد به کل دارایی‌ها | AA7: طی خرداد ماه
AA8: از ابتدای سال مالی تا پایان خرداد ماه
B9: حساب جاری بانک خاورمیانه مهستان | D9: حساب جاری | F9: 1393/04/25 | H9: 0 | J9: 50000000 | L9: 0 | N9: 0 | P9: 50000000 | R9: =P9/$R$19 -> 2.7260919e-06
B10: سپرده کوتاه مدت بانک خاورمیانه مهستان | D10: سپرده کوتاه مدت | F10: 1393/04/25 | H10: 0 | J10: 48392521 | L10: 205502 | N10: 0 | P10: 48598023 | R10: =P10/$R$19 -> 2.6496535e-06
B11: سپرده کوتاه مدت بانک گردشگری سعادت آباد | D11: سپرده کوتاه مدت | F11: 1402/06/19 | H11: 0 | J11: 224817691840 | L11: 4599929882920 | N11: 4539625617000 | P11: 285121957760 | R11: =P11/$R$19 -> 0.015545373
B12: سپرده کوتاه مدت بانک صادرات بلوار میرداماد | D12: سپرده کوتاه مدت | F12: 1404/08/01 | H12: 0 | J12: 394772 | L12: 0 | N12: 0 | P12: 394772 | R12: =P12/$R$19 -> 2.1523695e-08
B13: سپرده کوتاه مدت بانک تجارت مطهری دریای نور | D13: سپرده کوتاه مدت | F13: 1404/08/01 | H13: 0 | J13: 402500 | L13: 0 | N13: 0 | P13: 402500 | R13: =P13/$R$19 -> 2.194504e-08
B14: حساب جاری بانک گردشگری سعادت آباد | D14: حساب جاری | F14: 1404/09/19 | H14: 0 | J14: 3973500 | L14: 9584054700000 | N14: 9584004251582 | P14: 54421918 | R14: =P14/$R$19 -> 2.967183e-06
B15: سپرده کوتاه مدت بانک خاورمیانه نیاوران | D15: سپرده کوتاه مدت | F15: 1404/10/15 | H15: 0 | J15: 377595616 | L15: 449908799323 | N15: 450228098912 | P15: 58296027 | R15: =P15/$R$19 -> 3.1784065e-06
B16: جمع | J16: =SUM(J9:J15) -> 225298450749 | L16: =SUM(L9:L15) -> 14633893587745 | N16: =SUM(N9:N15) -> 14573857967494 | P16: =SUM(P9:P15) -> 285334071000 | R16: =SUM(R9:R15) -> 0.015556938
R19: 18341274631176
R58: 1783
R75: 2083

Sheet درآمدها
A1: صندوق سرمایه گذاری شاخص سی شرکت بزرگ فیروزه
A2: =سپرده!B2 -> صورت وضعیت پرتفوی
A3: =سپرده!B3 -> برای ماه منتهی به 1405/03/31
AC4: 1404/02/31
B5: شرح | D5: یادداشت | F5: مبلغ | H5: درصد از کل درآمدها | J5: درصد از کل دارایی ها | AC5: برای ماه منتهی به 1404/03/31
B6: درآمد حاصل از سرمایه گذاری در سهام و حق تقدم سهام | D6: 1-2 | F6: ='درآمد سرمایه گذاری در سهام '!T95 -> 3495258512294 | H6: =F6/$M$9 -> 0.98622897 | J6: =F6/M8 -> 0.19056792 | AC6: طی خرداد ماه
B7: سود اوراق بهادار با درآمد ثابت و سپرده بانکی | D7: 3-2 | F7: ='درآمد سپرده بانکی'!J13 -> 20982419373 | H7: =F7/$M$9 -> 0.0059204404 | J7: =F7/M8 -> 0.0011440001
B8: سایر درآمد ها | D8: 4-2 | F8: ='سایر درآمدها'!F8 -> 9548692296 | H8: =F8/$M$9 -> 0.0026942777 | J8: =F8/M8 -> 0.00052061225 | M8: 18341274631176
B9: جمع | F9: =SUM(F6:F8) -> 3525789623963 | H9: =SUM(H6:H8) -> 0.99484368 | J9: =SUM(J6:J8) -> 0.19223253 | M9: 3544063938478
R57: 1783
R74: 2083

Sheet تعدیل قیمت 
B1: صندوق سرمایه گذاری شاخص سی شرکت بزرگ فیروزه
B2: صورت وضعیت پرتفوی
B3: =' سهام'!AC6 -> برای ماه منتهی به 1405/03/31
B4: اوراق بهاداری که ارزش آنها در تاریخ گذشته تعدیل شده
B5: (بر اساس دستورالعمل نحوه تعیین قیمت خرید و فروش اوراق بهادار در صندوق های سرمایه گذاری )
B7: =' سهام'!AC5 -> 1405/03/31
B8: نام اوراق بهادار | D8: تعداد | F8: قیمت پایانی | H8: قیمت تعدیل شده | J8: درصد تعدیل | L8: خالص ارزش فروش تعدیل شده | N8: دلایل تعدیل
B10: کشتیرانی جمهوری اسلامی ایران | D10: 18000000 | F10: 6590 | H10: -30 | J10: -0.3 | L10: 83034000000 | N10: -
B11: پتروشیمی‌شیراز | D11: 9367191 | F11: 68850 | H11: -6 | J11: -0.06 | L11: 606235234329 | N11: -
B12: فولاد مبارکه اصفهان | D12: 12900000 | F12: 2610 | H12: -40 | J12: -0.4 | L12: 20201400000 | N12: -
B13: مبین انرژی خلیج فارس | D13: 10000000 | F13: 14860 | H13: -40 | J13: -0.4 | L13: 89160000000 | N13: -
B14: پتروشیمی نوری | D14: 5000000 | F14: 58650 | H14: -40 | J14: -0.3 | L14: 205275000000 | N14: -
B15: جمع | D15: =SUM(D10:D14) -> 55267191 | F15: =SUM(F10:F14) -> 151560 | L15: =SUM(L10:L14) -> 1003905634329

Sheet درآمد سرمایه گذاری در سهام 
B1: =درآمدها!A1 -> صندوق سرمایه گذاری شاخص سی شرکت بزرگ فیروزه
B2: صورت وضعیت درآمدها
B3: =' سهام'!AC6 -> برای ماه منتهی به 1405/03/31
AC4: 1404/02/31
B5: 1-2-درآمد حاصل از سرمایه گذاری در سهام و حق تقدم سهام: | AC5: 1404/03/31
AC6: برای ماه منتهی به 1404/03/31
D7: =' سهام'!AC7 -> طی خرداد ماه | N7: =' سهام'!AC8 -> از ابتدای سال مالی تا پایان خرداد ماه | AC7: طی خرداد ماه
B8: سهام | D8: درآمد سود سهام | F8: درآمد تغییر ارزش | H8: درآمد فروش | J8: جمع | N8: درآمد سود سهام | P8: درآمد تغییر ارزش | R8: درآمد فروش | T8: جمع | AC8: از ابتدای سال مالی تا پایان خرداد ماه
D10: یادداشت 2-1-1 | F10: یادداشت 2-1-2 | H10: یادداشت 2-1-3 | J10: مبلغ | L10: درصد از کل درآمد ها | N10: یادداشت 2-1-1 | P10: یادداشت 2-1-2 | R10: یادداشت 2-1-3 | T10: مبلغ | V10: درصد از کل درآمد ها
B11: سرمایه‌گذاری‌صندوق‌بازنشستگی‌ | D11: 0 | F11: 7094730498 | H11: -6820883242 | J11: =H11+F11+D11 -> 273847256 | L11: =J11/$X$12 -> -0.00026481508 | N11: 0 | P11: 9922707 | R11: -13819183771 | S11: -714562636 | T11: =N11+P11+R11 -> -13809261064 | U11: 11071728389 | V11: =T11/درآمدها!$F$9 -> -0.0039166435
B12: سرمایه گذاری خوارزمی | D12: 0 | F12: 266795677249 | H12: 7358682 | J12: =H12+F12+D12 -> 266803035931 | L12: =J12/$X$12 -> -0.2580032 | N12: 0 | P12: 266696467753 | R12: 7358682 | S12: -4741243411 | T12: =N12+P12+R12 -> 266703826435 | U12: 11071728390 | V12: =T12/درآمدها!$F$9 -> 0.075643715 | X12: -1034107475059
B13: ح . سرمایه گذاری صدرتامین | D13: 0 | F13: 6471099895 | H13: 45725351 | J13: =H13+F13+D13 -> 6516825246 | L13: =J13/$X$12 -> -0.0063018839 | N13: 0 | P13: 6651384263 | R13: 45716495 | S13: -3385001208 | T13: =N13+P13+R13 -> 6697100758 | U13: 11071728391 | V13: =T13/درآمدها!$F$9 -> 0.0018994612
B14: بیمه اتکایی ایران معین | D14: 0 | F14: 0 | H14: 2853482 | J14: =H14+F14+D14 -> 2853482 | L14: =J14/$X$12 -> -2.759367e-06 | N14: 0 | P14: 0 | R14: 2853482 | S14: -2880009787 | T14: =N14+P14+R14 -> 2853482 | U14: 11071728392 | V14: =T14/درآمدها!$F$9 -> 8.0931715e-07
B15: پالایش نفت اصفهان | D15: 0 | F15: 470218909940 | H15: 9452456 | J15: =H15+F15+D15 -> 470228362396 | L15: =J15/$X$12 -> -0.45471904 | N15: 0 | P15: 471938592437 | R15: 9452456 | S15: -664891573 | T15: =N15+P15+R15 -> 471948044893 | U15: 11071728393 | V15: =T15/درآمدها!$F$9 -> 0.13385599
B16: پالایش نفت تهران | D16: 0 | F16: 103592988060 | H16: 68254241855 | J16: =H16+F16+D16 -> 171847229915 | L16: =J16/$X$12 -> -0.16617927 | N16: 0 | P16: 103592988060 | R16: 68254241855 | S16: -2538727106 | T16: =N16+P16+R16 -> 171847229915 | U16: 11071728394 | V16: =T16/درآمدها!$F$9 -> 0.048740069
B17: س. و توسعه صنایع لاستیک | D17: 0 | F17: 0 | H17: 287383164 | J17: =H17+F17+D17 -> 287383164 | L17: =J17/$X$12 -> -0.00027790454 | N17: 0 | P17: 0 | R17: 287383164 | S17: -5759026841 | T17: =N17+P17+R17 -> 287383164 | U17: 11071728395 | V17: =T17/درآمدها!$F$9 -> 8.150888e-05
B18: کشت وصنعت و دامپروری پگاه فارس | D18: 0 | F18: 0 | H18: 2100289780 | J18: =H18+F18+D18 -> 2100289780 | L18: =J18/$X$12 -> -0.0020310169 | N18: 346245059 | P18: 0 | R18: 2100289780 | S18: -2808202366 | T18: =N18+P18+R18 -> 2446534839 | U18: 11071728392 | V18: =T18/درآمدها!$F$9 -> 0.000693897
B19: سرمایه‌ گذاری‌ آتیه‌ دماوند | D19: 2519831982 | F19: 28655147484 | H19: 20459970966 | J19: =H19+F19+D19 -> 51634950432 | L19: =J19/$X$12 -> -0.049931899 | N19: 2519831982 | P19: 25247692304 | R19: 20459970966 | T19: =N19+P19+R19 -> 48227495252 | U19: 11071728393 | V19: =T19/درآمدها!$F$9 -> 0.013678495
B20: گروه صنعتی درپاد تبریز | D20: 0 | F20: 0 | H20: 69437924 | J20: =H20+F20+D20 -> 69437924 | L20: =J20/$X$12 -> -6.7147686e-05 | N20: 0 | P20: 0 | R20: 69437924 | S20: 8828197833 | T20: =N20+P20+R20 -> 69437924 | U20: 11071728394 | V20: =T20/درآمدها!$F$9 -> 1.969429e-05
B21: سرمایه گذاری سبحان | D21: 0 | F21: 57718678885 | H21: 185978946 | J21: =H21+F21+D21 -> 57904657831 | L21: =J21/$X$12 -> -0.055994816 | N21: 0 | P21: 29341939887 | R21: -105933544 | S21: -40082741567 | T21: =N21+P21+R21 -> 29236006343 | U21: 11071728395 | V21: =T21/درآمدها!$F$9 -> 0.008292045
B22: ح . توسعه‌معادن‌وفلزات‌ | D22: 0 | F22: 0 | H22: 7835747 | J22: =H22+F22+D22 -> 7835747 | L22: =J22/$X$12 -> -7.5773043e-06 | N22: 0 | P22: 0 | R22: 7835747 | S22: 466959920 | T22: =N22+P22+R22 -> 7835747 | U22: 11071728396 | V22: =T22/درآمدها!$F$9 -> 2.2224091e-06
B23: بانک ملت | D23: 0 | F23: 265741510769 | H23: 32844651027 | J23: =H23+F23+D23 -> 298586161796 | L23: =J23/$X$12 -> -0.28873804 | N23: 0 | P23: 318510984783 | R23: 32844643239 | S23: -102059379029 | T23: =N23+P23+R23 -> 351355628022 | U23: 11071728398 | V23: =T23/درآمدها!$F$9 -> 0.099653033
B24: ایران‌ خودرو | D24: 0 | F24: 72202809032 | H24: 120362895 | J24: =H24+F24+D24 -> 72323171927 | L24: =J24/$X$12 -> -0.069937771 | N24: 0 | P24: 70813631032 | R24: 120362895 | S24: -11597631470 | T24: =N24+P24+R24 -> 70933993927 | U24: 11071728399 | V24: =T24/درآمدها!$F$9 -> 0.020118612
B25: صنایع پتروشیمی خلیج فارس | D25: 0 | F25: 518957210002 | H25: 30988857415 | J25: =H25+F25+D25 -> 549946067417 | L25: =J25/$X$12 -> -0.53180746 | N25: 0 | P25: 102203810001 | R25: 30988857415 | S25: 52167321915 | T25: =N25+P25+R25 -> 133192667416 | U25: 11071728400 | V25: =T25/درآمدها!$F$9 -> 0.037776692
B26: نیان باتری خاوران | D26: 0 | F26: 0 | H26: 315387909 | J26: =H26+F26+D26 -> 315387909 | L26: =J26/$X$12 -> -0.00030498562 | N26: 0 | P26: 0 | R26: 315387909 | S26: -6964477628 | T26: =N26+P26+R26 -> 315387909 | U26: 11071728401 | V26: =T26/درآمدها!$F$9 -> 8.9451709e-05
B27: س. نفت و گاز و پتروشیمی تأمین | D27: 0 | F27: 59213756747 | H27: 2480203631 | J27: =H27+F27+D27 -> 61693960378 | L27: =J27/$X$12 -> -0.059659138 | N27: 0 | P27: 30978713897 | R27: 2480203631 | S27: -13571699443 | T27: =N27+P27+R27 -> 33458917528 | U27: 11071728402 | V27: =T27/درآمدها!$F$9 -> 0.0094897657
B28: ایران خودرو دیزل | D28: 0 | F28: 27747760988 | H28: 2454833349 | J28: =H28+F28+D28 -> 30202594337 | L28: =J28/$X$12 -> -0.029206437 | N28: 0 | P28: 23937444188 | R28: 2454833349 | S28: 257545772 | T28: =N28+P28+R28 -> 26392277537 | U28: 11071728398 | V28: =T28/درآمدها!$F$9 -> 0.0074854941
B29: پتروشیمی پردیس | D29: 0 | F29: 190702009754 | H29: 4615923 | J29: =H29+F29+D29 -> 190706625677 | L29: =J29/$X$12 -> -0.18441664 | N29: 0 | P29: -5623392544 | R29: 4590063 | S29: 1026553445 | T29: =N29+P29+R29 -> -5618802481 | U29: 11071728399 | V29: =T29/درآمدها!$F$9 -> -0.0015936295
B30: تایدواترخاورمیانه | D30: 0 | F30: 46362625028 | H30: 10999983 | J30: =H30+F30+D30 -> 46373625011 | L30: =J30/$X$12 -> -0.044844106 | N30: 0 | P30: 46362625028 | R30: 10993872 | S30: -1161777565 | T30: =N30+P30+R30 -> 46373618900 | U30: -5155830316 | V30: =T30/درآمدها!$F$9 -> 0.01315269
B31: کیمیا کالای رازی | D31: 0 | F31: 0 | H31: 997817364 | J31: =H31+F31+D31 -> 997817364 | L31: =J31/$X$12 -> -0.00096490683 | N31: 0 | P31: 0 | R31: 997817364 | S31: 599022178 | T31: =N31+P31+R31 -> 997817364 | U31: -5155830315 | V31: =T31/درآمدها!$F$9 -> 0.00028300536
... B33: پتروشیمی خراسان | D33: 1392098005 | F33: 4802874519 | H33: 698916 | J33: =H33+F33+D33 -> 6195671440 | L33: =J33/$X$12 -> -0.0059913226 | N33: 1392098005 | P33: 5524661680 | R33: 698916 | S33: 28553005 | T33: =N33+P33+R33 -> 6917458601 | U33: -5155830313 | V33: =T33/درآمدها!$F$9 -> 0.0019619601
B34: توسعه‌معادن‌وفلزات‌ | D34: 0 | F34: -29495878816 | H34: 46243876 | J34: =H34+F34+D34 -> -29449634940 | L34: =J34/$X$12 -> 0.028478312 | N34: 0 | P34: -29457715680 | R34: 46242232 | T34: =N34+P34+R34 -> -29411473448 | V34: =T34/درآمدها!$F$9 -> -0.0083418118
B35: کارخانجات تولیدی نیروترانسفو | D35: 0 | F35: 0 | H35: 822859418 | J35: =H35+F35+D35 -> 822859418 | L35: =J35/$X$12 -> -0.00079571944 | N35: 0 | P35: 0 | R35: 822859418 | T35: =N35+P35+R35 -> 822859418 | V35: =T35/درآمدها!$F$9 -> 0.00023338302
B36: بانک تجارت | D36: 0 | F36: 53861609100 | H36: 20487101 | J36: =H36+F36+D36 -> 53882096201 | L36: =J36/$X$12 -> -0.052104929 | N36: 0 | P36: 56219771159 | R36: 20486728 | T36: =N36+P36+R36 -> 56240257887 | V36: =T36/درآمدها!$F$9 -> 0.01595111
B37: پتروشیمی‌شیراز | D37: 56148787077 | F37: 49931401865 | H37: -129879922 | J37: =H37+F37+D37 -> 105950309020 | L37: =J37/$X$12 -> -0.1024558 | N37: 56148787077 | P37: -58537600914 | R37: -129879922 | T37: =N37+P37+R37 -> -2518693759 | V37: =T37/درآمدها!$F$9 -> -0.00071436303
B38: ح.سرمایه گذاری خوارزمی | D38: 0 | F38: 0 | H38: 0 | J38: =H38+F38+D38 -> 0 | L38: =J38/$X$12 -> 0 | N38: 0 | P38: 0 | R38: 0 | T38: =N38+P38+R38 -> 0 | V38: =T38/درآمدها!$F$9 -> 0
B39: پالایش نفت بندرعباس | D39: 0 | F39: 377007950604 | H39: 37948611849 | J39: =H39+F39+D39 -> 414956562453 | L39: =J39/$X$12 -> -0.40127025 | N39: 0 | P39: 377007950604 | R39: 37948611849 | T39: =N39+P39+R39 -> 414956562453 | V39: =T39/درآمدها!$F$9 -> 0.11769181
B40: تولیدی کوچین | D40: 0 | F40: 0 | H40: 6557870676 | J40: =H40+F40+D40 -> 6557870676 | L40: =J40/$X$12 -> -0.0063415755 | N40: 399770799 | P40: 0 | R40: 6557870676 | T40: =N40+P40+R40 -> 6957641475 | V40: =T40/درآمدها!$F$9 -> 0.001973357
B41: سرمایه گذاری صدرتامین | D41: 0 | F41: 51588394042 | H41: 0 | J41: =H41+F41+D41 -> 51588394042 | L41: =J41/$X$12 -> -0.049886879 | N41: 0 | P41: 52125491358 | R41: -9849 | T41: =N41+P41+R41 -> 52125481509 | V41: =T41/درآمدها!$F$9 -> 0.014784059 | X41: =L41/$X$12 -> 4.8241483e-14
B42: معدنی‌وصنعتی‌چادرملو | D42: 0 | F42: 467014 | H42: 0 | J42: =H42+F42+D42 -> 467014 | L42: =J42/$X$12 -> -4.516107e-07 | N42: 190480 | P42: 301708 | R42: 0 | T42: =N42+P42+R42 -> 492188 | V42: =T42/درآمدها!$F$9 -> 1.3959653e-07
...

Sheet درآمد سود سهام
B1: =درآمدها!A1 -> صندوق سرمایه گذاری شاخص سی شرکت بزرگ فیروزه
B2: صورت وضعیت درآمدها
B3: =' سهام'!AC6 -> برای ماه منتهی به 1405/03/31
B4: 1-1-2-درآمد سود سهام | AG4: 1404/05/31
D5: اطلاعات مجمع | J5: =' سهام'!AC7 -> طی خرداد ماه | P5: =' سهام'!AC8 -> از ابتدای سال مالی تا پایان خرداد ماه | AE5: 1404/06/31
B6: نام سهام | D6: تاریخ مجمع | F6: تعداد سهام متعلقه در زمان مجمع | H6: سود متعلق به هر سهم | J6: جمع درآمد سود سهام | L6: هزینه تنزیل | N6: خالص درآمد سود سهام | P6: جمع درآمد سود سهام | R6: هزینه تنزیل | T6: خالص درآمد سود سهام | AC6: برای ماه منتهی به 1404/06/31
B7: سرمایه‌ گذاری‌ آتیه‌ دماوند | D7: 1405/03/31 | F7: 19617870 | H7: 150 | J7: 2942680500 | L7: -422848518 | N7: 2519831982 | P7: 2942680500 | R7: -422848518 | T7: 2519831982
B8: پتروشیمی‌شیراز | D8: 1405/03/27 | F8: 9442434 | H8: 6928 | J8: 65417182752 | L8: -9268395675 | N8: 56148787077 | P8: 65417182752 | R8: -9268395675 | T8: 56148787077
B9: معدنی‌وصنعتی‌چادرملو | D9: 1405/02/31 | F9: 1092 | H9: 200 | J9: 0 | L9: 0 | N9: 0 | P9: 218400 | R9: -27920 | T9: 190480
B10: معدنی و صنعتی گل گهر | D10: 1405/02/30 | F10: 1068 | H10: 190 | J10: 0 | L10: 0 | N10: 0 | P10: 202920 | R10: -25835 | T10: 177085
B11: پتروشیمی خراسان | D11: 1405/03/30 | F11: 335000 | H11: 4850 | J11: 1624750000 | L11: -232651995 | N11: 1392098005 | P11: 1624750000 | R11: -232651995 | T11: 1392098005
B12: کشت وصنعت و دامپروری پگاه فارس | D12: 1405/01/30 | F12: 360000 | H12: 1000 | J12: 0 | L12: 0 | N12: 0 | P12: 360000000 | R12: -13754941 | T12: 346245059
B13: تولیدی کوچین | D13: 1405/02/10 | F13: 1475169 | H13: 271 | J13: 0 | L13: 0 | N13: 0 | P13: 399770799 | R13: 0 | T13: 399770799
B14: جمع | F14: =SUM(F7:F13) -> 31232633 | J14: =SUM(J7:J13) -> 69984613252 | L14: =SUM(L7:L13) -> -9923896188 | N14: =SUM(N7:N13) -> 60060717064 | P14: =SUM(P7:P13) -> 70744805371 | R14: =SUM(R7:R13) -> -9937704884 | T14: =SUM(T7:T13) -> 60807100487 | AB14: از ابتدای سال مالی تا پایان مهر ماه
L17: =J14+L14-N14 -> 0

Sheet درآمد ناشی از تغییر قیمت اوراق 
B1: ='درآمد ناشی ازفروش'!B1:R1 -> صندوق سرمایه گذاری شاخص سی شرکت بزرگ فیروزه
B2: صورت وضعیت درآمدها
B3: =' سهام'!AC6 -> برای ماه منتهی به 1405/03/31
B4: 2-1-2-درآمد ناشی از تغییر قیمت اوراق بهادار | AB4: 1404/02/31
D5: =' سهام'!AC7 -> طی خرداد ماه | L5: =' سهام'!AC8 -> از ابتدای سال مالی تا پایان خرداد ماه | AB5: 1404/03/31
B6: شرح | D6: تعداد | F6: خالص ارزش فروش | H6: ارزش دفتری | J6: سود و زیان ناشی از تغییر قیمت | L6: تعداد | N6: خالص ارزش فروش | P6: ارزش دفتری | R6: سود و زیان ناشی از تغییر قیمت | AB6: برای ماه منتهی به 1404/03/31
B7: مبین انرژی خلیج فارس | D7: 10000000 | F7: 88470793200 | H7: -73725661000 | J7: =F7+H7 -> 14745132200 | L7: 10000000 | N7: 88470793200 | P7: -147451322000 | R7: =N7+P7 -> -58980528800 | AB7: طی خرداد ماه
B8: گروه مپنا (سهامی عام) | D8: 1000 | F8: 17642560 | H8: -12373606 | J8: =F8+H8 -> 5268954 | L8: 1000 | N8: 17642560 | P8: -12413297 | R8: =N8+P8 -> 5229263 | AB8: از ابتدای سال مالی تا پایان خرداد ماه
B9: ح . سرمایه گذاری صدرتامین | D9: 2400000 | F9: 27910570560 | H9: -21439470665 | J9: =F9+H9 -> 6471099895 | L9: 2400000 | N9: 27910570560 | P9: -21259186297 | R9: =N9+P9 -> 6651384263
B10: پالایش نفت تهران | D10: 50000000 | F10: 256997930000 | H10: -153404941940 | J10: =F10+H10 -> 103592988060 | L10: 50000000 | N10: 256997930000 | P10: -153404941940 | R10: =N10+P10 -> 103592988060
B11: ملی‌ صنایع‌ مس‌ ایران‌ | D11: 159500000 | F11: 3492954124550 | H11: -2451757801760 | J11: =F11+H11 -> 1041196322790 | L11: 159500000 | N11: 3492954124550 | P11: -2382338592560 | R11: =N11+P11 -> 1110615531990
B12: گروه توسعه مالی فیروزه | D12: 1101 | F12: 3726480 | H12: -3063875 | J12: =F12+H12 -> 662605 | L12: 1101 | N12: 3726480 | P12: -3063875 | R12: =N12+P12 -> 662605
B13: ح . معدنی و صنعتی گل گهر | D13: 111 | F13: 111023 | H13: -80293 | J13: =F13+H13 -> 30730 | L13: 111 | N13: 111023 | P13: -148185 | R13: =N13+P13 -> -37162
B14: سرمایه‌گذاری‌غدیر(هلدینگ‌ | D14: 44000000 | F14: 656207996400 | H14: -441084027586 | J14: =F14+H14 -> 215123968814 | L14: 44000000 | N14: 656207996400 | P14: -602784346786 | R14: =N14+P14 -> 53423649614
B15: نشاسته و گلوکز آردینه | D15: 500000 | F15: 13271611250 | H15: -13803569294 | J15: =F15+H15 -> -531958044 | L15: 500000 | N15: 13271611250 | P15: -13803569294 | R15: =N15+P15 -> -531958044
B16: معدنی‌وصنعتی‌چادرملو | D16: 1092 | F16: 2600541 | H16: -2133527 | J16: =F16+H16 -> 467014 | L16: 1092 | N16: 2600541 | P16: -2298833 | R16: =N16+P16 -> 301708
B17: پتروشیمی پردیس | D17: 50600000 | F17: 648698497040 | H17: -457996487286 | J17: =F17+H17 -> 190702009754 | L17: 50600000 | N17: 648698497040 | P17: -654321889584 | R17: =N17+P17 -> -5623392544
B18: بین المللی توسعه ص. معادن غدیر | D18: 1000 | F18: 3313189 | H18: -2732711 | J18: =F18+H18 -> 580478 | L18: 1000 | N18: 3313189 | P18: -2745611 | R18: =N18+P18 -> 567578
B19: تایدواترخاورمیانه | D19: 25800000 | F19: 204036511020 | H19: -157673885992 | J19: =F19+H19 -> 46362625028 | L19: 25800000 | N19: 204036511020 | P19: -157673885992 | R19: =N19+P19 -> 46362625028
B20: پتروشیمی خراسان | D20: 335000 | F20: 17411659371 | H20: -12608784852 | J20: =F20+H20 -> 4802874519 | L20: 335000 | N20: 17411659371 | P20: -11886997691 | R20: =N20+P20 -> 5524661680
... B37: سرمایه گذاری سبحان | D37: 89880000 | F37: 169897858578 | H37: -112179179693 | J37: =F37+H37 -> 57718678885 | L37: 89880000 | N37: 169897858578 | P37: -140555918690 | R37: =N37+P37 -> 29341939888
B38: نقل به صفحه بعد | D38: =SUM(D7:D37) -> 854185676 | F38: =SUM(F7:F37) -> 8461099526444 | H38: =SUM(H7:H37) -> -5742531486302 | J38: =SUM(J7:J37) -> 2718568040142 | L38: =SUM(L7:L37) -> 854185676 | N38: =SUM(N7:N37) -> 8461099526444 | P38: =SUM(P7:P37) -> -6709728261725 | R38: =SUM(R7:R37) -> 1751371264719
B40: 2-1-2-درآمد ناشی از تغییر قیمت اوراق بهادار | Z40: 1404/02/31
D41: =D5 -> طی خرداد ماه | L41: =L5 -> از ابتدای سال مالی تا پایان خرداد ماه | Z41: 1404/03/31
B42: شرح | D42: تعداد | F42: خالص ارزش فروش | H42: ارزش دفتری | J42: سود و زیان ناشی از تغییر قیمت | L42: تعداد | N42: خالص ارزش فروش | P42: ارزش دفتری | R42: سود و زیان ناشی از تغییر قیمت | Z42: برای ماه منتهی به 1404/03/31
B43: نقل از صفحه قبل | D43: =D38 -> 854185676 | F43: =F38 -> 8461099526444 | H43: =H38 -> -5742531486302 | J43: =J38 -> 2718568040142 | L43: =L38 -> 854185676 | N43: =N38 -> 8461099526444 | P43: =P38 -> -6709728261725 | R43: =R38 -> 1751371264719
B44: بانک‌اقتصادنوین‌ | D44: 60000000 | F44: 214151711400 | H44: -130938193105 | J44: =H44+F44 -> 83213518295 | L44: 60000000 | N44: 214151711400 | P44: -123916890585 | R44: =N44+P44 -> 90234820815
B45: پتروشیمی پارس | D45: 1147 | F45: 3109381 | H45: -1903173 | J45: =H45+F45 -> 1206208 | L45: 1147 | N45: 3109381 | P45: -2718819 | R45: =N45+P45 -> 390562
B46: توسعه‌معادن‌وفلزات‌ | D46: 388445097 | F46: 858380261323 | H46: -887876140140 | J46: =H46+F46 -> -29495878817 | L46: 388445097 | N46: 858380261323 | P46: -887837977004 | R46: =N46+P46 -> -29457715681
B47: گروه س توسعه صنعتی ایران | D47: 60000000 | F47: 121930137600 | H47: -88173112200 | J47: =H47+F47 -> 33757025400 | L47: 60000000 | N47: 121930137600 | P47: -86625171000 | R47: =N47+P47 -> 35304966600
B48: فروشگاههای زنجیره ای افق کوروش | D48: 2000000 | F48: 120560805000 | H48: -68923074200 | J48: =H48+F48 -> 51637730800 | L48: 2000000 | N48: 120560805000 | P48: -64477704600 | R48: =N48+P48 -> 56083100400
B49: بانک پاسارگاد | D49: 1000 | F49: 10061617 | H49: -5844470 | J49: =H49+F49 -> 4217147 | L49: 1000 | N49: 10061617 | P49: -5586480 | R49: =N49+P49 -> 4475137
B50: سایپا | D50: 668000000 | F50: 377816725200 | H50: -372741384113 | J50: =H50+F50 -> 5075341087 | L50: 668000000 | N50: 377816725200 | P50: -374527470113 | R50: =N50+P50 -> 3289255087
B51: کشتیرانی جمهوری اسلامی ایران | D51: 18000000 | F51: 82392147180 | H51: -71889961500 | J51: =H51+F51 -> 10502185680 | L51: 18000000 | N51: 82392147180 | P51: -102699945000 | R51: =N51+P51 -> -20307797820
B52: پتروشیمی نوری | D52: 5000000 | F52: 203688224250 | H52: -250156879981 | J52: =H52+F52 -> -46468655731 | L52: 5000000 | N52: 203688224250 | P52: -277305387181 | R52: =N52+P52 -> -73617162931
B53: پتروشیمی جم | D53: 100000 | F53: 3894659750 | H53: -3042299820 | J53: =H53+F53 -> 852359930 | L53: 100000 | N53: 3894659750 | P53: -4346142600 | R53: =N53+P53 -> -451482850
B54: مخابرات ایران | D54: 1000 | F54: 661844 | H54: -444536 | J54: =H54+F54 -> 217308 | L54: 1000 | N54: 661844 | P54: -419730 | R54: =N54+P54 -> 242114
B55: سرمایه‌گذاری‌صندوق‌بازنشستگی‌ | D55: 1000000 | F55: 16868590000 | H55: -9773859502 | J55: =H55+F55 -> 7094730498 | L55: 1000000 | N55: 16868590000 | P55: -16858667292 | R55: =N55+P55 -> 9922708
... B67: سرمایه گذاری تامین اجتماعی | D67: 660800000 | F67: 1343512940784 | H67: -1235195533505 | J67: =H67+F67 -> 108317407279 | L67: 660800000 | N67: 1343512940784 | P67: -1246031121905 | R67: =N67+P67 -> 97481818879
B68: جمع | D68: =SUM(D43:D67) -> 5756187350 | F68: =SUM(F43:F67) -> 17770071127248 | H68: =SUM(H43:H67) -> -13491690287002 | J68: =SUM(J43:J67) -> 4278380840246 | L68: =SUM(L43:L67) -> 5756187350 | N68: =SUM(N43:N67) -> 17770071127248 | P68: =SUM(P43:P67) -> -14528646362886 | R68: =SUM(R43:R67) -> 3241424764362
...

Sheet درآمد ناشی ازفروش
B1: ='سود اوراق بهادار و سپرده بانکی'!B1:U1 -> صندوق سرمایه گذاری شاخص سی شرکت بزرگ فیروزه
B2: صورت وضعیت درآمدها
B3: =' سهام'!B3:Z3 -> برای ماه منتهی به 1405/03/31
B4: 3-1-2-سود(زیان) حاصل از فروش اوراق بهادار | AC4: 1404/04/31
D5: =' سهام'!AC7 -> طی خرداد ماه | L5: =' سهام'!AC8 -> از ابتدای سال مالی تا پایان خرداد ماه | AC5: 1404/05/31
B6: شرح | D6: تعداد | F6: خالص بهای فروش | H6: ارزش دفتری | J6: سود و زیان ناشی از فروش | L6: تعداد | N6: خالص ارزش فروش | P6: ارزش دفتری | R6: سود و زیان ناشی از فروش | Z6: برای ماه منتهی به 1404/05/31
B7: سرمایه‌گذاری‌صندوق‌بازنشستگی‌ | D7: 5800000 | F7: 90959387096 | H7: -97780270338 | J7: -6820883242 | L7: 13000000 | N7: 205343491137 | P7: -219162674908 | R7: -13819183771
B8: سرمایه گذاری خوارزمی | D8: 14493 | F8: 63686737 | H8: -56328055 | J8: 7358682 | L8: 14493 | N8: 63686737 | P8: -56328055 | R8: 7358682
B9: ح . سرمایه گذاری صدرتامین | D9: 88888 | F9: 833094747 | H9: -787369396 | J9: 45725351 | L9: 88889 | N9: 833094748 | P9: -787378253 | R9: 45716495
B10: بیمه اتکایی ایران معین | D10: 232900 | F10: 462048552 | H10: -459195070 | J10: 2853482 | L10: 232900 | N10: 462048552 | P10: -459195070 | R10: 2853482
B11: پالایش نفت اصفهان | D11: 60440 | F11: 319238572 | H11: -309786116 | J11: 9452456 | L11: 60440 | N11: 319238572 | P11: -309786116 | R11: 9452456
B12: پالایش نفت تهران | D12: 34661723 | F12: 174599834043 | H12: -106345592188 | J12: 68254241855 | L12: 34661723 | N12: 174599834043 | P12: -106345592188 | R12: 68254241855
B13: س. و توسعه صنایع لاستیک | D13: 562500 | F13: 4920043726 | H13: -4632660562 | J13: 287383164 | L13: 562500 | N13: 4920043726 | P13: -4632660562 | R13: 287383164
B14: کشت وصنعت و دامپروری پگاه فارس | D14: 360000 | F14: 5965379884 | H14: -3865090104 | J14: 2100289780 | L14: 360000 | N14: 5965379884 | P14: -3865090104 | R14: 2100289780
B15: سرمایه‌ گذاری‌ آتیه‌ دماوند | D15: 14382130 | F15: 82724152535 | H15: -62264181569 | J15: 20459970966 | L15: 14382130 | N15: 82724152535 | P15: -62264181569 | R15: 20459970966
B16: گروه صنعتی درپاد تبریز | D16: 375000 | F16: 3727193211 | H16: -3657755287 | J16: 69437924 | L16: 375000 | N16: 3727193211 | P16: -3657755287 | R16: 69437924
B17: سرمایه گذاری سبحان | D17: 2520000 | F17: 4126799095 | H17: -3940820149 | J17: 185978946 | L17: 6120000 | N17: 9464629686 | P17: -9570563230 | R17: -105933544
B18: ح . توسعه‌معادن‌وفلزات‌ | D18: 14241 | F18: 15354995 | H18: -7519248 | J18: 7835747 | L18: 14241 | N18: 15354995 | P18: -7519248 | R18: 7835747
... B28: آلیاژ گستر هامون | D28: 837500 | F28: 3673905921 | H28: -3451251497 | J28: 222654424 | L28: 837500 | N28: 3673905921 | P28: -3451251497 | R28: 222654424
B29: پتروشیمی خراسان | D29: 212 | F29: 8221434 | H29: -7522518 | J29: 698916 | L29: 212 | N29: 8221434 | P29: -7522518 | R29: 698916 | Z29: طی مرداد ماه
B30: توسعه‌معادن‌وفلزات‌ | D30: 215748 | F30: 401650471 | H30: -355406595 | J30: 46243876 | L30: 215749 | N30: 401650472 | P30: -355408240 | R30: 46242232
B31: کارخانجات تولیدی نیروترانسفو | D31: 750000 | F31: 7379283443 | H31: -6556424025 | J31: 822859418 | L31: 750000 | N31: 7379283443 | P31: -6556424025 | R31: 822859418
B32: بانک تجارت | D32: 926440 | F32: 366083080 | H32: -345595979 | J32: 20487101 | L32: 926441 | N32: 366083081 | P32: -345596353 | R32: 20486728
B33: پتروشیمی‌شیراز | D33: 75243 | F33: 5172339142 | H33: -5302219064 | J33: -129879922 | L33: 75243 | N33: 5172339142 | P33: -5302219064 | R33: -129879922
B34: ح.سرمایه گذاری خوارزمی | D34: 190000000 | F34: 647162323018 | H34: -647162323018 | J34: 0 | L34: 190000000 | N34: 647162323018 | P34: -647162323018 | R34: 0
B35: پالایش نفت بندرعباس | D35: 8291414 | F35: 95046222129 | H35: -57097610280 | J35: 37948611849 | L35: 8291414 | N35: 95046222129 | P35: -57097610280 | R35: 37948611849
B36: تولیدی کوچین | D36: 1475169 | F36: 16827652536 | H36: -10269781860 | J36: 6557870676 | L36: 1475169 | N36: 16827652536 | P36: -10269781860 | R36: 6557870676
B37: سرمایه گذاری صدرتامین | D37: 0 | F37: 0 | H37: 0 | J37: 0 | L37: 1 | N37: 1 | P37: -9850 | R37: -9849 | Z37: از ابتدای سال مالی تا پایان مرداد ماه
B38: جمع | D38: =SUM(D7:D37) -> 421442027 | F38: =SUM(F7:F37) -> 1683436225448 | H38: =SUM(H7:H37) -> -1483119304503 | J38: =SUM(J7:J37) -> 200316920945 | L38: =SUM(L7:L37) -> 432242043 | N38: =SUM(N7:N37) -> 1803158160096 | P38: =SUM(P7:P37) -> -1610131512651 | R38: =SUM(R7:R37) -> 193026647445
B40: 3-1-2-سود(زیان) حاصل از فروش اوراق بهادار | Z40: 1404/02/31
D41: =D5 -> طی خرداد ماه | L41: =L5 -> از ابتدای سال مالی تا پایان خرداد ماه | Z41: 1404/03/31
B42: شرح | D42: تعداد | F42: خالص بهای فروش | H42: ارزش دفتری | J42: سود و زیان ناشی از فروش | L42: تعداد | N42: خالص ارزش فروش | P42: ارزش دفتری | R42: سود و زیان ناشی از فروش | X42: برای ماه منتهی به 1404/03/31
B43: نقل از صفحه قبل | D43: =D38 -> 421442027 | F43: =F38 -> 1683436225448 | H43: =H38 -> -1483119304503 | J43: =J38 -> 200316920945 | L43: =L38 -> 432242043 | N43: =N38 -> 1803158160096 | P43: =P38 -> -1610131512651 | R43: =R38 -> 193026647445
B44: جمع | D44: =SUM(D43:D43) -> 421442027 | F44: =SUM(F43:F43) -> 1683436225448 | H44: =SUM(H43:H43) -> -1483119304503 | J44: =SUM(J43:J43) -> 200316920945 | L44: =SUM(L43:L43) -> 432242043 | N44: =SUM(N43:N43) -> 1803158160096 | P44: =SUM(P43:P43) -> -1610131512651 | R44: =SUM(R43:R43) -> 193026647445

Sheet درآمد سرمایه گذاری در اوراق بها
A1: صندوق سرمایه‌گذاری صندوق شاخص سی شرکت بزرگ فیروزه
A2: صورت وضعیت درآمدها
A3: =' سهام'!AC6 -> برای ماه منتهی به 1405/03/31
B4: 2-2-درآمد حاصل از سرمایه گذاری در اوراق بهادار با درآمد ثابت:
C6: =' سهام'!AC7 -> طی خرداد ماه | M6: =' سهام'!AC8 -> از ابتدای سال مالی تا پایان خرداد ماه
C7: درآمد سود اوراق | E7: درآمد تغییر ارزش | G7: درآمد فروش | I7: جمع | M7: درآمد سود اوراق | O7: درآمد تغییر ارزش | Q7: درآمد فروش | R7: جمع
C9: یادداشت 2-2-1 | E9: یادداشت 2-1-2 | G9: یادداشت 3-1-2 | I9: مبلغ | K9: درصد از کل دارائیها | M9: یادداشت 2-2-1 | O9: یادداشت 2-1-2 | Q9: یادداشت 3-1-2 | R9: مبلغ | S9: درصد از کل دارائیها
B10: - | C10: 0 | D10: 0 | E10: 0 | F10: 0 | G10: 0 | H10: 0 | I10: 0 | J10: 0 | K10: 0 | L10: 0 | M10: 0 | N10: 0 | O10: 0 | P10: 875280 | Q10: 0 | R10: 0 | S10: =R10/S14 -> 0
B11: جمع | C11: =SUM(C10:C10) -> 0 | E11: =SUM(E10:E10) -> 0 | G11: =SUM(G10:G10) -> 0 | I11: =SUM(I10:I10) -> 0 | K11: =SUM(K10:K10) -> 0 | M11: =SUM(M10:M10) -> 0 | O11: =SUM(O10:O10) -> 0 | Q11: =SUM(Q10:Q10) -> 0 | R11: =SUM(R10:R10) -> 0 | S11: =SUM(S10:S10) -> 0
K14: 2807555599778 | S14: 2807555599778

Sheet سود اوراق بهادار و سپرده بانکی
B1: ='درآمد سود سهام'!B1:T1 -> صندوق سرمایه گذاری شاخص سی شرکت بزرگ فیروزه
B2: صورت وضعیت درآمدها
B3: =' سهام'!AC6 -> برای ماه منتهی به 1405/03/31
B4: 1-2-2-سود اوراق بهادار با درآمد ثابت و سپرده بانکی | AC4: 1404/06/31
G5: ابتدای دوره | K5: =' سهام'!AC7 -> طی خرداد ماه | Q5: =' سهام'!AC8 -> از ابتدای سال مالی تا پایان خرداد ماه | AC5: 1404/07/30
B6: شرح | C6: تاریخ دریافت سود | D6: تاریخ سررسید | E6: نرخ سود علی الحساب | G6: درآمد سود | I6: هزینه تنزیل | K6: درآمد سود | M6: هزینه تنزیل | O6: خالص درآمد | Q6: درآمد سود | S6: هزینه تنزیل | U6: خالص درآمد | AC6: برای ماه منتهی به 1404/07/30
B7: سپرده کوتاه مدت بانک خاورمیانه مهستان | H7: 0 | J7: 176683 | K7: 205502 | M7: 0 | O7: 205502 | Q7: 627768 | S7: 0 | U7: 627768 | AC7: طی مهر ماه
B8: سپرده کوتاه مدت بانک گردشگری سعادت آباد | K8: 10688581041 | M8: 0 | O8: 10688581041 | Q8: 20978574246 | S8: 0 | U8: 20978574246
B9: سپرده کوتاه مدت بانک صادرات بلوار میرداماد | K9: 0 | M9: 0 | O9: 0 | Q9: 4055 | S9: 0 | U9: 4055
B10: سپرده کوتاه مدت بانک خاورمیانه نیاوران | H10: 0 | J10: 2202729735 | K10: 35080 | M10: 0 | O10: 35080 | Q10: 3213304 | S10: 0 | U10: 3213304 | AC10: از ابتدای سال مالی تا پایان مهر ماه
K11: =SUM(K7:K10) -> 10688821623 | O11: =SUM(O7:O10) -> 10688821623 | Q11: =SUM(Q7:Q10) -> 20982419373 | U11: =SUM(U7:U10) -> 20982419373
R58: 1783
R75: 2083

Sheet درآمد سپرده بانکی
B1: ='سود اوراق بهادار و سپرده بانکی'!B1:U1 -> صندوق سرمایه گذاری شاخص سی شرکت بزرگ فیروزه
B2: صورت وضعیت درآمدها
B3: =' سهام'!B3:Z3 -> برای ماه منتهی به 1405/03/31
B4: 3-2-درآمد حاصل از سرمایه گذاری در سپرده بانکی و گواهی سپرده:
B6: نام سپرده بانکی | F6: =' سهام'!AC7 -> طی خرداد ماه | J6: =' سهام'!AC8 -> از ابتدای سال مالی تا پایان خرداد ماه
B7: نام سپرده | F7: سود سپرده بانکی و گواهی سپرده | H7: درصد سود به میانگین سپرده | J7: سود سپرده بانکی و گواهی سپرده | L7: درصد سود به میانگین سپرده
F8: یادداشت 2-2-1 | J8: یادداشت 2-2-1
B9: سپرده کوتاه مدت بانک خاورمیانه مهستان | F9: 205502 | H9: =F9/L18 -> 9.3557877e-07 | J9: 627768 | L9: =J9/L18 -> 2.8580083e-06
B10: سپرده کوتاه مدت بانک گردشگری سعادت آباد | F10: 10688581041 | H10: =F10/L18 -> 0.048661373 | J10: 20978574246 | L10: =J10/L18 -> 0.095508115
B11: سپرده کوتاه مدت بانک صادرات بلوار میرداماد | F11: 0 | H11: =F11/L18 -> 0 | J11: 4055 | L11: =J11/L18 -> 1.8460997e-08
B12: سپرده کوتاه مدت بانک خاورمیانه نیاوران | F12: 35080 | H12: =F12/L18 -> 1.5970698e-07 | J12: 3213304 | L12: =J12/L18 -> 1.462905e-05
B13: جمع | F13: =SUM(F9:F12) -> 10688821623 | H13: =SUM(H9:H12) -> 0.048662468 | J13: =SUM(J9:J12) -> 20982419373 | L13: =SUM(L9:L12) -> 0.095525621
J18: 6809220361173 | L18: =J18/31 -> 2.1965227e+11
R58: 1783
R75: 2083

Sheet Sheet1

Sheet سایر درآمدها
B1: ='درآمد سپرده بانکی'!B1:M1 -> صندوق سرمایه گذاری شاخص سی شرکت بزرگ فیروزه
B2: صورت وضعیت درآمدها
B3: =' سهام'!AC6 -> برای ماه منتهی به 1405/03/31
B4: 4-2-سایر درآمدها:
D5: =' سهام'!AC7 -> طی خرداد ماه | F5: =' سهام'!AC8 -> از ابتدای سال مالی تا پایان خرداد ماه
B6: سایر درآمدها | D6: 2382248 | F6: 2394375
B7: تعدیل کارمزد کارگزار | D7: 9546297921 | F7: 9546297921
D8: =SUM(D6:D7) -> 9548680169 | F8: =SUM(F6:F7) -> 9548692296
R57: 1783
R74: 2083
